Workbook

Sheet 样例及说明
A1: 1、根据控制要求与措施逐条落实责任部门、责任岗位、岗位职责，（对应形成岗位清单）
A2: 2、根据控制措施细化线上、系统已建和系统未建，对于线下的应明确线下监督措施及频率，对于线上的应明确控制系统名称、功能模块名称、稽核规则，其中系统已有的补充操作路径及优化建议，系统未建的补充建设需求（形成系统规则清单）
A3: 3、将控制措施按照不相容岗位、分级授权等分类细化补充至具体分类中，其中不相容控制的需要明确不相容岗位名称及职责（形成不相容岗位清单），涉及多个不相容岗位的逐条列示；分级授权的需要明确分级授权流程；业务真实性校验、预算、合同、收支等控制的，明确控制措施。该关键节点的控制措施合计应与《典设》矩阵打勾保持一致。
A4: 4、H列的内控载体与该条控制措施一一对应，并与AT-AV列业务自评价的评价资料保持一致。
A5: 5、Z、AA列对具体制度进行完善补充。
A6: 6、AT-AV列需要明确业务自评价的样本抽取比例、评价资料和评价要点，其中评价资料与H列内控载体需保持一致。
A7: 附件2（样表） | D7: 营销 | E7: 83 | F7: 财务 | G7: 20
A8: 风控矩阵适用性验证模板
A9: 业务条线 | B9: 业务领域 | C9: 控制目标 | D9: 业务流程步骤 | E9: 经营风险 | F9: 对应屡查屡犯问题清单 | G9: 关键控制点 | H9: 控制要求与措施 | I9: 责任层级和主体 | R9: 控制方式 | S9: 线上控制系统 | Y9: 线下人工控制 | Z9: 制度修订建议 | AB9: 不相容岗位 | AD9: 分级授权流程 | AF9: 业务真实性校验措施 | AH9: 预算管控措施 | AJ9: 合同控制措施 | AL9: 收付控制措施 | AN9: 会计监督 | AP9: 财产保护 | AR9: 分析与评价 | AT9: 业务自评价及集团监督评价 | AW9: 备注 （对矩阵内容的修改意见）
I10: 省公司责任部门 | J10: 省公司责任处室及岗位 | K10: 省公司岗位职责 | L10: 市公司责任部门 | M10: 市公司责任岗位 | N10: 市公司岗位职责 | O10: 县公司责任部门 | P10: 县公司责任岗位 | Q10: 县公司岗位职责 | R10: 措施分类（系统已有、系统待建或线下） | S10: 控制系统名称 | T10: 模块名称 | U10: 稽核规则 | V10: 如已建，操作路径 | W10: 如已建，有何优化建议 | X10: 如未建，有何建设需求 | Y10: 线下监督措施-频次、措施 | Z10: 制度名称 | AA10: 制度修订建议 | AB10: 是否涉及 | AC10: 不相容岗位名称及职责 | AD10: 是否涉及 | AE10: 分级授权流程 | AF10: 是否涉及 | AG10: 业务真实性校验措施 | AH10: 是否涉及 | AI10: 预算管控措施 | AJ10: 是否涉及 | AK10: 合同控制措施 | AL10: 是否涉及 | AM10: 收付控制措施 | AN10: 是否涉及 | AO10: 会计监督措施 | AP10: 是否涉及 | AQ10: 财产保护措施 | AR10: 是否涉及 | AS10: 分析与评价措施 | AT10: 样本抽取比例 | AU10: 评价资料 | AV10: 评价要点
A11: 营销售电 | B11: 七、营销退费管理 | C11: 资金资产安全 | D11: 退费审批 | E11: 退费未经有效审核审批，导致公司资金流失、财务数据失真风险。 | F11: 20.营销系统权限管控不严。 | G11: 29.退费审批权限及流程设置 | H11: 控制要求：退费资金分级授权科学、合理。 控制措施： 1.财务部建立电费退费资金分级授权审批机制，确保系统流程轨迹可视、授权管理科学；（系统-已有） 内控载体： 1.资金分级授权。 | I11: 财务部 | J11: 稽核处-风险内控与稽核评价管理；电价处-输配与销售电价管理 | K11: 1.风险内控与稽核评价管理负责内控体系建设与运行；组织开展内控评价及报告编制工作；负责运用数智风控系统开展风险穿透管控。 2.输配与销售电价管理负责销售电价及售电收入、上网电价及价外资金、政策性收费；负责分用户类别和电能类型对售电业务进行记录与反映；负责售电业务报表编制，负责配合完成成本监审相关工作。 | L11: 财务部 | M11: 风险内控管理；价格管理 | N11: 1.风险内控管理负责内控体系建设与运行；负责运用数智风控系统开展风险穿透管控。 2.价格管理负责销售电价及售电收入、上网电价及价外资金、政策性收费；负责分用户类别和电能类型对售电业务进行记录与反映；负责售电业务报表编制。 | O11: 财务部 | P11: 价格管理 | Q11: 价格管理负责销售电价及售电收入、上网电价及购电费、价外资金、政策性收费等管理。 | R11: 系统已有 | S11: 智慧财务 | T11: 营销退费 | U11: 按照付款信息完整性审核规则，用于检查电费退费付款信息是否完整。 | V11: 购售电结算管理-营销退费 | W11: 检查付款申请单中资金支付流程是否满足资金分级授权，若否，则为疑点。 | X11: - | Y11: - | AB11: 否 | AD11: 是 | AE11: 5万元以下，执行归口管理负责人、业务经办负责人审批；5万元及以上，执行分管业务领导、财务部负责人、归口管理负责人、业务经办负责人审批。 | AF11: 否 | AH11: 否 | AJ11: 否 | AL11: 否 | AN11: 否 | AP11: 否 | AR11: 否 | AU11: 资金分级授权 | AV11: 检查是否建立资金分级授权标准，标准是否统一，授权额度是否设置合理。
H12: 控制要求：退费审批流程设置应科学、合理，与资金分级授权匹配。 控制措施： 2.营销部按照资金分级授权建立内部退费审批流程（系统-已有），对权限配置与岗位权限一致性进行校核。（系统-待建） 内控载体： 1.系统退费审批单； 2.资金分级授权； 3.岗位权限配置； 4.退费影像。 | I12: 营销部 | J12: 营业处-电费电价管理 | K12: 负责组织开展结算依据核对，负责采抄一体、智能核算、自动发行、智能催费、自动对账、智能交费等技术研究与推广应用，负责多元交费渠道的建设运营；负责管理本省集团户、电费充值卡等业务；负责电费回收管理，建立本省电费回收风险防控体系，指导、监督下属各单位开展电费回收及电费风险防控工作，组织本省重大电费结算问题与欠费风险处置；负责第三方代收机构和支付平台渠道管理。 | L12: 营销部 | M12: 电费及电价管理 | N12: 负责电费回收管理；电费账务管理；处理客户投诉及意见；协助省公司营销部开展售电侧市场机制适应性研究、宣贯培训及咨询答复等。 | O12: 营销部 | P12: 电价及电费管理 | Q12: 负责电费回收管理；电费账务管理；处理客户投诉及意见等。 | R12: 系统待建 | S12: 营销2.0系统 | T12: 计费结算-收费管理-退费管理 | U12: 1.电费频繁性退费（规则描述:电费频繁退费，每月筛查营销业务所有用电客户发生2次及以上电费退费情况的用电客户，并进行稽查监控。 取数时间范围：上一自然月，即上月1日0点（含0点）至本月1日0点（不含0点）。）； 2）已销户未退费（规则描述:已销户未退费，每月筛查营销业务中销户归档日期已超3个月（销户流程归档时间在山东营销2.0系统上线时间之后，即2022年11月15日后）且账户余额大于0元的用电客户，并进行稽查监控。） | V12: - | W12: - | X12: 建议与人资2.0系统进行一致性校核。 | Z12: 《国家电网有限公司电费业务管理办法（征求意见稿）》 | AA12: 建议明确分级审批要求“退费申请、审核审批履行不相容控制，确保流程权限设置科学、合规” | AB12: 是 | AC12: 营业厅综合柜收-退费申请；电费管理岗-退费审核；供电所长/营业班长、电费专工/电费管理班长、营销部分管主任、公司分管领导-退费审批 | AD12: 是 | AE12: 1.500元以下，执行电费账务人员、供电所长/营业班长两级审批； 2.500元及以上、5000元以下，执行电费账务人员、供电所长/营业班长、电费专工/电费管控班三级审批； 3.5000元及以上、5万元以下，执行电费账务人员、供电所长/营业班长、电费专工/电费管控班、营销部分管主任四级审批； 4.5万元及以上，执行电费账务人员、供电所长/营业班长、电费专工/电费管控班、营销部分管主任、公司分管领导五级审批 | AF12: 否 | AH12: 否 | AJ12: 否 | AL12: 是 | AM12: 按照资金分级授权建立内部退费审批流程，对权限配置与岗位权限一致性进行校核 | AN12: 否 | AP12: 否 | AR12: 否 | AT12: 5万元及以上抽取10%，5万元以下抽取1% | AU12: 1.系统退费审批单； 2.资金分级授权； 3.岗位权限配置； 4.退费影像 | AV12: 1.检查退费分级授权是否符合资金分级授权标准；2.检查退费分级授权流程设置是否符合人资部岗位配置。

Sheet 营销售电（省公司审定0818）
A1: 风控矩阵-营销售电业务
A2: 业务条线 | B2: 业务领域 | C2: 控制目标 | D2: 业务流程步骤 | E2: 经营风险 | F2: 典型问题 | G2: 关键控制点 | H2: 控制要求 | I2: 控制措施编号 | J2: 控制措施 | K2: 控制措施分类 | T2: 控制方式 | U2: 控制系统 | V2: 控制载体 | W2: 责任主体 | X2: 业务自评价 | AA2: 集团监督评价 | AD2: 数字化监督场景 | AH2: 现有制度及文件落实情况 | AK2: 总部审核部门 | AL2: 层级 | AM2: 专业 | AN2: 是否适用
K3: 不相容岗位 | L3: 分级授权 | M3: 业务真实性控制 | N3: 预算管控 | O3: 合同控制 | P3: 收付控制 | Q3: 会计监督 | R3: 财产保护 | S3: 分析与评价 | X3: 评价频率 | Y3: 评价范围 | Z3: 评价结论 | AA3: 评价频率 | AB3: 评价范围 | AC3: 评价结论 | AD3: 数字化监督场景 | AE3: 监督频率 | AF3: 监督范围 | AG3: 评价结论 | AH3: 是否已要求 | AI3: 是否满足要求 | AJ3: 对应制度及文件名称
A4: 营销售电业务 | B4: 一、客户信息与合同签订管理 | C4: 会计信息真实完整、资金资产安全 | D4: 业扩报装受理 | E4: 客户信息录入不准确，与现场不一致，引发虚假立户及电费收取不规范风险。 | F4: 19.两部制电价执行不正确：存在应执行未执行两部制电价、分户报装规避两部制电价、变更用电少收基本电费、需量基本电费计收不准确等问题。 | G4: 1.系统客户信息创建 | H4: 系统客户信息应与客户报装资料、现场用电情况一致。 | I4: 营销售电业务-1.系统客户信息创建-控制措施01 | J4: 营销部门业务受理人员根据客户报装资料做好系统客户信息的创建，并对报装资料完整性、有效性负责。 | M4: √ | T4: 线下管控 | V4: 1.系统业扩工单； 2.客户报装原始资料； 3.系统客户档案 | W4: 各级单位供电公司-营销部门-业务受理人员 | X4: 每年 | Y4: 抽查 | AA4: 年度 | AB4: 抽查 | AH4: 是 | AI4: 是 | AJ4: 《国家电网有限公司业扩报装管理规则（征求意见稿）》第三章 业务受理 | AK4: 国网营销部 | AL4: 地市 | AM4: 业扩
I5: 营销售电业务-1.系统客户信息创建-控制措施02 | J5: 营销部门应在客户新装、增容、变更用电等申请受理时，建立稽查主题前置业务环节等数智审核功能，提高客户基础信息创建质量。 | M5: √ | T5: 系统待建 | U5: 营销2.0系统 | V5: 1.系统客户档案； 2.客户报装原始资料； 3.数智审核相关功能资料 | W5: 各省（自治区、直辖市）电力公司供服中心-营销部门-业扩报装管理人员 | X5: 每年 | Y5: 抽查 | AA5: 年度 | AB5: 抽查 | AH5: 是 | AI5: 是 | AJ5: 《国家电网有限公司业扩报装管理规则（征求意见稿）》第三章 业务受理 | AK5: 国网营销部 | AL5: 供服 | AM5: 业扩
I6: 营销售电业务-1.系统客户信息创建-控制措施03 | J6: 营销部门业务办理人员结合现场勘查情况对客户关键信息真实性、准确性复核，业务受理与业务办理执行不相容控制。 | K6: √ | M6: √ | T6: 线下管控 | V6: 1.系统业扩工单； 2.客户报装原始资料； 3.系统客户档案； 4.系统授权审批记录 | W6: 各级单位供电公司-营销部门-业务办理人员 | X6: 每年 | Y6: 抽查 | AA6: 年度 | AB6: 抽查 | AH6: 是 | AI6: 是 | AJ6: 《国家电网有限公司业扩报装管理规则（征求意见稿）》第三章 业务受理 | AK6: 国网营销部 | AL6: 地市 | AM6: 业扩
I7: 营销售电业务-1.系统客户信息创建-控制措施04 | J7: 营销部门对分户报装规避基本电费、违规改变用电性质等开展数字化在线监督与现场检查。 | M7: √ | S7: √ | T7: 系统已建 | U7: 营销2.0系统 | V7: 数字化监督相关资料或稽查工单及处理情况 | W7: 各级单位供电公司-营销部门-业务审核人员 | X7: 每半年 | Y7: 抽查 | AA7: 年度 | AB7: 抽查 | AD7: 分户报装规避基本电费监督——对一址多户开展在线监督 | AE7: 每季度 | AF7: 全量 | AH7: 是 | AI7: 是 | AJ7: 《国家电网有限公司业扩报装管理规则（征求意见稿）》第三章 业务受理 | AK7: 国网营销部 | AL7: 地市 | AM7: 业扩
C8: 会计信息真实完整、资金资产安全 | D8: 方案答复与工程实施 | E8: 客户用电容量核定不准确、录入错误，导致基本电费执行不准确、电费少收。 | F8: 19.两部制电价执行不正确：存在应执行未执行两部制电价、分户报装规避两部制电价、变更用电少收基本电费、需量基本电费计收不准确等问题。 | G8: 2.客户用电容量的确定 | H8: 系统容量与现场用电情况保持一致。 | I8: 营销售电业务-2.客户用电容量的确定创建-控制措施01 | J8: 营销部门现场勘查人员应准确核定客户用电容量与负荷性质，确保计量、计费方案、供电方式等准确。 | M8: √ | T8: 线下管控 | V8: 1.系统业扩工单（现场勘查验收单）； 2.系统客户档案（供电方案等） | W8: 各级单位供电公司-营销部门-现场勘查人员 | X8: 每年 | Y8: 抽查 | AA8: 年度 | AB8: 抽查 | AH8: 是 | AI8: 是 | AJ8: 《国家电网有限公司业扩报装管理规则（征求意见稿）》第四章 供电方案编制及答复 | AK8: 国网营销部 | AL8: 地市 | AM8: 业扩
I9: 营销售电业务-2.客户用电容量的确定创建-控制措施02 | J9: 对于加装变压器的高压客户，需取得变压器出厂合格证明及型式试验报告等容量信息佐证材料并上传系统，确保系统录入容量与现场用电情况一致。 | M9: √ | T9: 系统已建 | U9: 营销2.0系统 | V9: 1.系统业扩工单信息（现场勘查验收单）； 2.客户报装原始资料（含用电负荷清单、变压器出厂合格证明及型式试验报告等）； 3.系统客户档案 | W9: 各级单位供电公司-营销部门-业务办理人员 | X9: 每半年 | Y9: 抽查 | AA9: 年度 | AB9: 抽查 | AH9: 是 | AI9: 是 | AJ9: 《国家电网有限公司业扩报装管理规则（征求意见稿）》第四章 供电方案编制及答复 | AK9: 国网营销部 | AL9: 地市 | AM9: 业扩
I10: 营销售电业务-2.客户用电容量的确定创建-控制措施03 | J10: 营销部门对超容用电、基本电费异常、高可靠性供电费收取不规范开展数字化在线监督与现场检查。 | M10: √ | S10: √ | T10: 系统已建 | U10: 营销2.0系统 | V10: 数字化监督相关资料或稽查结果与处理情况 | W10: 各级单位供电公司-营销部门-业务审核人员 | X10: 每半年 | Y10: 抽查 | AA10: 年度 | AB10: 抽查 | AD10: 客户容量与电量联动监测——对超容用电、基本电费异常、高可靠性供电费收取不规范开展在线监督 | AE10: 每季度 | AF10: 全量 | AH10: 是 | AI10: 是 | AJ10: 《国家电网有限公司业扩报装管理规则（征求意见稿）》第四章 供电方案编制及答复 | AK10: 国网营销部 | AL10: 地市 | AM10: 业扩
A11: 营销售电业务 | B11: 一、客户信息与合同签订管理 | C11: 会计信息真实完整、资金资产安全 | D11: 客户信息变更 | E11: 客户信息变更不合规，导致电费计收不准确，引发合规风险。 | F11: 19.两部制电价执行不正确：存在应执行未执行两部制电价、分户报装规避两部制电价、变更用电少收基本电费、需量基本电费计收不准确等问题。 | G11: 3.系统客户信息变更 | H11: 客户关键信息变更应结合业务工单联动调整，严禁无业务动因创建或修改客户信息行为。 | I11: 营销售电业务-3.系统客户信息变更-控制措施01 | J11: 营销部门对客户户名、电价、用电容量等关键信息的变更，应结合变更业务联动调整并经审批后实施。 | L11: √ | M11: √ | T11: 系统已建 | U11: 营销2.0系统 | V11: 1.系统变更工单； 2.客户变更原始资料； 3.系统客户档案； 4.系统授权审批记录 | W11: 各级单位供电公司-营销部门-业务审核及各级审批人员 | X11: 每年 | Y11: 抽查 | AA11: 年度 | AB11: 抽查 | AH11: 是 | AI11: 是 | AJ11: 《变更用电业务规则（试行）》 | AK11: 国网营销部 | AL11: 地市 | AM11: 业扩
I12: 营销售电业务-3.系统客户信息变更-控制措施02 | J12: 营销部门对影响价费关键信息的变更业务开展现场查验，确保用电信息与现场一致。 | M12: √ | T12: 线下管控 | V12: 现场核查相关记录 | W12: 各级单位供电公司-营销部门-现场勘查人员 | X12: 每年 | Y12: 抽查 | AA12: 年度 | AB12: 抽查 | AH12: 是 | AI12: 是 | AJ12: 《变更用电业务规则（试行）》 | AK12: 国网营销部 | AL12: 地市 | AM12: 业扩
C13: 会计信息真实完整、资金资产安全 | D13: 合同签订 | E13: 合同签订未使用公司统一且生效文本，导致电费计收合法权益无法得到保障。 | G13: 4.供用电合同签订 | H13: 供用电合同签订应使用公司统一且生效的文本。 | I13: 营销售电业务-4.供用电合同签订-控制措施01 | J13: 国网营销部统一管理合同文本，并明确执行要求、生效时间，及客户业务变更时不需重签合同的业务类型。各省（自治区、直辖市）电力公司参考统一文本拟定本单位合同文本、特别约定事项等，经法律合规部门审核后使用。 | O13: √ | T13: 系统已建 | U13: 营销2.0系统 | V13: 1.合同统一文本； 2.制度或通知 | W13: 国网营销部-合同管理人员；各省（自治区、直辖市）电力公司省公司-营销部门-合同管理人员 | X13: 每年 | Y13: 抽查 | AA13: 年度 | AB13: 抽查 | AH13: 是 | AI13: 是 | AJ13: 《国家电网有限公司电费业务管理办法（征求意见稿）》第四章 合同协议 《国网营销部关于印发变更用电业务规则》 《国家电网有限公司业扩报装管理规则（征求意见稿）》第六十三、六十四条 《国家电网有限公司合同管理办法》四十六条、六十四-六十六条 | AK13: 国网营销部 | AL13: 省公司 | AM13: 业扩
I14: 营销售电业务-4.供用电合同签订-控制措施02 | J14: 营销部门合同签订人员应严格使用本省统一且生效文本。 | O14: √ | T14: 系统已建 | U14: 营销2.0系统 | V14: 1.供用电合同； 2.合同统一文本 | W14: 各级单位供电公司-营销部门-合同签订人员 | X14: 每年 | Y14: 抽查 | AA14: 年度 | AB14: 抽查 | AH14: 是 | AI14: 是 | AJ14: 《国家电网有限公司电费业务管理办法（征求意见稿）》第四章 合同协议 《国家电网有限公司业扩报装管理规则（征求意见稿）》第六十三条 | AK14: 国网营销部 | AL14: 地市 | AM14: 业扩
I15: 营销售电业务-4.供用电合同签订-控制措施03 | J15: 营销部门合同审核人员对合同文本使用情况开展审核。 | M15: √ | T15: 线下管控 | V15: 1.供用电合同； 2.合同统一文本； 3.系统合同信息； 4.系统合同签订及审批记录 | W15: 各级单位供电公司-营销部门-合同审核人员 | X15: 每年 | Y15: 抽查 | AA15: 年度 | AB15: 抽查 | AH15: 是 | AI15: 是 | AJ15: 《国家电网有限公司电费业务管理办法（征求意见稿）》第四章 合同协议 《国家电网有限公司业扩报装管理规则（征求意见稿）》第六十四条 | AK15: 国网营销部 | AL15: 地市 | AM15: 业扩
C16: 会计信息真实完整、资金资产安全 | D16: 合同签订 | E16: 合同条款与客户报装信息、现场不一致，导致公司收支条款失效，合法权益无法得到保障。 | G16: 5.供用电合同审核 | H16: 合同关键信息与客户报装信息保持一致。 | I16: 营销售电业务-5.供用电合同审核-控制措施01 | J16: 营销部门合同签订人员要确保合同信息与业扩报装产生的客户信息保持一致，不得变更。 | M16: √ | O16: √ | T16: 线下管控 | V16: 1.供用电合同信息； 2.系统客户信息 | W16: 各级单位供电公司-营销部门-合同签订人员 | X16: 每年 | Y16: 抽查 | AA16: 年度 | AB16: 抽查 | AH16: 是 | AI16: 是 | AJ16: 《国家电网有限公司电费业务管理办法（征求意见稿）》第四章 合同协议第二十六条 | AK16: 国网营销部 | AL16: 地市 | AM16: 业扩
I17: 营销售电业务-5.供用电合同审核-控制措施02 | J17: 营销部门合同审核人员对合同信息与业扩报装产生的信息一致性进行复核。 | M17: √ | O17: √ | T17: 线下管控 | V17: 1.供用电合同信息； 2.系统客户信息； 3.合同审核记录 | W17: 各级单位供电公司-营销部门-合同审核人员 | X17: 每年 | Y17: 抽查 | AA17: 年度 | AB17: 抽查 | AH17: 是 | AI17: 是 | AJ17: 《国家电网有限公司电费业务管理办法（征求意见稿）》第四章 合同协议 | AK17: 国网营销部 | AL17: 地市 | AM17: 业扩
I18: 营销售电业务-5.供用电合同审核-控制措施03 | J18: 营销部门合同管理人员应落实合同签订一致性要求，加强系统上传合同与线下纸质合同一致性管控。 | O18: √ | T18: 线下管控 | U18: 营销2.0系统 | V18: 1.供用电合同（线下）； 2.系统合同信息 | W18: 各级单位供电公司-营销部门-合同管理人员 | X18: 每年 | Y18: 抽查 | AA18: 年度 | AB18: 抽查 | AH18: 是 | AI18: 是 | AJ18: 《国家电网有限公司电费业务管理办法（征求意见稿）》第四章 合同协议 《国家电网有限公司业扩报装管理规则（征求意见稿）》第六十五条 | AK18: 国网营销部 | AL18: 地市 | AM18: 业扩
I19: 营销售电业务-5.供用电合同审核-控制措施04 | J19: 营销部门对系统合同上传及生效情况开展稽查监督。 | S19: √ | T19: 系统已建 | U19: 营销2.0系统 | V19: 数字化监督相关资料或稽查工单及处理情况 | W19: 各级单位供电公司-营销部门-合同管理人员 | X19: 每 半年 | Y19: 抽查 | AA19: 年度 | AB19: 抽查 | AH19: 是 | AI19: 是 | AJ19: 《国家电网有限公司电费业务管理办法（征求意见稿）》第四章 合同协议 《国家电网有限公司业扩报装管理规则（征求意见稿）》第六十五条 | AK19: 国网营销部 | AL19: 地市 | AM19: 业扩
A20: 营销售电业务 | B20: 二、电价执行管理 | C20: 会计信息真实完整、资金资产安全 | D20: 电价码制定 | E20: 电价政策执行不到位，系统配置不准确，导致公司电费收入计量不准确、不合规。 | G20: 6.电价码制定与执行 | H20: 电价标准与政策匹配，电价码准确配置与执行 | I20: 营销售电业务-6.电价码制定与执行-控制措施01 | J20: 电价码管理实行“统一管理、分级维护”原则，按照统一标准规范执行。财务部门负责根据国家或省内价格政策，对照标准化电价码编码规则，解析形成每类客户电价执行标准，将政策解析与电价码关联结果推送营销。 | M20: √ | Q20: √ | T20: 系统已建 | U20: 智慧财务 | V20: 1.电价政策文件； 2.政策解析结果 | W20: 国网财务部-销售电价管理人员；各省（自治区、直辖市）电力公司省公司-财务部门-销售电价管理人员 | X20: 每年 | Y20: 抽查 | AA20: 年度 | AB20: 抽查 | AH20: 是 | AI20: 是 | AJ20: 《国网营销部国网财务部国网数字化部关于加快标准化电价码部署应用的通知》（营销营业〔2025〕83号） | AK20: 国网财务部 | AL20: 省公司 | AM20: 电价、财务
I21: 营销售电业务-6.电价码制定与执行-控制措施02 | J21: 营销部门基于电价标准及政策依据匹配形成电价码调整方案，审批后推送智慧财务，经财务部门审核（新增电价码需总部审批）后下发执行。电价码的维护申请、审核、审批、确认均执行线上流转。 | M21: √ | Q21: √ | T21: 系统已建 | U21: 营销2.0系统、智慧财务 | V21: 1.电价标准与电价码匹配记录； 2.电价码调整方案； 3.电价码审核审批记录 | W21: 国网财务部-销售电价管理人员；各省（自治区、直辖市）电力公司省公司-营销部门-电价管理人员；各省（自治区、直辖市）电力公司省公司-财务部门-销售电价管理人员 | X21: 每年 | Y21: 抽查 | AA21: 年度 | AB21: 抽查 | AH21: 是 | AI21: 是 | AJ21: 《国网营销部国网财务部国网数字化部关于加快标准化电价码部署应用的通知》（营销营业〔2025〕83号） | AK21: 国网营销部、国网财务部 | AL21: 省公司 | AM21: 电价
I22: 营销售电业务-6.电价码制定与执行-控制措施03 | J22: 营销部门将电价码部署系统并建立电价码与用户档案信息关联关系，确保电价码精准匹配到户。 | M22: √ | T22: 系统已建 | U22: 营销2.0系统 | V22: 1.电价码与用户档案信息关联关系； 2.电价码系统配置记录 | W22: 各省（自治区、直辖市）电力公司省公司-营销部门-电价管理人员 | X22: 每年 | Y22: 抽查 | AA22: 年度 | AB22: 抽查 | AH22: 是 | AI22: 是 | AJ22: 《国网营销部国网财务部国网数字化部关于加快标准化电价码部署应用的通知》（营销营业〔2025〕83号） | AK22: 国网营销部 | AL22: 省公司 | AM22: 电价
I23: 营销售电业务-6.电价码制定与执行-控制措施04 | J23: 营销部门协同财务部门对电价码配置与价码执行情况开展数字化校核及在线监控分析。 | S23: √ | T23: 系统待建 | U23: 营销2.0系统 | V23: 1.电价码执行情况记录； 2.电价码统计分析功能及优惠电价执行预警等功能相关记录； 3.标准化电价码智能校核规则库； 4.数字化监督相关资料或稽查工单及处理情况 | W23: 各省（自治区、直辖市）电力公司省公司-营销部门-电价管理人员；各省（自治区、直辖市）电力公司省公司-财务部门-销售电价管理人员 | X23: 每半年 | Y23: 抽查 | AA23: 年度 | AB23: 抽查 | AD23: 电价码执行监督——对电价码配置与执行情况开展在线监督 | AE23: 每季度 | AF23: 全量 | AH23: 是 | AI23: 是 | AJ23: 《国网营销部国网财务部国网数字化部关于加快标准化电价码部署应用的通知》（营销营业〔2025〕83号） | AK23: 国网营销部、国网财务部 | AL23: 省公司 | AM23: 电价
C24: 会计信息真实完整、资金资产安全 | D24: 电价执行 | E24: 电价执行与客户用电性质不匹配，造成公司或用户电费资金损失，收入不实 | F24: 19.两部制电价执行不正确：存在应执行未执行两部制电价、分户报装规避两部制电价、变更用电少收基本电费、需量基本电费计收不准确等问题。 | G24: 7.客户电价执行管控 | H24: 客户电价执行与用电性质、行业类别等精准匹配 | I24: 营销售电业务-7.客户电价执行管控-控制措施01 | J24: 营销部门业务受理人员应严格按照客户用电性质、行业类别等匹配执行标准电价码并准确录入系统，经审核后生效。 | M24: √ | T24: 系统已建 | U24: 营销2.0系统 | V24: 1.系统业务工单记录； 2.系统客户电价信息 | W24: 各级单位供电公司-营销部门-业务受理、业务审核人员 | X24: 每半年 | Y24: 抽查 | AA24: 年度 | AB24: 抽查 | AH24: 是 | AI24: 是 | AJ24: 《国家电网有限公司电费业务管理办法（征求意见稿）》第三章 电价执行 | AK24: 国网营销部 | AL24: 地市 | AM24: 业扩
I25: 营销售电业务-7.客户电价执行管控-控制措施02 | J25: 营销部门加强客户电价变更管理，对于电价政策变动导致的电价变更应结合电价码联动调整，对于客户用电性质改变导致的电价变更应严格执行与工单关联，其他类型电价变更严格执行授权审批后进行调整。 | M25: √ | T25: 系统已建 | U25: 营销2.0系统 | V25: 系统业务工单记录 | W25: 各级单位供电公司-营销部门-电价管理人员 | X25: 每半年 | Y25: 抽查 | AA25: 年度 | AB25: 抽查 | AH25: 是 | AI25: 是 | AJ25: 《国家电网有限公司电费业务管理办法（征求意见稿）》第三章 电价执行 | AK25: 国网营销部 | AL25: 地市 | AM25: 电价
I26: 营销售电业务-7.客户电价执行管控-控制措施03 | J26: 营销部门对客户电价执行及变更情况开展数字化在线监督。 | M26: √ | S26: √ | T26: 系统已建 | U26: 营销2.0系统 电价执行辅助管理模块 | V26: 数字化监督相关资料或稽查工单及处理情况 | W26: 各级单位供服中心、供电公司-营销部门-电价管理人员 | X26: 每半年 | Y26: 抽查 | AA26: 年度 | AB26: 抽查 | AD26: 客户电价执行监督——对客户电价执行及变更开展在线监督 | AE26: 每季度 | AF26: 全量 | AH26: 是 | AI26: 是 | AJ26: 《国家电网有限公司电费业务管理办法（征求意见稿）》第三章 电价执行 国网湖南电力营销部关于印发电价执行管理规范指引的通知)（营销〔2025〕5号） | AK26: 国网营销部 | AL26: 供服、地市 | AM26: 电价
A27: 营销售电业务 | B27: 三、电量采集管理 | C27: 会计信息真实完整 | D27: 电量采集 | E27: 未严格执行采集策略，导致电量计量失真。 | G27: 8.采集规则配置 | H27: 电能表示数采集策略应纳入统一管理 | I27: 营销售电业务-8.采集规则配置-控制措施01 | J27: 营销部门要建立电能表示数采集策略统一管理机制，强化规则配置与实施管理。 | M27: √ | T27: 系统已建 | U27: 新一代用电信息采集系统 | V27: 电能表采集数据 | W27: 各省（自治区、直辖市）电力公司供服中心-营销部门-计量管理人员 | X27: 每年 | Y27: 抽查 | AA27: 年度 | AB27: 抽查 | AH27: 是 | AI27: 是 | AJ27: 《国家电网有限公司电费业务管理办法（征求意见稿）》第五章 采集抄表 | AK27: 国网营销部 | AL27: 供服 | AM27: 计量
I28: 营销售电业务-8.采集规则配置-控制措施02 | J28: 营销部门对电能表示数采集策略执行情况开展复核与监督。 | M28: √ | T28: 系统已建 | U28: 新一代用电信息采集系统 | V28: 电能表参数任务 | W28: 各省（自治区、直辖市）电力公司供服中心-营销部门-计量管理复核人员 | X28: 每年 | Y28: 抽查 | AA28: 年度 | AB28: 抽查 | AH28: 是 | AI28: 是 | AJ28: 《国家电网有限公司电费业务管理办法（征求意见稿）》第五章 采集抄表 | AK28: 国网营销部 | AL28: 供服 | AM28: 计量
C29: 会计信息真实完整 | D29: 电量采集 | E29: 电量采集范围不完整、抄表周期不准确，导致电费收入未可靠计量。 | G29: 9.电能表示数采集 | H29: 电能表示数采集应规范完整、应抄尽抄 | I29: 营销售电业务-9.电能表示数采集-控制措施01 | J29: 电能表示数采集应由用电信息采集系统统一出口，采集范围应完整。 | M29: √ | T29: 系统已建 | U29: 新一代用电信息采集系统 | V29: 1.电能表采集数据； 2.电能表抄表工单 | W29: 各省（自治区、直辖市）电力公司供服中心-营销部门-计量管理人员 | X29: 每 半年 | Y29: 抽查 | AA29: 年度 | AB29: 抽查 | AH29: 是 | AI29: 是 | AJ29: 《国家电网有限公司电费业务管理办法（征求意见稿）》第五章 采集抄表 | AK29: 国网营销部 | AL29: 供服 | AM29: 计量
I30: 营销售电业务-9.电能表示数采集-控制措施02 | J30: 营销部门对全量用户抄表完整性开展在线监控。 | S30: √ | T30: 系统已建 | U30: 新一代用电信息采集系统、营销2.0系统 | V30: 1.电能表采集数据； 2.电能表抄表工单 | W30: 各级单位供服中心-营销部门-计量（抄表）管理/电费电价管理人员 | X30: 每季度 | Y30: 抽查 | AA30: 年度 | AB30: 抽查 | AD30: 应抄未抄监督——对全量用户抄表完整性开展在线监控 | AE30: 每月 | AF30: 全量 | AH30: 是 | AI30: 是 | AJ30: 《国家电网有限公司电费业务管理办法（征求意见稿）》第五章 采集抄表 | AK30: 国网营销部 | AL30: 供服 | AM30: 计量
I31: 营销售电业务-9.电能表示数采集-控制措施03 | J31: 营销部门严格抄表周期管理，以自然月为周期对全体用户进行抄表，抄表周期调整履行严格审批程序。 | M31: √ | T31: 系统已建 | U31: 营销2.0系统 | V31: 1.电能表采集数据； 2.电能表抄表工单； 3.应参与本次抄表算费全量客户抄表信息、实际参与本次抄表算费全量客户抄表信息 | W31: 各级单位省公司、供服中心、供电公司-营销部门-计量（抄表）管理/电费电价管理人员 | X31: 每 半年 | Y31: 抽查 | AA31: 年度 | AB31: 抽查 | AH31: 是 | AI31: 是 | AJ31: 《国家电网有限公司电费业务管理办法（征求意见稿）》第五章 采集抄表 | AK31: 国网营销部 | AL31: 省公司、供服、地市 | AM31: 计量、抄表、电费核算
I32: 营销售电业务-9.电能表示数采集-控制措施04 | J32: 营销部门应结合当地市场规则及电费结算相关协议确定月内抄表频次。 | M32: √ | T32: 线下管控 | V32: 市场规则及相关文件 | W32: 各省（自治区、直辖市）电力公司省公司、供服中心、供电公司-营销部门-电费电价（抄表）管理人员 | X32: 每 半年 | Y32: 抽查 | AA32: 年度 | AB32: 抽查 | AH32: 是 | AI32: 是 | AJ32: 《国家电网有限公司电费业务管理办法（征求意见稿）》第五章 采集抄表 | AK32: 国网营销部 | AL32: 省公司、供服、地市 | AM32: 计量、抄表、电费核算
C33: 会计信息真实完整 | D33: 电量采集 | E33: 抄表结果异常，导致电费计算失真。 | F33: 20.营销系统权限管控不严：存在重要业务流程权限设置不合规；电费收费、账务处理、财务审核和违约用电查处、审批等不相容岗位未分离；信息系统权限未严格落实实名制，账号权限与实际权责不符、一人存在多个账号等问题。 | G33: 10.电量采集结果确认 | H33: 电量采集结果应完整、准确 | I33: 营销售电业务-10.电量采集结果确认-控制措施01 | J33: 营销部门建立电量采集结果集中复核机制，健全复核规则，异常事项消缺纳入在线管控。 | M33: √ | T33: 系统已建 | U33: 营销2.0系统 | V33: 电能表采集数据 | W33: 各省（自治区、直辖市）电力公司省公司、供服中心、供电公司-营销部门-计量（抄表）管理人员 | X33: 每年 | Y33: 抽查 | AA33: 年度 | AB33: 抽查 | AH33: 是 | AI33: 是 | AJ33: 《国家电网有限公司电费业务管理办法（征求意见稿）》第五章 采集抄表 | AK33: 国网营销部 | AL33: 省公司、供服、地市 | AM33: 计量、营业
I34: 营销售电业务-10.电量采集结果确认-控制措施02 | J34: 营销部门对抄表异常事项消缺实行工单化管理，对不影响量费调整的异常事项消缺，执行本级确认后闭环。对影响量费调整的异常事项消缺，执行分级授权审批机制。 | L34: √ | M34: √ | T34: 系统已建 | U34: 营销2.0系统 | V34: 采集异常工单及审核审批记录 | W34: 各级单位供电公司-营销部门-计量（抄表）管理及各级审批人员 | X34: 每 半年 | Y34: 抽查 | AA34: 年度 | AB34: 抽查 | AH34: 是 | AI34: 是 | AJ34: 《国家电网有限公司电费业务管理办法（征求意见稿）》第五章 采集抄表 | AK34: 国网营销部 | AL34: 地市 | AM34: 计量、营业
A35: 营销售电业务 | B35: 四、电费核算与发行管理 | C35: 会计信息真实完整 | D35: 量费计算 | E35: 未严格执行电费计算规则，电费计算结果未经有效复核，导致电费计算结果失真。 | G35: 11.电费计算结果复核 | H35: 电费核算与复核规则应纳入统一管理 | I35: 营销售电业务-11.电费计算结果复核-控制措施01 | J35: 国网营销部对电费核算与复核规则进行集中管理、二级配置与实施，规则应及时动态更新。 | M35: √ | T35: 系统已建 | U35: 营销2.0系统 | V35: 系统电费核算与复核规则 | W35: 国网营销部-电费电价管理人员；各省（自治区、直辖市）电力公司省公司-营销部门-电费电价管理人员 | X35: 每年 | Y35: 抽查 | AA35: 年度 | AB35: 抽查 | AH35: 是 | AI35: 是 | AJ35: 《国家电网有限公司电费业务管理办法（征求意见稿）》第七章 核算出账 | AK35: 国网营销部 | AL35: 国网营销部、省公司 | AM35: 电费电价
I36: 营销售电业务-11.电费计算结果复核-控制措施02 | J36: 省公司营销部门应确保通用规则执行到位，对个性化补充规则严格履行审批程序后实施。 | M36: √ | T36: 系统已建 | U36: 营销2.0系统 | V36: 1.系统电费核算与复核规则； 2.系统个性化规则授权审批记录 | W36: 各省（自治区、直辖市）电力公司省公司-营销部门-电费电价管理人员 | X36: 每年 | Y36: 抽查 | AA36: 年度 | AB36: 抽查 | AH36: 是 | AI36: 是 | AJ36: 《国家电网有限公司电费业务管理办法（征求意见稿）》第七章 核算出账 | AK36: 国网营销部 | AL36: 省公司 | AM36: 电费电价
I37: 营销售电业务-11.电费计算结果复核-控制措施03 | J37: 营销部门建立量费核算结果集中复核机制，异常事项消缺实行工单化管理，并明确分级分类审批标准。 | L37: √ | M37: √ | T37: 系统已建 | U37: 营销2.0系统 | V37: 量费异常工单及审核审批记录 | W37: 各级单位供服中心、供电公司-营销部门-电费电价管理及各级审批人员 | X37: 每 半年 | Y37: 抽查 | AA37: 年度 | AB37: 抽查 | AH37: 是 | AI37: 是 | AJ37: 《国家电网有限公司电费业务管理办法（征求意见稿）》第七章 核算出账 | AK37: 国网营销部 | AL37: 供服、地市 | AM37: 电费电价
C38: 会计信息真实完整、资金资产安全 | D38: 电费发行 | E38: 违规减免电费，导致收入不实、资金损失。 | F38: 20.营销系统权限管控不严：存在重要业务流程权限设置不合规；电费收费、账务处理、财务审核和违约用电查处、审批等不相容岗位未分离；信息系统权限未严格落实实名制，账号权限与实际权责不符、一人存在多个账号等问题。 | G38: 12.电费发行确认 | H38: 电费发行应真实、完整、准确 | I38: 营销售电业务-12.电费发行确认-控制措施01 | J38: 营销部门统一配置电费发行规则，强化电费发行与核算一体化管控，严禁手工篡改发行数据。 | M38: √ | T38: 系统已建 | U38: 营销2.0系统 | V38: 1.系统电费发行工单流转记录； 2.岗位权限配置 | W38: 各省（自治区、直辖市）电力公司供服中心-营销部门-电费电价管理人员 | X38: 每年 | Y38: 抽查 | AA38: 年度 | AB38: 抽查 | AH38: 是 | AI38: 是 | AJ38: 《国家电网有限公司电费业务管理办法（征求意见稿）》第七章 核算出账 国网湖南电力营销部关于印发电费结算管理办法的通知（营销〔2022〕27号） 国网湖南电力营销部关于加强电量电费差错风险防控工作的通知（营销〔2024〕36号） | AK38: 国网营销部 | AL38: 供服 | AM38: 电费电价
I39: 营销售电业务-12.电费发行确认-控制措施02 | J39: 营销部门协同交易明确月末预估量价规则，预估到日，预估结果确认严格履行审批程序，防止人为调整。 | M39: √ | T39: 系统已建 | U39: 营销2.0系统 | V39: 1.系统电费发行工单流转记录； 2.系统电费退补审批记录及支撑依据； 3.岗位权限配置 | W39: 各省（自治区、直辖市）电力公司供服中心-营销部门-电费电价管理人员 | X39: 每 季度 | Y39: 抽查 | AA39: 年度 | AB39: 抽查 | AH39: 是 | AI39: 是 | AJ39: 《国家电网有限公司电费业务管理办法（征求意见稿）》第七章 核算出账 | AK39: 国网营销部 | AL39: 供服 | AM39: 电费电价
I40: 营销售电业务-12.电费发行确认-控制措施03 | J40: 各单位业务核算人员在算费前，对当月审核规则拦截的涉费工单进行逐一检查，督导处理归档。 | M40: √ | T40: 系统已建 | U40: 营销2.0系统 | V40: 系统试算工单流转记录 | W40: 各级单位供服中心、供电公司-营销部门-业务核算人员 | X40: 每半年 | Y40: 抽查 | AA40: 年度 | AB40: 抽查 | AH40: 是 | AI40: 是 | AJ40: 《国家电网有限公司电费业务管理办法（征求意见稿）》第七章 核算出账 | AK40: 国网营销部 | AL40: 供服、地市 | AM40: 电费电价
...

Sheet 营销售电（核对过程7.20） (2)
A1: 风控矩阵-营销售电业务
A2: 业务条线 | B2: 业务领域 | C2: 控制目标 | D2: 业务流程步骤 | E2: 经营风险 | F2: 典型问题 | G2: 关键控制点 | H2: 控制要求 | I2: 控制措施编号 | J2: 控制措施 | K2: 控制措施分类 | T2: 控制方式 | U2: 控制系统 | V2: 控制载体 | W2: 责任主体 | X2: 业务自评价 | AA2: 集团监督评价 | AD2: 数字化监督场景 | AH2: 现有制度及文件落实情况 | AK2: 总部审核部门 | AL2: 变化分类 | AM2: 矩阵变化内容说明 | AN2: 层级 | AO2: 专业 | AP2: 专业审核意见
K3: 不相容岗位 | L3: 分级授权 | M3: 业务真实性控制 | N3: 预算管控 | O3: 合同控制 | P3: 收付控制 | Q3: 会计监督 | R3: 财产保护 | S3: 分析与评价 | X3: 评价频率 | Y3: 评价范围 | Z3: 评价结论 | AA3: 评价频率 | AB3: 评价范围 | AC3: 评价结论 | AD3: 数字化监督场景 | AE3: 监督频率 | AF3: 监督范围 | AG3: 评价结论 | AH3: 是否已要求 | AI3: 是否满足要求 | AJ3: 对应制度及文件名称
A4: 营销售电业务 | B4: 一、客户信息与合同签订管理 | C4: 会计信息真实完整、资金资产安全 | D4: 业扩报装受理 | E4: 客户信息录入不准确，与现场不一致，引发虚假立户及电费收取不规范风险。 | F4: 19.两部制电价执行不正确：存在应执行未执行两部制电价、分户报装规避两部制电价、变更用电少收基本电费、需量基本电费计收不准确等问题。 | G4: 1.系统客户信息创建 | H4: 系统客户信息应与客户报装资料、现场用电情况一致。 | I4: 营销售电业务-1.系统客户信息创建-控制措施01 | J4: 营销部门业务受理人员根据客户报装资料做好系统客户信息的创建，并对报装资料完整性、有效性负责。 | M4: √ | T4: 线下管控 | V4: 1.系统业扩工单； 2.客户报装原始资料； 3.系统客户档案 | W4: 各级单位-营销部门-业务受理人员 | X4: 每年 | Y4: 抽查 | AA4: 年度 | AB4: 抽查 | AH4: 是 | AI4: 是 | AJ4: 《国家电网有限公司业扩报装管理规则（征求意见稿）》第三章 业务受理 | AK4: 国网营销部 | AL4: 无变化，直接引用 | AM4: 无变化，直接引用 | AN4: 地市 | AO4: 业扩 | AP4: 业扩专业：无变化，直接引用 | AQ4: =A4=[1]营销售电!A4 -> TRUE | AR4: =B4=[1]营销售电!B4 -> TRUE | AS4: =C4=[1]营销售电!C4 -> TRUE | AT4: =D4=[1]营销售电!D4 -> TRUE | AU4: =E4=[1]营销售电!E4 -> TRUE | AV4: =F4=[1]营销售电!F4 -> TRUE | AW4: =G4=[1]营销售电!G4 -> TRUE | AX4: =H4=[1]营销售电!H4 -> TRUE | ... CA4: =AK4=[1]营销售电!AK4 -> TRUE
I5: 营销售电业务-1.系统客户信息创建-控制措施02 | J5: 营销部门应在客户新装、增容、变更用电等申请受理时，建立稽查主题前置业务环节等数智审核功能，提高客户基础信息创建质量。 | M5: √ | T5: 系统待建 | U5: 营销2.0系统 | V5: 1.系统客户档案； 2.客户报装原始资料； 3.数智审核相关功能资料 | W5: 各省（自治区、直辖市）电力公司--营销部门-业扩报装管理人员 | X5: 每年 | Y5: 抽查 | AA5: 年度 | AB5: 抽查 | AH5: 是 | AI5: 是 | AJ5: 《国家电网有限公司业扩报装管理规则（征求意见稿）》第三章 业务受理 | AK5: 国网营销部 | AL5: 无变化，直接引用 | AM5: 无变化，直接引用 | AN5: 供服 | AO5: 业扩 | AP5: 业扩专业：无变化，直接引用 | AQ5: =A5=[1]营销售电!A5 -> TRUE | AR5: =B5=[1]营销售电!B5 -> TRUE | AS5: =C5=[1]营销售电!C5 -> TRUE | AT5: =D5=[1]营销售电!D5 -> TRUE | AU5: =E5=[1]营销售电!E5 -> TRUE | AV5: =F5=[1]营销售电!F5 -> TRUE | AW5: =G5=[1]营销售电!G5 -> TRUE | AX5: =H5=[1]营销售电!H5 -> TRUE | ... CA5: =AK5=[1]营销售电!AK5 -> TRUE
I6: 营销售电业务-1.系统客户信息创建-控制措施03 | J6: 营销部门业务办理人员结合现场勘查情况对客户关键信息真实性、准确性复核，业务受理与业务办理执行不相容控制。 | K6: √ | M6: √ | T6: 线下管控 | V6: 1.系统业扩工单； 2.客户报装原始资料； 3.系统客户档案； 4.系统授权审批记录 | W6: 各级单位-营销部门-业务办理人员 | X6: 每年 | Y6: 抽查 | AA6: 年度 | AB6: 抽查 | AH6: 是 | AI6: 是 | AJ6: 《国家电网有限公司业扩报装管理规则（征求意见稿）》第三章 业务受理 | AK6: 国网营销部 | AL6: 无变化，直接引用 | AM6: 无变化，直接引用 | AN6: 地市 | AO6: 业扩 | AP6: 业扩专业：无变化，直接引用 | AQ6: =A6=[1]营销售电!A6 -> TRUE | AR6: =B6=[1]营销售电!B6 -> TRUE | AS6: =C6=[1]营销售电!C6 -> TRUE | AT6: =D6=[1]营销售电!D6 -> TRUE | AU6: =E6=[1]营销售电!E6 -> TRUE | AV6: =F6=[1]营销售电!F6 -> TRUE | AW6: =G6=[1]营销售电!G6 -> TRUE | AX6: =H6=[1]营销售电!H6 -> TRUE | ... CA6: =AK6=[1]营销售电!AK6 -> TRUE
I7: 营销售电业务-1.系统客户信息创建-控制措施04 | J7: 营销部门对分户报装规避基本电费、违规改变用电性质等开展数字化在线监督与现场检查。 | M7: √ | S7: √ | T7: 系统已建 | U7: 营销2.0系统 | V7: 数字化监督相关资料或稽查工单及处理情况 | W7: 各级单位-营销部门-业务审核人员 | X7: 每半年 | Y7: 抽查 | AA7: 年度 | AB7: 抽查 | AD7: 分户报装规避基本电费监督——对一址多户开展在线监督 | AE7: 每季度 | AF7: 全量 | AH7: 是 | AI7: 是 | AJ7: 《国家电网有限公司业扩报装管理规则（征求意见稿）》第三章 业务受理 | AK7: 国网营销部 | AL7: 无变化，直接引用 | AM7: 无变化，直接引用 | AN7: 地市 | AO7: 业扩 | AP7: 业扩专业：无变化，直接引用 | AQ7: =A7=[1]营销售电!A7 -> TRUE | AR7: =B7=[1]营销售电!B7 -> TRUE | AS7: =C7=[1]营销售电!C7 -> TRUE | AT7: =D7=[1]营销售电!D7 -> TRUE | AU7: =E7=[1]营销售电!E7 -> TRUE | AV7: =F7=[1]营销售电!F7 -> TRUE | AW7: =G7=[1]营销售电!G7 -> TRUE | AX7: =H7=[1]营销售电!H7 -> TRUE | ... CA7: =AK7=[1]营销售电!AK7 -> TRUE
C8: 会计信息真实完整、资金资产安全 | D8: 方案答复与工程实施 | E8: 客户用电容量核定不准确、录入错误，导致基本电费执行不准确、电费少收。 | F8: 19.两部制电价执行不正确：存在应执行未执行两部制电价、分户报装规避两部制电价、变更用电少收基本电费、需量基本电费计收不准确等问题。 | G8: 2.客户用电容量的确定 | H8: 系统容量与现场用电情况保持一致。 | I8: 营销售电业务-2.客户用电容量的确定创建-控制措施01 | J8: 营销部门现场勘查人员应准确核定客户用电容量与负荷性质，确保计量、计费方案、供电方式等准确。 | M8: √ | T8: 线下管控 | V8: 1.系统业扩工单（现场勘查验收单）； 2.系统客户档案（供电方案等） | W8: 各级单位-营销部门-现场勘查人员 | X8: 每年 | Y8: 抽查 | AA8: 年度 | AB8: 抽查 | AH8: 是 | AI8: 是 | AJ8: 《国家电网有限公司业扩报装管理规则（征求意见稿）》第四章 供电方案编制及答复 | AK8: 国网营销部 | AL8: 无变化，但建议省公司优化系统。 | AM8: 建议新装增容的供电方案会审实现配电、调控、发展、营销多专业线上会审（株洲、岳阳） | AN8: 地市 | AO8: 业扩 | AP8: 业扩专业：无变化，直接引用 | AQ8: =A8=[1]营销售电!A8 -> TRUE | AR8: =B8=[1]营销售电!B8 -> TRUE | AS8: =C8=[1]营销售电!C8 -> TRUE | AT8: =D8=[1]营销售电!D8 -> TRUE | AU8: =E8=[1]营销售电!E8 -> TRUE | AV8: =F8=[1]营销售电!F8 -> TRUE | AW8: =G8=[1]营销售电!G8 -> TRUE | AX8: =H8=[1]营销售电!H8 -> TRUE | ... CA8: =AK8=[1]营销售电!AK8 -> TRUE
I9: 营销售电业务-2.客户用电容量的确定创建-控制措施02 | J9: 对于加装变压器的高压客户，需取得变压器出厂合格证明及型式试验报告等容量信息佐证材料并上传系统，确保系统录入容量与现场用电情况一致。 | M9: √ | T9: 系统已建 | U9: 营销2.0系统 | V9: 1.系统业扩工单信息（现场勘查验收单）； 2.客户报装原始资料（含用电负荷清单、变压器出厂合格证明及型式试验报告等）； 3.系统客户档案 | W9: 各级单位-营销部门-业务办理人员 | X9: 每半年 | Y9: 抽查 | AA9: 年度 | AB9: 抽查 | AH9: 是 | AI9: 是 | AJ9: 《国家电网有限公司业扩报装管理规则（征求意见稿）》第四章 供电方案编制及答复 | AK9: 国网营销部 | AL9: 无变化，直接引用 | AM9: 无变化，直接引用 | AN9: 地市 | AO9: 业扩 | AP9: 业扩专业：无变化，直接引用 | AQ9: =A9=[1]营销售电!A9 -> TRUE | AR9: =B9=[1]营销售电!B9 -> TRUE | AS9: =C9=[1]营销售电!C9 -> TRUE | AT9: =D9=[1]营销售电!D9 -> TRUE | AU9: =E9=[1]营销售电!E9 -> TRUE | AV9: =F9=[1]营销售电!F9 -> TRUE | AW9: =G9=[1]营销售电!G9 -> TRUE | AX9: =H9=[1]营销售电!H9 -> TRUE | ... CA9: =AK9=[1]营销售电!AK9 -> TRUE
I10: 营销售电业务-2.客户用电容量的确定创建-控制措施03 | J10: 营销部门对超容用电、基本电费异常、高可靠性供电费收取不规范开展数字化在线监督与现场检查。 | M10: √ | S10: √ | T10: 系统已建 | U10: 营销2.0系统 | V10: 数字化监督相关资料或稽查结果与处理情况 | W10: 各级单位-营销部门-业务审核人员 | X10: 每半年 | Y10: 抽查 | AA10: 年度 | AB10: 抽查 | AD10: 客户容量与电量联动监测——对超容用电、基本电费异常、高可靠性供电费收取不规范开展在线监督 | AE10: 每季度 | AF10: 全量 | AH10: 是 | AI10: 是 | AJ10: 《国家电网有限公司业扩报装管理规则（征求意见稿）》第四章 供电方案编制及答复 | AK10: 国网营销部 | AL10: 无变化，直接引用 | AM10: 无变化，直接引用 | AN10: 地市 | AO10: 业扩 | AP10: 业扩专业：无变化，直接引用 | AQ10: =A10=[1]营销售电!A10 -> TRUE | AR10: =B10=[1]营销售电!B10 -> TRUE | AS10: =C10=[1]营销售电!C10 -> TRUE | AT10: =D10=[1]营销售电!D10 -> TRUE | AU10: =E10=[1]营销售电!E10 -> TRUE | AV10: =F10=[1]营销售电!F10 -> TRUE | AW10: =G10=[1]营销售电!G10 -> TRUE | AX10: =H10=[1]营销售电!H10 -> TRUE | ... CA10: =AK10=[1]营销售电!AK10 -> TRUE
A11: 营销售电业务 | B11: 一、客户信息与合同签订管理 | C11: 会计信息真实完整、资金资产安全 | D11: 客户信息变更 | E11: 客户信息变更不合规，导致电费计收不准确，引发合规风险。 | F11: 19.两部制电价执行不正确：存在应执行未执行两部制电价、分户报装规避两部制电价、变更用电少收基本电费、需量基本电费计收不准确等问题。 | G11: 3.系统客户信息变更 | H11: 客户关键信息变更应结合业务工单联动调整，严禁无业务动因创建或修改客户信息行为。 | I11: 营销售电业务-3.系统客户信息变更-控制措施01 | J11: 营销部门对客户户名、电价、用电容量等关键信息的变更，应结合变更业务联动调整并经审批后实施。 | L11: √ | M11: √ | T11: 系统已建 | U11: 营销2.0系统 | V11: 1.系统变更工单； 2.客户变更原始资料； 3.系统客户档案； 4.系统授权审批记录 | W11: 各级单位-营销部门-业务审核及各级审批人员 | X11: 每年 | Y11: 抽查 | AA11: 年度 | AB11: 抽查 | AH11: 是 | AI11: 是 | AJ11: 《变更用电业务规则（试行）》 | AK11: 国网营销部 | AL11: 无变化，但建议省公司优化系统。 | AM11: 【补充需求】变更办理是规避一址多户的系统控制需求（同片区 / 临近地址）（岳阳） | AN11: 地市 | AO11: 业扩 | AP11: 业扩专业：无变化，直接引用 | AQ11: =A11=[1]营销售电!A11 -> TRUE | AR11: =B11=[1]营销售电!B11 -> TRUE | AS11: =C11=[1]营销售电!C11 -> TRUE | AT11: =D11=[1]营销售电!D11 -> TRUE | AU11: =E11=[1]营销售电!E11 -> TRUE | AV11: =F11=[1]营销售电!F11 -> TRUE | AW11: =G11=[1]营销售电!G11 -> TRUE | AX11: =H11=[1]营销售电!H11 -> TRUE | ... CA11: =AK11=[1]营销售电!AK11 -> TRUE
I12: 营销售电业务-3.系统客户信息变更-控制措施02 | J12: 营销部门对影响价费关键信息的变更业务开展现场查验，确保用电信息与现场一致。 | M12: √ | T12: 线下管控 | V12: 现场核查相关记录 | W12: 各级单位-营销部门-现场勘查人员 | X12: 每年 | Y12: 抽查 | AA12: 年度 | AB12: 抽查 | AH12: 是 | AI12: 是 | AJ12: 《变更用电业务规则（试行）》 | AK12: 国网营销部 | AL12: 无变化，直接引用 | AM12: 无变化，直接引用 | AN12: 地市 | AO12: 业扩 | AP12: 业扩专业：无变化，直接引用 | AQ12: =A12=[1]营销售电!A12 -> TRUE | AR12: =B12=[1]营销售电!B12 -> TRUE | AS12: =C12=[1]营销售电!C12 -> TRUE | AT12: =D12=[1]营销售电!D12 -> TRUE | AU12: =E12=[1]营销售电!E12 -> TRUE | AV12: =F12=[1]营销售电!F12 -> TRUE | AW12: =G12=[1]营销售电!G12 -> TRUE | AX12: =H12=[1]营销售电!H12 -> TRUE | ... CA12: =AK12=[1]营销售电!AK12 -> TRUE
C13: 会计信息真实完整、资金资产安全 | D13: 合同签订 | E13: 合同签订未使用公司统一且生效文本，导致电费计收合法权益无法得到保障。 | G13: 4.供用电合同签订 | H13: 供用电合同签订应使用公司统一且生效的文本。 | I13: 营销售电业务-4.供用电合同签订-控制措施01 | J13: 国网营销部统一管理合同文本，并明确执行要求、生效时间，及客户业务变更时不需重签合同的业务类型。各省（自治区、直辖市）电力公司参考统一文本拟定本单位合同文本、特别约定事项等，经法律合规部门审核后使用。 | O13: √ | T13: 系统已建 | U13: 营销2.0系统 | V13: 1.合同统一文本； 2.制度或通知 | W13: 国网营销部-合同管理人员；各省（自治区、直辖市）电力公司-营销部门-合同管理人员 | X13: 每年 | Y13: 抽查 | AA13: 年度 | AB13: 抽查 | AH13: 是 | AI13: 是 | AJ13: 《国家电网有限公司电费业务管理办法（征求意见稿）》第四章 合同协议 《国网营销部关于印发变更用电业务规则》 《国家电网有限公司业扩报装管理规则（征求意见稿）》第六十三、六十四条 《国家电网有限公司合同管理办法》四十六条、六十四-六十六条 | AK13: 国网营销部 | AL13: 无变化，但建议省公司优化系统。 | AM13: 从业务流程中提取相应字段，生成系统标准化合同（株洲） | AN13: 省公司 | AO13: 业扩 | AP13: 业扩专业：无变化，直接引用 | AQ13: =A13=[1]营销售电!A13 -> TRUE | AR13: =B13=[1]营销售电!B13 -> TRUE | AS13: =C13=[1]营销售电!C13 -> TRUE | AT13: =D13=[1]营销售电!D13 -> TRUE | AU13: =E13=[1]营销售电!E13 -> TRUE | AV13: =F13=[1]营销售电!F13 -> TRUE | AW13: =G13=[1]营销售电!G13 -> TRUE | AX13: =H13=[1]营销售电!H13 -> TRUE | ... CA13: =AK13=[1]营销售电!AK13 -> TRUE
I14: 营销售电业务-4.供用电合同签订-控制措施02 | J14: 营销部门合同签订人员应严格使用本省统一且生效文本。 | O14: √ | T14: 系统已建 | U14: 营销2.0系统 | V14: 1.供用电合同； 2.合同统一文本 | W14: 各级单位-营销部门-合同签订人员 | X14: 每年 | Y14: 抽查 | AA14: 年度 | AB14: 抽查 | AH14: 是 | AI14: 是 | AJ14: 《国家电网有限公司电费业务管理办法（征求意见稿）》第四章 合同协议 《国家电网有限公司业扩报装管理规则（征求意见稿）》第六十三条 | AK14: 国网营销部 | AL14: 无变化，直接引用 | AM14: 无变化，直接引用 | AN14: 地市 | AO14: 业扩 | AP14: 业扩专业：无变化，直接引用 | AQ14: =A14=[1]营销售电!A14 -> TRUE | AR14: =B14=[1]营销售电!B14 -> TRUE | AS14: =C14=[1]营销售电!C14 -> TRUE | AT14: =D14=[1]营销售电!D14 -> TRUE | AU14: =E14=[1]营销售电!E14 -> TRUE | AV14: =F14=[1]营销售电!F14 -> TRUE | AW14: =G14=[1]营销售电!G14 -> TRUE | AX14: =H14=[1]营销售电!H14 -> TRUE | ... CA14: =AK14=[1]营销售电!AK14 -> TRUE
I15: 营销售电业务-4.供用电合同签订-控制措施03 | J15: 营销部门合同审核人员对合同文本使用情况开展审核。 | M15: √ | T15: 线下管控 | V15: 1.供用电合同； 2.合同统一文本； 3.系统合同信息； 4.系统合同签订及审批记录 | W15: 各级单位-营销部门-合同审核人员 | X15: 每年 | Y15: 抽查 | AA15: 年度 | AB15: 抽查 | AH15: 是 | AI15: 是 | AJ15: 《国家电网有限公司电费业务管理办法（征求意见稿）》第四章 合同协议 《国家电网有限公司业扩报装管理规则（征求意见稿）》第六十四条 | AK15: 国网营销部 | AL15: 无变化，直接引用 | AM15: 无变化，直接引用 | AN15: 地市 | AO15: 业扩 | AP15: 业扩专业：无变化，直接引用 | AQ15: =A15=[1]营销售电!A15 -> TRUE | AR15: =B15=[1]营销售电!B15 -> TRUE | AS15: =C15=[1]营销售电!C15 -> TRUE | AT15: =D15=[1]营销售电!D15 -> TRUE | AU15: =E15=[1]营销售电!E15 -> TRUE | AV15: =F15=[1]营销售电!F15 -> TRUE | AW15: =G15=[1]营销售电!G15 -> TRUE | AX15: =H15=[1]营销售电!H15 -> TRUE | ... CA15: =AK15=[1]营销售电!AK15 -> TRUE
C16: 会计信息真实完整、资金资产安全 | D16: 合同签订 | E16: 合同条款与客户报装信息、现场不一致，导致公司收支条款失效，合法权益无法得到保障。 | G16: 5.供用电合同审核 | H16: 合同关键信息与客户报装信息保持一致。 | I16: 营销售电业务-5.供用电合同审核-控制措施01 | J16: 营销部门合同签订人员要确保合同信息与业扩报装产生的客户信息保持一致，不得变更。 | M16: √ | O16: √ | T16: 线下管控 | V16: 1.供用电合同信息； 2.系统客户信息 | W16: 各级单位-营销部门-合同签订人员 | X16: 每年 | Y16: 抽查 | AA16: 年度 | AB16: 抽查 | AH16: 是 | AI16: 是 | AJ16: 《国家电网有限公司电费业务管理办法（征求意见稿）》第四章 合同协议第二十六条 | AK16: 国网营销部 | AL16: 无变化，但建议省公司优化系统。 | AM16: 增加系统客户信息校验（株洲） | AN16: 地市 | AO16: 业扩 | AP16: 业扩专业：无变化，直接引用 | AQ16: =A16=[1]营销售电!A16 -> TRUE | AR16: =B16=[1]营销售电!B16 -> TRUE | AS16: =C16=[1]营销售电!C16 -> TRUE | AT16: =D16=[1]营销售电!D16 -> TRUE | AU16: =E16=[1]营销售电!E16 -> TRUE | AV16: =F16=[1]营销售电!F16 -> TRUE | AW16: =G16=[1]营销售电!G16 -> TRUE | AX16: =H16=[1]营销售电!H16 -> TRUE | ... CA16: =AK16=[1]营销售电!AK16 -> TRUE
I17: 营销售电业务-5.供用电合同审核-控制措施02 | J17: 营销部门合同审核人员对合同信息与业扩报装产生的信息一致性进行复核。 | M17: √ | O17: √ | T17: 线下管控 | V17: 1.供用电合同信息； 2.系统客户信息； 3.合同审核记录 | W17: 各级单位-营销部门-合同审核人员 | X17: 每年 | Y17: 抽查 | AA17: 年度 | AB17: 抽查 | AH17: 是 | AI17: 是 | AJ17: 《国家电网有限公司电费业务管理办法（征求意见稿）》第四章 合同协议 | AK17: 国网营销部 | AL17: 无变化，直接引用 | AM17: 无变化，直接引用 | AN17: 地市 | AO17: 业扩 | AP17: 业扩专业：无变化，直接引用 | AQ17: =A17=[1]营销售电!A17 -> TRUE | AR17: =B17=[1]营销售电!B17 -> TRUE | AS17: =C17=[1]营销售电!C17 -> TRUE | AT17: =D17=[1]营销售电!D17 -> TRUE | AU17: =E17=[1]营销售电!E17 -> TRUE | AV17: =F17=[1]营销售电!F17 -> TRUE | AW17: =G17=[1]营销售电!G17 -> TRUE | AX17: =H17=[1]营销售电!H17 -> TRUE | ... CA17: =AK17=[1]营销售电!AK17 -> TRUE
I18: 营销售电业务-5.供用电合同审核-控制措施03 | J18: 营销部门合同管理人员应落实合同签订一致性要求，加强系统上传合同与线下纸质合同一致性管控。 | O18: √ | T18: 线下管控 | U18: 营销2.0系统 | V18: 1.供用电合同（线下）； 2.系统合同信息 | W18: 各级单位-营销部门-合同管理人员 | X18: 每年 | Y18: 抽查 | AA18: 年度 | AB18: 抽查 | AH18: 是 | AI18: 是 | AJ18: 《国家电网有限公司电费业务管理办法（征求意见稿）》第四章 合同协议 《国家电网有限公司业扩报装管理规则（征求意见稿）》第六十五条 | AK18: 国网营销部 | AL18: 无变化，但建议省公司优化系统。 | AM18: 在营销2.0增加自动校验合同中关键信息功能，如表计倍率、电价、线损等关键信息。（岳阳） | AN18: 地市 | AO18: 业扩 | AP18: 业扩专业：无变化，直接引用 | AQ18: =A18=[1]营销售电!A18 -> TRUE | AR18: =B18=[1]营销售电!B18 -> TRUE | AS18: =C18=[1]营销售电!C18 -> TRUE | AT18: =D18=[1]营销售电!D18 -> TRUE | AU18: =E18=[1]营销售电!E18 -> TRUE | AV18: =F18=[1]营销售电!F18 -> TRUE | AW18: =G18=[1]营销售电!G18 -> TRUE | AX18: =H18=[1]营销售电!H18 -> TRUE | ... CA18: =AK18=[1]营销售电!AK18 -> TRUE
I19: 营销售电业务-5.供用电合同审核-控制措施04 | J19: 营销部门对系统合同上传及生效情况开展稽查监督。 | S19: √ | T19: 系统已建 | U19: 营销2.0系统 | V19: 数字化监督相关资料或稽查工单及处理情况 | W19: 各级单位-营销部门-合同管理人员 | X19: 每 半年 | Y19: 抽查 | AA19: 年度 | AB19: 抽查 | AH19: 是 | AI19: 是 | AJ19: 《国家电网有限公司电费业务管理办法（征求意见稿）》第四章 合同协议 《国家电网有限公司业扩报装管理规则（征求意见稿）》第六十五条 | AK19: 国网营销部 | AL19: 无变化，直接引用 | AM19: 无变化，直接引用 | AN19: 地市 | AO19: 业扩 | AP19: 业扩专业：无变化，直接引用 | AQ19: =A19=[1]营销售电!A19 -> TRUE | AR19: =B19=[1]营销售电!B19 -> TRUE | AS19: =C19=[1]营销售电!C19 -> TRUE | AT19: =D19=[1]营销售电!D19 -> TRUE | AU19: =E19=[1]营销售电!E19 -> TRUE | AV19: =F19=[1]营销售电!F19 -> TRUE | AW19: =G19=[1]营销售电!G19 -> TRUE | AX19: =H19=[1]营销售电!H19 -> TRUE | ... CA19: =AK19=[1]营销售电!AK19 -> TRUE
A20: 营销售电业务 | B20: 二、电价执行管理 | C20: 会计信息真实完整、资金资产安全 | D20: 电价码制定 | E20: 电价政策执行不到位，系统配置不准确，导致公司电费收入计量不准确、不合规。 | G20: 6.电价码制定与执行 | H20: 电价标准与政策匹配，电价码准确配置与执行 | I20: 营销售电业务-6.电价码制定与执行-控制措施01 | J20: 电价码管理实行“统一管理、分级维护”原则，按照统一标准规范执行。财务部门负责根据国家或省内价格政策，对照标准化电价码编码规则，解析形成每类客户电价执行标准，将政策解析与电价码关联结果推送营销。 | M20: √ | Q20: √ | T20: 系统已建 | U20: 智慧财务 | V20: 1.电价政策文件； 2.政策解析结果 | W20: 国网财务部-销售电价管理人员；各省（自治区、直辖市）电力公司-财务部门-销售电价管理人员 | X20: 每年 | Y20: 抽查 | AA20: 年度 | AB20: 抽查 | AH20: 是 | AI20: 是 | AJ20: 《国网营销部国网财务部国网数字化部关于加快标准化电价码部署应用的通知》（营销营业〔2025〕83号） | AK20: 国网财务部 | AL20: 无变化，直接引用 | AM20: 无变化，直接引用 | AN20: 省公司 | AO20: 电价、财务 | AP20: 电价专业无意见 | AQ20: =A20=[1]营销售电!A20 -> TRUE | AR20: =B20=[1]营销售电!B20 -> TRUE | AS20: =C20=[1]营销售电!C20 -> TRUE | AT20: =D20=[1]营销售电!D20 -> TRUE | AU20: =E20=[1]营销售电!E20 -> TRUE | AV20: =F20=[1]营销售电!F20 -> TRUE | AW20: =G20=[1]营销售电!G20 -> TRUE | AX20: =H20=[1]营销售电!H20 -> TRUE | ... CA20: =AK20=[1]营销售电!AK20 -> TRUE
I21: 营销售电业务-6.电价码制定与执行-控制措施02 | J21: 营销部门基于电价标准及政策依据匹配形成电价码调整方案，审批后推送智慧财务，经财务部门审核（新增电价码需总部审批）后下发执行。电价码的维护申请、审核、审批、确认均执行线上流转。 | M21: √ | Q21: √ | T21: 系统已建 | U21: 营销2.0系统、智慧财务 | V21: 1.电价标准与电价码匹配记录； 2.电价码调整方案； 3.电价码审核审批记录 | W21: 国网财务部-销售电价管理人员；各省（自治区、直辖市）电力公司-营销部门-电价管理人员；各省（自治区、直辖市）电力公司-财务部门-销售电价管理人员 | X21: 每年 | Y21: 抽查 | AA21: 年度 | AB21: 抽查 | AH21: 是 | AI21: 是 | AJ21: 《国网营销部国网财务部国网数字化部关于加快标准化电价码部署应用的通知》（营销营业〔2025〕83号） | AK21: 国网营销部、国网财务部 | AL21: 无变化，直接引用 | AM21: 无变化，直接引用 | AN21: 省公司 | AO21: 电价 | AP21: 电价专业无意见 | AQ21: =A21=[1]营销售电!A21 -> TRUE | AR21: =B21=[1]营销售电!B21 -> TRUE | AS21: =C21=[1]营销售电!C21 -> TRUE | AT21: =D21=[1]营销售电!D21 -> TRUE | AU21: =E21=[1]营销售电!E21 -> TRUE | AV21: =F21=[1]营销售电!F21 -> TRUE | AW21: =G21=[1]营销售电!G21 -> TRUE | AX21: =H21=[1]营销售电!H21 -> TRUE | ... CA21: =AK21=[1]营销售电!AK21 -> TRUE
I22: 营销售电业务-6.电价码制定与执行-控制措施03 | J22: 营销部门将电价码部署系统并建立电价码与用户档案信息关联关系，确保电价码精准匹配到户。 | M22: √ | T22: 系统已建 | U22: 营销2.0系统 | V22: 1.电价码与用户档案信息关联关系； 2.电价码系统配置记录 | W22: 各省（自治区、直辖市）电力公司-营销部门-电价管理人员 | X22: 每年 | Y22: 抽查 | AA22: 年度 | AB22: 抽查 | AH22: 是 | AI22: 是 | AJ22: 《国网营销部国网财务部国网数字化部关于加快标准化电价码部署应用的通知》（营销营业〔2025〕83号） | AK22: 国网营销部 | AL22: 无变化，直接引用 | AM22: 无变化，直接引用 | AN22: 省公司 | AO22: 电价 | AP22: 电价专业无意见 | AQ22: =A22=[1]营销售电!A22 -> TRUE | AR22: =B22=[1]营销售电!B22 -> TRUE | AS22: =C22=[1]营销售电!C22 -> TRUE | AT22: =D22=[1]营销售电!D22 -> TRUE | AU22: =E22=[1]营销售电!E22 -> TRUE | AV22: =F22=[1]营销售电!F22 -> TRUE | AW22: =G22=[1]营销售电!G22 -> TRUE | AX22: =H22=[1]营销售电!H22 -> TRUE | ... CA22: =AK22=[1]营销售电!AK22 -> TRUE
I23: 营销售电业务-6.电价码制定与执行-控制措施04 | J23: 营销部门协同财务部门对电价码配置与价码执行情况开展数字化校核及在线监控分析。 | S23: √ | T23: 系统待建 | U23: 营销2.0系统 | V23: 1.电价码执行情况记录； 2.电价码统计分析功能及优惠电价执行预警等功能相关记录； 3.标准化电价码智能校核规则库； 4.数字化监督相关资料或稽查工单及处理情况 | W23: 各省（自治区、直辖市）电力公司-营销部门-电价管理人员；各省（自治区、直辖市）电力公司-财务部门-销售电价管理人员 | X23: 每半年 | Y23: 抽查 | AA23: 年度 | AB23: 抽查 | AD23: 电价码执行监督——对电价码配置与执行情况开展在线监督 | AE23: 每季度 | AF23: 全量 | AH23: 是 | AI23: 是 | AJ23: 《国网营销部国网财务部国网数字化部关于加快标准化电价码部署应用的通知》（营销营业〔2025〕83号） | AK23: 国网营销部、国网财务部 | AL23: 无变化，直接引用 | AM23: 无变化，直接引用 | AN23: 省公司 | AO23: 电价 | AP23: 电价专业无意见 | AQ23: =A23=[1]营销售电!A23 -> TRUE | AR23: =B23=[1]营销售电!B23 -> TRUE | AS23: =C23=[1]营销售电!C23 -> TRUE | AT23: =D23=[1]营销售电!D23 -> TRUE | AU23: =E23=[1]营销售电!E23 -> TRUE | AV23: =F23=[1]营销售电!F23 -> TRUE | AW23: =G23=[1]营销售电!G23 -> TRUE | AX23: =H23=[1]营销售电!H23 -> TRUE | ... CA23: =AK23=[1]营销售电!AK23 -> TRUE
C24: 会计信息真实完整、资金资产安全 | D24: 电价执行 | E24: 电价执行与客户用电性质不匹配，造成公司或用户电费资金损失，收入不实 | F24: 19.两部制电价执行不正确：存在应执行未执行两部制电价、分户报装规避两部制电价、变更用电少收基本电费、需量基本电费计收不准确等问题。 | G24: 7.客户电价执行管控 | H24: 客户电价执行与用电性质、行业类别等精准匹配 | I24: 营销售电业务-7.客户电价执行管控-控制措施01 | J24: 营销部门业务受理人员应严格按照客户用电性质、行业类别等匹配执行标准电价码并准确录入系统，经审核后生效。 | M24: √ | T24: 系统已建 | U24: 营销2.0系统 | V24: 1.系统业务工单记录； 2.系统客户电价信息 | W24: 各级单位-营销部门-业务受理、业务审核人员 | X24: 每半年 | Y24: 抽查 | AA24: 年度 | AB24: 抽查 | AH24: 是 | AI24: 是 | AJ24: 《国家电网有限公司电费业务管理办法（征求意见稿）》第三章 电价执行 | AK24: 国网营销部 | AL24: 无变化，直接引用 | AM24: 无变化，直接引用 | AN24: 地市 | AO24: 业扩 | AP24: 业扩专业：无变化，直接引用 | AQ24: =A24=[1]营销售电!A24 -> TRUE | AR24: =B24=[1]营销售电!B24 -> TRUE | AS24: =C24=[1]营销售电!C24 -> TRUE | AT24: =D24=[1]营销售电!D24 -> TRUE | AU24: =E24=[1]营销售电!E24 -> TRUE | AV24: =F24=[1]营销售电!F24 -> TRUE | AW24: =G24=[1]营销售电!G24 -> TRUE | AX24: =H24=[1]营销售电!H24 -> TRUE | ... CA24: =AK24=[1]营销售电!AK24 -> TRUE
I25: 营销售电业务-7.客户电价执行管控-控制措施02 | J25: 营销部门加强客户电价变更管理，对于电价政策变动导致的电价变更应结合电价码联动调整，对于客户用电性质改变导致的电价变更应严格执行与工单关联，其他类型电价变更严格执行授权审批后进行调整。 | M25: √ | T25: 系统已建 | U25: 营销2.0系统 | V25: 系统业务工单记录 | W25: 各级单位-营销部门-电价管理人员 | X25: 每半年 | Y25: 抽查 | AA25: 年度 | AB25: 抽查 | AH25: 是 | AI25: 是 | AJ25: 《国家电网有限公司电费业务管理办法（征求意见稿）》第三章 电价执行 | AK25: 国网营销部 | AL25: 无变化，直接引用 | AM25: 无变化，直接引用 | AN25: 地市 | AO25: 电价 | AP25: 电价专业无意见 | AQ25: =A25=[1]营销售电!A25 -> TRUE | AR25: =B25=[1]营销售电!B25 -> TRUE | AS25: =C25=[1]营销售电!C25 -> TRUE | AT25: =D25=[1]营销售电!D25 -> TRUE | AU25: =E25=[1]营销售电!E25 -> TRUE | AV25: =F25=[1]营销售电!F25 -> TRUE | AW25: =G25=[1]营销售电!G25 -> TRUE | AX25: =H25=[1]营销售电!H25 -> TRUE | ... CA25: =AK25=[1]营销售电!AK25 -> TRUE
I26: 营销售电业务-7.客户电价执行管控-控制措施03 | J26: 营销部门对客户电价执行及变更情况开展数字化在线监督。 | M26: √ | S26: √ | T26: 系统已建 | U26: 营销2.0系统 电价执行辅助管理模块 | V26: 数字化监督相关资料或稽查工单及处理情况 | W26: 各级单位-营销部门-电价管理人员 | X26: 每半年 | Y26: 抽查 | AA26: 年度 | AB26: 抽查 | AD26: 客户电价执行监督——对客户电价执行及变更开展在线监督 | AE26: 每季度 | AF26: 全量 | AH26: 是 | AI26: 是 | AJ26: 《国家电网有限公司电费业务管理办法（征求意见稿）》第三章 电价执行 国网湖南电力营销部关于印发电价执行管理规范指引的通知)（营销〔2025〕5号） | AK26: 国网营销部 | AL26: 新增制度完善、系统优化清单 | AM26: 新增制度完善、系统优化清单 | AN26: 供服、地市 | AO26: 电价 | AP26: 电价专业无意见 | AQ26: =A26=[1]营销售电!A26 -> TRUE | AR26: =B26=[1]营销售电!B26 -> TRUE | AS26: =C26=[1]营销售电!C26 -> TRUE | AT26: =D26=[1]营销售电!D26 -> TRUE | AU26: =E26=[1]营销售电!E26 -> TRUE | AV26: =F26=[1]营销售电!F26 -> TRUE | AW26: =G26=[1]营销售电!G26 -> TRUE | AX26: =H26=[1]营销售电!H26 -> TRUE | ... CA26: =AK26=[1]营销售电!AK26 -> TRUE
A27: 营销售电业务 | B27: 三、电量采集管理 | C27: 会计信息真实完整 | D27: 电量采集 | E27: 未严格执行采集策略，导致电量计量失真。 | G27: 8.采集规则配置 | H27: 电能表示数采集策略应纳入统一管理 | I27: 营销售电业务-8.采集规则配置-控制措施01 | J27: 营销部门要建立电能表示数采集策略统一管理机制，强化规则配置与实施管理。 | M27: √ | T27: 系统已建 | U27: 新一代用电信息采集系统 | V27: 电能表采集数据 | W27: 各省（自治区、直辖市）电力公司-营销部门-计量管理人员 | X27: 每年 | Y27: 抽查 | AA27: 年度 | AB27: 抽查 | AH27: 是 | AI27: 是 | AJ27: 《国家电网有限公司电费业务管理办法（征求意见稿）》第五章 采集抄表 | AK27: 国网营销部 | AL27: 无变化，直接引用 | AM27: 无变化，直接引用 | AN27: 供服 | AO27: 计量 | AP27: 计量无意见 | AQ27: =A27=[1]营销售电!A27 -> TRUE | AR27: =B27=[1]营销售电!B27 -> TRUE | AS27: =C27=[1]营销售电!C27 -> TRUE | AT27: =D27=[1]营销售电!D27 -> TRUE | AU27: =E27=[1]营销售电!E27 -> TRUE | AV27: =F27=[1]营销售电!F27 -> TRUE | AW27: =G27=[1]营销售电!G27 -> TRUE | AX27: =H27=[1]营销售电!H27 -> TRUE | ... CA27: =AK27=[1]营销售电!AK27 -> TRUE
I28: 营销售电业务-8.采集规则配置-控制措施02 | J28: 营销部门对电能表示数采集策略执行情况开展复核与监督。 | M28: √ | T28: 系统已建 | U28: 新一代用电信息采集系统 | V28: 电能表参数任务 | W28: 各省（自治区、直辖市）电力公司-营销部门-计量管理复核人员 | X28: 每年 | Y28: 抽查 | AA28: 年度 | AB28: 抽查 | AH28: 是 | AI28: 是 | AJ28: 《国家电网有限公司电费业务管理办法（征求意见稿）》第五章 采集抄表 | AK28: 国网营销部 | AL28: 无变化，直接引用 | AM28: 无变化，直接引用 | AN28: 供服 | AO28: 计量 | AP28: 计量无意见 | AQ28: =A28=[1]营销售电!A28 -> TRUE | AR28: =B28=[1]营销售电!B28 -> TRUE | AS28: =C28=[1]营销售电!C28 -> TRUE | AT28: =D28=[1]营销售电!D28 -> TRUE | AU28: =E28=[1]营销售电!E28 -> TRUE | AV28: =F28=[1]营销售电!F28 -> TRUE | AW28: =G28=[1]营销售电!G28 -> TRUE | AX28: =H28=[1]营销售电!H28 -> TRUE | ... CA28: =AK28=[1]营销售电!AK28 -> TRUE
C29: 会计信息真实完整 | D29: 电量采集 | E29: 电量采集范围不完整、抄表周期不准确，导致电费收入未可靠计量。 | G29: 9.电能表示数采集 | H29: 电能表示数采集应规范完整、应抄尽抄 | I29: 营销售电业务-9.电能表示数采集-控制措施01 | J29: 电能表示数采集应由用电信息采集系统统一出口，采集范围应完整。 | M29: √ | T29: 系统已建 | U29: 新一代用电信息采集系统 | V29: 1.电能表采集数据； 2.电能表抄表工单 | W29: 各省（自治区、直辖市）电力公司-营销部门-计量管理人员 | X29: 每 半年 | Y29: 抽查 | AA29: 年度 | AB29: 抽查 | AH29: 是 | AI29: 是 | AJ29: 《国家电网有限公司电费业务管理办法（征求意见稿）》第五章 采集抄表 | AK29: 国网营销部 | AL29: 无变化，直接引用 | AM29: 无变化，直接引用 | AN29: 供服 | AO29: 计量 | AP29: 计量无意见 | AQ29: =A29=[1]营销售电!A29 -> TRUE | AR29: =B29=[1]营销售电!B29 -> TRUE | AS29: =C29=[1]营销售电!C29 -> TRUE | AT29: =D29=[1]营销售电!D29 -> TRUE | AU29: =E29=[1]营销售电!E29 -> TRUE | AV29: =F29=[1]营销售电!F29 -> TRUE | AW29: =G29=[1]营销售电!G29 -> TRUE | AX29: =H29=[1]营销售电!H29 -> TRUE | ... CA29: =AK29=[1]营销售电!AK29 -> TRUE
I30: 营销售电业务-9.电能表示数采集-控制措施02 | J30: 营销部门对全量用户抄表完整性开展在线监控。 | S30: √ | T30: 系统已建 | U30: 新一代用电信息采集系统、营销2.0系统 | V30: 1.电能表采集数据； 2.电能表抄表工单 | W30: 各级单位-营销部门-计量（抄表）管理/电费电价管理人员 | X30: 每季度 | Y30: 抽查 | AA30: 年度 | AB30: 抽查 | AD30: 应抄未抄监督——对全量用户抄表完整性开展在线监控 | AE30: 每月 | AF30: 全量 | AH30: 是 | AI30: 是 | AJ30: 《国家电网有限公司电费业务管理办法（征求意见稿）》第五章 采集抄表 | AK30: 国网营销部 | AL30: 无变化，但建议省公司优化系统。 | AM30: 建议在营销2.0系统增加抄表例日缺抄的监控界面。(供服） | AN30: 供服 | AO30: 计量 | AP30: 计量无意见 | AQ30: =A30=[1]营销售电!A30 -> TRUE | AR30: =B30=[1]营销售电!B30 -> TRUE | AS30: =C30=[1]营销售电!C30 -> TRUE | AT30: =D30=[1]营销售电!D30 -> TRUE | AU30: =E30=[1]营销售电!E30 -> TRUE | AV30: =F30=[1]营销售电!F30 -> TRUE | AW30: =G30=[1]营销售电!G30 -> TRUE | AX30: =H30=[1]营销售电!H30 -> TRUE | ... CA30: =AK30=[1]营销售电!AK30 -> TRUE
I31: 营销售电业务-9.电能表示数采集-控制措施03 | J31: 营销部门严格抄表周期管理，以自然月为周期对全体用户进行抄表，抄表周期调整履行严格审批程序。 | M31: √ | T31: 系统已建 | U31: 营销2.0系统 | V31: 1.电能表采集数据； 2.电能表抄表工单； 3.应参与本次抄表算费全量客户抄表信息、实际参与本次抄表算费全量客户抄表信息 | W31: 各级单位-营销部门-计量（抄表）管理/电费电价管理人员 | X31: 每 半年 | Y31: 抽查 | AA31: 年度 | AB31: 抽查 | AH31: 是 | AI31: 是 | AJ31: 《国家电网有限公司电费业务管理办法（征求意见稿）》第五章 采集抄表 | AK31: 国网营销部 | AL31: 无变化，直接引用 | AM31: 无变化，直接引用 | AN31: 省公司、供服、地市 | AO31: 计量、抄表、电费核算 | AP31: 电费专业无意见 | AQ31: =A31=[1]营销售电!A31 -> TRUE | AR31: =B31=[1]营销售电!B31 -> TRUE | AS31: =C31=[1]营销售电!C31 -> TRUE | AT31: =D31=[1]营销售电!D31 -> TRUE | AU31: =E31=[1]营销售电!E31 -> TRUE | AV31: =F31=[1]营销售电!F31 -> TRUE | AW31: =G31=[1]营销售电!G31 -> TRUE | AX31: =H31=[1]营销售电!H31 -> TRUE | ... CA31: =AK31=[1]营销售电!AK31 -> TRUE
I32: 营销售电业务-9.电能表示数采集-控制措施04 | J32: 营销部门应结合当地市场规则及电费结算相关协议确定月内抄表频次。 | M32: √ | T32: 线下管控 | V32: 市场规则及相关文件 | W32: 各省（自治区、直辖市）电力公司-营销部门-电费电价（抄表）管理人员 | X32: 每 半年 | Y32: 抽查 | AA32: 年度 | AB32: 抽查 | AH32: 是 | AI32: 是 | AJ32: 《国家电网有限公司电费业务管理办法（征求意见稿）》第五章 采集抄表 | AK32: 国网营销部 | AL32: 无变化，直接引用 | AM32: 无变化，直接引用 | AN32: 省公司、供服、地市 | AO32: 计量、抄表、电费核算 | AP32: 电费专业无意见 | AQ32: =A32=[1]营销售电!A32 -> TRUE | AR32: =B32=[1]营销售电!B32 -> TRUE | AS32: =C32=[1]营销售电!C32 -> TRUE | AT32: =D32=[1]营销售电!D32 -> TRUE | AU32: =E32=[1]营销售电!E32 -> TRUE | AV32: =F32=[1]营销售电!F32 -> TRUE | AW32: =G32=[1]营销售电!G32 -> TRUE | AX32: =H32=[1]营销售电!H32 -> TRUE | ... CA32: =AK32=[1]营销售电!AK32 -> TRUE
C33: 会计信息真实完整 | D33: 电量采集 | E33: 抄表结果异常，导致电费计算失真。 | F33: 20.营销系统权限管控不严：存在重要业务流程权限设置不合规；电费收费、账务处理、财务审核和违约用电查处、审批等不相容岗位未分离；信息系统权限未严格落实实名制，账号权限与实际权责不符、一人存在多个账号等问题。 | G33: 10.电量采集结果确认 | H33: 电量采集结果应完整、准确 | I33: 营销售电业务-10.电量采集结果确认-控制措施01 | J33: 营销部门建立电量采集结果集中复核机制，健全复核规则，异常事项消缺纳入在线管控。 | M33: √ | T33: 系统已建 | U33: 营销2.0系统 | V33: 电能表采集数据 | W33: 各省（自治区、直辖市）电力公司-营销部门-计量（抄表）管理人员 | X33: 每年 | Y33: 抽查 | AA33: 年度 | AB33: 抽查 | AH33: 是 | AI33: 是 | AJ33: 《国家电网有限公司电费业务管理办法（征求意见稿）》第五章 采集抄表 | AK33: 国网营销部 | AL33: 待定 | AM33: 待定 | AN33: 省公司、供服、地市 | AO33: 计量、营业 | AP33: 计量无意见 | AQ33: =A33=[1]营销售电!A33 -> TRUE | AR33: =B33=[1]营销售电!B33 -> TRUE | AS33: =C33=[1]营销售电!C33 -> TRUE | AT33: =D33=[1]营销售电!D33 -> TRUE | AU33: =E33=[1]营销售电!E33 -> TRUE | AV33: =F33=[1]营销售电!F33 -> TRUE | AW33: =G33=[1]营销售电!G33 -> TRUE | AX33: =H33=[1]营销售电!H33 -> TRUE | ... CA33: =AK33=[1]营销售电!AK33 -> TRUE
I34: 营销售电业务-10.电量采集结果确认-控制措施02 | J34: 营销部门对抄表异常事项消缺实行工单化管理，对不影响量费调整的异常事项消缺，执行本级确认后闭环。对影响量费调整的异常事项消缺，执行分级授权审批机制。 | L34: √ | M34: √ | T34: 系统已建 | U34: 营销2.0系统 | V34: 采集异常工单及审核审批记录 | W34: 各级单位-营销部门-计量（抄表）管理及各级审批人员 | X34: 每 半年 | Y34: 抽查 | AA34: 年度 | AB34: 抽查 | AH34: 是 | AI34: 是 | AJ34: 《国家电网有限公司电费业务管理办法（征求意见稿）》第五章 采集抄表 | AK34: 国网营销部 | AL34: 无变化，直接引用 | AM34: 无变化，直接引用 | AN34: 地市 | AO34: 计量、营业 | AP34: 计量无意见 | AQ34: =A34=[1]营销售电!A34 -> TRUE | AR34: =B34=[1]营销售电!B34 -> TRUE | AS34: =C34=[1]营销售电!C34 -> TRUE | AT34: =D34=[1]营销售电!D34 -> TRUE | AU34: =E34=[1]营销售电!E34 -> TRUE | AV34: =F34=[1]营销售电!F34 -> TRUE | AW34: =G34=[1]营销售电!G34 -> TRUE | AX34: =H34=[1]营销售电!H34 -> TRUE | ... CA34: =AK34=[1]营销售电!AK34 -> TRUE
A35: 营销售电业务 | B35: 四、电费核算与发行管理 | C35: 会计信息真实完整 | D35: 量费计算 | E35: 未严格执行电费计算规则，电费计算结果未经有效复核，导致电费计算结果失真。 | G35: 11.电费计算结果复核 | H35: 电费核算与复核规则应纳入统一管理 | I35: 营销售电业务-11.电费计算结果复核-控制措施01 | J35: 国网营销部对电费核算与复核规则进行集中管理、二级配置与实施，规则应及时动态更新。 | M35: √ | T35: 系统已建 | U35: 营销2.0系统 | V35: 系统电费核算与复核规则 | W35: 国网营销部-电费电价管理人员；各省（自治区、直辖市）电力公司-营销部门-电费电价管理人员 | X35: 每年 | Y35: 抽查 | AA35: 年度 | AB35: 抽查 | AH35: 是 | AI35: 是 | AJ35: 《国家电网有限公司电费业务管理办法（征求意见稿）》第七章 核算出账 | AK35: 国网营销部 | AL35: 无变化，直接引用 | AM35: 无变化，直接引用 | AN35: 国网营销部、省公司 | AO35: 电费电价 | AP35: 电费专业无意见 | AQ35: =A35=[1]营销售电!A35 -> TRUE | AR35: =B35=[1]营销售电!B35 -> TRUE | AS35: =C35=[1]营销售电!C35 -> TRUE | AT35: =D35=[1]营销售电!D35 -> TRUE | AU35: =E35=[1]营销售电!E35 -> TRUE | AV35: =F35=[1]营销售电!F35 -> TRUE | AW35: =G35=[1]营销售电!G35 -> TRUE | AX35: =H35=[1]营销售电!H35 -> TRUE | ... CA35: =AK35=[1]营销售电!AK35 -> TRUE
I36: 营销售电业务-11.电费计算结果复核-控制措施02 | J36: 省公司营销部门应确保通用规则执行到位，对个性化补充规则严格履行审批程序后实施。 | M36: √ | T36: 系统已建 | U36: 营销2.0系统 | V36: 1.系统电费核算与复核规则； 2.系统个性化规则授权审批记录 | W36: 各省（自治区、直辖市）电力公司-营销部门-电费电价管理人员 | X36: 每年 | Y36: 抽查 | AA36: 年度 | AB36: 抽查 | AH36: 是 | AI36: 是 | AJ36: 《国家电网有限公司电费业务管理办法（征求意见稿）》第七章 核算出账 | AK36: 国网营销部 | AL36: 无变化，直接引用 | AM36: 无变化，直接引用 | AN36: 省公司 | AO36: 电费电价 | AP36: 电费专业无意见 | AQ36: =A36=[1]营销售电!A36 -> TRUE | AR36: =B36=[1]营销售电!B36 -> TRUE | AS36: =C36=[1]营销售电!C36 -> TRUE | AT36: =D36=[1]营销售电!D36 -> TRUE | AU36: =E36=[1]营销售电!E36 -> TRUE | AV36: =F36=[1]营销售电!F36 -> TRUE | AW36: =G36=[1]营销售电!G36 -> TRUE | AX36: =H36=[1]营销售电!H36 -> TRUE | ... CA36: =AK36=[1]营销售电!AK36 -> TRUE
I37: 营销售电业务-11.电费计算结果复核-控制措施03 | J37: 营销部门建立量费核算结果集中复核机制，异常事项消缺实行工单化管理，并明确分级分类审批标准。 | L37: √ | M37: √ | T37: 系统已建 | U37: 营销2.0系统 | V37: 量费异常工单及审核审批记录 | W37: 各级单位-营销部门-电费电价管理及各级审批人员 | X37: 每 半年 | Y37: 抽查 | AA37: 年度 | AB37: 抽查 | AH37: 是 | AI37: 是 | AJ37: 《国家电网有限公司电费业务管理办法（征求意见稿）》第七章 核算出账 | AK37: 国网营销部 | AL37: 无变化，直接引用 | AM37: 无变化，直接引用 | AN37: 供服、地市 | AO37: 电费电价 | AP37: 电费专业无意见 | AQ37: =A37=[1]营销售电!A37 -> TRUE | AR37: =B37=[1]营销售电!B37 -> TRUE | AS37: =C37=[1]营销售电!C37 -> TRUE | AT37: =D37=[1]营销售电!D37 -> TRUE | AU37: =E37=[1]营销售电!E37 -> TRUE | AV37: =F37=[1]营销售电!F37 -> TRUE | AW37: =G37=[1]营销售电!G37 -> TRUE | AX37: =H37=[1]营销售电!H37 -> TRUE | ... CA37: =AK37=[1]营销售电!AK37 -> TRUE
C38: 会计信息真实完整、资金资产安全 | D38: 电费发行 | E38: 违规减免电费，导致收入不实、资金损失。 | F38: 20.营销系统权限管控不严：存在重要业务流程权限设置不合规；电费收费、账务处理、财务审核和违约用电查处、审批等不相容岗位未分离；信息系统权限未严格落实实名制，账号权限与实际权责不符、一人存在多个账号等问题。 | G38: 12.电费发行确认 | H38: 电费发行应真实、完整、准确 | I38: 营销售电业务-12.电费发行确认-控制措施01 | J38: 营销部门统一配置电费发行规则，强化电费发行与核算一体化管控，严禁手工篡改发行数据。 | M38: √ | T38: 系统已建 | U38: 营销2.0系统 | V38: 1.系统电费发行工单流转记录； 2.岗位权限配置 | W38: 各省（自治区、直辖市）电力公司-营销部门-电费电价管理人员 | X38: 每年 | Y38: 抽查 | AA38: 年度 | AB38: 抽查 | AH38: 是 | AI38: 是 | AJ38: 《国家电网有限公司电费业务管理办法（征求意见稿）》第七章 核算出账 国网湖南电力营销部关于印发电费结算管理办法的通知（营销〔2022〕27号） 国网湖南电力营销部关于加强电量电费差错风险防控工作的通知（营销〔2024〕36号） | AK38: 国网营销部 | AL38: 新增制度完善清单 | AM38: 新增制度完善清单 | AN38: 供服 | AO38: 电费电价 | AP38: 电价专业无意见 | AQ38: =A38=[1]营销售电!A38 -> TRUE | AR38: =B38=[1]营销售电!B38 -> TRUE | AS38: =C38=[1]营销售电!C38 -> TRUE | AT38: =D38=[1]营销售电!D38 -> TRUE | AU38: =E38=[1]营销售电!E38 -> TRUE | AV38: =F38=[1]营销售电!F38 -> TRUE | AW38: =G38=[1]营销售电!G38 -> TRUE | AX38: =H38=[1]营销售电!H38 -> TRUE | ... CA38: =AK38=[1]营销售电!AK38 -> TRUE
I39: 营销售电业务-12.电费发行确认-控制措施02 | J39: 营销部门协同交易明确月末预估量价规则，预估到日，预估结果确认严格履行审批程序，防止人为调整。 | M39: √ | T39: 系统已建 | U39: 营销2.0系统 | V39: 1.系统电费发行工单流转记录； 2.系统电费退补审批记录及支撑依据； 3.岗位权限配置 | W39: 各省（自治区、直辖市）电力公司-营销部门-电费电价管理人员 | X39: 每 季度 | Y39: 抽查 | AA39: 年度 | AB39: 抽查 | AH39: 是 | AI39: 是 | AJ39: 《国家电网有限公司电费业务管理办法（征求意见稿）》第七章 核算出账 | AK39: 国网营销部 | AL39: 修改控制措施 | AM39: 修改说明：删除预估到日。因国网电费管理办法中未要求预估到日，实际业务是按月预估 | AN39: 供服 | AO39: 电费电价 | AP39: 电价专业无意见 | AQ39: =A39=[1]营销售电!A39 -> TRUE | AR39: =B39=[1]营销售电!B39 -> TRUE | AS39: =C39=[1]营销售电!C39 -> TRUE | AT39: =D39=[1]营销售电!D39 -> TRUE | AU39: =E39=[1]营销售电!E39 -> TRUE | AV39: =F39=[1]营销售电!F39 -> TRUE | AW39: =G39=[1]营销售电!G39 -> TRUE | AX39: =H39=[1]营销售电!H39 -> TRUE | ... CA39: =AK39=[1]营销售电!AK39 -> TRUE
I40: 营销售电业务-12.电费发行确认-控制措施03 | J40: 各单位业务核算人员在算费前，对当月审核规则拦截的涉费工单进行逐一检查，督导处理归档。 | M40: √ | T40: 系统已建 | U40: 营销2.0系统 | V40: 系统试算工单流转记录 | W40: 各级单位-营销部门-业务核算人员 | X40: 每半年 | Y40: 抽查 | AA40: 年度 | AB40: 抽查 | AH40: 是 | AI40: 是 | AJ40: 《国家电网有限公司电费业务管理办法（征求意见稿）》第七章 核算出账 | AK40: 国网营销部 | AL40: 无变化，直接引用 | AM40: 无变化，直接引用 | AN40: 供服、地市 | AO40: 电费电价 | AP40: 电费专业无意见 | AQ40: =A40=[1]营销售电!A40 -> TRUE | AR40: =B40=[1]营销售电!B40 -> TRUE | AS40: =C40=[1]营销售电!C40 -> TRUE | AT40: =D40=[1]营销售电!D40 -> TRUE | AU40: =E40=[1]营销售电!E40 -> TRUE | AV40: =F40=[1]营销售电!F40 -> TRUE | AW40: =G40=[1]营销售电!G40 -> TRUE | AX40: =H40=[1]营销售电!H40 -> TRUE | ... CA40: =AK40=[1]营销售电!AK40 -> TRUE
...

Sheet 典设
A1: 风控矩阵-营销售电
A2: 业务条线 | B2: 业务领域 | C2: 控制目标 | D2: 业务流程步骤 | E2: 经营风险 | F2: 对应屡查屡犯问题清单 | G2: 关键控制节点 | H2: 控制要求与措施 | I2: 控制措施数量 | M2: 控制方式 | N2: 控制系统 | O2: 控制措施分类 | X2: 责任主体 | Y2: 业务自评价 | AC2: 集团监督评价 | AD2: 集团监督评价 | AG2: 数字化监督场景 | AK2: 现有制度及文件落实情况 | AN2: 总部审核部门
I3: 总数量 | J3: 系统-已有数量 | K3: 系统-待建数量 | L3: 线下数量 | O3: 不相容岗位 | P3: 分级授权 | Q3: 业务真实性校验 | R3: 预算管控 | S3: 合同控制 | T3: 收付控制 | U3: 会计监督 | V3: 财产保护 | W3: 分析与评价 | Y3: 评价频率 | Z3: 评价范围 | AA3: 查阅资料 （原始凭证文件） | AB3: 评价结论 | AC3: 评价程序 | AD3: 评价频率 | AE3: 评价范围 | AF3: 评价结论 | AG3: 数字化监督场景 | AH3: 评价频率 | AI3: 评价范围 | AJ3: 评价结论 | AK3: 是否已要求 | AL3: 是否满足要求 | AM3: 对应制度及文件名称
A4: 营销售电业务 | B4: 一、客户信息与合同签订管理 | C4: 会计信息真实完整、资金资产安全 | D4: 业扩报装受理 | E4: 客户信息录入不准确，与现场不一致，引发虚假立户及电费收取不规范风险。 | F4: 19.两部制电价执行不正确：存在应执行未执行两部制电价、分户报装规避两部制电价、变更用电少收基本电费、需量基本电费计收不准确等问题。 | G4: 1.系统客户信息创建 | H4: 控制要求：系统客户信息应与客户报装资料、现场用电情况一致。 控制措施： 1.营销部业务受理人员根据客户报装资料做好系统客户信息的创建，并对报装资料完整性、有效性负责；（线下） 2.营销部业务办理人员结合现场勘查情况对客户关键信息真实性、准确性复核，业务受理与业务办理执行不相容控制；（线下） 3.营销部对分户报装规避基本电费、违规改变用电性质等开展数字化在线监督与现场检查。（系统-已有） 内控载体： 1.系统业扩工单； 2.客户报装原始资料； 3.系统客户档案； 4.系统授权审批记录； 5.工商登记信息。 | I4: 3 | J4: 1 | L4: 2 | M4: 人工控制 系统自动控制 | N4: 营销2.0系统 | O4: √ | Q4: √ | W4: √ | X4: 各单位-营销部-综合柜员、客户经理 | Y4: 年度 | Z4: 抽查 | AA4: 包括不限于： 1、系统业扩工单 2、系统客户档案 3、客户工商登记信息 4、系统授权审批记录 | AC4: 1、检查客户信息登记的完整性，复核已登记客户的工商信息； 2、检查业务经办人与审核人符合不相容岗位分离的原则，避免同一人员同时进行业务办理与审核。 | AD4: 年度 | AE4: 抽查 | AG4: 分户报装规避基本电费监测 | AH4: 每季度 | AI4: 抽查 | AK4: 是 | AL4: 是 | AM4: 《国家电网有限公司业扩报装管理规则（征求意见稿）》第三章 业务受理 | AN4: 营销部
C5: 会计信息真实完整、资金资产安全 | D5: 方案答复与工程实施 | E5: 客户用电容量核定不准确、录入错误，导致基本电费执行不准确、电费少收。 | F5: 19.两部制电价执行不正确：存在应执行未执行两部制电价、分户报装规避两部制电价、变更用电少收基本电费、需量基本电费计收不准确等问题。 | G5: 2.客户用电容量的确定 | H5: 控制要求：系统容量与现场用电情况保持一致。 控制措施： 1.营销部现场勘查人员应准确核定客户用电容量与负荷性质，确保计量、计费方案、供电方式等准确；（线下） 2.对于加装变压器的高压客户，需取得变压器出厂合格证明及型式试验报告等容量信息佐证材料并上传系统，确保系统录入容量与现场用电情况一致；（系统-已有） 3.营销部对超容用电、基本电费异常、高可靠性供电费收取不规范开展数字化在线监督与现场检查。（系统-已有） 内控载体： 1.系统业扩工单（现场勘查验收单）； 2.客户报装原始资料（含用电负荷清单、变压器出厂合格证明及型式试验报告等）； 3.系统客户档案； 4.系统授权审批记录。 | I5: 3 | J5: 2 | L5: 1 | M5: 人工控制 系统自动控制 | N5: 营销2.0系统 | O5: √ | Q5: √ | W5: √ | X5: 各单位-营销部-综合柜员、客户经理 | Y5: 年度 | Z5: 抽查 | AA5: 包括不限于： 1、系统业扩工单 2、客户报装原始资料 3、系统客户档案 4、系统授权审批记录 | AC5: 检核复核客户报装单、作业单、设备领用记录、营销系统客户档案等业务资料，财务结算凭证等，确保业务真实，各项信息记录一致。 | AD5: 年度 | AE5: 抽查 | AG5: 客户容量与电量联动监测​​ | AH5: 每季度 | AI5: 抽查 | AK5: 是 | AL5: 是 | AM5: 《国家电网有限公司业扩报装管理规则（征求意见稿）》第四章 供电方案编制及答复 | AN5: 营销部
C6: 会计信息真实完整、资金资产安全 | D6: 客户信息变更 | E6: 客户信息变更不合规，导致电费计收不准确，引发合规风险。 | F6: 19.两部制电价执行不正确：存在应执行未执行两部制电价、分户报装规避两部制电价、变更用电少收基本电费、需量基本电费计收不准确等问题。 | G6: 3.系统客户信息变更 | H6: 控制要求：客户关键信息变更应结合业务工单联动调整，严禁无业务动因创建或修改客户信息行为。 控制措施： 1.营销部对客户户名、电价、用电容量等关键信息的变更，应结合变更业务联动调整并经审批后实施，业务受理与审批执行不相容控制；（系统-已有） 2.营销部对影响价费关键信息的变更业务开展现场查验，确保用电信息与现场一致。（线下） 内控载体： 1.系统变更工单； 2.客户变更原始资料； 3.系统客户档案； 4.系统授权审批记录。 | I6: 2 | J6: 1 | L6: 1 | M6: 人工控制 系统自动控制 | N6: 营销2.0系统 | O6: √ | Q6: √ | X6: 各单位-营销部-综合柜员、客户经理、电费电价 | Y6: 年度 | Z6: 抽查 | AA6: 包括不限于： 1、系统客户档案 2、系统业扩工单 3、系统授权审批记录 | AC6: 1、检查客户关键信息变更的必要性、合理性，保证信息变更依据充分，支撑资料完整。 2、检查信息变更经办人与审核人符合不相容岗位分离的原则，避免同一人员同时进行信息变更录入与审核。 | AD6: 年度 | AE6: 抽查 | AG6: — | AH6: — | AI6: — | AK6: 是 | AL6: 是 | AM6: 《变更用电业务规则（试行）》 | AN6: 营销部
C7: 会计信息真实完整、资金资产安全 | D7: 合同签订 | E7: 合同签订未使用公司统一且生效文本，导致电费计收合法权益无法得到保障。 | G7: 4.供用电合同签订 | H7: 控制要求：供用电合同签订应使用公司统一且生效的文本。 控制措施： 1.国网营销部统一管理合同文本，并明确执行要求、生效时间，及客户业务变更时不需重签合同的业务类型；（系统-已有） 2.营销部合同签订人员应严格使用统一且生效文本；（系统-已有）； 3.营销部合同审核人员对合同文本使用情况开展审核，合同经办与审核执行不相容控制；（线下） 4.营销部对统一文本之外的特殊约定事项，明确分级审批范围，履行审批流程。（线下） 内控载体： 1.供用电合同； 2.合同统一文本； 3.系统合同信息； 4.系统合同签订及审批记录。 | I7: 4 | J7: 2 | L7: 2 | M7: 人工控制 系统自动控制 | N7: 营销2.0系统 | O7: √ | P7: √ | S7: √ | X7: 总部-营销部-合同管理；各省公司-营销部-合同管理；各单位-营销部-合同管理 | Y7: 年度 | Z7: 抽查 | AA7: 包括不限于： 1、现行有效的合同统一文本 2、供用电合同 3、合同签订及审批记录 | AC7: 1、检查供用电合同归口管理情况，合同文本应使用公司统一模板； 2、供用电合同应及时签订并按规定权限履行复核、审批程序。 | AD7: 年度 | AE7: 抽查 | AG7: — | AH7: — | AI7: — | AK7: 是 | AL7: 否 | AM7: 《国家电网有限公司电费业务管理办法（征求意见稿）》第四章 合同协议 建议明确统一文本执行及特殊约定事项 | AN7: 营销部
C8: 会计信息真实完整、资金资产安全 | D8: 合同签订 | E8: 合同条款与客户报装信息、现场不一致，导致公司收支条款失效，合法权益无法得到保障。 | G8: 5.供用电合同审核 | H8: 控制要求：合同关键信息与客户报装信息保持一致。 控制措施： 1.营销部合同签订人员要确保合同客户信息与业扩报装产生的客户信息保持一致，不得变更；（系统-已有） 2.营销部合同审核人员对合同信息与业扩报装产生的信息一致性进行复核，合同经办与审核执行不相容控制；（线下） 3.营销部合同管理人员应落实合同签订一致性要求，加强系统上传合同与线下纸质合同一致性管控；（系统-已有） 4.营销部对系统合同上传及生效情况开展数字化在线监测（系统-待建）。 内控载体： 1.供用电合同（线下）； 2.系统合同信息； 3.系统客户信息。 | I8: 4 | J8: 2 | K8: 1 | L8: 1 | M8: 人工控制 系统自动控制 | N8: 营销2.0系统 | O8: √ | Q8: √ | S8: √ | W8: √ | X8: 各省公司-营销部-合同管理；各单位-营销部-合同管理 | Y8: 年度 | Z8: 抽查 | AA8: 包括不限于： 1、供用电合同 2、系统客户档案 | AC8: 检查复核合同客户信息与营销系统档案信息的一致性。 | AD8: 年度 | AE8: 抽查 | AG8: 系统生效合同在线监督 | AH8: 每季度 | AI8: 抽查 | AK8: 是 | AL8: 否 | AM8: 《国家电网有限公司电费业务管理办法（征求意见稿）》第四章 合同协议 建议明确合同签订及线上化要求 | AN8: 营销部
B9: 二、电价执行管理 | C9: 会计信息真实完整、资金资产安全 | D9: 电价码制定 | E9: 电价政策执行不到位，系统配置不准确，导致公司电费收入计量不准确、不合规。 | G9: 6.电价码制定与执行 | H9: 控制要求：电价标准与政策匹配，电价码准确配置与执行。 控制措施： 1.财务部根据国家或省内价格政策将电价政策解析形成每类客户执行标准；（线下） 2.营销部匹配形成标准电价码，电价码制定及下发执行审批与复核控制；（线下） 3.营销部建立电价码与分类客户对应关系，并在系统进行配置，确保电价码精准匹配到户；（系统-已有） 4.财务部、营销部对电价码配置与执行情况开展数字化在线监督（系统-待建）。 内控载体： 1.电价政策文件； 2.电价标准与电价码匹配记录； 3.电价码部署及下发记录。 | I9: 4 | J9: 1 | K9: 1 | L9: 2 | M9: 人工控制 系统自动控制 | N9: 智慧财务、营销2.0系统 | O9: √ | P9: √ | Q9: √ | W9: √ | X9: 各省公司-营销部-电费电价；各省公司-财务部-销售电价管理 | Y9: 年度 | Z9: 抽查 | AA9: 包括不限于： 1、电力价格政策文件 2、电价码标准与电价政策文件对应记录 3、电价码部署及下发情况 | AC9: 检查价格管理人员收集价格政策的及时性、准确性，及时完成电价标准的制定与维护工作。 | AD9: 年度 | AE9: 抽查 | AG9: 电价码配置与执行情况监督 | AH9: 每半年； 每季度 | AI9: 全量 | AK9: 是 | AL9: 是 | AM9: 《国网营销部国网财务部国网数字化部关于加快标准化电价码部署应用的通知》（营销营业〔2025〕83号） | AN9: 财务部、营销部
C10: 会计信息真实完整、资金资产安全 | D10: 电价执行 | E10: 电价执行与客户用电性质不匹配，造成公司或用户电费资金损失，收入不实 | F10: 19.两部制电价执行不正确：存在应执行未执行两部制电价、分户报装规避两部制电价、变更用电少收基本电费、需量基本电费计收不准确等问题。 | G10: 7.客户电价执行管控 | H10: 控制要求：客户电价执行与用电性质、行业类别等精准匹配。 控制措施： 1.营销部业务受理人员应严格按照客户用电性质、行业类别等匹配执行标准电价码并准确录入系统，经审核后生效，业务办理与审核执行不相容控制；（系统-已有） 2.营销部应加强客户电价变更管理，对于电价政策变动导致的电价变更应结合电价码联动调整，对于客户用电性质改变导致的电价变更应严格执行与工单关联，其他类型电价变更严格执行授权审批后进行调整；（系统-已有） 3.营销部对客户电价执行及变更情况开展数字化在线监督（系统-已有）。 内控载体： 1.系统业务工单记录； 2.系统客户电价信息。 | I10: 3 | J10: 3 | M10: 系统自动控制 | N10: 营销2.0系统 | O10: √ | Q10: √ | W10: √ | X10: 各省公司-营销部-电费电价；各省公司-财务部-销售电价管理；各单位-营销部-电费电价 | Y10: 半年度 | Z10: 抽查 | AA10: 包括不限于： 1、电价变更工单记录 2、电价码标准与电价政策文件对应记录 3、电价码变更审批记录 | AC10: 1、检查新制定的标准电价应及时准确的录入营销系统，审批人员应对客户用电性质、行业类别、合同主要条款与标准电价匹配复核，保证结算的准确性； 2、检查电价录入与审核符合不相容岗位分离的原则，避免同一人员同时进行标准电价录入与审核工作。 | AD10: 年度 | AE10: 抽查 | AG10: 客户电价执行及变更情况在线监测 | AH10: 每季度 | AI10: 全量 | AK10: 是 | AL10: 否 | AM10: 《国家电网有限公司电费业务管理办法（征求意见稿）》第三章 电价执行 | AN10: 营销部
B11: 三、电量采集管理 | C11: 会计信息真实完整 | D11: 电量采集 | E11: 未严格执行采集策略，导致电量计量失真。 | G11: 8.采集规则配置 | H11: 控制要求：电能表示数采集策略应纳入统一管理。 控制措施： 1.营销部要建立电能表示数采集策略统一管理机制，强化规则配置与实施管理；（系统-已有） 2.营销部对电能表示数采集策略执行情况开展复核与监督。（系统-已有） 内控载体： 1.系统电能表采集策略； 2.电能表采集规则个性化配置审批记录。 | I11: 2 | J11: 2 | M11: 系统自动控制 | N11: 用电信息采集系统、营销2.0系统 | O11: √ | P11: √ | Q11: √ | X11: 各省公司-营销部-计量管理 | Y11: 年度 | Z11: 抽查 | AA11: 包括不限于： 1、计量采集规则 2、计量采集规则变更审批记录 | AC11: 检查电量采集规则的统一性、合理性，各环节业务操作人员权限设置符合不相容岗位分离原则。 | AD11: 年度 | AE11: 抽查 | AG11: — | AH11: — | AI11: — | AK11: 是 | AL11: 是 | AM11: 《国家电网有限公司电费业务管理办法（征求意见稿）》第五章 采集抄表 | AN11: 营销部
C12: 会计信息真实完整 | D12: 电量采集 | E12: 电量采集范围不完整、抄表周期不准确，导致电费收入未可靠计量。 | G12: 9.电能表示数采集 | H12: 控制要求：电能表示数采集应规范完整、应抄尽抄。 控制措施： 1.电能表示数采集应由用电信息采集系统统一出口，采集范围应完整，营销部对全量用户抄表完整性开展在线监控；（系统-已有） 2.营销部严格抄表周期管理，以自然月为周期对全体用户进行抄表，抄表周期调整履行严格审批程序；（系统-已有） 3.营销部应结合当地市场规则及电费结算相关协议确定月内抄表频次。（线下） 内控载体： 1.系统抄表工单； 2.系统客户抄表记录。 | I12: 3 | J12: 2 | L12: 1 | M12: 人工控制 系统自动控制 | N12: 用电信息采集系统、营销2.0系统 | O12: √ | P12: √ | Q12: √ | W12: √ | X12: 各省公司-营销部-计量管理、电费电价；各单位-营销部-采集抄表、业务核算、客户经理 | Y12: 年度 | Z12: 抽查 | AA12: 包括不限于： 1、计量采集规则 2、计量采集规则变更审批记录 | AC12: 检查抄表周期的统一性，按照当地市场规则制定统一的抄表机制。 | AD12: 年度 | AE12: 抽查 | AG12: 电量全量采集在线监督 | AH12: 每月 | AI12: 全量 | AK12: 是 | AL12: 是 | AM12: 《国家电网有限公司电费业务管理办法（征求意见稿）》第五章 采集抄表 | AN12: 营销部
C13: 会计信息真实完整 | D13: 电量采集 | E13: 抄表结果异常，导致电费计算失真。 | F13: 20.营销系统权限管控不严：存在重要业务流程权限设置不合规；电费收费、账务处理、财务审核和违约用电查处、审批等不相容岗位未分离；信息系统权限未严格落实实名制，账号权限与实际权责不符、一人存在多个账号等问题。 | G13: 10.电量采集结果确认 | H13: 控制要求：电量采集结果应完整、准确。 控制措施： 1.营销部建立电量采集结果集中复核机制，健全复核规则，异常事项消缺纳入在线管控；（系统-已有） 2.营销部对异常事项消缺实行工单化管理，对不影响量费调整的异常事项消缺，执行本级确认后闭环；对影响量费调整的异常事项消缺，执行分级授权审批机制。（系统-已有） 内控载体： 1.系统电量采集结果复核规则； 2.系统异常事项处理及审批记录； 3.岗位权限配置。 | I13: 2 | J13: 2 | M13: 系统自动控制 | N13: 营销2.0系统 | O13: √ | P13: √ | Q13: √ | X13: 各省公司-营销部-电费电价；各单位-营销部-业务核算、采集抄表、客户经理 | Y13: 半年度 | Z13: 抽查 | AA13: 包括不限于： 1、计量采集结果复核规则 2、计量采集结果复核规则变更审批记录 | AC13: 检查省公司电量采集结果复核情况，建立重点对异常数据进行复核分析机制。 | AD13: 年度 | AE13: 抽查 | AG13: — | AH13: — | AI13: — | AK13: 是 | AL13: 是 | AM13: 《国家电网有限公司电费业务管理办法（征求意见稿）》第五章 采集抄表 | AN13: 营销部
B14: 四、电费核算与发行管理 | C14: 会计信息真实完整 | D14: 量费计算 | E14: 未严格执行电费计算规则，导致电费计算失真。 | G14: 11.电费计算结果复核 | H14: 控制要求：电费核算与复核规则应纳入统一管理。 控制措施： 1.国网营销部对电费核算与复核规则进行集中管理、二级配置与实施；（系统-已有） 2.省公司营销部应确保通用规则执行到位；（系统-已有） 3.省公司营销部对个性化补充规则严格履行审批程序后实施。（线下） 内控载体： 1.系统电费核算与复核规则； 2.系统个性化规则授权审批记录。 | I14: 3 | J14: 2 | L14: 1 | M14: 人工控制 系统自动控制 | N14: 营销2.0系统 | O14: √ | P14: √ | Q14: √ | X14: 总部-营销部-电费电价；各省公司-营销部-电费电价 | Y14: 半年度 | Z14: 抽查 | AA14: 包括不限于： 1、电费核算规则 2、电费核算规则分级下发记录 3、电费核算规则提报审批记录 | AC14: 检查电费核算执行情况，保证通用规则执行到位，对于差异化补充规则应报国网总部审批。 | AD14: 年度 | AE14: 抽查 | AG14: — | AH14: — | AI14: — | AK14: 是 | AL14: 是 | AM14: 《国家电网有限公司电费业务管理办法（征求意见稿）》第七章 核算出账 | AN14: 营销部
C15: 会计信息真实完整、资金资产安全 | D15: 电费发行 | E15: 违规减免电费，导致收入不实、资金损失。 | F15: 20.营销系统权限管控不严：存在重要业务流程权限设置不合规；电费收费、账务处理、财务审核和违约用电查处、审批等不相容岗位未分离；信息系统权限未严格落实实名制，账号权限与实际权责不符、一人存在多个账号等问题。 | G15: 12.电费发行确认 | H15: 控制要求：电费发行应真实、完整、准确。 控制措施： 1.营销部统一配置电费发行规则，强化电费发行与核算一体化管控，严禁手工篡改发行数据；（系统-已有） 2.营销部协同交易明确月末预估量价规则，预估到日，预估结果确认严格履行审批程序，防止人为调整；（系统-已有） 3.各单位业务核算人员在算费前，对当月审核规则拦截的涉费工单进行逐一检查，督导处理归档；（线下） 4.营销部对非政策性电费退补应严格履行分级审批程序；（系统-已有） 5.营销部对非政策性电费退补开展数字化在线监督。（系统-已有） 内控载体： 1.系统电费发行工单流转记录； 2.系统电费退补审批记录及支撑依据； 3.岗位权限配置。 | I15: 5 | J15: 4 | L15: 1 | M15: 人工控制 系统自动控制 | N15: 营销2.0系统 | O15: √ | P15: √ | Q15: √ | W15: √ | X15: 各省公司营销部-电费电价；各单位-营销部-业务核算 | Y15: 年度 | Z15: 抽查 | AA15: 包括不限于： 1、电费核算结果数据 2、电费发行数据 | AC15: 检查电费核算与发行的一体化建设情况，严禁人为更改相关数据。 | AD15: 年度 | AE15: 抽查 | AG15: 非政策性电费退补在线监督 | AH15: 每月 | AI15: 全量 | AK15: 是 | AL15: 是 | AM15: 《国家电网有限公司电费业务管理办法（征求意见稿）》第七章 核算出账 | AN15: 营销部
C16: 会计信息真实完整、资金资产安全 | D16: 业务费确认 | E16: 业务费收取不规范，造成电费资金损失。 | F16: 18.违约窃电查处不规范：存在未及时查处用户违约用电、窃电行为；违规减免、暂缓应补交的追补电费和违约使用电费等问题。 20.营销系统权限管控不严：存在重要业务流程权限设置不合规；电费收费、账务处理、财务审核和违约用电查处、审批等不相容岗位未分离；信息系统权限未严格落实实名制，账号权限与实际权责不符、一人存在多个账号等问题。 | G16: 13.业务费确认 | H16: 控制要求：业务费应足额、准确收取。 控制措施： 1.营销部应严格执行价格主管部门批准的收费项目和计算标准，统一配置业务费计费规则，严禁手工修改系统计算结果；（系统-已有） 2.营销部对业务费减免（暂缓、退费等）严格履行分级审批程序后实施，并确保足额收取；（系统-已有） 3.营销部对违规减免（暂缓）业务费开展数字化在线监督。（系统-已有） 内控载体： 1.业务费收费标准； 2.系统业务费调整（退费）审批记录及支撑依据； 3.岗位权限配置。 | I16: 3 | J16: 3 | M16: 系统自动控制 | N16: 营销2.0系统 | O16: √ | P16: √ | Q16: √ | W16: √ | X16: 各省公司营销部-电费电价；各单位-营销部-业务核算 | Y16: 年度 | Z16: 抽查 | AA16: 包括不限于： 1、计费结果异常事项清单 2、销号处理审批记录及工单流转记录 | AC16: 检查电计费结果异常事项处理情况，异常事项处理完成后，经销号人员与审批人共同确认，进行销号闭环处理。 | AD16: 年度 | AE16: 抽查 | AG16: 违规减免（暂缓）业务费监督 | AH16: 每月 | AI16: 全量 | AK16: 是 | AL16: 是 | AM16: 《供电营业规则》 | AN16: 营销部
C17: 会计信息真实完整、资金资产安全 | D17: 电费违约金减免 | E17: 违规减免电费违约金，掩盖其欠费事实，后期存在电费无法回收风险。 | F17: 17.违规减免电费违约金：存在电费未足额收回，通过全减另发等方式违规减免应收电费；违规减免或暂缓电费违约金等问题。 20.营销系统权限管控不严：存在重要业务流程权限设置不合规；电费收费、账务处理、财务审核和违约用电查处、审批等不相容岗位未分离；信息系统权限未严格落实实名制，账号权限与实际权责不符、一人存在多个账号等问题。 | G17: 14.电费违约金减免 | H17: 控制要求：电费违约金应足额、准确收取。 控制措施： 1.营销部明确电费违约金减免（暂缓）适用情形、支撑材料及分级授权标准；（线下） 2.营销部统一配置电费违约金减免（暂缓）工单及系统审批程序；（系统-已有） 3.营销部对电费违约金减免（暂缓）开展数字化在线监督。（系统-已有） 内控载体： 1.系统电费违约金减免（暂缓）工单流转记录； 2.电费违约金减免（暂缓）支撑依据； 3.岗位权限配置。 | I17: 3 | J17: 2 | L17: 1 | M17: 人工控制 系统自动控制 | N17: 营销2.0系统 | O17: √ | P17: √ | Q17: √ | W17: √ | X17: 各省公司营销部-电费电价；各单位-营销部-业务核算 | Y17: 年度 | Z17: 抽查 | AA17: 包括不限于： 1、电费核算结果数据 2、电费发行数据 | AC17: 检查电费核算与发行的一体化建设情况，严禁人为更改相关数据。 | AD17: 年度 | AE17: 抽查 | AG17: 违规减免（暂缓）电费违约金监督 | AH17: 每月 | AI17: 全量 | AK17: 是 | AL17: 是 | AM17: 《国家电网有限公司电费业务管理办法（征求意见稿）》第八章 电费收支 第五十条规范电费违约金管理 | AN17: 营销部
