Workbook

Sheet 业务流程
A1: 一级流程 | B1: 二级流程 | C1: 三级流程 | D1: 末级流程编号 | E1: 末级流程名称 | F1: 涉及价值管控风险的流程
A2: 市场营销 | B2: 电力市场营销管理 | C2: 有序用电管理 | D2: YX-01-01-01 | E2: 有序用电基础信息管理流程
D3: YX-01-01-02 | E3: 有序用电方案制定流程
D4: YX-01-01-03 | E4: 有序用电预警管理流程
D5: YX-01-01-04 | E5: 有序用电方案实施流程
D6: YX-01-01-05 | E6: 有序用电监督检查管理流程
D7: YX-01-01-06 | E7: 有序用电统计分析管理流程
C8: 市场分析预测管理 | D8: YX-01-02-01 | E8: 短期电力市场分析预测管理流程
D9: YX-01-02-02 | E9: 迎峰度夏（冬）电力供需分析预测管理流程
C10: 能效服务管理 | D10: YX-01-03-01 | E10: 能效服务网络建设运行管理流程
D11: YX-01-03-02 | E11: 能效服务指标管理流程
D12: YX-01-03-03 | E12: 能效服务项目管理流程
C13: 综合能源管理 | D13: YX-01-04-01 | E13: 综合能源服务管理流程 | F13: √
D14: YX-01-04-02 | E14: 需求侧响应管理流程
C15: 自备电厂管理 | D15: YX-01-04-01 | E15: 自备电厂机组并网与电力供应协议管理流程
C16: 智能用电管理 | D16: YX-01-05-01 | E16: 智能充换电服务网络建设项目实施管理流程
D17: YX-01-05-02 | E17: 智能充换电服务网络运营服务管理流程
D18: YX-01-05-03 | E18: 智能充换电服务网络充电设施缺陷管理流程
B19: 营业管理 | C19: 供电营业区管理 | D19: YX-02-01-01 | E19: 供电营业区域管理流程
D20: YX-02-01-02 | E20: 供电营业许可证管理流程
C21: 业扩报装 | D21: YX-02-02-01 | E21: 业扩报装流程与服务要求制定流程 | F21: √
D22: YX-02-02-02 | E22: 220kV及以上业扩报装管理流程
D23: YX-02-02-03 | E23: 110kV业扩报装管理流程
D24: YX-02-02-04 | E24: 35kV业扩报装管理流程
D25: YX-02-02-05 | E25: 10kV业扩报装管理流程
D26: YX-02-02-06 | E26: 低压业扩报装管理流程
D27: YX-02-02-07 | E27: 国家重点工程业扩报装协调管理流程
C28: 变更用电管理 | D28: YX-02-03-01 | E28: 减容管理流程
D29: YX-02-03-02 | E29: 减容恢复管理流程
D30: YX-02-03-03 | E30: 暂停管理流程
D31: YX-02-03-04 | E31: 暂停恢复管理流程
D32: YX-02-03-05 | E32: 暂拆管理流程
D33: YX-02-03-06 | E33: 暂拆复装管理流程
D34: YX-02-03-07 | E34: 暂换管理流程
D35: YX-02-03-08 | E35: 暂换恢复管理流程
D36: YX-02-03-09 | E36: 迁址管理流程
D37: YX-02-03-10 | E37: 移表管理流程
D38: YX-02-03-11 | E38: 销户管理流程
D39: YX-02-03-12 | E39: 过户管理流程
D40: YX-02-03-13 | E40: 更名管理流程
...

Sheet 流程图

Sheet 员工报账（核对过程7.23）
A1: 风控矩阵-员工报账
A2: 业务条线 | B2: 业务领域 | C2: 控制目标 | D2: 业务流程步骤 | E2: 经营风险 | F2: 典型问题 | G2: 关键控制点 | H2: 控制要求 | I2: 控制措施 编号 | J2: 控制措施 | K2: 控制措施分类 | T2: 控制方式 | U2: 控制系统 | V2: 控制载体 | W2: 责任主体 | X2: 业务自评价 | AA2: 集团监督 评价 | AD2: 数字化监督场景 | AH2: 现有制度及文件落实情况 | AK2: 总部审核部门 | AL2: 湖南公司审核部门 | AM2: 其他备注
K3: 不相容岗位 | L3: 分级授权 | M3: 业务真实性控制 | N3: 预算管控 | O3: 合同控制 | P3: 收付控制 | Q3: 会计监督 | R3: 财产保护 | S3: 分析与评价 | X3: 评价频率 | Y3: 评价范围 | Z3: 评价结论 | AA3: 评价频率 | AB3: 评价范围 | AC3: 评价结论 | AD3: 数字化监督场景 | AE3: 评价频率 | AF3: 评价范围 | AG3: 评价结论 | AH3: 是否已要求 | AI3: 是否满足要求 | AJ3: 对应制度及文件名称 | AN3: 7.23
A4: 员工报账 | B4: 一、员工差旅 | C4: 资金资产安全 | D4: 出差申请 | E4: 出差事项不真实，出差无实质内容，无明确公务目的，虚列套取费用，导致资金安全风险。 | F4: 87.违规发放津贴补贴：存在多报差旅补贴、虚报差旅补贴等问题。 | G4: 1.出差申请发起 | H4: 出差有明确公务目的，出差时间、地点、人员与出差通知一致。 | I4: 员工报账业务-1.出差申请发起-控制措施01 | J4: 出差员工部门负责人对员工出差内容的复核，重点审查出差申请单人员、地点、事由等信息。 | M4: √ | T4: 系统已建 | U4: 国网商旅 | V4: 1.出差通知、培训通知等出差缘由证明材料。 | W4: 各级单位-各部门-出差人员、各级单位-各部门-负责人、商旅云公司 | X4: 每日 | Y4: 全量检查 | AA4: 每年 | AB4: 抽查 | AD4: 员工差旅出差申请监督场景 | AE4: 每月 | AF4: 抽查 | AH4: 是 | AI4: 是 | AJ4: 《国家电网有限公司差旅费管理办法》（国家电网企管〔2026〕101号）第四条、第二十四条、《国网湖南省电力有限公司关于印发加强差旅费管理有关规定的通知》第二条、第三条 | AK4: 国网财务部 | AL4: 各级单位财务部 | AN4: 补充制度 | AO4: =A4=[1]员工报账!A4 -> TRUE | AP4: =B4=[1]员工报账!B4 -> TRUE | AQ4: =C4=[1]员工报账!C4 -> TRUE | AR4: =D4=[1]员工报账!D4 -> TRUE | AS4: =E4=[1]员工报账!E4 -> TRUE | AT4: =F4=[1]员工报账!F4 -> TRUE | AU4: =G4=[1]员工报账!G4 -> TRUE | AV4: =H4=[1]员工报账!H4 -> TRUE | ... BX4: =AJ4=[1]员工报账!AJ4 -> FALSE
I5: 员工报账业务-1.出差申请发起-控制措施02 | J5: 健全“申请-预订-报销”数据联动校验规则，落实预算控制，系统自动比对出差事项与出差产生的票据的逻辑一致性。 | M5: √ | N5: √ | T5: 系统已建 | U5: 国网商旅 | V5: 1.出差审批单。 | W5: 各级单位-各部门-出差人员、商旅云公司 | X5: 每日 | Y5: 全量检查 | AA5: 每年 | AB5: 抽查 | AD5: 员工差旅出差申请监督场景 | AE5: 每月 | AF5: 抽查 | AH5: 是 | AI5: 是 | AJ5: 《国家电网有限公司差旅费管理办法》（国家电网企管〔2026〕101号）第四条、第二十四条、《国网湖南省电力有限公司关于印发加强差旅费管理有关规定的通知》第二条、第三条 | AK5: 国网财务部 | AL5: 各级单位财务部 | AN5: 补充制度 | AO5: =A5=[1]员工报账!A5 -> TRUE | AP5: =B5=[1]员工报账!B5 -> TRUE | AQ5: =C5=[1]员工报账!C5 -> TRUE | AR5: =D5=[1]员工报账!D5 -> TRUE | AS5: =E5=[1]员工报账!E5 -> TRUE | AT5: =F5=[1]员工报账!F5 -> TRUE | AU5: =G5=[1]员工报账!G5 -> TRUE | AV5: =H5=[1]员工报账!H5 -> TRUE | ... BX5: =AJ5=[1]员工报账!AJ5 -> FALSE
I6: 员工报账业务-1.出差申请发起-控制措施03 | J6: 健全差旅费成本中心校验机制，赴异地挂职、按照规定探亲在途期间出差申请选择原单位成本中心，挂职期间出差申请选择挂职单位成本中心。 | N6: √ | Q6: √ | T6: 系统已建 | U6: 国网商旅 | V6: 1.系统出差申请单校验记录等。 | W6: 各级单位-各部门-出差人员、商旅云公司 | X6: 每日 | Y6: 全量检查 | AA6: 每年 | AB6: 抽查 | AD6: 员工差旅出差申请监督场景 | AE6: 每月 | AF6: 抽查 | AH6: 是 | AI6: 是 | AJ6: 《国家电网有限公司差旅费管理办法》（国家电网企管〔2026〕101号）第四条、第二十四条、《国网湖南省电力有限公司关于印发加强差旅费管理有关规定的通知》第二条、第三条 | AK6: 国网财务部 | AL6: 各级单位财务部 | AN6: 补充制度 | AO6: =A6=[1]员工报账!A6 -> TRUE | AP6: =B6=[1]员工报账!B6 -> TRUE | AQ6: =C6=[1]员工报账!C6 -> TRUE | AR6: =D6=[1]员工报账!D6 -> TRUE | AS6: =E6=[1]员工报账!E6 -> TRUE | AT6: =F6=[1]员工报账!F6 -> TRUE | AU6: =G6=[1]员工报账!G6 -> TRUE | AV6: =H6=[1]员工报账!H6 -> TRUE | ... BX6: =AJ6=[1]员工报账!AJ6 -> FALSE
G7: 2.出差申请审批 | H7: 按规定执行出差审批制度。 | I7: 员工报账业务-2.出差申请审批-控制措施01 | J7: 流程固化与防逆向控制，商旅云公司固化“审批-预订-报销”流程，严格限制并需特殊授权才能“取消审批”等逆向操作。 | L7: √ | Q7: √ | T7: 系统已建 | U7: 国网商旅 | V7: 1.出差通知、培训通知等出差缘由证明材料； 2.出差审批单； 3.系统出差申请单审批轨迹。 | W7: 各级单位-各部门-出差人员、商旅云公司 | X7: 每日 | Y7: 全量检查 | AA7: 每年 | AB7: 抽查 | AD7: 员工差旅出差申请监督场景 | AE7: 每月 | AF7: 抽查 | AH7: 是 | AI7: 是 | AJ7: 《国家电网有限公司差旅费管理办法》（国家电网企管〔2026〕101号）第二十二条 | AK7: 国网财务部 | AL7: 各级单位财务部 | AO7: =A7=[1]员工报账!A7 -> TRUE | AP7: =B7=[1]员工报账!B7 -> TRUE | AQ7: =C7=[1]员工报账!C7 -> TRUE | AR7: =D7=[1]员工报账!D7 -> TRUE | AS7: =E7=[1]员工报账!E7 -> TRUE | AT7: =F7=[1]员工报账!F7 -> TRUE | AU7: =G7=[1]员工报账!G7 -> TRUE | AV7: =H7=[1]员工报账!H7 -> TRUE | ... BX7: =AJ7=[1]员工报账!AJ7 -> TRUE
I8: 员工报账业务-2.出差申请审批-控制措施02 | J8: 全链条强制关联控制，系统强制将“审批单号”作为商旅预订及费用报销的唯一前提。 | Q8: √ | T8: 系统已建 | U8: 国网商旅 | V8: 1.出差通知、培训通知等出差缘由证明材料； 2.出差审批单。 | W8: 各级单位-各部门-出差人员、商旅云公司 | X8: 每日 | Y8: 全量检查 | AA8: 每年 | AB8: 抽查 | AD8: 员工差旅出差申请监督场景 | AE8: 每月 | AF8: 抽查 | AH8: 是 | AI8: 是 | AJ8: 《国家电网有限公司差旅费管理办法》（国家电网企管〔2026〕101号）第四条、第二十四条、第二十六条 | AK8: 国网财务部 | AL8: 各级单位财务部 | AO8: =A8=[1]员工报账!A8 -> TRUE | AP8: =B8=[1]员工报账!B8 -> TRUE | AQ8: =C8=[1]员工报账!C8 -> TRUE | AR8: =D8=[1]员工报账!D8 -> TRUE | AS8: =E8=[1]员工报账!E8 -> TRUE | AT8: =F8=[1]员工报账!F8 -> TRUE | AU8: =G8=[1]员工报账!G8 -> TRUE | AV8: =H8=[1]员工报账!H8 -> TRUE | ... BX8: =AJ8=[1]员工报账!AJ8 -> TRUE
I9: 员工报账业务-2.出差申请审批-控制措施03 | J9: 商旅云公司严禁后台“绿色通道”操作，禁止平台通过电话申请取消审批行为。 | M9: √ | T9: 系统待建 | U9: 国网商旅 | V9: 1.出差通知、培训通知等出差缘由证明材料； 2.出差审批单； 3.系统出差申请单审批轨迹。 | W9: 各级单位-各部门-出差人员、商旅云公司 | X9: 每日 | Y9: 全量检查 | AA9: 每年 | AB9: 抽查 | AD9: 员工差旅出差申请监督场景 | AE9: 每月 | AF9: 抽查 | AH9: 是 | AI9: 是 | AJ9: 《国家电网有限公司差旅费管理办法》（国家电网企管〔2026〕101号）第四条、第二十四条、第二十六条 | AK9: 国网财务部 | AL9: 各级单位财务部 | AO9: =A9=[1]员工报账!A9 -> TRUE | AP9: =B9=[1]员工报账!B9 -> TRUE | AQ9: =C9=[1]员工报账!C9 -> TRUE | AR9: =D9=[1]员工报账!D9 -> TRUE | AS9: =E9=[1]员工报账!E9 -> TRUE | AT9: =F9=[1]员工报账!F9 -> TRUE | AU9: =G9=[1]员工报账!G9 -> TRUE | AV9: =H9=[1]员工报账!H9 -> TRUE | ... BX9: =AJ9=[1]员工报账!AJ9 -> TRUE
A10: 员工报账 | B10: 一、员工差旅 | C10: 税务合规 | D10: 出差申请 | E10: 商旅平台违规取消事前审批流程，导致出现“先出差后申请”的情况，引发舞弊及合规管理风险。 | F10: 87.违规发放津贴补贴：存在多报差旅补贴、虚报差旅补贴等问题。 | G10: 3.出差申请流程控制 | H10: 出差申请日期早于出差日期。 | I10: 员工报账业务-3.出差申请流程控制-控制措施01 | J10: 审批要素完整性校验，系统强制校验审批单的必备要素，对缺少出差事由等关键要素的申请单不予通过。 | M10: √ | T10: 系统已建 | U10: 国网商旅 | V10: 1.系统出差申请单审批轨迹； 2.系统记录的申请单提交时间和出差时间。 | W10: 各级单位-各部门-出差人员、各级单位-各部门-负责人、商旅云公司 | X10: 每日 | Y10: 全量检查 | AA10: 每年 | AB10: 抽查 | AD10: 员工差旅流程配置监督场景 | AE10: 每月 | AF10: 抽查 | AH10: 是 | AI10: 是 | AJ10: 《国家电网有限公司差旅费管理办法》（国家电网企管〔2026〕101号）第五条 | AK10: 国网财务部 | AL10: 各级单位财务部 | AN10: 修改责任主体 | AO10: =A10=[1]员工报账!A10 -> TRUE | AP10: =B10=[1]员工报账!B10 -> TRUE | AQ10: =C10=[1]员工报账!C10 -> TRUE | AR10: =D10=[1]员工报账!D10 -> TRUE | AS10: =E10=[1]员工报账!E10 -> TRUE | AT10: =F10=[1]员工报账!F10 -> TRUE | AU10: =G10=[1]员工报账!G10 -> TRUE | AV10: =H10=[1]员工报账!H10 -> TRUE | ... BX10: =AJ10=[1]员工报账!AJ10 -> TRUE
I11: 员工报账业务-3.出差申请流程控制-控制措施02 | J11: 严格执行不相容控制，系统根据组织架构与授权清单自动匹配并校验审批人权限，防范越权审批 | R11: √ | T11: 系统已建 | U11: 国网商旅 | V11: 1.系统记录的申请单提交时间和出差时间。 | W11: 商旅云公司、各级单位-各部门-出差人员、各级单位-各部门-负责人 | X11: 每日 | Y11: 全量检查 | AA11: 每年 | AB11: 抽查 | AD11: 员工差旅流程配置监督场景 | AE11: 每月 | AF11: 抽查 | AH11: 是 | AI11: 是 | AJ11: 《国家电网有限公司差旅费管理办法》（国家电网企管〔2026〕101号）第五条 | AK11: 国网财务部 | AL11: 各级单位财务部 | AO11: =A11=[1]员工报账!A11 -> TRUE | AP11: =B11=[1]员工报账!B11 -> TRUE | AQ11: =C11=[1]员工报账!C11 -> TRUE | AR11: =D11=[1]员工报账!D11 -> TRUE | AS11: =E11=[1]员工报账!E11 -> TRUE | AT11: =F11=[1]员工报账!F11 -> TRUE | AU11: =G11=[1]员工报账!G11 -> TRUE | AV11: =H11=[1]员工报账!H11 -> TRUE | ... BX11: =AJ11=[1]员工报账!AJ11 -> TRUE
I12: 员工报账业务-3.出差申请流程控制-控制措施03 | J12: 建立定期分析、评价与问责机制，各部门对审批时效、驳回率、特批事项进行专项分析，审计部门、纪检部门等监督部门对违规审批、补批行为依规问责。 | M12: √ | R12: √ | S12: √ | T12: 线下管控 | V12: 1.系统记录的申请单提交时间和出差时间。 | W12: 商旅云公司、各级单位-审计部门、纪检部门等监督部门-监督、纪检管理人员 | X12: 每日 | Y12: 全量检查 | AA12: 每年 | AB12: 抽查 | AD12: 员工差旅流程配置监督场景 | AE12: 每月 | AF12: 抽查 | AH12: 是 | AI12: 是 | AJ12: 《国家电网有限公司差旅费管理办法》（国家电网企管〔2026〕101号）第五条 | AK12: 国网财务部 | AL12: 各级单位财务部 | AN12: 修改责任主体 | AO12: =A12=[1]员工报账!A12 -> TRUE | AP12: =B12=[1]员工报账!B12 -> TRUE | AQ12: =C12=[1]员工报账!C12 -> TRUE | AR12: =D12=[1]员工报账!D12 -> TRUE | AS12: =E12=[1]员工报账!E12 -> TRUE | AT12: =F12=[1]员工报账!F12 -> TRUE | AU12: =G12=[1]员工报账!G12 -> TRUE | AV12: =H12=[1]员工报账!H12 -> TRUE | ... BX12: =AJ12=[1]员工报账!AJ12 -> TRUE
C13: 税务合规 | D13: 差旅预订 | E13: 商旅平台酒店存在棋牌、麻将、电竞等敏感字眼，商旅平台违规上架引发合规风险。 | G13: 4.酒店入驻上架控制 | H13: 酒店资源上架流程合规，且履行必要的审批手续。 | I13: 员工报账业务-4.酒店入驻上架控制-控制措施01 | J13: 商旅云公司强化供应商准入审核，对新签约酒店的的资质有效性、服务适配性以及风险可控性等信息进行事前审核。 | O13: √ | T13: 系统待建 | U13: 国网商旅 | V13: 1.酒店资质、营业执照、房型清单。 | W13: 商旅云公司 | X13: 每日 | Y13: 全量检查 | AA13: 每年 | AB13: 抽查 | AD13: 员工差旅预订监督场景 | AE13: 每月 | AF13: 抽查 | AH13: 是 | AI13: 是 | AJ13: 《国家电网有限公司差旅费管理办法》（国家电网企管〔2026〕101号）第五条 | AK13: 国网财务部 | AL13: 各级单位财务部 | AO13: =A13=[1]员工报账!A13 -> TRUE | AP13: =B13=[1]员工报账!B13 -> TRUE | AQ13: =C13=[1]员工报账!C13 -> TRUE | AR13: =D13=[1]员工报账!D13 -> TRUE | AS13: =E13=[1]员工报账!E13 -> TRUE | AT13: =F13=[1]员工报账!F13 -> TRUE | AU13: =G13=[1]员工报账!G13 -> TRUE | AV13: =H13=[1]员工报账!H13 -> TRUE | ... BX13: =AJ13=[1]员工报账!AJ13 -> TRUE
I14: 员工报账业务-4.酒店入驻上架控制-控制措施02 | J14: 商旅云公司建立并动态更新《敏感词库与酒店属性负面清单》，系统自动拦截负面清单内容并转人工复核。 | O14: √ | Q14: √ | S14: √ | T14: 系统待建 | U14: 国网商旅 | V14: 1.系统敏感词库与酒店属性负面清单。 | W14: 商旅云公司 | X14: 每日 | Y14: 全量检查 | AA14: 每年 | AB14: 抽查 | AD14: 员工差旅预订监督场景 | AE14: 每月 | AF14: 抽查 | AH14: 是 | AI14: 是 | AJ14: 《国家电网有限公司差旅费管理办法》（国家电网企管〔2026〕101号）第五条 | AK14: 国网财务部 | AL14: 各级单位财务部 | AO14: =A14=[1]员工报账!A14 -> TRUE | AP14: =B14=[1]员工报账!B14 -> TRUE | AQ14: =C14=[1]员工报账!C14 -> TRUE | AR14: =D14=[1]员工报账!D14 -> TRUE | AS14: =E14=[1]员工报账!E14 -> TRUE | AT14: =F14=[1]员工报账!F14 -> TRUE | AU14: =G14=[1]员工报账!G14 -> TRUE | AV14: =H14=[1]员工报账!H14 -> TRUE | ... BX14: =AJ14=[1]员工报账!AJ14 -> TRUE
I15: 员工报账业务-4.酒店入驻上架控制-控制措施03 | J15: 追回违规上架酒店产生的资金浪费，并对相关负责人按规定给予处分处理。 | R15: √ | S15: √ | T15: 线下管控 | V15: 1.问责证明材料。 | W15: 商旅云公司 | X15: 每日 | Y15: 全量检查 | AA15: 每年 | AB15: 抽查 | AD15: 员工差旅预订监督场景 | AE15: 每月 | AF15: 抽查 | AH15: 是 | AI15: 是 | AJ15: 《国家电网有限公司差旅费管理办法》（国家电网企管〔2026〕101号）第五条 | AK15: 国网财务部 | AL15: 各级单位财务部 | AO15: =A15=[1]员工报账!A15 -> TRUE | AP15: =B15=[1]员工报账!B15 -> TRUE | AQ15: =C15=[1]员工报账!C15 -> TRUE | AR15: =D15=[1]员工报账!D15 -> TRUE | AS15: =E15=[1]员工报账!E15 -> TRUE | AT15: =F15=[1]员工报账!F15 -> TRUE | AU15: =G15=[1]员工报账!G15 -> TRUE | AV15: =H15=[1]员工报账!H15 -> TRUE | ... BX15: =AJ15=[1]员工报账!AJ15 -> TRUE
C16: 资金资产安全 | D16: 差旅预订 | E16: 酒店价格虚高易引发套取资金，引发廉政风险。 | F16: 87.违规发放津贴补贴：存在多报差旅补贴、虚报差旅补贴等问题。 | G16: 5.单体酒店上架及价格定价管控 | H16: 商旅平台酒店资源价格真实合理。 | I16: 员工报账业务-5.单体酒店上架及价格定价管控-控制措施01 | J16: 增加单体酒店上架申请审批流程，由各单位办公室汇总审核本单位酒店需求，向商旅云公司提交上架。 | L16: √ | O16: √ | T16: 系统已建 | U16: 国网商旅 | V16: 1.协议单体酒店推荐表单。 | W16: 商旅云公司、各级单位-办公室财务部 | X16: 每日 | Y16: 全量检查 | AA16: 每年 | AB16: 抽查 | AD16: 员工差旅预订监督场景 | AE16: 每月 | AF16: 抽查 | AH16: 是 | AI16: 是 | AJ16: 《国家电网有限公司差旅费管理办法》（国家电网企管〔2026〕101号）第五条 | AK16: 国网财务部 | AL16: 各级单位财务部 | AN16: 修改责任主体 | AO16: =A16=[1]员工报账!A16 -> TRUE | AP16: =B16=[1]员工报账!B16 -> TRUE | AQ16: =C16=[1]员工报账!C16 -> TRUE | AR16: =D16=[1]员工报账!D16 -> TRUE | AS16: =E16=[1]员工报账!E16 -> TRUE | AT16: =F16=[1]员工报账!F16 -> TRUE | AU16: =G16=[1]员工报账!G16 -> TRUE | AV16: =H16=[1]员工报账!H16 -> TRUE | ... BX16: =AJ16=[1]员工报账!AJ16 -> TRUE
I17: 员工报账业务-5.单体酒店上架及价格定价管控-控制措施02 | J17: 商旅云公司强化协议签订管控，严格审核酒店资质，严控无理由上架，防范舞弊行为。 | O17: √ | T17: 系统已建 | U17: 国网商旅 | V17: 1.酒单违规风险清单； 2.采购协议酒店清单； 3.酒店上架评审报告。 | W17: 商旅云公司 | X17: 每日 | Y17: 全量检查 | AA17: 每年 | AB17: 抽查 | AD17: 员工差旅预订监督场景 | AE17: 每月 | AF17: 抽查 | AH17: 是 | AI17: 是 | AJ17: 《国家电网有限公司差旅费管理办法》（国家电网企管〔2026〕101号）第五条 | AK17: 国网财务部 | AL17: 各级单位财务部 | AO17: =A17=[1]员工报账!A17 -> TRUE | AP17: =B17=[1]员工报账!B17 -> TRUE | AQ17: =C17=[1]员工报账!C17 -> TRUE | AR17: =D17=[1]员工报账!D17 -> TRUE | AS17: =E17=[1]员工报账!E17 -> TRUE | AT17: =F17=[1]员工报账!F17 -> TRUE | AU17: =G17=[1]员工报账!G17 -> TRUE | AV17: =H17=[1]员工报账!H17 -> TRUE | ... BX17: =AJ17=[1]员工报账!AJ17 -> TRUE
I18: 员工报账业务-5.单体酒店上架及价格定价管控-控制措施03 | J18: 加强员工行为管控，商旅云公司强化酒店订单在线监督，防范员工违规套取资金。 | M18: √ | R18: √ | T18: 系统已建 | U18: 国网商旅 | V18: 1.酒店合作协议。 | W18: 商旅云公司 | X18: 每日 | Y18: 全量检查 | AA18: 每年 | AB18: 抽查 | AD18: 员工差旅预订监督场景 | AE18: 每月 | AF18: 抽查 | AH18: 是 | AI18: 是 | AJ18: 《国家电网有限公司差旅费管理办法》（国家电网企管〔2026〕101号）第五条 | AK18: 国网财务部 | AL18: 各级单位财务部 | AO18: =A18=[1]员工报账!A18 -> TRUE | AP18: =B18=[1]员工报账!B18 -> TRUE | AQ18: =C18=[1]员工报账!C18 -> TRUE | AR18: =D18=[1]员工报账!D18 -> TRUE | AS18: =E18=[1]员工报账!E18 -> TRUE | AT18: =F18=[1]员工报账!F18 -> TRUE | AU18: =G18=[1]员工报账!G18 -> TRUE | AV18: =H18=[1]员工报账!H18 -> TRUE | ... BX18: =AJ18=[1]员工报账!AJ18 -> TRUE
A19: 员工报账 | B19: 一、员工差旅 | C19: 资金资产安全 | D19: 差旅预订 | E19: 酒店价格虚高易引发套取资金，引发廉政风险。 | F19: 87.违规发放津贴补贴：存在多报差旅补贴、虚报差旅补贴等问题。 | G19: 5.单体酒店上架及价格定价管控 | H19: 商旅平台酒店资源价格真实合理。 | I19: 员工报账业务-5.单体酒店上架及价格定价管控-控制措施04 | J19: 建立负面清单，及时清退违规酒店。 | R19: √ | S19: √ | T19: 线下管控 | V19: 1.酒店风险识别机制； 2.员工体验反馈。 | W19: 商旅云公司 | X19: 每日 | Y19: 全量检查 | AA19: 每年 | AB19: 抽查 | AD19: 员工差旅预订监督场景 | AE19: 每月 | AF19: 抽查 | AH19: 是 | AI19: 是 | AJ19: 《国家电网有限公司差旅费管理办法》（国家电网企管〔2026〕101号）第五条 | AK19: 国网财务部 | AL19: 各级单位财务部 | AO19: =A19=[1]员工报账!A19 -> TRUE | AP19: =B19=[1]员工报账!B19 -> TRUE | AQ19: =C19=[1]员工报账!C19 -> TRUE | AR19: =D19=[1]员工报账!D19 -> TRUE | AS19: =E19=[1]员工报账!E19 -> TRUE | AT19: =F19=[1]员工报账!F19 -> TRUE | AU19: =G19=[1]员工报账!G19 -> TRUE | AV19: =H19=[1]员工报账!H19 -> TRUE | ... BX19: =AJ19=[1]员工报账!AJ19 -> TRUE
D20: 差旅预订 | E20: 员工在同一时间段内重复预订酒店资源，存在套取资金风险。 | F20: 87.违规发放津贴补贴：存在多报差旅补贴、虚报差旅补贴等问题。 | G20: 6.酒店预订 | H20: 同一员工在同一时间段内，就同一出差行程，仅能生成一个有效住宿订单。 | I20: 员工报账业务-6.酒店预订-控制措施01 | J20: 商旅云公司完善重复订单系统校验规则，自动拦截并预警同一人员、时段重叠的酒店订单申请。 | M20: √ | T20: 系统已建 | U20: 国网商旅 | V20: 1.商旅订单； 2.出差通知、培训通知等出差缘由证明材料。 | W20: 各级单位-各部门-出差人员、商旅云公司 | X20: 每日 | Y20: 全量检查 | AA20: 每年 | AB20: 抽查 | AD20: 员工差旅预订监督场景 | AE20: 每月 | AF20: 抽查 | AH20: 是 | AI20: 是 | AJ20: 《国家电网有限公司差旅费管理办法》（国家电网企管〔2026〕101号）第二十四条 | AK20: 国网财务部 | AL20: 各级单位财务部 | AO20: =A20=[1]员工报账!A20 -> TRUE | AP20: =B20=[1]员工报账!B20 -> TRUE | AQ20: =C20=[1]员工报账!C20 -> TRUE | AR20: =D20=[1]员工报账!D20 -> TRUE | AS20: =E20=[1]员工报账!E20 -> TRUE | AT20: =F20=[1]员工报账!F20 -> TRUE | AU20: =G20=[1]员工报账!G20 -> TRUE | AV20: =H20=[1]员工报账!H20 -> TRUE | ... BX20: =AJ20=[1]员工报账!AJ20 -> TRUE
I21: 员工报账业务-6.酒店预订-控制措施02 | J21: 商旅云公司健全入住轨迹验证与反馈机制，自动识别入住轨迹异常情况，即时预警有关责任人。 | M21: √ | S21: √ | T21: 系统已建 | U21: 国网商旅 | V21: 1.系统拦截记录。 | W21: 各级单位-各部门-出差人员、商旅云公司 | X21: 每日 | Y21: 全量检查 | AA21: 每年 | AB21: 抽查 | AD21: 员工差旅预订监督场景 | AE21: 每月 | AF21: 抽查 | AH21: 是 | AI21: 是 | AJ21: 《国家电网有限公司差旅费管理办法》（国家电网企管〔2026〕101号）第二十四条 | AK21: 国网财务部 | AL21: 各级单位财务部 | AO21: =A21=[1]员工报账!A21 -> TRUE | AP21: =B21=[1]员工报账!B21 -> TRUE | AQ21: =C21=[1]员工报账!C21 -> TRUE | AR21: =D21=[1]员工报账!D21 -> TRUE | AS21: =E21=[1]员工报账!E21 -> TRUE | AT21: =F21=[1]员工报账!F21 -> TRUE | AU21: =G21=[1]员工报账!G21 -> TRUE | AV21: =H21=[1]员工报账!H21 -> TRUE | ... BX21: =AJ21=[1]员工报账!AJ21 -> TRUE
I22: 员工报账业务-6.酒店预订-控制措施03 | J22: 财务部门加强出差申请与酒店订单的交叉复核，校验人员、时间、订单的合理性与唯一性。 | M22: √ | T22: 系统已建 | U22: 国网商旅 | V22: 1.出差报销单； 2.入住轨迹与异常情况反馈。 | W22: 各级单位-各部门-出差人员、各级单位-财务部门-成本管理人员、商旅云公司 | X22: 每日 | Y22: 全量检查 | AA22: 每年 | AB22: 抽查 | AD22: 员工差旅预订监督场景 | AE22: 每月 | AF22: 抽查 | AH22: 是 | AI22: 是 | AJ22: 《国家电网有限公司差旅费管理办法》（国家电网企管〔2026〕101号）第二十四条 | AK22: 国网财务部 | AL22: 各级单位财务部 | AN22: 修改责任主体 | AO22: =A22=[1]员工报账!A22 -> TRUE | AP22: =B22=[1]员工报账!B22 -> TRUE | AQ22: =C22=[1]员工报账!C22 -> TRUE | AR22: =D22=[1]员工报账!D22 -> TRUE | AS22: =E22=[1]员工报账!E22 -> TRUE | AT22: =F22=[1]员工报账!F22 -> TRUE | AU22: =G22=[1]员工报账!G22 -> TRUE | AV22: =H22=[1]员工报账!H22 -> TRUE | ... BX22: =AJ22=[1]员工报账!AJ22 -> TRUE
C23: 税务合规 | D23: 差旅报销 | E23: 擅自扩大差旅费开支范围，提高差旅费开支标准，增加差旅出行成本。 | F23: 87.违规发放津贴补贴：存在多报差旅补贴、虚报差旅补贴等问题。 | G23: 7.差旅标准执行 | H23: 差旅费开支标准、开支范围符合本单位差旅费标准。 | I23: 员工报账业务-7.差旅标准执行-控制措施01 | J23: 商旅云公司完善差旅费超标刚性管控功能，系统对超标申请酒店、交通工具和差旅补助进行自动隐藏。 | M23: √ | R23: √ | T23: 系统已建 | U23: 国网商旅 | V23: 1.差旅标准系统校验规则库； 2.出差通知、培训通知等出差缘由证明材料； 3.出差审批单； 4.出差报销单。 | W23: 各级单位-财务部门-预算管理人员、各级单位-各部门-出差人员、各级单位-各部门-负责人、各级单位-财务部门-成本管理人员、商旅云公司 | X23: 每日 | Y23: 全量检查 | AA23: 每年 | AB23: 抽查 | AD23: 员工差旅费用标准监督场景 | AE23: 每月 | AF23: 抽查 | AH23: 是 | AI23: 是 | AJ23: 《国家电网有限公司差旅费管理办法》（国家电网企管〔2026〕101号）第八条、第十一条至第十九条 | AK23: 国网财务部 | AL23: 各级单位财务部 | AO23: =A23=[1]员工报账!A23 -> TRUE | AP23: =B23=[1]员工报账!B23 -> TRUE | AQ23: =C23=[1]员工报账!C23 -> TRUE | AR23: =D23=[1]员工报账!D23 -> TRUE | AS23: =E23=[1]员工报账!E23 -> TRUE | AT23: =F23=[1]员工报账!F23 -> TRUE | AU23: =G23=[1]员工报账!G23 -> TRUE | AV23: =H23=[1]员工报账!H23 -> TRUE | ... BX23: =AJ23=[1]员工报账!AJ23 -> TRUE
I24: 员工报账业务-7.差旅标准执行-控制措施02 | J24: 财务部门加强出差类别与出差性质审核，重点关注评标、培训等特殊出差事项政策执行情况。 | M24: √ | Q24: √ | T24: 系统已建 | U24: 国网商旅 | V24: 1.差旅标准系统校验规则库； 2.出差通知、培训通知等出差缘由证明材料； 3.出差审批单； 4.出差报销单。 | W24: 各级单位-财务部门-预算管理人员、各级单位-各部门-负责人、各级单位-财务部门-成本管理人员、商旅云公司 | X24: 每日 | Y24: 全量检查 | AA24: 每年 | AB24: 抽查 | AD24: 员工差旅费用标准监督场景 | AE24: 每月 | AF24: 抽查 | AH24: 是 | AI24: 是 | AJ24: 《国家电网有限公司差旅费管理办法》（国家电网企管〔2026〕101号）第八条、第十一条至第十九条 | AK24: 国网财务部 | AL24: 各级单位财务部 | AO24: =A24=[1]员工报账!A24 -> TRUE | AP24: =B24=[1]员工报账!B24 -> TRUE | AQ24: =C24=[1]员工报账!C24 -> TRUE | AR24: =D24=[1]员工报账!D24 -> TRUE | AS24: =E24=[1]员工报账!E24 -> TRUE | AT24: =F24=[1]员工报账!F24 -> TRUE | AU24: =G24=[1]员工报账!G24 -> TRUE | AV24: =H24=[1]员工报账!H24 -> TRUE | ... BX24: =AJ24=[1]员工报账!AJ24 -> TRUE
I25: 员工报账业务-7.差旅标准执行-控制措施03 | J25: 纪检部门推动退赔与整改机制，对超标报销行为依规严肃问责。 | R25: √ | S25: √ | T25: 线下管控 | V25: 1.问责证明材料。 | W25: 各级单位-财务部门-预算管理人员、各级单位-各部门-出差人员、各级单位-各部门-负责人、各级单位-财务部门-成本管理人员、商旅云公司、各级单位-纪检部门-纪检管理人员 | X25: 每日 | Y25: 全量检查 | AA25: 每年 | AB25: 抽查 | AD25: 员工差旅费用标准监督场景 | AE25: 每月 | AF25: 抽查 | AH25: 是 | AI25: 是 | AJ25: 《国家电网有限公司差旅费管理办法》（国家电网企管〔2026〕101号）第八条、第十一条至第十九条、《国网湖南省电力有限公司关于印发加强差旅费管理有关规定的通知》第一条 | AK25: 国网财务部 | AL25: 各级单位财务部 | AN25: 补充制度 | AO25: =A25=[1]员工报账!A25 -> TRUE | AP25: =B25=[1]员工报账!B25 -> TRUE | AQ25: =C25=[1]员工报账!C25 -> TRUE | AR25: =D25=[1]员工报账!D25 -> TRUE | AS25: =E25=[1]员工报账!E25 -> TRUE | AT25: =F25=[1]员工报账!F25 -> TRUE | AU25: =G25=[1]员工报账!G25 -> TRUE | AV25: =H25=[1]员工报账!H25 -> TRUE | ... BX25: =AJ25=[1]员工报账!AJ25 -> FALSE
A26: 员工报账 | B26: 一、员工差旅 | C26: 资金资产安全 | D26: 差旅报销 | E26: 虚报冒领差旅费，虚列套取费用，导致资金安全风险。 | F26: 87.违规发放津贴补贴：存在多报差旅补贴、虚报差旅补贴等问题。 | G26: 8.差旅报销合规性控制 | H26: 交通费、公杂费、住宿费等报销真实发生，差旅费报销准确。 | I26: 员工报账业务-8.差旅报销合规性控制-控制措施01 | J26: 建立业务部门费用报销前置审核机制，对机票、酒店、火车、补助等金额准确性复核。 | M26: √ | Q26: √ | R26: √ | T26: 系统已建 | U26: 国网商旅 | V26: 1.出差通知、培训通知等出差缘由证明材料； 2.出差审批单； 3.预订的商旅订单； 4.发票； 5.考勤记录。 | W26: 各级单位-各部门-出差人员、各级单位-各部门-出差报销审核人、各级单位-财务部门-成本管理人员、商旅云公司 | X26: 每日 | Y26: 全量检查 | AA26: 每年 | AB26: 抽查 | AD26: 员工差旅报销监督场景 | AE26: 每月 | AF26: 抽查 | AH26: 是 | AI26: 是 | AJ26: 《国网财务部、后勤部关于进一步规范差旅伙食费和交通费收交管理有关事项的通知》第三条、第四条 《国家电网有限公司差旅费管理办法》（国家电网企管〔2026〕101号）第十二条、第十三条、第十七条、第二十四条 | AK26: 国网财务部 | AL26: 各级单位财务部 | AO26: =A26=[1]员工报账!A26 -> TRUE | AP26: =B26=[1]员工报账!B26 -> TRUE | AQ26: =C26=[1]员工报账!C26 -> TRUE | AR26: =D26=[1]员工报账!D26 -> TRUE | AS26: =E26=[1]员工报账!E26 -> TRUE | AT26: =F26=[1]员工报账!F26 -> TRUE | AU26: =G26=[1]员工报账!G26 -> TRUE | AV26: =H26=[1]员工报账!H26 -> TRUE | ... BX26: =AJ26=[1]员工报账!AJ26 -> TRUE
I27: 员工报账业务-8.差旅报销合规性控制-控制措施02 | J27: 商旅云公司强化时空逻辑系统校验，对“出差时间-住宿时间-车票时间”进行自动校验，拦截或预警重叠数据。 | M27: √ | Q27: √ | T27: 系统已建 | U27: 国网商旅 | V27: 1.出差通知、培训通知等出差缘由证明材料； 2.出差审批单； 3.预订的商旅订单； 4.发票； 5.考勤记录。 | W27: 商旅云公司 | X27: 每日 | Y27: 全量检查 | AA27: 每年 | AB27: 抽查 | AD27: 员工差旅报销监督场景 | AE27: 每月 | AF27: 抽查 | AH27: 是 | AI27: 是 | AJ27: 《国网财务部、后勤部关于进一步规范差旅伙食费和交通费收交管理有关事项的通知》第三条、第四条 《国家电网有限公司差旅费管理办法》（国家电网企管〔2026〕101号第十二条、第十三条、第十七条、第二十四条 | AK27: 国网财务部 | AL27: 各级单位财务部 | AO27: =A27=[1]员工报账!A27 -> TRUE | AP27: =B27=[1]员工报账!B27 -> TRUE | AQ27: =C27=[1]员工报账!C27 -> TRUE | AR27: =D27=[1]员工报账!D27 -> TRUE | AS27: =E27=[1]员工报账!E27 -> TRUE | AT27: =F27=[1]员工报账!F27 -> TRUE | AU27: =G27=[1]员工报账!G27 -> TRUE | AV27: =H27=[1]员工报账!H27 -> TRUE | ... BX27: =AJ27=[1]员工报账!AJ27 -> TRUE
I28: 员工报账业务-8.差旅报销合规性控制-控制措施03 | J28: 商旅云公司健全票据使用状态规则，重点筛查“未使用”的交通票据，防范员工利用废票虚报费用或重复报销。 | M28: √ | R28: √ | T28: 系统已建 | U28: 国网商旅 | V28: 1.出差通知、培训通知等出差缘由证明材料； 2.出差审批单； 3.预订的商旅订单； 4.发票； 5.考勤记录。 | W28: 各级单位-各部门-出差人员、各级单位-各部门-出差报销审核人、各级单位-财务部门-成本管理人员、商旅云公司 | X28: 每日 | Y28: 全量检查 | AA28: 每年 | AB28: 抽查 | AD28: 员工差旅报销监督场景 | AE28: 每月 | AF28: 抽查 | AH28: 是 | AI28: 是 | AJ28: 《国网财务部、后勤部关于进一步规范差旅伙食费和交通费收交管理有关事项的通知》第三条、第四条 《国家电网有限公司差旅费管理办法》（国家电网企管〔2026〕101号）第十七条、第二十四条 | AK28: 国网财务部 | AL28: 各级单位财务部 | AO28: =A28=[1]员工报账!A28 -> TRUE | AP28: =B28=[1]员工报账!B28 -> TRUE | AQ28: =C28=[1]员工报账!C28 -> TRUE | AR28: =D28=[1]员工报账!D28 -> TRUE | AS28: =E28=[1]员工报账!E28 -> TRUE | AT28: =F28=[1]员工报账!F28 -> TRUE | AU28: =G28=[1]员工报账!G28 -> TRUE | AV28: =H28=[1]员工报账!H28 -> TRUE | ... BX28: =AJ28=[1]员工报账!AJ28 -> TRUE
I29: 员工报账业务-8.差旅报销合规性控制-控制措施04 | J29: 财务部门加强差旅报销审核力度，对同一时段连续出差公杂费、伙食补助费进行复核，避免重复计算。 | M29: √ | Q29: √ | T29: 系统已建 | U29: 国网商旅 | V29: 1.出差通知、培训通知等出差缘由证明材料； 2.出差审批单； 3.预订的商旅订单； 4.发票； 5.考勤记录。 | W29: 各级单位-各部门-出差人员、各级单位-各部门-出差报销审核人、各级单位-财务部门-成本管理人员、商旅云公司 | X29: 每日 | Y29: 全量检查 | AA29: 每年 | AB29: 抽查 | AD29: 员工差旅报销监督场景 | AE29: 每月 | AF29: 抽查 | AH29: 是 | AI29: 是 | AJ29: 《国网财务部、后勤部关于进一步规范差旅伙食费和交通费收交管理有关事项的通知》第三条、第四条 《国家电网有限公司差旅费管理办法》（国家电网企管〔2026〕101号第十二条、第十三条、第十七条、第二十四条 | AK29: 国网财务部 | AL29: 各级单位财务部 | AO29: =A29=[1]员工报账!A29 -> TRUE | AP29: =B29=[1]员工报账!B29 -> TRUE | AQ29: =C29=[1]员工报账!C29 -> TRUE | AR29: =D29=[1]员工报账!D29 -> TRUE | AS29: =E29=[1]员工报账!E29 -> TRUE | AT29: =F29=[1]员工报账!F29 -> TRUE | AU29: =G29=[1]员工报账!G29 -> TRUE | AV29: =H29=[1]员工报账!H29 -> TRUE | ... BX29: =AJ29=[1]员工报账!AJ29 -> TRUE
A30: 员工报账 | B30: 一、员工差旅 | C30: 资金资产安全 | D30: 差旅报销 | E30: 虚报冒领差旅费，虚列套取费用，导致资金安全风险。 | F30: 87.违规发放津贴补贴：存在多报差旅补贴、虚报差旅补贴等问题。 | G30: 8.差旅报销合规性控制 | H30: 交通费、公杂费、住宿费等报销真实发生，差旅费报销准确。 | I30: 员工报账业务-8.差旅报销合规性控制-控制措施05 | J30: 纪检部门完善违规问责与闭环管理机制，对未缴纳伙食费用套取各类补助和虚报行为进行问责，追回资金，并纳入个人诚信记录。 | M30: √ | R30: √ | S30: √ | T30: 线下管控 | V30: 1.问责证明材料。 | W30: 各级单位-各部门-出差人员、各级单位-各部门-出差报销审核人、各级单位-财务部门-成本管理人员、商旅云公司、各级单位-纪检部门-纪检管理人员 | X30: 每日 | Y30: 全量检查 | AA30: 每年 | AB30: 抽查 | AD30: 员工差旅报销监督场景 | AE30: 每月 | AF30: 抽查 | AH30: 是 | AI30: 是 | AJ30: 《国网财务部、后勤部关于进一步规范差旅伙食费和交通费收交管理有关事项的通知》第三条、第四条 《国家电网有限公司差旅费管理办法》（国家电网企管〔2026〕101号）第十七条、第二十四条、《国网湖南省电力有限公司关于印发加强差旅费管理有关规定的通知》第一条 | AK30: 国网财务部 | AL30: 各级单位财务部 | AN30: 补充制度 | AO30: =A30=[1]员工报账!A30 -> TRUE | AP30: =B30=[1]员工报账!B30 -> TRUE | AQ30: =C30=[1]员工报账!C30 -> TRUE | AR30: =D30=[1]员工报账!D30 -> TRUE | AS30: =E30=[1]员工报账!E30 -> TRUE | AT30: =F30=[1]员工报账!F30 -> TRUE | AU30: =G30=[1]员工报账!G30 -> TRUE | AV30: =H30=[1]员工报账!H30 -> TRUE | ... BX30: =AJ30=[1]员工报账!AJ30 -> FALSE
E31: 员工自付单据中的人员、时间与地点未在出差范围内，虚报支出，套取资金，导致公司经济利益受损。 | G31: 9.自付单据审核 | H31: 自付单据中人员、时间、地点与出差申请单一致，自付交通费、住宿费符合差旅费标准。 | I31: 员工报账业务-9.自付单据审核-控制措施01 | J31: 商旅云公司健全“单轨控制”，系统强制关联“已完成审批单”与“线上支付订单”，并推动与税务平台直连，减少发票人工上传环节。 | S31: √ | T31: 系统待建 | U31: 国网商旅 | V31: 1.发票； 2.差旅费标准； 3.出差通知、培训通知等出差缘由证明材料； 4.出差审批单； 5.出差报销单。 | W31: 各级单位-各部门-出差人员、商旅云公司 | X31: 每日 | Y31: 全量检查 | AA31: 每年 | AB31: 抽查 | AD31: 员工差旅报销监督场景 | AE31: 每月 | AF31: 抽查 | AH31: 是 | AI31: 是 | AJ31: 《国家电网有限公司差旅费管理办法》（国家电网企管〔2026〕101号）第八条、第十一条、第二十四条 | AK31: 国网财务部 | AL31: 各级单位财务部 | AO31: =A31=[1]员工报账!A31 -> TRUE | AP31: =B31=[1]员工报账!B31 -> TRUE | AQ31: =C31=[1]员工报账!C31 -> TRUE | AR31: =D31=[1]员工报账!D31 -> TRUE | AS31: =E31=[1]员工报账!E31 -> TRUE | AT31: =F31=[1]员工报账!F31 -> TRUE | AU31: =G31=[1]员工报账!G31 -> TRUE | AV31: =H31=[1]员工报账!H31 -> TRUE | ... BX31: =AJ31=[1]员工报账!AJ31 -> TRUE
I32: 员工报账业务-9.自付单据审核-控制措施02 | J32: 强化线下报销验证，未实现系统“单轨控制”的单位强化事前审批，强制“行程轨迹佐证”，同时借助第三方工具“建立发票真伪与重复报销”校验机制。 | M32: √ | Q32: √ | R32: √ | T32: 线下管控 | V32: 1.发票； 2.差旅费标准； 3.出差通知、培训通知等出差缘由证明材料； 4.出差审批单； 5.出差报销单。 | W32: 各级单位-各部门-出差人员、各级单位-各部门-负责人、商旅云公司 | X32: 每日 | Y32: 全量检查 | AA32: 每年 | AB32: 抽查 | AD32: 员工差旅报销监督场景 | AE32: 每月 | AF32: 抽查 | AH32: 是 | AI32: 是 | AJ32: 《国家电网有限公司差旅费管理办法》（国家电网企管〔2026〕101号）第八条、第十一条、第二十四条 | AK32: 国网财务部 | AL32: 各级单位财务部 | AN32: 修改责任主体 | AO32: =A32=[1]员工报账!A32 -> TRUE | AP32: =B32=[1]员工报账!B32 -> TRUE | AQ32: =C32=[1]员工报账!C32 -> TRUE | AR32: =D32=[1]员工报账!D32 -> TRUE | AS32: =E32=[1]员工报账!E32 -> TRUE | AT32: =F32=[1]员工报账!F32 -> TRUE | AU32: =G32=[1]员工报账!G32 -> TRUE | AV32: =H32=[1]员工报账!H32 -> TRUE | ... BX32: =AJ32=[1]员工报账!AJ32 -> TRUE
I33: 员工报账业务-9.自付单据审核-控制措施03 | J33: 财务部门规范自付单据与标准审核流程，逐一核对自付单据人员、时间、地点，并审核费用标准是否符合公司规定。 | M33: √ | Q33: √ | R33: √ | T33: 系统已建 | U33: 国网商旅 | V33: 1.发票； 2.差旅费标准； 3.出差通知、培训通知等出差缘由证明材料； 4.出差审批单； 5.出差报销单。 | W33: 各级单位-各部门-出差人员、商旅云公司、各级单位-财务部门-成本管理人员 | X33: 每日 | Y33: 全量检查 | AA33: 每年 | AB33: 抽查 | AD33: 员工差旅报销监督场景 | AE33: 每月 | AF33: 抽查 | AH33: 是 | AI33: 是 | AJ33: 《国家电网有限公司差旅费管理办法》（国家电网企管〔2026〕101号）第八条、第十一条、第二十四条 | AK33: 国网财务部 | AL33: 各级单位财务部 | AO33: =A33=[1]员工报账!A33 -> TRUE | AP33: =B33=[1]员工报账!B33 -> TRUE | AQ33: =C33=[1]员工报账!C33 -> TRUE | AR33: =D33=[1]员工报账!D33 -> TRUE | AS33: =E33=[1]员工报账!E33 -> TRUE | AT33: =F33=[1]员工报账!F33 -> TRUE | AU33: =G33=[1]员工报账!G33 -> TRUE | AV33: =H33=[1]员工报账!H33 -> TRUE | ... BX33: =AJ33=[1]员工报账!AJ33 -> TRUE
I34: 员工报账业务-9.自付单据审核-控制措施04 | J34: 纪检部门严肃查处违规行为，追回资金损失，严肃查处并予以通报。 | M34: √ | R34: √ | T34: 线下管控 | V34: 1.商旅平台数据线上预订率、电子票据抓取率。 | W34: 各级单位-各部门-出差人员、商旅云公司、各级单位-纪检部门-纪检管理人员 | X34: 每日 | Y34: 全量检查 | AA34: 每年 | AB34: 抽查 | AD34: 员工差旅报销监督场景 | AE34: 每月 | AF34: 抽查 | AH34: 是 | AI34: 是 | AJ34: 《国家电网有限公司差旅费管理办法》（国家电网企管〔2026〕101号）第八条、第十一条、第二十四条、《国网湖南省电力有限公司关于印发加强差旅费管理有关规定的通知》第一条 | AK34: 国网财务部 | AL34: 各级单位财务部 | AN34: 补充制度 | AO34: =A34=[1]员工报账!A34 -> TRUE | AP34: =B34=[1]员工报账!B34 -> TRUE | AQ34: =C34=[1]员工报账!C34 -> TRUE | AR34: =D34=[1]员工报账!D34 -> TRUE | AS34: =E34=[1]员工报账!E34 -> TRUE | AT34: =F34=[1]员工报账!F34 -> TRUE | AU34: =G34=[1]员工报账!G34 -> TRUE | AV34: =H34=[1]员工报账!H34 -> TRUE | ... BX34: =AJ34=[1]员工报账!AJ34 -> FALSE
A35: 员工报账 | B35: 一、员工差旅 | C35: 税务合规、资金资产安全 | D35: 报销申请 | E35: 成本费用报销事项不真实、审批流程不规范，导致成本入账科目错误、虚列成本费用、套取资金私设“小金库”。 | G35: 10.报销事项合规性控制 | H35: 在规定列支范围内，以真实发生的事项发起报销申请，履行规范审批流程。 | I35: 员工报账业务-10.报销事项合规性控制-控制措施01 | J35: 费用报销部门履行费用报销分级授权审批流程，对报销申请事项的真实性进行人工复核，复核报销审批单、费用明细清单、发票或收据、合同或协议等附件的完整性。 | L35: √ | R35: √ | T35: 线下管控 | V35: 1.成本费用报销审批单； 2.费用明细清单； 3.发票或收据； 4.合同或协议； 5.系统审批记录。 | W35: 各级单位-各部门-报账人员、各级单位-各部门-负责人、各级单位-财务部门-成本管理人员 | X35: 每季度 | Y35: 抽查 | AA35: 每年 | AB35: 抽查 | AD35: 报销真实性监督场景 | AE35: 每年 | AF35: 抽查 | AH35: 是 | AI35: 是 | AJ35: 《国家电网有限公司会计基础管理办法》（国家电网企管〔2019〕132号）第八条、第五十四条 《关于加强中央企业资金内部控制管理有关事项的通知》（国资发监督〔2021〕19 号）第十三条、《国网湖南省电力有限公司关于印发加强差旅费管理有关规定的通知》第一条 | AK35: 国网财务部、国网企管部、国网后勤部、国网国际部 | AL35: 各级单位财务部、各级单位企管部（人资部）、各级单位后勤部、 | AN35: 补充制度 | AO35: =A35=[1]员工报账!A35 -> TRUE | AP35: =B35=[1]员工报账!B35 -> TRUE | AQ35: =C35=[1]员工报账!C35 -> TRUE | AR35: =D35=[1]员工报账!D35 -> TRUE | AS35: =E35=[1]员工报账!E35 -> TRUE | AT35: =F35=[1]员工报账!F35 -> TRUE | AU35: =G35=[1]员工报账!G35 -> TRUE | AV35: =H35=[1]员工报账!H35 -> TRUE | ... BX35: =AJ35=[1]员工报账!AJ35 -> FALSE
I36: 员工报账业务-10.报销事项合规性控制-控制措施02 | J36: 加强挂职人员费用报销成本中心校验，挂职期间费用报销申请需选择挂职单位成本中心。 | Q36: √ | T36: 系统已建 | U36: 智慧共享财务平台 | V36: 1.成本费用报销审批单； 2.费用明细清单； 3.发票或收据； 4.合同或协议； 5.系统审批记录。 | W36: 各级单位-各部门-报账人员、各级单位-各部门-负责人、各级单位-财务部门-成本管理人员 | X36: 每季度 | Y36: 抽查 | AA36: 每年 | AB36: 抽查 | AD36: 报销真实性监督场景 | AE36: 每年 | AF36: 抽查 | AH36: 是 | AI36: 是 | AJ36: 《国家电网有限公司会计基础管理办法》（国家电网企管〔2019〕132号）第八条、第五十四条 《关于加强中央企业资金内部控制管理有关事项的通知》（国资发监督〔2021〕19 号）第十三条、《国网湖南省电力有限公司关于印发加强差旅费管理有关规定的通知》第三条 | AK36: 国网财务部、国网企管部、国网后勤部、国网国际部 | AL36: 各级单位财务部、各级单位企管部（人资部）、各级单位后勤部、 | AN36: 补充制度 | AO36: =A36=[1]员工报账!A36 -> TRUE | AP36: =B36=[1]员工报账!B36 -> TRUE | AQ36: =C36=[1]员工报账!C36 -> TRUE | AR36: =D36=[1]员工报账!D36 -> TRUE | AS36: =E36=[1]员工报账!E36 -> TRUE | AT36: =F36=[1]员工报账!F36 -> TRUE | AU36: =G36=[1]员工报账!G36 -> TRUE | AV36: =H36=[1]员工报账!H36 -> TRUE | ... BX36: =AJ36=[1]员工报账!AJ36 -> FALSE
I37: 员工报账业务-10.报销事项合规性控制-控制措施03 | J37: 财务部门对费用报销选择业务事项准确性进行复核，校验报销流程和成本中心准确性。 | M37: √ | Q37: √ | T37: 系统已建 | U37: 智慧共享财务平台 | V37: 1.成本费用报销审批单； 2.费用明细清单； 3.发票或收据； 4.合同或协议； 5.系统审批记录。 | W37: 各级单位-各部门-报账人员、各级单位-各部门-负责人、各级单位-财务部门-成本管理人员 | X37: 每季度 | Y37: 抽查 | AA37: 每年 | AB37: 抽查 | AD37: 报销真实性监督场景 | AE37: 每年 | AF37: 抽查 | AH37: 是 | AI37: 是 | AJ37: 《国家电网有限公司会计基础管理办法》（国家电网企管〔2019〕132号）第八条、第五十四条 《关于加强中央企业资金内部控制管理有关事项的通知》（国资发监督〔2021〕19 号）第十三条 | AK37: 国网财务部、国网企管部、国网后勤部、国网国际部 | AL37: 各级单位财务部、各级单位企管部（人资部）、各级单位后勤部、 | AO37: =A37=[1]员工报账!A37 -> TRUE | AP37: =B37=[1]员工报账!B37 -> TRUE | AQ37: =C37=[1]员工报账!C37 -> TRUE | AR37: =D37=[1]员工报账!D37 -> TRUE | AS37: =E37=[1]员工报账!E37 -> TRUE | AT37: =F37=[1]员工报账!F37 -> TRUE | AU37: =G37=[1]员工报账!G37 -> TRUE | AV37: =H37=[1]员工报账!H37 -> TRUE | ... BX37: =AJ37=[1]员工报账!AJ37 -> TRUE
I38: 员工报账业务-10.报销事项合规性控制-控制措施04 | J38: 进行违规责任追究，对虚列成本费用、套取资金私设“小金库”的人员根据相关规定进行违规责任追究。 | R38: √ | T38: 线下管控 | V38: 1.责任追究证明材料。 | W38: 各级单位-各部门-报账人员、各级单位-各部门-负责人、各级单位-财务部门-成本管理人员、各级单位-纪检部门-纪检管理人员 | X38: 每季度 | Y38: 抽查 | AA38: 每年 | AB38: 抽查 | AD38: 报销真实性监督场景 | AE38: 每年 | AF38: 抽查 | AH38: 是 | AI38: 是 | AJ38: 《国家电网有限公司会计基础管理办法》（国家电网企管〔2019〕132号）第八条、第五十四条 《关于加强中央企业资金内部控制管理有关事项的通知》（国资发监督〔2021〕19 号）第十三条 | AK38: 国网财务部、国网企管部、国网后勤部、国网国际部 | AL38: 各级单位财务部、各级单位企管部（人资部）、各级单位后勤部、 | AO38: =A38=[1]员工报账!A38 -> TRUE | AP38: =B38=[1]员工报账!B38 -> TRUE | AQ38: =C38=[1]员工报账!C38 -> TRUE | AR38: =D38=[1]员工报账!D38 -> TRUE | AS38: =E38=[1]员工报账!E38 -> TRUE | AT38: =F38=[1]员工报账!F38 -> TRUE | AU38: =G38=[1]员工报账!G38 -> TRUE | AV38: =H38=[1]员工报账!H38 -> TRUE | ... BX38: =AJ38=[1]员工报账!AJ38 -> TRUE
B39: 二、通用报账 | C39: 税务合规 | D39: 费用报销 | E39: 发票信息不准确、不完整，与报销业务不一致导致税务风险 | G39: 11.报销发票审核 | H39: 报销发票真实、准确、完整 | I39: 员工报账业务-11.报销发票审核-控制措施01 | J39: 归口管理部门对报销发票、入库单、采购订单物品对应关系进行复核，确认购物清单通过税务防伪系统开具。 | L39: √ | M39: √ | T39: 系统已建 | U39: 智慧共享财务平台 | V39: 1.成本费用报销申请单； 2.费用明细清单； 3.发票或收据、购物清单； 4.合同或协议。 | W39: 各级单位-各部门-报账人员、各级单位-各部门-负责人、各级单位-财务部门-成本管理人员 | X39: 每季度 | Y39: 抽查 | AA39: 每年 | AB39: 抽查 | AD39: 发票审核管理监督场景 | AE39: 每年 | AF39: 抽查 | AH39: 是 | AI39: 是 | AJ39: 国家电网企管〔2019〕132号《国家电网有限公司会计基础管理办法》第五十条 | AK39: 国网财务部、国网企管部、国网后勤部、国网国际部 | AL39: 各级单位财务部、各级单位企管部（人资部）、各级单位后勤部、 | AO39: =A39=[1]员工报账!A39 -> TRUE | AP39: =B39=[1]员工报账!B39 -> TRUE | AQ39: =C39=[1]员工报账!C39 -> TRUE | AR39: =D39=[1]员工报账!D39 -> TRUE | AS39: =E39=[1]员工报账!E39 -> TRUE | AT39: =F39=[1]员工报账!F39 -> TRUE | AU39: =G39=[1]员工报账!G39 -> TRUE | AV39: =H39=[1]员工报账!H39 -> TRUE | ... BX39: =AJ39=[1]员工报账!AJ39 -> TRUE
I40: 员工报账业务-11.报销发票审核-控制措施02 | J40: 各部门建立发票“谁提交、谁审核、谁负责”闭环管理机制,发票提交人落实发票验真责任。 | M40: √ | R40: √ | T40: 系统已建 | U40: 智慧共享财务平台 | V40: 1.成本费用报销申请单； 2.费用明细清单； 3.发票或收据、购物清单； 4.合同或协议。 | W40: 各级单位-各部门-报账人员、各级单位-各部门-负责人 | X40: 每季度 | Y40: 抽查 | AA40: 每年 | AB40: 抽查 | AD40: 发票审核管理监督场景 | AE40: 每年 | AF40: 抽查 | AH40: 是 | AI40: 是 | AJ40: 国家电网企管〔2019〕132号《国家电网有限公司会计基础管理办法》第五十条 | AK40: 国网企管部、国网后勤部、国网国际部 | AL40: 各级单位财务部、各级单位企管部（人资部）、各级单位后勤部 | AO40: =A40=[1]员工报账!A40 -> TRUE | AP40: =B40=[1]员工报账!B40 -> TRUE | AQ40: =C40=[1]员工报账!C40 -> TRUE | AR40: =D40=[1]员工报账!D40 -> TRUE | AS40: =E40=[1]员工报账!E40 -> TRUE | AT40: =F40=[1]员工报账!F40 -> TRUE | AU40: =G40=[1]员工报账!G40 -> TRUE | AV40: =H40=[1]员工报账!H40 -> TRUE | ... BX40: =AJ40=[1]员工报账!AJ40 -> TRUE
...

Sheet 员工报账（确认三清单版本核对过程7.30）
A1: 风控矩阵-员工报账
A2: 业务条线 | B2: 业务领域 | C2: 控制目标 | D2: 业务流程步骤 | E2: 经营风险 | F2: 典型问题 | G2: 关键控制点 | H2: 控制要求 | I2: 控制措施 编号 | J2: 控制措施 | K2: 控制措施分类 | T2: 控制方式 | U2: 控制系统 | V2: 控制载体 | W2: 责任主体 | X2: 业务自评价 | AA2: 集团监督 评价 | AD2: 数字化监督场景 | AH2: 现有制度及文件落实情况 | AK2: 总部审核部门 | AL2: 湖南公司审核部门 | AM2: 其他备注 | AN2: 7.23 | AO2: 7.3
K3: 不相容岗位 | L3: 分级授权 | M3: 业务真实性控制 | N3: 预算管控 | O3: 合同控制 | P3: 收付控制 | Q3: 会计监督 | R3: 财产保护 | S3: 分析与评价 | X3: 评价频率 | Y3: 评价范围 | Z3: 评价结论 | AA3: 评价频率 | AB3: 评价范围 | AC3: 评价结论 | AD3: 数字化监督场景 | AE3: 评价频率 | AF3: 评价范围 | AG3: 评价结论 | AH3: 是否已要求 | AI3: 是否满足要求 | AJ3: 对应制度及文件名称
A4: 员工报账 | B4: 一、员工差旅 | C4: 资金资产安全 | D4: 出差申请 | E4: 出差事项不真实，出差无实质内容，无明确公务目的，虚列套取费用，导致资金安全风险。 | F4: 87.违规发放津贴补贴：存在多报差旅补贴、虚报差旅补贴等问题。 | G4: 1.出差申请发起 | H4: 出差有明确公务目的，出差时间、地点、人员与出差通知一致。 | I4: 员工报账业务-1.出差申请发起-控制措施01 | J4: 出差员工部门负责人对员工出差内容的复核，重点审查出差申请单人员、地点、事由等信息。 | M4: √ | T4: 系统已建 | U4: 国网商旅 | V4: 1.出差通知、培训通知等出差缘由证明材料。 | W4: 各级单位-各部门-出差人员、各级单位-各部门-负责人、商旅云公司 | X4: 每日 | Y4: 全量检查 | AA4: 每年 | AB4: 抽查 | AD4: 员工差旅出差申请监督场景 | AE4: 每月 | AF4: 抽查 | AH4: 是 | AI4: 是 | AJ4: 《国家电网有限公司差旅费管理办法》（国家电网企管〔2026〕101号）第四条、第二十四条、《国网湖南省电力有限公司关于印发加强差旅费管理有关规定的通知》第二条、第三条 | AK4: 国网财务部 | AL4: 各级单位财务部 | AN4: 补充制度 | AP4: =A4=[2]员工报账!A4 -> TRUE | AQ4: =B4=[2]员工报账!B4 -> TRUE | AR4: =C4=[2]员工报账!C4 -> TRUE | AS4: =D4=[2]员工报账!D4 -> TRUE | AT4: =E4=[2]员工报账!E4 -> TRUE | AU4: =F4=[2]员工报账!F4 -> TRUE | AV4: =G4=[2]员工报账!G4 -> TRUE | AW4: =H4=[2]员工报账!H4 -> TRUE | ... BZ4: =AK4=[2]员工报账!AK4 -> TRUE
I5: 员工报账业务-1.出差申请发起-控制措施02 | J5: 健全“申请-预订-报销”数据联动校验规则，落实预算控制，系统自动比对出差事项与出差产生的票据的逻辑一致性。 | M5: √ | N5: √ | T5: 系统已建 | U5: 国网商旅 | V5: 1.出差审批单。 | W5: 各级单位-各部门-出差人员、商旅云公司 | X5: 每日 | Y5: 全量检查 | AA5: 每年 | AB5: 抽查 | AD5: 员工差旅出差申请监督场景 | AE5: 每月 | AF5: 抽查 | AH5: 是 | AI5: 是 | AJ5: 《国家电网有限公司差旅费管理办法》（国家电网企管〔2026〕101号）第四条、第二十四条、《国网湖南省电力有限公司关于印发加强差旅费管理有关规定的通知》第二条、第三条 | AK5: 国网财务部 | AL5: 各级单位财务部 | AN5: 补充制度 | AP5: =A5=[2]员工报账!A5 -> TRUE | AQ5: =B5=[2]员工报账!B5 -> TRUE | AR5: =C5=[2]员工报账!C5 -> TRUE | AS5: =D5=[2]员工报账!D5 -> TRUE | AT5: =E5=[2]员工报账!E5 -> TRUE | AU5: =F5=[2]员工报账!F5 -> TRUE | AV5: =G5=[2]员工报账!G5 -> TRUE | AW5: =H5=[2]员工报账!H5 -> TRUE | ... BZ5: =AK5=[2]员工报账!AK5 -> TRUE
I6: 员工报账业务-1.出差申请发起-控制措施03 | J6: 健全差旅费成本中心校验机制，赴异地挂职、按照规定探亲在途期间出差申请选择原单位成本中心，挂职期间出差申请选择挂职单位成本中心。 | N6: √ | Q6: √ | T6: 系统已建 | U6: 国网商旅 | V6: 1.系统出差申请单校验记录等。 | W6: 各级单位-各部门-出差人员、商旅云公司 | X6: 每日 | Y6: 全量检查 | AA6: 每年 | AB6: 抽查 | AD6: 员工差旅出差申请监督场景 | AE6: 每月 | AF6: 抽查 | AH6: 是 | AI6: 是 | AJ6: 《国家电网有限公司差旅费管理办法》（国家电网企管〔2026〕101号）第四条、第二十四条、《国网湖南省电力有限公司关于印发加强差旅费管理有关规定的通知》第二条、第三条 | AK6: 国网财务部 | AL6: 各级单位财务部 | AN6: 补充制度 | AP6: =A6=[2]员工报账!A6 -> TRUE | AQ6: =B6=[2]员工报账!B6 -> TRUE | AR6: =C6=[2]员工报账!C6 -> TRUE | AS6: =D6=[2]员工报账!D6 -> TRUE | AT6: =E6=[2]员工报账!E6 -> TRUE | AU6: =F6=[2]员工报账!F6 -> TRUE | AV6: =G6=[2]员工报账!G6 -> TRUE | AW6: =H6=[2]员工报账!H6 -> TRUE | ... BZ6: =AK6=[2]员工报账!AK6 -> TRUE
G7: 2.出差申请审批 | H7: 按规定执行出差审批制度。 | I7: 员工报账业务-2.出差申请审批-控制措施01 | J7: 流程固化与防逆向控制，商旅云公司固化“审批-预订-报销”流程，严格限制并需特殊授权才能“取消审批”等逆向操作。 | L7: √ | Q7: √ | T7: 系统已建 | U7: 国网商旅 | V7: 1.出差通知、培训通知等出差缘由证明材料； 2.出差审批单； 3.系统出差申请单审批轨迹。 | W7: 各级单位-各部门-出差人员、商旅云公司 | X7: 每日 | Y7: 全量检查 | AA7: 每年 | AB7: 抽查 | AD7: 员工差旅出差申请监督场景 | AE7: 每月 | AF7: 抽查 | AH7: 是 | AI7: 是 | AJ7: 《国家电网有限公司差旅费管理办法》（国家电网企管〔2026〕101号）第二十二条 | AK7: 国网财务部 | AL7: 各级单位财务部 | AP7: =A7=[2]员工报账!A7 -> TRUE | AQ7: =B7=[2]员工报账!B7 -> TRUE | AR7: =C7=[2]员工报账!C7 -> TRUE | AS7: =D7=[2]员工报账!D7 -> TRUE | AT7: =E7=[2]员工报账!E7 -> TRUE | AU7: =F7=[2]员工报账!F7 -> TRUE | AV7: =G7=[2]员工报账!G7 -> TRUE | AW7: =H7=[2]员工报账!H7 -> TRUE | ... BZ7: =AK7=[2]员工报账!AK7 -> TRUE
I8: 员工报账业务-2.出差申请审批-控制措施02 | J8: 全链条强制关联控制，系统强制将“审批单号”作为商旅预订及费用报销的唯一前提。 | Q8: √ | T8: 系统已建 | U8: 国网商旅 | V8: 1.出差通知、培训通知等出差缘由证明材料； 2.出差审批单。 | W8: 各级单位-各部门-出差人员、商旅云公司 | X8: 每日 | Y8: 全量检查 | AA8: 每年 | AB8: 抽查 | AD8: 员工差旅出差申请监督场景 | AE8: 每月 | AF8: 抽查 | AH8: 是 | AI8: 是 | AJ8: 《国家电网有限公司差旅费管理办法》（国家电网企管〔2026〕101号）第四条、第二十四条、第二十六条 | AK8: 国网财务部 | AL8: 各级单位财务部 | AP8: =A8=[2]员工报账!A8 -> TRUE | AQ8: =B8=[2]员工报账!B8 -> TRUE | AR8: =C8=[2]员工报账!C8 -> TRUE | AS8: =D8=[2]员工报账!D8 -> TRUE | AT8: =E8=[2]员工报账!E8 -> TRUE | AU8: =F8=[2]员工报账!F8 -> TRUE | AV8: =G8=[2]员工报账!G8 -> TRUE | AW8: =H8=[2]员工报账!H8 -> TRUE | ... BZ8: =AK8=[2]员工报账!AK8 -> TRUE
I9: 员工报账业务-2.出差申请审批-控制措施03 | J9: 商旅云公司严禁后台“绿色通道”操作，禁止平台通过电话申请取消审批行为。 | M9: √ | T9: 系统待建 | U9: 国网商旅 | V9: 1.出差通知、培训通知等出差缘由证明材料； 2.出差审批单； 3.系统出差申请单审批轨迹。 | W9: 各级单位-各部门-出差人员、商旅云公司 | X9: 每日 | Y9: 全量检查 | AA9: 每年 | AB9: 抽查 | AD9: 员工差旅出差申请监督场景 | AE9: 每月 | AF9: 抽查 | AH9: 是 | AI9: 是 | AJ9: 《国家电网有限公司差旅费管理办法》（国家电网企管〔2026〕101号）第四条、第二十四条、第二十六条 | AK9: 国网财务部 | AL9: 各级单位财务部 | AP9: =A9=[2]员工报账!A9 -> TRUE | AQ9: =B9=[2]员工报账!B9 -> TRUE | AR9: =C9=[2]员工报账!C9 -> TRUE | AS9: =D9=[2]员工报账!D9 -> TRUE | AT9: =E9=[2]员工报账!E9 -> TRUE | AU9: =F9=[2]员工报账!F9 -> TRUE | AV9: =G9=[2]员工报账!G9 -> TRUE | AW9: =H9=[2]员工报账!H9 -> TRUE | ... BZ9: =AK9=[2]员工报账!AK9 -> TRUE
A10: 员工报账 | B10: 一、员工差旅 | C10: 税务合规 | D10: 出差申请 | E10: 商旅平台违规取消事前审批流程，导致出现“先出差后申请”的情况，引发舞弊及合规管理风险。 | F10: 87.违规发放津贴补贴：存在多报差旅补贴、虚报差旅补贴等问题。 | G10: 3.出差申请流程控制 | H10: 出差申请日期早于出差日期。 | I10: 员工报账业务-3.出差申请流程控制-控制措施01 | J10: 审批要素完整性校验，系统强制校验审批单的必备要素，对缺少出差事由等关键要素的申请单不予通过。 | M10: √ | T10: 系统已建 | U10: 国网商旅 | V10: 1.系统出差申请单审批轨迹； 2.系统记录的申请单提交时间和出差时间。 | W10: 各级单位-各部门-出差人员、各级单位-各部门-负责人、商旅云公司 | X10: 每日 | Y10: 全量检查 | AA10: 每年 | AB10: 抽查 | AD10: 员工差旅流程配置监督场景 | AE10: 每月 | AF10: 抽查 | AH10: 是 | AI10: 是 | AJ10: 《国家电网有限公司差旅费管理办法》（国家电网企管〔2026〕101号）第五条 | AK10: 国网财务部 | AL10: 各级单位财务部 | AN10: 修改责任主体 | AP10: =A10=[2]员工报账!A10 -> TRUE | AQ10: =B10=[2]员工报账!B10 -> TRUE | AR10: =C10=[2]员工报账!C10 -> TRUE | AS10: =D10=[2]员工报账!D10 -> TRUE | AT10: =E10=[2]员工报账!E10 -> TRUE | AU10: =F10=[2]员工报账!F10 -> TRUE | AV10: =G10=[2]员工报账!G10 -> TRUE | AW10: =H10=[2]员工报账!H10 -> TRUE | ... BZ10: =AK10=[2]员工报账!AK10 -> TRUE
I11: 员工报账业务-3.出差申请流程控制-控制措施02 | J11: 严格执行不相容控制，系统根据组织架构与授权清单自动匹配并校验审批人权限，防范越权审批 | R11: √ | T11: 系统已建 | U11: 国网商旅 | V11: 1.系统记录的申请单提交时间和出差时间。 | W11: 商旅云公司、各级单位-各部门-出差人员、各级单位-各部门-负责人 | X11: 每日 | Y11: 全量检查 | AA11: 每年 | AB11: 抽查 | AD11: 员工差旅流程配置监督场景 | AE11: 每月 | AF11: 抽查 | AH11: 是 | AI11: 是 | AJ11: 《国家电网有限公司差旅费管理办法》（国家电网企管〔2026〕101号）第五条 | AK11: 国网财务部 | AL11: 各级单位财务部 | AP11: =A11=[2]员工报账!A11 -> TRUE | AQ11: =B11=[2]员工报账!B11 -> TRUE | AR11: =C11=[2]员工报账!C11 -> TRUE | AS11: =D11=[2]员工报账!D11 -> TRUE | AT11: =E11=[2]员工报账!E11 -> TRUE | AU11: =F11=[2]员工报账!F11 -> TRUE | AV11: =G11=[2]员工报账!G11 -> TRUE | AW11: =H11=[2]员工报账!H11 -> TRUE | ... BZ11: =AK11=[2]员工报账!AK11 -> TRUE
I12: 员工报账业务-3.出差申请流程控制-控制措施03 | J12: 建立定期分析、评价与问责机制，各部门对审批时效、驳回率、特批事项进行专项分析，审计部门、纪检部门等监督部门对违规审批、补批行为依规问责。 | M12: √ | R12: √ | S12: √ | T12: 线下管控 | V12: 1.系统记录的申请单提交时间和出差时间。 | W12: 商旅云公司、各级单位-审计部门、纪检部门等监督部门-监督、纪检管理人员 | X12: 每日 | Y12: 全量检查 | AA12: 每年 | AB12: 抽查 | AD12: 员工差旅流程配置监督场景 | AE12: 每月 | AF12: 抽查 | AH12: 是 | AI12: 是 | AJ12: 《国家电网有限公司差旅费管理办法》（国家电网企管〔2026〕101号）第五条 | AK12: 国网财务部 | AL12: 各级单位财务部 | AN12: 修改责任主体 | AP12: =A12=[2]员工报账!A12 -> TRUE | AQ12: =B12=[2]员工报账!B12 -> TRUE | AR12: =C12=[2]员工报账!C12 -> TRUE | AS12: =D12=[2]员工报账!D12 -> TRUE | AT12: =E12=[2]员工报账!E12 -> TRUE | AU12: =F12=[2]员工报账!F12 -> TRUE | AV12: =G12=[2]员工报账!G12 -> TRUE | AW12: =H12=[2]员工报账!H12 -> TRUE | ... BZ12: =AK12=[2]员工报账!AK12 -> TRUE
C13: 税务合规 | D13: 差旅预订 | E13: 商旅平台酒店存在棋牌、麻将、电竞等敏感字眼，商旅平台违规上架引发合规风险。 | G13: 4.酒店入驻上架控制 | H13: 酒店资源上架流程合规，且履行必要的审批手续。 | I13: 员工报账业务-4.酒店入驻上架控制-控制措施01 | J13: 商旅云公司强化供应商准入审核，对新签约酒店的的资质有效性、服务适配性以及风险可控性等信息进行事前审核。 | O13: √ | T13: 系统待建 | U13: 国网商旅 | V13: 1.酒店资质、营业执照、房型清单。 | W13: 商旅云公司 | X13: 每日 | Y13: 全量检查 | AA13: 每年 | AB13: 抽查 | AD13: 员工差旅预订监督场景 | AE13: 每月 | AF13: 抽查 | AH13: 是 | AI13: 是 | AJ13: 《国家电网有限公司差旅费管理办法》（国家电网企管〔2026〕101号）第五条 | AK13: 国网财务部 | AL13: 各级单位财务部 | AP13: =A13=[2]员工报账!A13 -> TRUE | AQ13: =B13=[2]员工报账!B13 -> TRUE | AR13: =C13=[2]员工报账!C13 -> TRUE | AS13: =D13=[2]员工报账!D13 -> TRUE | AT13: =E13=[2]员工报账!E13 -> TRUE | AU13: =F13=[2]员工报账!F13 -> TRUE | AV13: =G13=[2]员工报账!G13 -> TRUE | AW13: =H13=[2]员工报账!H13 -> TRUE | ... BZ13: =AK13=[2]员工报账!AK13 -> TRUE
I14: 员工报账业务-4.酒店入驻上架控制-控制措施02 | J14: 商旅云公司建立并动态更新《敏感词库与酒店属性负面清单》，系统自动拦截负面清单内容并转人工复核。 | O14: √ | Q14: √ | S14: √ | T14: 系统待建 | U14: 国网商旅 | V14: 1.系统敏感词库与酒店属性负面清单。 | W14: 商旅云公司 | X14: 每日 | Y14: 全量检查 | AA14: 每年 | AB14: 抽查 | AD14: 员工差旅预订监督场景 | AE14: 每月 | AF14: 抽查 | AH14: 是 | AI14: 是 | AJ14: 《国家电网有限公司差旅费管理办法》（国家电网企管〔2026〕101号）第五条 | AK14: 国网财务部 | AL14: 各级单位财务部 | AP14: =A14=[2]员工报账!A14 -> TRUE | AQ14: =B14=[2]员工报账!B14 -> TRUE | AR14: =C14=[2]员工报账!C14 -> TRUE | AS14: =D14=[2]员工报账!D14 -> TRUE | AT14: =E14=[2]员工报账!E14 -> TRUE | AU14: =F14=[2]员工报账!F14 -> TRUE | AV14: =G14=[2]员工报账!G14 -> TRUE | AW14: =H14=[2]员工报账!H14 -> TRUE | ... BZ14: =AK14=[2]员工报账!AK14 -> TRUE
I15: 员工报账业务-4.酒店入驻上架控制-控制措施03 | J15: 追回违规上架酒店产生的资金浪费，并对相关负责人按规定给予处分处理。 | R15: √ | S15: √ | T15: 线下管控 | V15: 1.问责证明材料。 | W15: 商旅云公司 | X15: 每日 | Y15: 全量检查 | AA15: 每年 | AB15: 抽查 | AD15: 员工差旅预订监督场景 | AE15: 每月 | AF15: 抽查 | AH15: 是 | AI15: 是 | AJ15: 《国家电网有限公司差旅费管理办法》（国家电网企管〔2026〕101号）第五条 | AK15: 国网财务部 | AL15: 各级单位财务部 | AP15: =A15=[2]员工报账!A15 -> TRUE | AQ15: =B15=[2]员工报账!B15 -> TRUE | AR15: =C15=[2]员工报账!C15 -> TRUE | AS15: =D15=[2]员工报账!D15 -> TRUE | AT15: =E15=[2]员工报账!E15 -> TRUE | AU15: =F15=[2]员工报账!F15 -> TRUE | AV15: =G15=[2]员工报账!G15 -> TRUE | AW15: =H15=[2]员工报账!H15 -> TRUE | ... BZ15: =AK15=[2]员工报账!AK15 -> TRUE
C16: 资金资产安全 | D16: 差旅预订 | E16: 酒店价格虚高易引发套取资金，引发廉政风险。 | F16: 87.违规发放津贴补贴：存在多报差旅补贴、虚报差旅补贴等问题。 | G16: 5.单体酒店上架及价格定价管控 | H16: 商旅平台酒店资源价格真实合理。 | I16: 员工报账业务-5.单体酒店上架及价格定价管控-控制措施01 | J16: 增加单体酒店上架申请审批流程，由各单位办公室汇总审核本单位酒店需求，向商旅云公司提交上架。 | L16: √ | O16: √ | T16: 系统已建 | U16: 国网商旅 | V16: 1.协议单体酒店推荐表单。 | W16: 商旅云公司、各级单位-办公室财务部 | X16: 每日 | Y16: 全量检查 | AA16: 每年 | AB16: 抽查 | AD16: 员工差旅预订监督场景 | AE16: 每月 | AF16: 抽查 | AH16: 是 | AI16: 是 | AJ16: 《国家电网有限公司差旅费管理办法》（国家电网企管〔2026〕101号）第五条 | AK16: 国网财务部 | AL16: 各级单位财务部 | AN16: 修改责任主体 | AP16: =A16=[2]员工报账!A16 -> TRUE | AQ16: =B16=[2]员工报账!B16 -> TRUE | AR16: =C16=[2]员工报账!C16 -> TRUE | AS16: =D16=[2]员工报账!D16 -> TRUE | AT16: =E16=[2]员工报账!E16 -> TRUE | AU16: =F16=[2]员工报账!F16 -> TRUE | AV16: =G16=[2]员工报账!G16 -> TRUE | AW16: =H16=[2]员工报账!H16 -> TRUE | ... BZ16: =AK16=[2]员工报账!AK16 -> TRUE
I17: 员工报账业务-5.单体酒店上架及价格定价管控-控制措施02 | J17: 商旅云公司强化协议签订管控，严格审核酒店资质，严控无理由上架，防范舞弊行为。 | O17: √ | T17: 系统已建 | U17: 国网商旅 | V17: 1.酒单违规风险清单； 2.采购协议酒店清单； 3.酒店上架评审报告。 | W17: 商旅云公司 | X17: 每日 | Y17: 全量检查 | AA17: 每年 | AB17: 抽查 | AD17: 员工差旅预订监督场景 | AE17: 每月 | AF17: 抽查 | AH17: 是 | AI17: 是 | AJ17: 《国家电网有限公司差旅费管理办法》（国家电网企管〔2026〕101号）第五条 | AK17: 国网财务部 | AL17: 各级单位财务部 | AP17: =A17=[2]员工报账!A17 -> TRUE | AQ17: =B17=[2]员工报账!B17 -> TRUE | AR17: =C17=[2]员工报账!C17 -> TRUE | AS17: =D17=[2]员工报账!D17 -> TRUE | AT17: =E17=[2]员工报账!E17 -> TRUE | AU17: =F17=[2]员工报账!F17 -> TRUE | AV17: =G17=[2]员工报账!G17 -> TRUE | AW17: =H17=[2]员工报账!H17 -> TRUE | ... BZ17: =AK17=[2]员工报账!AK17 -> TRUE
I18: 员工报账业务-5.单体酒店上架及价格定价管控-控制措施03 | J18: 加强员工行为管控，商旅云公司强化酒店订单在线监督，防范员工违规套取资金。 | M18: √ | R18: √ | T18: 系统已建 | U18: 国网商旅 | V18: 1.酒店合作协议。 | W18: 商旅云公司 | X18: 每日 | Y18: 全量检查 | AA18: 每年 | AB18: 抽查 | AD18: 员工差旅预订监督场景 | AE18: 每月 | AF18: 抽查 | AH18: 是 | AI18: 是 | AJ18: 《国家电网有限公司差旅费管理办法》（国家电网企管〔2026〕101号）第五条 | AK18: 国网财务部 | AL18: 各级单位财务部 | AP18: =A18=[2]员工报账!A18 -> TRUE | AQ18: =B18=[2]员工报账!B18 -> TRUE | AR18: =C18=[2]员工报账!C18 -> TRUE | AS18: =D18=[2]员工报账!D18 -> TRUE | AT18: =E18=[2]员工报账!E18 -> TRUE | AU18: =F18=[2]员工报账!F18 -> TRUE | AV18: =G18=[2]员工报账!G18 -> TRUE | AW18: =H18=[2]员工报账!H18 -> TRUE | ... BZ18: =AK18=[2]员工报账!AK18 -> TRUE
A19: 员工报账 | B19: 一、员工差旅 | C19: 资金资产安全 | D19: 差旅预订 | E19: 酒店价格虚高易引发套取资金，引发廉政风险。 | F19: 87.违规发放津贴补贴：存在多报差旅补贴、虚报差旅补贴等问题。 | G19: 5.单体酒店上架及价格定价管控 | H19: 商旅平台酒店资源价格真实合理。 | I19: 员工报账业务-5.单体酒店上架及价格定价管控-控制措施04 | J19: 建立负面清单，及时清退违规酒店。 | R19: √ | S19: √ | T19: 线下管控 | V19: 1.酒店风险识别机制； 2.员工体验反馈。 | W19: 商旅云公司 | X19: 每日 | Y19: 全量检查 | AA19: 每年 | AB19: 抽查 | AD19: 员工差旅预订监督场景 | AE19: 每月 | AF19: 抽查 | AH19: 是 | AI19: 是 | AJ19: 《国家电网有限公司差旅费管理办法》（国家电网企管〔2026〕101号）第五条 | AK19: 国网财务部 | AL19: 各级单位财务部 | AP19: =A19=[2]员工报账!A19 -> TRUE | AQ19: =B19=[2]员工报账!B19 -> TRUE | AR19: =C19=[2]员工报账!C19 -> TRUE | AS19: =D19=[2]员工报账!D19 -> TRUE | AT19: =E19=[2]员工报账!E19 -> TRUE | AU19: =F19=[2]员工报账!F19 -> TRUE | AV19: =G19=[2]员工报账!G19 -> TRUE | AW19: =H19=[2]员工报账!H19 -> TRUE | ... BZ19: =AK19=[2]员工报账!AK19 -> TRUE
D20: 差旅预订 | E20: 员工在同一时间段内重复预订酒店资源，存在套取资金风险。 | F20: 87.违规发放津贴补贴：存在多报差旅补贴、虚报差旅补贴等问题。 | G20: 6.酒店预订 | H20: 同一员工在同一时间段内，就同一出差行程，仅能生成一个有效住宿订单。 | I20: 员工报账业务-6.酒店预订-控制措施01 | J20: 商旅云公司完善重复订单系统校验规则，自动拦截并预警同一人员、时段重叠的酒店订单申请。 | M20: √ | T20: 系统已建 | U20: 国网商旅 | V20: 1.商旅订单； 2.出差通知、培训通知等出差缘由证明材料。 | W20: 各级单位-各部门-出差人员、商旅云公司 | X20: 每日 | Y20: 全量检查 | AA20: 每年 | AB20: 抽查 | AD20: 员工差旅预订监督场景 | AE20: 每月 | AF20: 抽查 | AH20: 是 | AI20: 是 | AJ20: 《国家电网有限公司差旅费管理办法》（国家电网企管〔2026〕101号）第二十四条 | AK20: 国网财务部 | AL20: 各级单位财务部 | AP20: =A20=[2]员工报账!A20 -> TRUE | AQ20: =B20=[2]员工报账!B20 -> TRUE | AR20: =C20=[2]员工报账!C20 -> TRUE | AS20: =D20=[2]员工报账!D20 -> TRUE | AT20: =E20=[2]员工报账!E20 -> TRUE | AU20: =F20=[2]员工报账!F20 -> TRUE | AV20: =G20=[2]员工报账!G20 -> TRUE | AW20: =H20=[2]员工报账!H20 -> TRUE | ... BZ20: =AK20=[2]员工报账!AK20 -> TRUE
I21: 员工报账业务-6.酒店预订-控制措施02 | J21: 商旅云公司健全入住轨迹验证与反馈机制，自动识别入住轨迹异常情况，即时预警有关责任人。 | M21: √ | S21: √ | T21: 系统已建 | U21: 国网商旅 | V21: 1.系统拦截记录。 | W21: 各级单位-各部门-出差人员、商旅云公司 | X21: 每日 | Y21: 全量检查 | AA21: 每年 | AB21: 抽查 | AD21: 员工差旅预订监督场景 | AE21: 每月 | AF21: 抽查 | AH21: 是 | AI21: 是 | AJ21: 《国家电网有限公司差旅费管理办法》（国家电网企管〔2026〕101号）第二十四条 | AK21: 国网财务部 | AL21: 各级单位财务部 | AP21: =A21=[2]员工报账!A21 -> TRUE | AQ21: =B21=[2]员工报账!B21 -> TRUE | AR21: =C21=[2]员工报账!C21 -> TRUE | AS21: =D21=[2]员工报账!D21 -> TRUE | AT21: =E21=[2]员工报账!E21 -> TRUE | AU21: =F21=[2]员工报账!F21 -> TRUE | AV21: =G21=[2]员工报账!G21 -> TRUE | AW21: =H21=[2]员工报账!H21 -> TRUE | ... BZ21: =AK21=[2]员工报账!AK21 -> TRUE
I22: 员工报账业务-6.酒店预订-控制措施03 | J22: 财务部门加强出差申请与酒店订单的交叉复核，校验人员、时间、订单的合理性与唯一性。 | M22: √ | T22: 系统已建 | U22: 国网商旅 | V22: 1.出差报销单； 2.入住轨迹与异常情况反馈。 | W22: 各级单位-各部门-出差人员、各级单位-财务部门-成本管理人员、商旅云公司 | X22: 每日 | Y22: 全量检查 | AA22: 每年 | AB22: 抽查 | AD22: 员工差旅预订监督场景 | AE22: 每月 | AF22: 抽查 | AH22: 是 | AI22: 是 | AJ22: 《国家电网有限公司差旅费管理办法》（国家电网企管〔2026〕101号）第二十四条 | AK22: 国网财务部 | AL22: 各级单位财务部 | AN22: 修改责任主体 | AP22: =A22=[2]员工报账!A22 -> TRUE | AQ22: =B22=[2]员工报账!B22 -> TRUE | AR22: =C22=[2]员工报账!C22 -> TRUE | AS22: =D22=[2]员工报账!D22 -> TRUE | AT22: =E22=[2]员工报账!E22 -> TRUE | AU22: =F22=[2]员工报账!F22 -> TRUE | AV22: =G22=[2]员工报账!G22 -> TRUE | AW22: =H22=[2]员工报账!H22 -> TRUE | ... BZ22: =AK22=[2]员工报账!AK22 -> TRUE
C23: 税务合规 | D23: 差旅报销 | E23: 擅自扩大差旅费开支范围，提高差旅费开支标准，增加差旅出行成本。 | F23: 87.违规发放津贴补贴：存在多报差旅补贴、虚报差旅补贴等问题。 | G23: 7.差旅标准执行 | H23: 差旅费开支标准、开支范围符合本单位差旅费标准。 | I23: 员工报账业务-7.差旅标准执行-控制措施01 | J23: 商旅云公司完善差旅费超标刚性管控功能，系统对超标申请酒店、交通工具和差旅补助进行自动隐藏。 | M23: √ | R23: √ | T23: 系统已建 | U23: 国网商旅 | V23: 1.差旅标准系统校验规则库； 2.出差通知、培训通知等出差缘由证明材料； 3.出差审批单； 4.出差报销单。 | W23: 各级单位-财务部门-预算管理人员、各级单位-各部门-出差人员、各级单位-各部门-负责人、各级单位-财务部门-成本管理人员、商旅云公司 | X23: 每日 | Y23: 全量检查 | AA23: 每年 | AB23: 抽查 | AD23: 员工差旅费用标准监督场景 | AE23: 每月 | AF23: 抽查 | AH23: 是 | AI23: 是 | AJ23: 《国家电网有限公司差旅费管理办法》（国家电网企管〔2026〕101号）第八条、第十一条至第十九条 | AK23: 国网财务部 | AL23: 各级单位财务部 | AP23: =A23=[2]员工报账!A23 -> TRUE | AQ23: =B23=[2]员工报账!B23 -> TRUE | AR23: =C23=[2]员工报账!C23 -> TRUE | AS23: =D23=[2]员工报账!D23 -> TRUE | AT23: =E23=[2]员工报账!E23 -> TRUE | AU23: =F23=[2]员工报账!F23 -> TRUE | AV23: =G23=[2]员工报账!G23 -> TRUE | AW23: =H23=[2]员工报账!H23 -> TRUE | ... BZ23: =AK23=[2]员工报账!AK23 -> TRUE
I24: 员工报账业务-7.差旅标准执行-控制措施02 | J24: 财务部门加强出差类别与出差性质审核，重点关注评标、培训等特殊出差事项政策执行情况。 | M24: √ | Q24: √ | T24: 系统已建 | U24: 国网商旅 | V24: 1.差旅标准系统校验规则库； 2.出差通知、培训通知等出差缘由证明材料； 3.出差审批单； 4.出差报销单。 | W24: 各级单位-财务部门-预算管理人员、各级单位-各部门-负责人、各级单位-财务部门-成本管理人员、商旅云公司 | X24: 每日 | Y24: 全量检查 | AA24: 每年 | AB24: 抽查 | AD24: 员工差旅费用标准监督场景 | AE24: 每月 | AF24: 抽查 | AH24: 是 | AI24: 是 | AJ24: 《国家电网有限公司差旅费管理办法》（国家电网企管〔2026〕101号）第八条、第十一条至第十九条 | AK24: 国网财务部 | AL24: 各级单位财务部 | AP24: =A24=[2]员工报账!A24 -> TRUE | AQ24: =B24=[2]员工报账!B24 -> TRUE | AR24: =C24=[2]员工报账!C24 -> TRUE | AS24: =D24=[2]员工报账!D24 -> TRUE | AT24: =E24=[2]员工报账!E24 -> TRUE | AU24: =F24=[2]员工报账!F24 -> TRUE | AV24: =G24=[2]员工报账!G24 -> TRUE | AW24: =H24=[2]员工报账!H24 -> TRUE | ... BZ24: =AK24=[2]员工报账!AK24 -> TRUE
I25: 员工报账业务-7.差旅标准执行-控制措施03 | J25: 纪检部门推动退赔与整改机制，对超标报销行为依规严肃问责。 | R25: √ | S25: √ | T25: 线下管控 | V25: 1.问责证明材料。 | W25: 各级单位-财务部门-预算管理人员、各级单位-各部门-出差人员、各级单位-各部门-负责人、各级单位-财务部门-成本管理人员、商旅云公司、各级单位-纪检部门-纪检管理人员 | X25: 每日 | Y25: 全量检查 | AA25: 每年 | AB25: 抽查 | AD25: 员工差旅费用标准监督场景 | AE25: 每月 | AF25: 抽查 | AH25: 是 | AI25: 是 | AJ25: 《国家电网有限公司差旅费管理办法》（国家电网企管〔2026〕101号）第八条、第十一条至第十九条、《国网湖南省电力有限公司关于印发加强差旅费管理有关规定的通知》第一条 | AK25: 国网财务部 | AL25: 各级单位财务部 | AN25: 补充制度 | AP25: =A25=[2]员工报账!A25 -> TRUE | AQ25: =B25=[2]员工报账!B25 -> TRUE | AR25: =C25=[2]员工报账!C25 -> TRUE | AS25: =D25=[2]员工报账!D25 -> TRUE | AT25: =E25=[2]员工报账!E25 -> TRUE | AU25: =F25=[2]员工报账!F25 -> TRUE | AV25: =G25=[2]员工报账!G25 -> TRUE | AW25: =H25=[2]员工报账!H25 -> TRUE | ... BZ25: =AK25=[2]员工报账!AK25 -> TRUE
A26: 员工报账 | B26: 一、员工差旅 | C26: 资金资产安全 | D26: 差旅报销 | E26: 虚报冒领差旅费，虚列套取费用，导致资金安全风险。 | F26: 87.违规发放津贴补贴：存在多报差旅补贴、虚报差旅补贴等问题。 | G26: 8.差旅报销合规性控制 | H26: 交通费、公杂费、住宿费等报销真实发生，差旅费报销准确。 | I26: 员工报账业务-8.差旅报销合规性控制-控制措施01 | J26: 建立业务部门费用报销前置审核机制，对机票、酒店、火车、补助等金额准确性复核。 | M26: √ | Q26: √ | R26: √ | T26: 系统已建 | U26: 国网商旅 | V26: 1.出差通知、培训通知等出差缘由证明材料； 2.出差审批单； 3.预订的商旅订单； 4.发票； 5.考勤记录。 | W26: 各级单位-各部门-出差人员、各级单位-各部门-出差报销审核人、各级单位-财务部门-成本管理人员、商旅云公司 | X26: 每日 | Y26: 全量检查 | AA26: 每年 | AB26: 抽查 | AD26: 员工差旅报销监督场景 | AE26: 每月 | AF26: 抽查 | AH26: 是 | AI26: 是 | AJ26: 《国网财务部、后勤部关于进一步规范差旅伙食费和交通费收交管理有关事项的通知》第三条、第四条 《国家电网有限公司差旅费管理办法》（国家电网企管〔2026〕101号）第十二条、第十三条、第十七条、第二十四条 | AK26: 国网财务部 | AL26: 各级单位财务部 | AP26: =A26=[2]员工报账!A26 -> TRUE | AQ26: =B26=[2]员工报账!B26 -> TRUE | AR26: =C26=[2]员工报账!C26 -> TRUE | AS26: =D26=[2]员工报账!D26 -> TRUE | AT26: =E26=[2]员工报账!E26 -> TRUE | AU26: =F26=[2]员工报账!F26 -> TRUE | AV26: =G26=[2]员工报账!G26 -> TRUE | AW26: =H26=[2]员工报账!H26 -> TRUE | ... BZ26: =AK26=[2]员工报账!AK26 -> TRUE
I27: 员工报账业务-8.差旅报销合规性控制-控制措施02 | J27: 商旅云公司强化时空逻辑系统校验，对“出差时间-住宿时间-车票时间”进行自动校验，拦截或预警重叠数据。 | M27: √ | Q27: √ | T27: 系统已建 | U27: 国网商旅 | V27: 1.出差通知、培训通知等出差缘由证明材料； 2.出差审批单； 3.预订的商旅订单； 4.发票； 5.考勤记录。 | W27: 商旅云公司 | X27: 每日 | Y27: 全量检查 | AA27: 每年 | AB27: 抽查 | AD27: 员工差旅报销监督场景 | AE27: 每月 | AF27: 抽查 | AH27: 是 | AI27: 是 | AJ27: 《国网财务部、后勤部关于进一步规范差旅伙食费和交通费收交管理有关事项的通知》第三条、第四条 《国家电网有限公司差旅费管理办法》（国家电网企管〔2026〕101号第十二条、第十三条、第十七条、第二十四条 | AK27: 国网财务部 | AL27: 各级单位财务部 | AP27: =A27=[2]员工报账!A27 -> TRUE | AQ27: =B27=[2]员工报账!B27 -> TRUE | AR27: =C27=[2]员工报账!C27 -> TRUE | AS27: =D27=[2]员工报账!D27 -> TRUE | AT27: =E27=[2]员工报账!E27 -> TRUE | AU27: =F27=[2]员工报账!F27 -> TRUE | AV27: =G27=[2]员工报账!G27 -> TRUE | AW27: =H27=[2]员工报账!H27 -> TRUE | ... BZ27: =AK27=[2]员工报账!AK27 -> TRUE
I28: 员工报账业务-8.差旅报销合规性控制-控制措施03 | J28: 商旅云公司健全票据使用状态规则，重点筛查“未使用”的交通票据，防范员工利用废票虚报费用或重复报销。 | M28: √ | R28: √ | T28: 系统已建 | U28: 国网商旅 | V28: 1.出差通知、培训通知等出差缘由证明材料； 2.出差审批单； 3.预订的商旅订单； 4.发票； 5.考勤记录。 | W28: 各级单位-各部门-出差人员、各级单位-各部门-出差报销审核人、各级单位-财务部门-成本管理人员、商旅云公司 | X28: 每日 | Y28: 全量检查 | AA28: 每年 | AB28: 抽查 | AD28: 员工差旅报销监督场景 | AE28: 每月 | AF28: 抽查 | AH28: 是 | AI28: 是 | AJ28: 《国网财务部、后勤部关于进一步规范差旅伙食费和交通费收交管理有关事项的通知》第三条、第四条 《国家电网有限公司差旅费管理办法》（国家电网企管〔2026〕101号）第十七条、第二十四条 | AK28: 国网财务部 | AL28: 各级单位财务部 | AP28: =A28=[2]员工报账!A28 -> TRUE | AQ28: =B28=[2]员工报账!B28 -> TRUE | AR28: =C28=[2]员工报账!C28 -> TRUE | AS28: =D28=[2]员工报账!D28 -> TRUE | AT28: =E28=[2]员工报账!E28 -> TRUE | AU28: =F28=[2]员工报账!F28 -> TRUE | AV28: =G28=[2]员工报账!G28 -> TRUE | AW28: =H28=[2]员工报账!H28 -> TRUE | ... BZ28: =AK28=[2]员工报账!AK28 -> TRUE
I29: 员工报账业务-8.差旅报销合规性控制-控制措施04 | J29: 财务部门加强差旅报销审核力度，对同一时段连续出差公杂费、伙食补助费进行复核，避免重复计算。 | M29: √ | Q29: √ | T29: 系统已建 | U29: 国网商旅 | V29: 1.出差通知、培训通知等出差缘由证明材料； 2.出差审批单； 3.预订的商旅订单； 4.发票； 5.考勤记录。 | W29: 各级单位-各部门-出差人员、各级单位-各部门-出差报销审核人、各级单位-财务部门-成本管理人员、商旅云公司 | X29: 每日 | Y29: 全量检查 | AA29: 每年 | AB29: 抽查 | AD29: 员工差旅报销监督场景 | AE29: 每月 | AF29: 抽查 | AH29: 是 | AI29: 是 | AJ29: 《国网财务部、后勤部关于进一步规范差旅伙食费和交通费收交管理有关事项的通知》第三条、第四条 《国家电网有限公司差旅费管理办法》（国家电网企管〔2026〕101号第十二条、第十三条、第十七条、第二十四条 | AK29: 国网财务部 | AL29: 各级单位财务部 | AP29: =A29=[2]员工报账!A29 -> TRUE | AQ29: =B29=[2]员工报账!B29 -> TRUE | AR29: =C29=[2]员工报账!C29 -> TRUE | AS29: =D29=[2]员工报账!D29 -> TRUE | AT29: =E29=[2]员工报账!E29 -> TRUE | AU29: =F29=[2]员工报账!F29 -> TRUE | AV29: =G29=[2]员工报账!G29 -> TRUE | AW29: =H29=[2]员工报账!H29 -> TRUE | ... BZ29: =AK29=[2]员工报账!AK29 -> TRUE
A30: 员工报账 | B30: 一、员工差旅 | C30: 资金资产安全 | D30: 差旅报销 | E30: 虚报冒领差旅费，虚列套取费用，导致资金安全风险。 | F30: 87.违规发放津贴补贴：存在多报差旅补贴、虚报差旅补贴等问题。 | G30: 8.差旅报销合规性控制 | H30: 交通费、公杂费、住宿费等报销真实发生，差旅费报销准确。 | I30: 员工报账业务-8.差旅报销合规性控制-控制措施05 | J30: 纪检部门完善违规问责与闭环管理机制，对未缴纳伙食费用套取各类补助和虚报行为进行问责，追回资金，并纳入个人诚信记录。 | M30: √ | R30: √ | S30: √ | T30: 线下管控 | V30: 1.问责证明材料。 | W30: 各级单位-各部门-出差人员、各级单位-各部门-出差报销审核人、各级单位-财务部门-成本管理人员、商旅云公司、各级单位-纪检部门-纪检管理人员 | X30: 每日 | Y30: 全量检查 | AA30: 每年 | AB30: 抽查 | AD30: 员工差旅报销监督场景 | AE30: 每月 | AF30: 抽查 | AH30: 是 | AI30: 是 | AJ30: 《国网财务部、后勤部关于进一步规范差旅伙食费和交通费收交管理有关事项的通知》第三条、第四条 《国家电网有限公司差旅费管理办法》（国家电网企管〔2026〕101号）第十七条、第二十四条、《国网湖南省电力有限公司关于印发加强差旅费管理有关规定的通知》第一条 | AK30: 国网财务部 | AL30: 各级单位财务部 | AN30: 补充制度 | AP30: =A30=[2]员工报账!A30 -> TRUE | AQ30: =B30=[2]员工报账!B30 -> TRUE | AR30: =C30=[2]员工报账!C30 -> TRUE | AS30: =D30=[2]员工报账!D30 -> TRUE | AT30: =E30=[2]员工报账!E30 -> TRUE | AU30: =F30=[2]员工报账!F30 -> TRUE | AV30: =G30=[2]员工报账!G30 -> TRUE | AW30: =H30=[2]员工报账!H30 -> TRUE | ... BZ30: =AK30=[2]员工报账!AK30 -> TRUE
E31: 员工自付单据中的人员、时间与地点未在出差范围内，虚报支出，套取资金，导致公司经济利益受损。 | G31: 9.自付单据审核 | H31: 自付单据中人员、时间、地点与出差申请单一致，自付交通费、住宿费符合差旅费标准。 | I31: 员工报账业务-9.自付单据审核-控制措施01 | J31: 商旅云公司健全“单轨控制”，系统强制关联“已完成审批单”与“线上支付订单”，并推动与税务平台直连，减少发票人工上传环节。 | S31: √ | T31: 系统待建 | U31: 国网商旅 | V31: 1.发票； 2.差旅费标准； 3.出差通知、培训通知等出差缘由证明材料； 4.出差审批单； 5.出差报销单。 | W31: 各级单位-各部门-出差人员、商旅云公司 | X31: 每日 | Y31: 全量检查 | AA31: 每年 | AB31: 抽查 | AD31: 员工差旅报销监督场景 | AE31: 每月 | AF31: 抽查 | AH31: 是 | AI31: 是 | AJ31: 《国家电网有限公司差旅费管理办法》（国家电网企管〔2026〕101号）第八条、第十一条、第二十四条 | AK31: 国网财务部 | AL31: 各级单位财务部 | AP31: =A31=[2]员工报账!A31 -> TRUE | AQ31: =B31=[2]员工报账!B31 -> TRUE | AR31: =C31=[2]员工报账!C31 -> TRUE | AS31: =D31=[2]员工报账!D31 -> TRUE | AT31: =E31=[2]员工报账!E31 -> TRUE | AU31: =F31=[2]员工报账!F31 -> TRUE | AV31: =G31=[2]员工报账!G31 -> TRUE | AW31: =H31=[2]员工报账!H31 -> TRUE | ... BZ31: =AK31=[2]员工报账!AK31 -> TRUE
I32: 员工报账业务-9.自付单据审核-控制措施02 | J32: 强化线下报销验证，未实现系统“单轨控制”的单位强化事前审批，强制“行程轨迹佐证”，同时借助第三方工具“建立发票真伪与重复报销”校验机制。 | M32: √ | Q32: √ | R32: √ | T32: 线下管控 | V32: 1.发票； 2.差旅费标准； 3.出差通知、培训通知等出差缘由证明材料； 4.出差审批单； 5.出差报销单。 | W32: 各级单位-各部门-出差人员、各级单位-各部门-负责人、商旅云公司 | X32: 每日 | Y32: 全量检查 | AA32: 每年 | AB32: 抽查 | AD32: 员工差旅报销监督场景 | AE32: 每月 | AF32: 抽查 | AH32: 是 | AI32: 是 | AJ32: 《国家电网有限公司差旅费管理办法》（国家电网企管〔2026〕101号）第八条、第十一条、第二十四条 | AK32: 国网财务部 | AL32: 各级单位财务部 | AN32: 修改责任主体 | AP32: =A32=[2]员工报账!A32 -> TRUE | AQ32: =B32=[2]员工报账!B32 -> TRUE | AR32: =C32=[2]员工报账!C32 -> TRUE | AS32: =D32=[2]员工报账!D32 -> TRUE | AT32: =E32=[2]员工报账!E32 -> TRUE | AU32: =F32=[2]员工报账!F32 -> TRUE | AV32: =G32=[2]员工报账!G32 -> TRUE | AW32: =H32=[2]员工报账!H32 -> TRUE | ... BZ32: =AK32=[2]员工报账!AK32 -> TRUE
I33: 员工报账业务-9.自付单据审核-控制措施03 | J33: 财务部门规范自付单据与标准审核流程，逐一核对自付单据人员、时间、地点，并审核费用标准是否符合公司规定。 | M33: √ | Q33: √ | R33: √ | T33: 系统已建 | U33: 国网商旅 | V33: 1.发票； 2.差旅费标准； 3.出差通知、培训通知等出差缘由证明材料； 4.出差审批单； 5.出差报销单。 | W33: 各级单位-各部门-出差人员、商旅云公司、各级单位-财务部门-成本管理人员 | X33: 每日 | Y33: 全量检查 | AA33: 每年 | AB33: 抽查 | AD33: 员工差旅报销监督场景 | AE33: 每月 | AF33: 抽查 | AH33: 是 | AI33: 是 | AJ33: 《国家电网有限公司差旅费管理办法》（国家电网企管〔2026〕101号）第八条、第十一条、第二十四条 | AK33: 国网财务部 | AL33: 各级单位财务部 | AP33: =A33=[2]员工报账!A33 -> TRUE | AQ33: =B33=[2]员工报账!B33 -> TRUE | AR33: =C33=[2]员工报账!C33 -> TRUE | AS33: =D33=[2]员工报账!D33 -> TRUE | AT33: =E33=[2]员工报账!E33 -> TRUE | AU33: =F33=[2]员工报账!F33 -> TRUE | AV33: =G33=[2]员工报账!G33 -> TRUE | AW33: =H33=[2]员工报账!H33 -> TRUE | ... BZ33: =AK33=[2]员工报账!AK33 -> TRUE
I34: 员工报账业务-9.自付单据审核-控制措施04 | J34: 纪检部门严肃查处违规行为，追回资金损失，严肃查处并予以通报。 | M34: √ | R34: √ | T34: 线下管控 | V34: 1.商旅平台数据线上预订率、电子票据抓取率。 | W34: 各级单位-各部门-出差人员、商旅云公司、各级单位-纪检部门-纪检管理人员 | X34: 每日 | Y34: 全量检查 | AA34: 每年 | AB34: 抽查 | AD34: 员工差旅报销监督场景 | AE34: 每月 | AF34: 抽查 | AH34: 是 | AI34: 是 | AJ34: 《国家电网有限公司差旅费管理办法》（国家电网企管〔2026〕101号）第八条、第十一条、第二十四条、《国网湖南省电力有限公司关于印发加强差旅费管理有关规定的通知》第一条 | AK34: 国网财务部 | AL34: 各级单位财务部 | AN34: 补充制度 | AP34: =A34=[2]员工报账!A34 -> TRUE | AQ34: =B34=[2]员工报账!B34 -> TRUE | AR34: =C34=[2]员工报账!C34 -> TRUE | AS34: =D34=[2]员工报账!D34 -> TRUE | AT34: =E34=[2]员工报账!E34 -> TRUE | AU34: =F34=[2]员工报账!F34 -> TRUE | AV34: =G34=[2]员工报账!G34 -> TRUE | AW34: =H34=[2]员工报账!H34 -> TRUE | ... BZ34: =AK34=[2]员工报账!AK34 -> TRUE
A35: 员工报账 | B35: 一、员工差旅 | C35: 税务合规、资金资产安全 | D35: 报销申请 | E35: 成本费用报销事项不真实、审批流程不规范，导致成本入账科目错误、虚列成本费用、套取资金私设“小金库”。 | G35: 10.报销事项合规性控制 | H35: 在规定列支范围内，以真实发生的事项发起报销申请，履行规范审批流程。 | I35: 员工报账业务-10.报销事项合规性控制-控制措施01 | J35: 费用报销部门履行费用报销分级授权审批流程，对报销申请事项的真实性进行人工复核，复核报销审批单、费用明细清单、发票或收据、合同或协议等附件的完整性。 | L35: √ | R35: √ | T35: 线下管控 | V35: 1.成本费用报销审批单； 2.费用明细清单； 3.发票或收据； 4.合同或协议； 5.系统审批记录。 | W35: 各级单位-各部门-报账人员、各级单位-各部门-负责人、各级单位-财务部门-成本管理人员 | X35: 每季度 | Y35: 抽查 | AA35: 每年 | AB35: 抽查 | AD35: 报销真实性监督场景 | AE35: 每年 | AF35: 抽查 | AH35: 是 | AI35: 是 | AJ35: 《国家电网有限公司会计基础管理办法》（国家电网企管〔2019〕132号）第八条、第五十四条 《关于加强中央企业资金内部控制管理有关事项的通知》（国资发监督〔2021〕19 号）第十三条、《国网湖南省电力有限公司关于印发加强差旅费管理有关规定的通知》第一条 | AK35: 国网财务部、国网企管部、国网后勤部、国网国际部 | AL35: 各级单位财务部、各级单位企管部（人资部）、各级单位后勤部、 | AN35: 补充制度 | AP35: =A35=[2]员工报账!A35 -> TRUE | AQ35: =B35=[2]员工报账!B35 -> TRUE | AR35: =C35=[2]员工报账!C35 -> TRUE | AS35: =D35=[2]员工报账!D35 -> TRUE | AT35: =E35=[2]员工报账!E35 -> TRUE | AU35: =F35=[2]员工报账!F35 -> TRUE | AV35: =G35=[2]员工报账!G35 -> TRUE | AW35: =H35=[2]员工报账!H35 -> TRUE | ... BZ35: =AK35=[2]员工报账!AK35 -> TRUE
I36: 员工报账业务-10.报销事项合规性控制-控制措施02 | J36: 加强挂职人员费用报销成本中心校验，挂职期间费用报销申请需选择挂职单位成本中心。 | Q36: √ | T36: 系统已建 | U36: 智慧共享财务平台 | V36: 1.成本费用报销审批单； 2.费用明细清单； 3.发票或收据； 4.合同或协议； 5.系统审批记录。 | W36: 各级单位-各部门-报账人员、各级单位-各部门-负责人、各级单位-财务部门-成本管理人员 | X36: 每季度 | Y36: 抽查 | AA36: 每年 | AB36: 抽查 | AD36: 报销真实性监督场景 | AE36: 每年 | AF36: 抽查 | AH36: 是 | AI36: 是 | AJ36: 《国家电网有限公司会计基础管理办法》（国家电网企管〔2019〕132号）第八条、第五十四条 《关于加强中央企业资金内部控制管理有关事项的通知》（国资发监督〔2021〕19 号）第十三条、《国网湖南省电力有限公司关于印发加强差旅费管理有关规定的通知》第三条 | AK36: 国网财务部、国网企管部、国网后勤部、国网国际部 | AL36: 各级单位财务部、各级单位企管部（人资部）、各级单位后勤部、 | AN36: 补充制度 | AP36: =A36=[2]员工报账!A36 -> TRUE | AQ36: =B36=[2]员工报账!B36 -> TRUE | AR36: =C36=[2]员工报账!C36 -> TRUE | AS36: =D36=[2]员工报账!D36 -> TRUE | AT36: =E36=[2]员工报账!E36 -> TRUE | AU36: =F36=[2]员工报账!F36 -> TRUE | AV36: =G36=[2]员工报账!G36 -> TRUE | AW36: =H36=[2]员工报账!H36 -> TRUE | ... BZ36: =AK36=[2]员工报账!AK36 -> TRUE
I37: 员工报账业务-10.报销事项合规性控制-控制措施03 | J37: 财务部门对费用报销选择业务事项准确性进行复核，校验报销流程和成本中心准确性。 | M37: √ | Q37: √ | T37: 系统已建 | U37: 智慧共享财务平台 | V37: 1.成本费用报销审批单； 2.费用明细清单； 3.发票或收据； 4.合同或协议； 5.系统审批记录。 | W37: 各级单位-各部门-报账人员、各级单位-各部门-负责人、各级单位-财务部门-成本管理人员 | X37: 每季度 | Y37: 抽查 | AA37: 每年 | AB37: 抽查 | AD37: 报销真实性监督场景 | AE37: 每年 | AF37: 抽查 | AH37: 是 | AI37: 是 | AJ37: 《国家电网有限公司会计基础管理办法》（国家电网企管〔2019〕132号）第八条、第五十四条 《关于加强中央企业资金内部控制管理有关事项的通知》（国资发监督〔2021〕19 号）第十三条 | AK37: 国网财务部、国网企管部、国网后勤部、国网国际部 | AL37: 各级单位财务部、各级单位企管部（人资部）、各级单位后勤部、 | AP37: =A37=[2]员工报账!A37 -> TRUE | AQ37: =B37=[2]员工报账!B37 -> TRUE | AR37: =C37=[2]员工报账!C37 -> TRUE | AS37: =D37=[2]员工报账!D37 -> TRUE | AT37: =E37=[2]员工报账!E37 -> TRUE | AU37: =F37=[2]员工报账!F37 -> TRUE | AV37: =G37=[2]员工报账!G37 -> TRUE | AW37: =H37=[2]员工报账!H37 -> TRUE | ... BZ37: =AK37=[2]员工报账!AK37 -> TRUE
I38: 员工报账业务-10.报销事项合规性控制-控制措施04 | J38: 进行违规责任追究，对虚列成本费用、套取资金私设“小金库”的人员根据相关规定进行违规责任追究。 | R38: √ | T38: 线下管控 | V38: 1.责任追究证明材料。 | W38: 各级单位-各部门-报账人员、各级单位-各部门-负责人、各级单位-财务部门-成本管理人员、各级单位-纪检部门-纪检管理人员 | X38: 每季度 | Y38: 抽查 | AA38: 每年 | AB38: 抽查 | AD38: 报销真实性监督场景 | AE38: 每年 | AF38: 抽查 | AH38: 是 | AI38: 是 | AJ38: 《国家电网有限公司会计基础管理办法》（国家电网企管〔2019〕132号）第八条、第五十四条 《关于加强中央企业资金内部控制管理有关事项的通知》（国资发监督〔2021〕19 号）第十三条 | AK38: 国网财务部、国网企管部、国网后勤部、国网国际部 | AL38: 各级单位财务部、各级单位企管部（人资部）、各级单位后勤部、 | AP38: =A38=[2]员工报账!A38 -> TRUE | AQ38: =B38=[2]员工报账!B38 -> TRUE | AR38: =C38=[2]员工报账!C38 -> TRUE | AS38: =D38=[2]员工报账!D38 -> TRUE | AT38: =E38=[2]员工报账!E38 -> TRUE | AU38: =F38=[2]员工报账!F38 -> TRUE | AV38: =G38=[2]员工报账!G38 -> TRUE | AW38: =H38=[2]员工报账!H38 -> TRUE | ... BZ38: =AK38=[2]员工报账!AK38 -> TRUE
B39: 二、通用报账 | C39: 税务合规 | D39: 费用报销 | E39: 发票信息不准确、不完整，与报销业务不一致导致税务风险 | G39: 11.报销发票审核 | H39: 报销发票真实、准确、完整 | I39: 员工报账业务-11.报销发票审核-控制措施01 | J39: 归口管理部门对报销发票、入库单、采购订单物品对应关系进行复核，确认购物清单通过税务防伪系统开具。 | L39: √ | M39: √ | T39: 系统已建 | U39: 智慧共享财务平台 | V39: 1.成本费用报销申请单； 2.费用明细清单； 3.发票或收据、购物清单； 4.合同或协议。 | W39: 各级单位-各部门-报账人员、各级单位-各部门-负责人、各级单位-财务部门-成本管理人员 | X39: 每季度 | Y39: 抽查 | AA39: 每年 | AB39: 抽查 | AD39: 发票审核管理监督场景 | AE39: 每年 | AF39: 抽查 | AH39: 是 | AI39: 是 | AJ39: 国家电网企管〔2019〕132号《国家电网有限公司会计基础管理办法》第五十条 | AK39: 国网财务部、国网企管部、国网后勤部、国网国际部 | AL39: 各级单位财务部、各级单位企管部（人资部）、各级单位后勤部、 | AP39: =A39=[2]员工报账!A39 -> TRUE | AQ39: =B39=[2]员工报账!B39 -> TRUE | AR39: =C39=[2]员工报账!C39 -> TRUE | AS39: =D39=[2]员工报账!D39 -> TRUE | AT39: =E39=[2]员工报账!E39 -> TRUE | AU39: =F39=[2]员工报账!F39 -> TRUE | AV39: =G39=[2]员工报账!G39 -> TRUE | AW39: =H39=[2]员工报账!H39 -> TRUE | ... BZ39: =AK39=[2]员工报账!AK39 -> TRUE
I40: 员工报账业务-11.报销发票审核-控制措施02 | J40: 各部门建立发票“谁提交、谁审核、谁负责”闭环管理机制,发票提交人落实发票验真责任。 | M40: √ | R40: √ | T40: 系统已建 | U40: 智慧共享财务平台 | V40: 1.成本费用报销申请单； 2.费用明细清单； 3.发票或收据、购物清单； 4.合同或协议。 | W40: 各级单位-各部门-报账人员、各级单位-各部门-负责人 | X40: 每季度 | Y40: 抽查 | AA40: 每年 | AB40: 抽查 | AD40: 发票审核管理监督场景 | AE40: 每年 | AF40: 抽查 | AH40: 是 | AI40: 是 | AJ40: 国家电网企管〔2019〕132号《国家电网有限公司会计基础管理办法》第五十条 | AK40: 国网企管部、国网后勤部、国网国际部 | AL40: 各级单位财务部、各级单位企管部（人资部）、各级单位后勤部 | AP40: =A40=[2]员工报账!A40 -> TRUE | AQ40: =B40=[2]员工报账!B40 -> TRUE | AR40: =C40=[2]员工报账!C40 -> TRUE | AS40: =D40=[2]员工报账!D40 -> TRUE | AT40: =E40=[2]员工报账!E40 -> TRUE | AU40: =F40=[2]员工报账!F40 -> TRUE | AV40: =G40=[2]员工报账!G40 -> TRUE | AW40: =H40=[2]员工报账!H40 -> TRUE | ... BZ40: =AK40=[2]员工报账!AK40 -> TRUE
...

Sheet 员工报账（9.2）
A1: 风控矩阵-员工报账
A2: 业务条线 | B2: 业务领域 | C2: 控制目标 | D2: 业务流程步骤 | E2: 经营风险 | F2: 典型问题 | G2: 关键控制点 | H2: 控制要求 | I2: 控制措施 编号 | J2: 控制措施 | K2: 控制措施分类 | T2: 控制方式 | U2: 控制系统 | V2: 控制载体 | W2: 责任主体 | X2: 业务自评价 | AA2: 集团监督 评价 | AD2: 数字化监督场景 | AH2: 现有制度及文件落实情况 | AK2: 总部审核部门 | AL2: 湖南公司审核部门 | AM2: 是否适用
