Workbook

Sheet 业务流程
A1: 一级流程 | B1: 二级流程 | C1: 三级流程 | D1: 末级流程编号 | E1: 末级流程名称 | F1: 涉及价值管控风险的流程
A2: 市场营销 | B2: 电力市场营销管理 | C2: 有序用电管理 | D2: YX-01-01-01 | E2: 有序用电基础信息管理流程
D3: YX-01-01-02 | E3: 有序用电方案制定流程
D4: YX-01-01-03 | E4: 有序用电预警管理流程
D5: YX-01-01-04 | E5: 有序用电方案实施流程
D6: YX-01-01-05 | E6: 有序用电监督检查管理流程
D7: YX-01-01-06 | E7: 有序用电统计分析管理流程
C8: 市场分析预测管理 | D8: YX-01-02-01 | E8: 短期电力市场分析预测管理流程
D9: YX-01-02-02 | E9: 迎峰度夏（冬）电力供需分析预测管理流程
C10: 能效服务管理 | D10: YX-01-03-01 | E10: 能效服务网络建设运行管理流程
D11: YX-01-03-02 | E11: 能效服务指标管理流程
D12: YX-01-03-03 | E12: 能效服务项目管理流程
C13: 综合能源管理 | D13: YX-01-04-01 | E13: 综合能源服务管理流程 | F13: √
D14: YX-01-04-02 | E14: 需求侧响应管理流程
C15: 自备电厂管理 | D15: YX-01-04-01 | E15: 自备电厂机组并网与电力供应协议管理流程
C16: 智能用电管理 | D16: YX-01-05-01 | E16: 智能充换电服务网络建设项目实施管理流程
D17: YX-01-05-02 | E17: 智能充换电服务网络运营服务管理流程
D18: YX-01-05-03 | E18: 智能充换电服务网络充电设施缺陷管理流程
B19: 营业管理 | C19: 供电营业区管理 | D19: YX-02-01-01 | E19: 供电营业区域管理流程
D20: YX-02-01-02 | E20: 供电营业许可证管理流程
C21: 业扩报装 | D21: YX-02-02-01 | E21: 业扩报装流程与服务要求制定流程 | F21: √
D22: YX-02-02-02 | E22: 220kV及以上业扩报装管理流程
D23: YX-02-02-03 | E23: 110kV业扩报装管理流程
D24: YX-02-02-04 | E24: 35kV业扩报装管理流程
D25: YX-02-02-05 | E25: 10kV业扩报装管理流程
D26: YX-02-02-06 | E26: 低压业扩报装管理流程
D27: YX-02-02-07 | E27: 国家重点工程业扩报装协调管理流程
C28: 变更用电管理 | D28: YX-02-03-01 | E28: 减容管理流程
D29: YX-02-03-02 | E29: 减容恢复管理流程
D30: YX-02-03-03 | E30: 暂停管理流程
D31: YX-02-03-04 | E31: 暂停恢复管理流程
D32: YX-02-03-05 | E32: 暂拆管理流程
D33: YX-02-03-06 | E33: 暂拆复装管理流程
D34: YX-02-03-07 | E34: 暂换管理流程
D35: YX-02-03-08 | E35: 暂换恢复管理流程
D36: YX-02-03-09 | E36: 迁址管理流程
D37: YX-02-03-10 | E37: 移表管理流程
D38: YX-02-03-11 | E38: 销户管理流程
D39: YX-02-03-12 | E39: 过户管理流程
D40: YX-02-03-13 | E40: 更名管理流程
...

Sheet 流程图

Sheet 数字化与研发投入（0818）
A1: 风控矩阵-数字化与研发投入
A2: 业务条线 | B2: 业务领域 | C2: 控制目标 | D2: 业务流程步骤 | E2: 经营风险 | F2: 典型问题 | G2: 关键控制点 | H2: 控制要求 | I2: 控制措施编号 | J2: 控制措施 | K2: 控制措施分类 | T2: 控制方式 | U2: 控制系统 | V2: 控制载体 | W2: 责任主体 | X2: 业务自评价 | AA2: 集团监督评价 | AD2: 数字化监督场景 | AH2: 现有制度及文件落实情况 | AK2: 总部审核部门 | AL2: 矩阵变化内容说明
K3: 不相容岗位 | L3: 分级授权 | M3: 业务真实性控制 | N3: 预算管控 | O3: 合同控制 | P3: 收付控制 | Q3: 会计监督 | R3: 财产保护 | S3: 分析与评价 | X3: 评价频率 | Y3: 评价范围 | Z3: 评价结论 | AA3: 评价频率 | AB3: 评价范围 | AC3: 评价结论 | AD3: 数字化监督场景 | AE3: 评价频率 | AF3: 评价范围 | AG3: 评价结论 | AH3: 是否已要求 | AI3: 是否满足要求 | AJ3: 对应制度及文件名称
A4: 数字化项目管理业务 | B4: 一、项目立项管理 | C4: 资金资产安全 | D4: 储备及立项 | E4: 不符合公司数字化建设规划和统一技术路线，缺乏必要性和可行性，造成重复建设、资源浪费、投资回报低下风险。 | G4: 1.储备立项的程序控制 | H4: 符合公司数字化建设规划和统一技术路线，具备经济性、可行性和必要性。 | I4: 数字化项目管理业务-1.储备立项的程序控制-控制措施01 | J4: 需求提报部门建立历史项目比对机制，避免重复需求提报和立项。 | L4: √ | M4: √ | T4: 系统待建 系统已建 | U4: 数字化项目管理微应用、数字化项目智慧管控平台 | V4: 1.需求报告； 2.历史项目应用评价； 3.需求查重清单 4.数字化项目统筹清单。 | W4: 各级单位-项目需求部门-需求提报人、各级单位-项目需求部门-负责人、各级单位-归口管理部门-项目管理人员、各级单位-归口管理部门-负责人、 省公司-项目管理中心-项目储备管控专责、省公司-数字化部-规划技术处处长 | X4: 每季度 | Y4: 抽查 | AA4: 年度 | AB4: 抽查 | AD4: 需求查重监督场景 | AH4: 是 | AI4: 是 | AJ4: 《国家电网有限公司关于优化调整公司数字化建设投入管理的通知》（国家电网数字〔2025〕17号） 《国家电网有限公司电网数字化建设管理办法》（国家电网企管〔2020〕849号） 《国网湖南省电力有限公司数字化项目管理实施细则》（湘电公司数字〔2024〕447号 ） | AK4: 国网数字化部 | AL4: 增加对应制度及文件名称
I5: 数字化项目管理业务-1.储备立项的程序控制-控制措施02 | J5: 归口管理部门建立“谁主管、谁负责”机制，开展可研经济性、立项合规性分析，获取可研批复后方可立项。 | L5: √ | S5: √ | T5: 线下管控 | V5: 1.各级评审意见文件； 2.总部科研报告批复文件。 | W5: 各级单位-项目需求部门-需求提报人、各级单位-项目需求部门-负责人、各级单位-归口管理部门-项目管理人员、各级单位-归口管理部门-负责人、 省公司-数字化部-规划技术处处长 | X5: 每季度 | Y5: 抽查 | AA5: 年度 | AB5: 抽查 | AH5: 是 | AI5: 是 | AJ5: 《国家电网有限公司关于优化调整公司数字化建设投入管理的通知》（国家电网数字〔2025〕17号） 《国家电网有限公司电网数字化建设管理办法》（国家电网企管〔2020〕849号）《国网湖南省电力有限公司数字化项目管理实施细则》（湘电公司数字〔2024〕447号 ） | AK5: 国网数字化部 | AL5: 增加对应制度及文件名称
I6: 数字化项目管理业务-1.储备立项的程序控制-控制措施03 | J6: 归口管理部门开展项目投入后评估，基于评价结果优化后续项目安排。 | O6: √ | S6: √ | T6: 线下管控 | V6: 历史项目应用评价资料 （数字化综合绩效评估、管理规范问题清单等）。 | W6: 各级单位-项目承担部门-项目负责人、各级单位-项目承担部门-负责人、各级单位-归口管理部门-项目管理人员、各级单位-归口管理部门-负责人、省公司-数字化部-数字化项目管理中心项目储备管控专责、省公司-数字化部-规划技术处处长 | X6: 每季度 | Y6: 抽查 | AA6: 年度 | AB6: 抽查 | AH6: 是 | AI6: 是 | AJ6: 《国家电网有限公司关于优化调整公司数字化建设投入管理的通知》（国家电网数字〔2025〕17号） 《国家电网有限公司电网数字化建设管理办法》（国家电网企管〔2020〕849号） 《国家电网公司信息系统深化应用管理办法》国家电网企管〔2014〕1216号 《国网湖南省电力有限公司数字化项目管理实施细则》（湘电公司数字〔2024〕447号 ） | AK6: 国网数字化部 | AL6: 增加对应制度及文件名称
I7: 数字化项目管理业务-1.储备立项的程序控制-控制措施04 | J7: 强化立项不相容控制，落实评审与复核责任。 | T7: 线下管控 | V7: 项目评审意见。 | W7: 各级单位-项目需求部门-需求提报人、各级单位-项目需求部门-负责人、各级单位-归口管理部门-项目管理人员、各级单位-归口管理部门-负责人、经研院-项目投资管理中心（评审中心）-非基建项目评审专责 | X7: 每季度 | Y7: 抽查 | AA7: 年度 | AB7: 抽查 | AH7: 是 | AI7: 是 | AJ7: 《国家电网有限公司关于优化调整公司数字化建设投入管理的通知》（国家电网数字〔2025〕17号） 《国家电网有限公司电网数字化建设管理办法》（国家电网企管〔2020〕849号）《国网湖南省电力有限公司数字化项目管理实施细则》（湘电公司数字〔2024〕447号 ） | AK7: 国网数字化部 | AL7: 增加对应制度及文件名称
F8: 一是建设成效不足，普遍采用“提升效率”等模糊词汇描述预期成果，实际项目未对公司财务提质增效、机构编制精干、减员增效等方面产生实质性效益；二是建设依据不足，所依据的文件与本项目的建设内容缺乏直接关联，难以支撑立项合理性；三是跨专业协同不足，各部门仅从自身视角提出需求，忽视了与其他系统的数据贯通与流程衔接，导致重复建设与数据孤岛问题。 | I8: 数字化项目管理业务-1.储备立项的程序控制-控制措施05 | J8: 归口管理部门对需求统筹进行评审。新建信息系统（功能模块）的设计开发类需求需进行需求论证 | L8: √ | T8: 线下管控 | V8: 1.需求统筹意见 2.公司级需求论证意见（新建开发类需求） | W8: 各级单位-项目需求部门-需求提报人、各级单位-项目需求部门-负责人、省公司-数字化部-规划技术处处长 | X8: 每季度 | Y8: 抽查 | AA8: 年度 | AB8: 抽查 | AJ8: 《国网湖南省电力有限公司关于加强 数字化项目前期管理的指导意见（试行）》 | AK8: 国网数字化部 | AL8: 新增控制措施及对增加对应制度及文件名称
D9: 计划和预算安排 | E9: 项目计划预算安排不合理、调整不及时，未根据项目实际情况进行计划分解和调整，导致提前或滞后确认成本，引发合规风险。 | G9: 2.计划预算安排合规性 | H9: 项目计划预算安排与项目实际进度的一致性控制。 | I9: 数字化项目管理业务-2.计划预算安排合规性-控制措施01 | J9: 归口管理部门对项目储备金额建立计划与预算的复核机制，按实际预估周期安排年度计划和预算。 | L9: √ | N9: √ | Q9: √ | S9: √ | T9: 线下管控 | V9: 1.项目储备资料； 2.计划调整文件； 3.预算下达文件。 | W9: 各级单位-项目承担部门-项目负责人、各级单位-项目承担部门-负责人、各级单位-归口管理部门-计划管理人员项目管理人员、各级单位-归口管理部门-负责人、各级单位-财务部门-预算管理人员、各级单位-财务部门-负责人 | X9: 每月 | Y9: 抽查 | AA9: 年度 | AB9: 抽查 | AH9: 是 | AI9: 是 | AJ9: 《国家电网有限公司工程财务管理办法》（国家电网企管〔2023〕28号） 《国家电网有限公司全面预算管理办法》（国家电网企管〔2026〕101号） 《国网湖南省电力有限公司数字化项目管理实施细则》（湘电公司数字〔2024〕447号 ） | AK9: 国网数字化部 | AL9: 增加对应制度及文件名称
I10: 数字化项目管理业务-2.计划预算安排合规性-控制措施02 | J10: 年中增补项目分年度下达计划和预算。 | N10: √ | Q10: √ | S10: √ | T10: 线下管控 | V10: 1.可研资料； 2.项目立项文件； 3.进度确认材料； 4.项目采购文件； 5.合同； 6.预算下达文件； 7.预算计划调整文件。 | W10: 各级单位-项目承担部门-项目负责人、各级单位-项目承担部门-负责人、各级单位-归口管理部门-计划管理人员项目管理人员、各级单位-归口管理部门-负责人、各级单位-财务部门-预算管理人员、各级单位-财务部门-负责人、各级单位-发展部门-综合计划管理人员、各级单位-发展部门-负责人、省公司-数字化部-项目管理专责 | X10: 每月 | Y10: 抽查 | AA10: 年度 | AB10: 抽查 | AH10: 是 | AI10: 是 | AJ10: 《国家电网有限公司电网数字化建设管理办法》（国家电网企管〔2020〕849号） 《国家电网有限公司工程财务管理办法》（国家电网企管〔2023〕28号） 《国家电网有限公司全面预算管理办法》（国家电网企管〔2026〕101号） 《国网湖南省电力有限公司数字化项目管理实施细则》（湘电公司数字〔2024〕447号 ） | AK10: 国网数字化部 | AL10: 增加对应制度及文件名称
I11: 数字化项目管理业务-2.计划预算安排合规性-控制措施03 | J11: 根据外部环境和项目本身变化，及时调整计划和预算。 | N11: √ | Q11: √ | S11: √ | T11: 线下管控 | V11: 1.可研资料； 2.项目立项文件； 3.项目采购文件； 4.综合计划； 5.预算下达文件； 6.进度确认材料； 7.调整文件； 8.合同。 | W11: 各级单位-项目承担部门-项目负责人、各级单位-项目承担部门-负责人、各级单位-归口管理部门-计划管理人员项目管理人员、各级单位-归口管理部门-负责人、各级单位-财务部门-预算管理人员、各级单位-财务部门-负责人、各级单位-发展部门-综合计划管理人员、各级单位-发展部门-负责人、省公司-数字化部-计划建设处处长 | X11: 每月 | Y11: 抽查 | AA11: 年度 | AB11: 抽查 | AH11: 是 | AI11: 是 | AJ11: 《国家电网有限公司电网数字化建设管理办法》（国家电网企管〔2020〕849号） 《国家电网有限公司工程财务管理办法》（国家电网企管〔2023〕28号） 《国家电网有限公司全面预算管理办法》（国家电网企管〔2026〕101号） 《国网湖南省电力有限公司数字化项目管理实施细则》（湘电公司数字〔2024〕447号 ） | AK11: 国网数字化部 | AL11: 增加对应制度及文件名称
A12: 数字化项目管理业务 | B12: 二、项目实施管理 | C12: 会计信息真实完整 | D12: 成本入账 | E12: 成本入账与进度结算金额不符，项目审核缺位，易引发虚列研发成本、提前确认项目成本风险。 | F12: 5.会计信息不准确：存在虚增隐瞒收入，虚增减成本费用；隐瞒负债，少计应付账款或借款；收入成本不匹配；收入、成本确认不及时、不准确等问题。 25.结算不准确，多结算工程款：存在费用多计（甲供物资、施工费、监理费、监造费、设计费、其他费用及税金等定额套用错误）；工程保险费等费用重复计列；部分服务内容（可研、设计、结算等）未全部开展但全额计列费用；无正当理由变更初始合同计价规则，调增劳务分包费；重复结算人工费用；超标准列支人工费、外委研究支出等问题。 | G12: 3.入账成本准确性 | H12: 入账金额准确性、成本支出真实性控制。 | I12: 数字化项目管理业务-3.入账成本准确性-控制措施01 | J12: 项目承担部门严格按合同约定管控项目执行进度，审核是否存在违约行为，根据实际进度收取发票、填写报账单。 | L12: √ | M12: √ | O12: √ | T12: 线下管控 | V12: 1.项目费用支出明细清单及相关资料； 2.合同； 3.项目进度报审表； 4.项目人员备案表。 | W12: 各级单位-项目承担部门-项目负责人、各级单位-项目承担部门-负责人 | X12: 每年 | Y12: 抽查 | AA12: 年度 | AB12: 抽查 | AH12: 是 | AI12: 是 | AJ12: 《国家电网有限公司电网数字化建设管理办法》（国家电网企管〔2020〕849号）《国网湖南省电力有限公司数字化项目管理实施细则》（湘电公司数字〔2024〕447号 ） | AK12: 国网数字化部 | AL12: 增加对应制度及文件名称
I13: 数字化项目管理业务-3.入账成本准确性-控制措施02 | J13: 归口管理部门复核项目完成情况、项目人员备案表等材料的完整性和合规性。 | O13: √ | T13: 线下管控 | V13: 1.项目费用支出明细清单及相关资料； 2.合同； 3.项目人员备案表； 4.项目进度材料。 | W13: 各级单位-归口管理部门-项目管理人员、各级单位-归口管理部门-负责人、省公司-数字化部-项目管理专责、省公司-项目管理中心-进度管控专责 | X13: 每年 | Y13: 抽查 | AA13: 年度 | AB13: 抽查 | AH13: 是 | AI13: 是 | AJ13: 《国家电网有限公司电网数字化建设管理办法》（国家电网企管〔2020〕849号）《国网湖南省电力有限公司数字化项目管理实施细则》（湘电公司数字〔2024〕447号 ） | AK13: 国网数字化部 | AL13: 增加对应制度及文件名称
I14: 数字化项目管理业务-3.入账成本准确性-控制措施03 | J14: 财务部门对成本报账单金额与结算金额、发票金额一致性、准确性进行审核。 | N14: √ | O14: √ | P14: √ | Q14: √ | T14: 系统已建 | U14: 智慧共享财务平台 | V14: 1.发票； 2.报账单； 3.合同； 4.项目进度报审表。 | W14: 各级单位-财务部门-成本管理人员、各级单位-财务部门-负责人 | X14: 每年 | Y14: 抽查 | AA14: 年度 | AB14: 抽查 | AD14: 成本入账监督场景 | AE14: 每月 | AF14: 全量检查 | AH14: 是 | AI14: 是 | AJ14: 《国家电网有限公司电网数字化建设管理办法》（国家电网企管〔2020〕849号） | AK14: 国网数字化部 | AL14: 1.无变化，直接引用
B15: 二、项目实施管理 | C15: 资金资产安全 | D15: 专业分包 | E15: 分包超范围、超比例，易致信息系统建设质量失控，滋生虚增成本、套取资金等风险。 | F15: 45.数字化项目建设环节管控不严：存在项目建设内容发生变更未按规定履行审批程序；系统开发环境、测试环境和运行环境未进行分离；承建单位专业分包比例过高等问题。 5.会计信息不准确：存在虚增隐瞒收入，虚增减成本费用；隐瞒负债，少计应付账款或借款；收入成本不匹配；收入、成本确认不及时、不准确等问题。 | G15: 4.专业分包比例合规性 | H15: 专业分包链路穿透与比例合规性控制。 | I15: 数字化项目管理业务-4.专业分包比例合规性-控制措施01 | J15: 项目承担部门对分包内容备案、分包人员台账、实际分包比例进行检查，不得将核心业务分包、超出规定比例分包等。 | M15: √ | O15: √ | T15: 线下管控 | V15: 1.合同； 2.分包备案资料； 3.可研资料； 4.技术规范书。 | W15: 各级单位-项目承担部门-项目负责人、各级单位-项目承担部门-负责人 | X15: 每月 | Y15: 抽查 | AA15: 年度 | AB15: 抽查 | AH15: 是 | AI15: 是 | AJ15: 《国网信通部关于进一步规范和加强信息化建设分包管理工作的通知》（信通计划〔2018〕20号） 《国家电网有限公司电网数字化项目技术管理办法》（国网（信息/3）287-2021） 《国家电网有限公司电网数字化项目分包管理规范（试行）》（国家电网数字〔2024〕81 号 ） | AK15: 国网数字化部 | AL15: 1.无变化，直接引用
G16: 4.专业分包比例合规性 | H16: 专业分包链路穿透与比例合规性控制。 | I16: 数字化项目管理业务-4.专业分包比例合规性-控制措施02 | J16: 项目承担部门建立分包台账，定期排查分包情况，禁止超比例分包、层层分包。 | M16: √ | O16: √ | T16: 线下管控 | V16: 1.合同； 2.分包备案资料； 3.可研资料； 4.技术规范书。 | W16: 各级单位-项目承担部门-项目负责人、各级单位-项目承担部门-负责人 | X16: 每月 | Y16: 抽查 | AA16: 年度 | AB16: 抽查 | AH16: 是 | AI16: 是 | AJ16: 《国网信通部关于进一步规范和加强信息化建设分包管理工作的通知》（信通计划〔2018〕20号） 《国家电网有限公司电网数字化项目技术管理办法》（国网（信息/3）287-2021） 《国家电网有限公司电网数字化项目分包管理规范（试行）》（国家电网数字〔2024〕81 号 ） | AK16: 国网数字化部 | AL16: 1.无变化，直接引用
I17: 数字化项目管理业务-4.专业分包比例合规性-控制措施03 | J17: 归口管理部门建立“总包-分包”合同穿透链路，通过合同与项目的关联查看总包单位为系统内单位的业主单位、总包单位、分包单位的对应关系。 数字化部负责落实公司电网数字化项目分包管理制度，建立健全本单位电网数字化项目分包管理机制。 | M17: √ | O17: √ | S17: √ | T17: 系统待建 | U17: 数字化法治企业建设平台 | V17: 1.合同； 2.分包备案资料； 3.可研资料； 4.技术规范书。 | W17: 各级单位-归口管理部门-项目管理人员、各级单位-归口管理部门-负责人、省公司-数字化部-项目管理专责 | X17: 每月 | Y17: 抽查 | AA17: 年度 | AB17: 抽查 | AD17: 项目分包管理监督场景 | AE17: 每年 | AF17: 抽查 | AH17: 是 | AI17: 是 | AJ17: 《国网信通部关于进一步规范和加强信息化建设分包管理工作的通知》（信通计划〔2018〕20号） 《国家电网有限公司电网数字化项目技术管理办法》（国网（信息/3）287-2021） 《国家电网有限公司电网数字化项目分包管理规范（试行）》（国家电网数字〔2024〕81 号 ） | AK17: 国网数字化部 | AL17: 修改了控制措施
I18: 数字化项目管理业务-4.专业分包比例合规性-控制措施04 | J18: 归口管理部门建立“总包-分包”人员的穿透链路，核查总包单位为系统内单位的项目团队成员单位信息，分析人员隶属是否遵循合同约定。 数字化部负责本单位电网数字化项目分包工作的督导和检查。 | M18: √ | O18: √ | S18: √ | T18: 线下管控 | V18: 1.合同； 2.分包备案资料； 3.可研资料； 4.技术规范书。 | W18: 各级单位-归口管理部门-项目管理人员、各级单位-归口管理部门-负责人、省公司-数字化部-项目管理专责 | X18: 每月 | Y18: 抽查 | AA18: 年度 | AB18: 抽查 | AD18: 项目分包管理监督场景 | AE18: 每年 | AF18: 抽查 | AH18: 是 | AI18: 是 | AJ18: 《国网信通部关于进一步规范和加强信息化建设分包管理工作的通知》（信通计划〔2018〕20号） 《国家电网有限公司电网数字化项目技术管理办法》（国网（信息/3）287-2021） 《国家电网有限公司电网数字化项目分包管理规范（试行）》（国家电网数字〔2024〕81 号 ） | AK18: 国网数字化部 | AL18: 修改了控制措施
I19: 数字化项目管理业务-4.专业分包比例合规性-控制措施05 | J19: 财务部门构建“总包-分包”资金支付穿透链路，分析总包单位为系统内单位的资金流向是否符合合同主体穿透控制要求。 | M19: √ | O19: √ | P19: √ | Q19: √ | S19: √ | T19: 系统待建 | U19: 智慧共享财务平台 | V19: 1.合同； 2.分包备案资料； 3.可研资料； 4.技术规范书。 | W19: 各级单位-财务部门-工程管理人员、各级单位-财务部门-负责人 | X19: 每月 | Y19: 抽查 | AA19: 年度 | AB19: 抽查 | AD19: 项目分包管理监督场景 | AE19: 每年 | AF19: 抽查 | AH19: 是 | AI19: 是 | AJ19: 《国网信通部关于进一步规范和加强信息化建设分包管理工作的通知》（信通计划〔2018〕20号） 《国家电网有限公司电网数字化项目技术管理办法》（国网（信息/3）287-2021） 《国家电网有限公司电网数字化项目分包管理规范（试行）》（国家电网数字〔2024〕81 号 ） | AK19: 国网数字化部 | AL19: 1.无变化，直接引用
A20: 数字化项目管理业务 | B20: 三、竣工验收转资 | C20: 资金资产安全 | D20: 现场资产盘点 | E20: 资产卡片信息与合同信息、研发及信息系统设备台账、设备实物不符，资产管理不规范，存在资产流失风险。 | F20: 46.数字化项目验收管控不严：存在部分数字化项目合同约定的交付物雷同或内容不实；部分功能未实现；未履行测试或验证；验收人员组成不合理，业务部门未参与验收等问题。 | G20: 5.资产信息真实性 | H20: 账卡物一致性控制。 | I20: 数字化项目管理业务-5.资产信息真实性-控制措施01 | J20: 使用保管部门规范保管、使用资产，不得未经审批处置。 | L20: √ | M20: √ | R20: √ | T20: 系统已建 | U20: 智慧共享财务平台（目前ERP） | V20: 1.资产卡片清单； 2.I6000台账。 | W20: 各级单位-使用保管部门-使用保管人员、各级单位-使用保管部门-负责人 | X20: 每年 | Y20: 抽查 | AA20: 年度 | AB20: 抽查 | AD20: 资产建卡与赋值监督场景 | AE20: 每季度 | AF20: 抽查 | AH20: 是 | AI20: 是 | AJ20: 《国家电网公司固定资产管理办法》国网（财/2）593-2023（通用） 《国家电网公司无形资产管理办法》国网（财/2）205-2014 | AK20: 国网数字化部 | AL20: 1.无变化，直接引用
I21: 数字化项目管理业务-5.资产信息真实性-控制措施02 | J21: 实物管理部门数字化部定期开展实物盘点，核对设备台账与现场实物的一致性。 | M21: √ | R21: √ | T21: 线下管控 | V21: I6000台账。 | W21: 各级单位-使用保管部门-使用保管人员、各级单位-使用保管部门-负责人、各级单位-实物管理部门-设备管理人员、各级单位-实物管理部门-负责人、各级单位-使用保管单位-综合计划管理人员、省公司-数字化部-信息运行专责 | X21: 每年 | Y21: 抽查 | AA21: 年度 | AB21: 抽查 | AH21: 是 | AI21: 是 | AJ21: 《国家电网公司固定资产管理办法》国网（财/2）593-2023（通用） 《国家电网公司无形资产管理办法》国网（财/2）205-2014 | AK21: 国网数字化部 | AL21: 修改责任主体
I22: 数字化项目管理业务-5.资产信息真实性-控制措施03 | J22: 财务部门对固定资产购置价值信息与决算金额一致性进行检查。 | O22: √ | Q22: √ | T22: 系统待建 | U22: 智慧共享财务平台 | V22: 1.合同； 2.资产卡片清单； 3.转资信息表； 4.验收盘点表； 5.竣工决算报告。 | W22: 各级单位-财务部门-工程财务人员、各级单位-财务部门-负责人 | X22: 每年 | Y22: 抽查 | AA22: 年度 | AB22: 抽查 | AD22: 资产建卡与赋值监督场景 | AE22: 每季度 | AF22: 抽查 | AH22: 是 | AI22: 是 | AJ22: 《国家电网公司固定资产管理办法》国网（财/2）593-2023（通用） 《国家电网公司无形资产管理办法》国网（财/2）205-2014 | AK22: 国网数字化部 | AL22: 1.无变化，直接引用
C23: 资金资产安全 | D23: 项目验收 | E23: 合同交付物雷同或内容不实，验收人员组成不合理，未发现项目存在的问题，造成资源浪费风险。 | F23: 46.数字化项目验收管控不严：存在部分数字化项目合同约定的交付物雷同或内容不实；部分功能未实现；未履行测试或验证；验收人员组成不合理，业务部门未参与验收等问题。 | G23: 6.项目验收质量 | H23: 验收流程规范性、人员组成合规性、资料准确完整性控制 | I23: 数字化项目管理业务-6.项目验收质量-控制措施01 | J23: 归口管理部门规范验收流程，实行内部交叉验收机制，相互监督制约。 | L23: √ | M23: √ | T23: 线下管控 | V23: 1.验收计划； 2.验收报告。 | W23: 各级单位-归口管理部门-项目管理人员、各级单位-归口管理部门-负责人、省公司-项目管理中心-项目评审管理专责、省公司-数字化部-项目管理专责 | X23: 每月 | Y23: 抽查 | AA23: 年度 | AB23: 抽查 | AH23: 是 | AI23: 是 | AJ23: 《国家电网有限公司电网数字化项目竣工验收管理规范》（试行）数字计划〔2025〕13号 《国网数字化部关于进一步加强信息系统上下线及检修管理的通知》数字运行〔2024〕54 号《国网湖南省电力有限公司数字化项目管理实施细则》（湘电公司数字〔2024〕447号 ） | AK23: 国网数字化部 | AL23: 增加对应制度及文件名称：《国网湖南省电力有限公司数字化项目管理实施细则》（湘电公司数字〔2024〕447号 ）、《关于进一步加强数字化项目验收管理的通知（试行）》
I24: 数字化项目管理业务-6.项目验收质量-控制措施02 | J24: 归口管理部门根据项目可研和合同等资料，对项目成果进行审核。 | O24: √ | R24: √ | T24: 线下管控 | V24: 1.验收计划； 2.验收报告； 3.项目可研及合同； 4.项目档案资料。 | W24: 各级单位-项目承担部门-项目负责人、各级单位-项目承担部门-负责人、各级单位-归口管理部门-管理部门人员项目管理人员、各级单位-归口管理部门-负责人、省公司-项目管理中心-评审管理专责 | X24: 每月 | Y24: 抽查 | AA24: 年度 | AB24: 抽查 | AH24: 是 | AI24: 是 | AJ24: 《国家电网有限公司电网数字化项目竣工验收管理规范》（试行）数字计划〔2025〕13号 《国网数字化部关于进一步加强信息系统上下线及检修管理的通知》数字运行〔2024〕54 号 《国网湖南省电力有限公司数字化项目管理实施细则》（湘电公司数字〔2024〕447号 ） 《关于进一步加强数字化项目验收管理的通知（试行）》 | AK24: 国网数字化部 | AL24: 增加对应制度及文件、修改主体
I25: 数字化项目管理业务-6.项目验收质量-控制措施03 | J25: 归口管理部门复核验收组构成合理性，检查业务部门参与。 | S25: √ | T25: 线下管控 | V25: 1.验收计划； 2.验收报告（重点查阅验收意见及专家签到表）。 | W25: 各级单位-归口管理部门-项目管理人员、各级单位-归口管理部门-负责人、省公司-项目管理中心-评审管理专责 | X25: 每月 | Y25: 抽查 | AA25: 年度 | AB25: 抽查 | AH25: 是 | AI25: 是 | AJ25: 《国家电网有限公司电网数字化建设管理办法》（国家电网企管〔2020〕849号） 《国家电网有限公司电网数字化项目竣工验收管理规范》（试行）数字计划〔2025〕13号 《国网湖南省电力有限公司数字化项目管理实施细则》（湘电公司数字〔2024〕447号 ） | AK25: 国网数字化部 | AL25: 增加对应制度及文件名称
C26: 资金资产安全、税务合规 | D26: 项目转资 | E26: 未及时完成转资，造成资产折旧计提延迟，进而引发当期利润虚增、资产账面价值不实及税务合规风险。 | G26: 7.项目转资合规性 | H26: 项目转资及时性，折旧计提准确性控制。 | I26: 数字化项目管理业务-7.项目转资合规性-控制措施01 | J26: 归口管理部门对转资及时性、竣工验收资料完整性和审批流程合规性进行检查。 | M26: √ | O26: √ | R26: √ | T26: 线下管控 | V26: 1.合同； 2.项目验收意见。 | W26: 各级单位-归口管理部门-项目管理人员、各级单位-归口管理部门-负责人 | X26: 每季度 | Y26: 全量检查 | AA26: 年度 | AB26: 抽查 | AH26: 是 | AI26: 是 | AJ26: 《国家电网有限公司电网数字化项目竣工验收管理规范（试行）》（数字计划〔2025〕13号） 《国家电网有限公司工程财务管理办法》（国家电网企管〔2023〕28号） | AK26: 国网数字化部 | AL26: 1.无变化，直接引用
I27: 数字化项目管理业务-7.项目转资合规性-控制措施02 | J27: 财务部门负责资产卡片计提折旧的检查。 | Q27: √ | T27: 系统已建 | U27: 智慧共享财务平台 | V27: 1.固定资产卡片清单。 | W27: 各级单位-财务部门-资产管理人员、各级单位-财务部门-负责人 | X27: 每季度 | Y27: 全量检查 | AA27: 年度 | AB27: 抽查 | AH27: 是 | AI27: 是 | AJ27: 《国家电网有限公司电网数字化项目竣工验收管理规范（试行）》（数字计划〔2025〕13号） 《国家电网有限公司工程财务管理办法》（国家电网企管〔2023〕28号） | AK27: 国网数字化部 | AL27: 1.无变化，直接引用
A28: 科技项目管理业务 | B28: 一、项目立项管理 | C28: 资金资产安全 | D28: 项目储备及立项 | E28: 未依据科技规划及公司实际需求，项目储备存在偏离主业与战略方向，重复立项风险。 | F28: 42.研究开发项目管理不规范：存在专利申请时间早于项目开始时间；复用以前年度科技项目的研究内容。 | G28: 8.储备立项的程序 | H28: 项目储备规范化、精益化。 | I28: 科技项目管理业务-8.储备立项的程序-控制措施01 | J28: 科技部门建立项目查重机制，避免重复储备和立项。 | L28: √ | M28: √ | S28: √ | T28: 系统已建 | U28: 科技项目管理系统（一体化创新平台） | V28: 1.项目库； 2.可研报告/项目建议书； 3.评审意见表。 | W28: 各级单位-科技部门-管理人员 | X28: 年度 | Y28: 全量 | AA28: 年度 | AB28: 全量 | AH28: 是 | AI28: 是 | AJ28: 《国家电网有限公司科技项目管理办法》国家电网企管〔2024〕71号 《国家电网有限公司科技项目储备库管理细则》国家电网企管〔2019〕429号 《国网湖南省电力有限公司关于印发进一步加强科技项目全过程管理具体举措》湘电公司科〔2025〕239号 | AK28: 国网科技部 | AL28: 增加对应制度及文件名称
I29: 科技项目管理业务-8.储备立项的程序-控制措施02 | J29: 科技部门建立项目论证机制，避免项目偏离主业和战略方向。 | L29: √ | M29: √ | S29: √ | T29: 线下管控 | V29: 1.项目库； 2.可研报告； 3.可研评审意见以及批复。 | W29: 各级单位-科技部门-负责人 | X29: 年度 | Y29: 全量 | AA29: 年度 | AB29: 全量 | AH29: 是 | AI29: 是 | AJ29: 《国家电网有限公司科技项目管理办法》国家电网企管〔2024〕71号 《国家电网有限公司科技项目储备库管理细则》国家电网企管〔2019〕429号 《国网湖南省电力有限公司关于印发进一步加强科技项目全过程管理具体举措》湘电公司科〔2025〕239号 | AK29: 国网科技部 | AL29: 增加对应制度及文件名称
A30: 科技项目管理业务 | B30: 二、项目实施管理 | C30: 会计信息真实完整 | D30: 计划和预算安排 | E30: 项目计划未根据项目实际进展情况及时调整，导致合同执行不到位等合规风险。 | G30: 9.计划调整及时性 | H30: 项目计划预算安排与项目实际进度的一致性。 | I30: 科技项目管理业务-9.计划调整及时性-控制措施01 | J30: 科技项目承担部门根据外部环境和项目实施情况，及时申请调整。 | M30: √ | N30: √ | T30: 系统已建 | U30: 智慧共享财务平台 | V30: 1.项目实施材料； 2.合同； 3.项目立项文件； 4.经费变更申请表、科技项目责任书、科技项目变更申请表等调整文件。 | W30: 各级单位-科技项目承担部门-项目负责人、各级单位-科技项目承担部门-负责人、各级单位-科技部门-管理人员、各级单位-科技部门-负责人、各级单位-发展部门-管理人员、各级单位-发展部门-负责人、各级单位-财务部门-预算管理人员、各级单位-财务部门-负责人 | X30: 年度 | Y30: 抽查 | AA30: 年度 | AB30: 抽查 | AD30: 预算编制及调整 | AE30: 年度 | AF30: 抽查 | AH30: 是 | AI30: 是 | AJ30: 《国家电网有限公司科技项目管理办法》国家电网企管〔2024〕71号 《国家电网公司科技项目预算编制实施细则》国家电网企管〔2017〕1066号 《国家电网有限公司总部管理科技项目实施及验收管理细则》国家电网企管〔2024〕71号 《国网湖南省电力有限公司关于印发进一步加强科技项目全过程管理具体举措》湘电公司科〔2025〕239号 | AK30: 国网科技部 | AL30: 增加对应制度及文件名称
I31: 科技项目管理业务-9.计划调整及时性-控制措施02 | J31: 外部环境和项目本身情况发生重大变化，未按规定及时调整投资方案并采取止损措施的，按照中央企业违规经营管理办法追究责任。 | S31: √ | T31: 线下管控 | V31: 1.项目实施材料； 2.合同； 3.项目立项文件； 4.调整文件。 | W31: 各级单位-科技项目承担部门-项目负责人、各级单位-科技项目承担部门-负责人、各级单位-科技部门-管理人员、各级单位-科技部门-负责人 | X31: 年度 | Y31: 抽查 | AA31: 年度 | AB31: 抽查 | AH31: 是 | AI31: 是 | AJ31: 《国家电网有限公司科技项目管理办法》国家电网企管〔2024〕71号 《国家电网有限公司总部管理科技项目实施工作指南(2026年版)》 《国家电网有限公司总部管理科技项目实施及验收管理细则》国家电网企管〔2024〕71号 《中央企业违规经营投资责任追究实施办法》国务院国资委令第46号 《国网湖南省电力有限公司关于印发进一步加强科技项目全过程管理具体举措》湘电公司科〔2025〕239号 | AK31: 国网科技部 | AL31: 增加对应制度及文件名称
D32: 成本入账 | E32: 成本入账与进度结算金额不符，项目审核缺位，易引发提前或滞后确认项目成本风险。 | F32: 5.会计信息不准确：存在虚增隐瞒收入、虚增减成本费用、隐瞒负债、少计应付账款或借款、收入成本不匹配、收入和成本确认不及时或不准确等问题。 25.结算不准确，多结算工程款：存在费用多计（甲供物资、施工费、监理费、监造费、设计费、其他费用及税金等定额套用错误）、工程保险费等费用重复计列、部分服务内容（可研、设计、结算等）未全部开展但全额计列费用、无正当理由变更初始合同计价规则并调增劳务分包费、重复结算人工费用、超标准列支人工费和外委研究支出等问题。 | G32: 10.入账成本准确性 | H32: 报账金额准确性、成本支出真实性 | I32: 科技项目管理业务-10.入账成本准确性-控制措施01 | J32: 项目承担部门严格按合同约定管控项目执行进度，根据实际进度办理入账流程。 | M32: √ | O32: √ | P32: √ | T32: 系统已建 | U32: 智慧共享财务平台 | V32: 1.报账单； 2.合同； 3.进度确认单； 4.技术合同相关登记、认定材料。 | W32: 各级单位-科技项目承担部门-项目负责人、各级单位-科技项目承担部门-负责人、各级单位-科技部门-管理人员、各级单位-科技部门-负责人、各级单位-财务部门-成本管理人员、各级单位-财务部门-负责人 | X32: 每月 | Y32: 全量检查 | AA32: 每月 | AB32: 全量检查 | AD32: 在报账单提交环节，检查报账金额与项目实际结算金额、发票金额是否一致；若不一致，系统自动预警并反馈经办人，经办人修改后可重新提交。 | AE32: 实时 | AF32: 全量检查 | AH32: 是 | AI32: 是 | AJ32: 《研发经费投入统计与核算管理规范》国家电网财〔2025〕25 号 《国家电网公司研究开发费财务管理办法》国家电网企管〔2014〕742号 《国家电网公司科技预算项目实施细则》国家电网企管（2017）1066号 《国网湖南省电力有限公司关于印发进一步加强科技项目全过程管理具体举措》湘电公司科〔2025〕239号 | AK32: 国网科技部、国网 财务部 | AL32: 增加对应制度及文件名称
I33: 科技项目管理业务-10.入账成本准确性-控制措施02 | J33: 项目承担部门负责核查研发费用明细，杜绝研发费用与日常经费混淆列支、规范专家咨询费等人工成本按标准列支、审核专利费用承担主体与合同约定完全一致。 | M33: √ | O33: √ | T33: 线下管控 | V33: 项目费用支出明细清单及相关资料。 | W33: 各级单位-科技项目承担部门-项目负责人、各级单位-科技项目承担部门-负责人、各级单位-科技部门-管理人员、各级单位-科技部门-负责人 | X33: 每月 | Y33: 全量检查 | AA33: 每月 | AB33: 全量检查 | AH33: 是 | AI33: 是 | AJ33: 《研发经费投入统计与核算管理规范》国家电网财〔2025〕25 号 《国家电网公司研究开发费财务管理办法》国家电网企管〔2014〕742号 《国家电网公司科技预算项目实施细则》国家电网企管（2017）1066号 《国网湖南省电力有限公司关于印发进一步加强科技项目全过程管理具体举措》湘电公司科〔2025〕239号 | AK33: 国网科技部、国网 财务部 | AL33: 增加对应制度及文件名称
I34: 科技项目管理业务-10.入账成本准确性-控制措施03 | J34: 财务部门对成本报账单金额与结算金额、发票金额一致性、合规性，列支范围准确性进行审核。 | N34: √ | O34: √ | P34: √ | Q34: √ | T34: 系统已建 | U34: 智慧共享财务平台 | V34: 发票、报账单、合同、服务确认单。 | W34: 各级单位-科技项目承担部门-项目负责人、各级单位-科技项目承担部门-负责人、各级单位-科技部门-管理人员、各级单位-财务部门-成本管理人员 | X34: 每月 | Y34: 全量检查 | AA34: 每月 | AB34: 全量检查 | AD34: 在报账单入账审核环节，检查报账金额与项目实际结算金额、发票金额是否一致；若不一致，系统自动预警并反馈经办人，经办人修改后可重新提交。 | AE34: 实时 | AF34: 全量检查 | AH34: 是 | AI34: 是 | AJ34: 《研发经费投入统计与核算管理规范》国家电网财〔2025〕25 号 《国家电网公司研究开发费财务管理办法》国家电网企管〔2014〕742号 《国家电网公司科技预算项目实施细则》国家电网企管（2017）1066号 《国网湖南省电力有限公司关于印发进一步加强科技项目全过程管理具体举措》湘电公司科〔2025〕239号 | AK34: 国网科技部、国网 财务部 | AL34: 增加对应制度及文件名称
C35: 资金资产安全、税务合规 | D35: 研发加计扣除 | E35: 加计扣除项目界定不准确，导致公司面临税务合规风险。 | G35: 11.研发项目加计扣除合规性 | H35: 研发支出加计扣除准确性、合规性。 | I35: 科技项目管理业务-11.研发项目加计扣除合规性-控制措施01 | J35: 项目承担部门对项目是否属于新技术、新产品、新工艺等符合条件的研发活动进行判断，为准确申报研发费用加计扣除提供依据。 | M35: √ | O35: √ | T35: 线下管控 | V35: 1.任务书； 2.合同； 3.发票； 4.技术合同相关登记、认定材料； 5.研发成果佐证资料； 6.关联交易明细账。 | W35: 各级单位-科技项目承担部门-项目负责人、各级单位-科技部门-管理人员 | X35: 每季度 | Y35: 抽查 | AA35: 每季度 | AB35: 抽查 | AH35: 是 | AI35: 是 | AJ35: 《研发费用加计扣除政策执行指引（2.0版）》 《国家电网公司研究开发费财务管理办法》国家电网企管〔2014〕742号 《国网湖南电力科网部关于加强研究开发项目合同认定登记工作的通知》 | AK35: 国网科技部、国网 财务部 | AL35: 增加对应制度及文件名称
I36: 科技项目管理业务-11.研发项目加计扣除合规性-控制措施02 | J36: 项目承担部门负责提供研发成果佐证资料和技术合同相关登记、认定材料。 | M36: √ | O36: √ | T36: 线下管控 | V36: 1.任务书； 2.合同； 3.发票； 4.技术合同相关登记、认定材料； 5.研发成果佐证资料； 6.关联交易明细账。 | W36: 各级单位-科技项目承担部门-项目负责人 | X36: 每季度 | Y36: 抽查 | AA36: 每季度 | AB36: 抽查 | AH36: 是 | AI36: 是 | AJ36: 《研发费用加计扣除政策执行指引（2.0版）》 《国家电网公司研究开发费财务管理办法》国家电网企管〔2014〕742号 《国网湖南电力科网部关于加强研究开发项目合同认定登记工作的通知》 | AK36: 国网科技部、国网 财务部 | AL36: 增加对应制度及文件名称
A37: 科技项目管理业务 | B37: 二、项目实施管理 | C37: 资金资产安全、税务合规 | D37: 研发加计扣除 | E37: 加计扣除项目界定不准确，导致公司面临税务合规风险。 | G37: 11.研发项目加计扣除合规性 | I37: 科技项目管理业务-11.研发项目加计扣除合规性-控制措施03 | J37: 财务部门根据政府科技主管部门出具的技术合同相关登记、认定材料和第三方审计机构出具的专项鉴定报告，对研发加计扣除金额进行复核计算。 | M37: √ | O37: √ | T37: 系统已建 | U37: 智慧共享财务平台 | V37: 1.任务书； 2.合同； 3.发票； 4.技术合同相关登记、认定材料； 5.研发成果佐证资料； 6.关联交易明细账。 | W37: 各级单位-财务部门-税务管理人员、各级单位-财务部门-负责人 | X37: 每季度 | Y37: 抽查 | AA37: 每季度 | AB37: 抽查 | AD37: 建立研发项目准确合规享受加计扣除监督场景，加计扣除整体情况及明细进行监督展示。 | AE37: 每月 | AF37: 抽查 | AH37: 是 | AI37: 是 | AJ37: 《研发费用加计扣除政策执行指引（2.0版）》 《国家电网公司研究开发费财务管理办法》国家电网企管〔2014〕742号 | AK37: 国网科技部、国网 财务部
C38: 会计信息真实完整 | D38: 研发投入统计 | E38: 研发费用与生产、管理费用边界模糊，未通过“研发支出”科目核算，存在研发投入统计不准确风险。 | F38: 43.研究开发项目关键环节管控不严：存在研究开发项目项目自主度不高，外委比例过高；研发经费统计不精准；科研经费列支不正确；采取组装、集成、套牌贴牌等手段，虚假完成攻关任务等问题。 | G38: 12.研发费用核算与分摊准确性 | H38: 研发投入核算准确性、规范性。 | I38: 科技项目管理业务-12.研发费用核算与分摊准确性-控制措施01 | J38: 各项目承担部门根据项目立项信息及实际情况，负责识别本专业管理项目的研发属性，并对合理性负责，维护“研发项目分类”“学科领域及研究方向”数据标签。 | M38: √ | T38: 系统已建 | U38: 智慧共享财务平台 科技创新综合服务管理平台 | V38: 1.各类项目清单； 2.项目建议书或可研报告； 3.任务书。 | W38: 各级单位-科技项目承担部门-项目负责人 | X38: 年度 | Y38: 全量检查 | AA38: 年度 | AB38: 全量检查 | AD38: 预算发布校验研发投入相关字段必填性。 | AE38: 年度 | AF38: 全量检查 | AH38: 是 | AI38: 是 | AJ38: 《研发经费投入统计与核算管理规范》国家电网财〔2025〕25 号 《中央企业违规经营投资责任追究实施办法》国务院国资委令第46号 《国网湖南省电力有限公司关于进一步做好研发经费投入统计与核算管理工作》湘电公司财〔2025〕126号 | AK38: 国网科技部、国网 财务部 | AL38: 增加对应制度及文件名称
I39: 科技项目管理业务-12.研发费用核算与分摊准确性-控制措施02 | J39: 对项目管理部门科技研发投入统计不实，虚列虚报研发投入的，依照中央企业违规经营投资管理办法追究责任。 | S39: √ | T39: 线下管控 | V39: 1.各类项目清单； 2.项目建议书或可研报告； 3.任务书。 | W39: 各级单位-科技部门-管理人员、各级单位-科技部门-负责人 | X39: 年度 | Y39: 全量检查 | AA39: 年度 | AB39: 全量检查 | AH39: 是 | AI39: 是 | AJ39: 《研发经费投入统计与核算管理规范》国家电网财〔2025〕25 号 《中央企业违规经营投资责任追究实施办法》国务院国资委令第46号 《国网湖南省电力有限公司关于进一步做好研发经费投入统计与核算管理工作》湘电公司财〔2025〕126号 | AK39: 国网科技部、国网 财务部 | AL39: 增加对应制度及文件名称
D40: 研发项目核算 | E40: 各级统一管理的科技项目，牵头方、受托方、委托方项目信息不一致，可能导致项目投入统计不准确。 | G40: 13.内部受托研发项目三方信息一致性控制 | H40: 内部受托项目牵头方、委托方、受托方项目信息的一致性。 | I40: 科技项目管理业务-13.内部受托研发项目三方信息一致性-控制措施01 | J40: 牵头方单位负责牵头创建内部受委托项目，并建立内部项目管理共享机制，项目同步传递至受托方并系统控制，受托方不再单独建项。 | M40: √ | O40: √ | P40: √ | Q40: √ | T40: 系统已建 | U40: 科技创新综合服务管理平台 | V40: 1.科技创新综合服务管理平台项目台账； 2.项目可研批复； 3.项目任务书及合同。 | W40: 各级单位-科技项目承担部门-项目负责人、各级单位-科技部门-管理人员 | X40: 每季度 | Y40: 全量检查 | AA40: 每季度 | AB40: 全量检查 | AD40: 建立内部受委托方项目关联关系，通过牵头方项目可穿透查询受委托方项目及项目的结算、牵头方项目编码自动关联形成协同单据及凭证，对项目信息的一致性进行提示。 | AE40: 每年 | AF40: 全量检查 | AH40: 是 | AI40: 是 | AJ40: 《研发经费投入统计与核算管理规范》国家电网财〔2025〕25 号 《国网湖南省电力有限公司关于进一步做好研发经费投入统计与核算管理工作》湘电公司财〔2025〕126号 | AK40: 国网科技部 | AL40: 增加对应制度及文件名称
...

Sheet 数字化与研发投入 (核对过程7.29)
A1: 风控矩阵-数字化与研发投入
A2: 业务条线 | B2: 业务领域 | C2: 控制目标 | D2: 业务流程步骤 | E2: 经营风险 | F2: 典型问题 | G2: 关键控制点 | H2: 控制要求 | I2: 控制措施编号 | J2: 控制措施 | K2: 控制措施分类 | T2: 控制方式 | U2: 控制系统 | V2: 控制载体 | W2: 责任主体 | X2: 业务自评价 | AA2: 集团监督评价 | AD2: 数字化监督场景 | AH2: 现有制度及文件落实情况 | AK2: 总部审核部门 | AL2: 矩阵变化内容说明
K3: 不相容岗位 | L3: 分级授权 | M3: 业务真实性控制 | N3: 预算管控 | O3: 合同控制 | P3: 收付控制 | Q3: 会计监督 | R3: 财产保护 | S3: 分析与评价 | X3: 评价频率 | Y3: 评价范围 | Z3: 评价结论 | AA3: 评价频率 | AB3: 评价范围 | AC3: 评价结论 | AD3: 数字化监督场景 | AE3: 评价频率 | AF3: 评价范围 | AG3: 评价结论 | AH3: 是否已要求 | AI3: 是否满足要求 | AJ3: 对应制度及文件名称 | AM3: 7.27
A4: 数字化项目管理业务 | B4: 一、项目立项管理 | C4: 资金资产安全 | D4: 储备及立项 | E4: 不符合公司数字化建设规划和统一技术路线，缺乏必要性和可行性，造成重复建设、资源浪费、投资回报低下风险。 | G4: 1.储备立项的程序控制 | H4: 符合公司数字化建设规划和统一技术路线，具备经济性、可行性和必要性。 | I4: 数字化项目管理业务-1.储备立项的程序控制-控制措施01 | J4: 需求提报部门建立历史项目比对机制，避免重复需求提报和立项。 | L4: √ | M4: √ | T4: 系统待建 系统已建 | U4: 数字化项目管理微应用、数字化项目智慧管控平台 | V4: 1.需求报告； 2.历史项目应用评价； 3.需求查重清单 4.数字化项目统筹清单。 | W4: 各级单位-项目需求部门-需求提报人、各级单位-项目需求部门-负责人、各级单位-归口管理部门-项目管理人员、各级单位-归口管理部门-负责人、 省公司-项目管理中心-项目储备管控专责、省公司-数字化部-规划技术处处长 | X4: 每季度 | Y4: 抽查 | AA4: 年度 | AB4: 抽查 | AD4: 需求查重监督场景 | AH4: 是 | AI4: 是 | AJ4: 《国家电网有限公司关于优化调整公司数字化建设投入管理的通知》（国家电网数字〔2025〕17号） 《国家电网有限公司电网数字化建设管理办法》（国家电网企管〔2020〕849号） 《国网湖南省电力有限公司数字化项目管理实施细则》（湘电公司数字〔2024〕447号 ） | AK4: 国网数字化部 | AL4: 增加对应制度及文件名称：《国网湖南省电力有限公司数字化项目管理实施细则》（湘电公司数字〔2024〕447号 ） | AM4: 修改控制方式，修改控制系统，修改控制载体，修改责任主体，补充制度，数字化监督场景 | AN4: =A4=[2]数字化与研发投入!A4 -> TRUE | AO4: =B4=[2]数字化与研发投入!B4 -> TRUE | AP4: =C4=[2]数字化与研发投入!C4 -> TRUE | AQ4: =D4=[2]数字化与研发投入!D4 -> TRUE | AR4: =E4=[2]数字化与研发投入!E4 -> TRUE | AS4: =F4=[2]数字化与研发投入!F4 -> TRUE | AT4: =G4=[2]数字化与研发投入!G4 -> TRUE | AU4: =H4=[2]数字化与研发投入!H4 -> TRUE | ... BX4: =AK4=[2]数字化与研发投入!AK4 -> TRUE
I5: 数字化项目管理业务-1.储备立项的程序控制-控制措施02 | J5: 归口管理部门建立“谁主管、谁负责”机制，开展可研经济性、立项合规性分析，获取可研批复后方可立项。 | L5: √ | S5: √ | T5: 线下管控 | V5: 1.各级评审意见文件； 2.总部科研报告批复文件。 | W5: 各级单位-项目需求部门-需求提报人、各级单位-项目需求部门-负责人、各级单位-归口管理部门-项目管理人员、各级单位-归口管理部门-负责人、 省公司-数字化部-规划技术处处长 | X5: 每季度 | Y5: 抽查 | AA5: 年度 | AB5: 抽查 | AH5: 是 | AI5: 是 | AJ5: 《国家电网有限公司关于优化调整公司数字化建设投入管理的通知》（国家电网数字〔2025〕17号） 《国家电网有限公司电网数字化建设管理办法》（国家电网企管〔2020〕849号）《国网湖南省电力有限公司数字化项目管理实施细则》（湘电公司数字〔2024〕447号 ） | AK5: 国网数字化部 | AL5: 增加对应制度及文件名称：《国网湖南省电力有限公司数字化项目管理实施细则》（湘电公司数字〔2024〕447号 ） | AM5: 修改责任主体，补充制度 | AN5: =A5=[2]数字化与研发投入!A5 -> TRUE | AO5: =B5=[2]数字化与研发投入!B5 -> TRUE | AP5: =C5=[2]数字化与研发投入!C5 -> TRUE | AQ5: =D5=[2]数字化与研发投入!D5 -> TRUE | AR5: =E5=[2]数字化与研发投入!E5 -> TRUE | AS5: =F5=[2]数字化与研发投入!F5 -> TRUE | AT5: =G5=[2]数字化与研发投入!G5 -> TRUE | AU5: =H5=[2]数字化与研发投入!H5 -> TRUE | ... BX5: =AK5=[2]数字化与研发投入!AK5 -> TRUE
I6: 数字化项目管理业务-1.储备立项的程序控制-控制措施03 | J6: 归口管理部门开展项目投入后评估，基于评价结果优化后续项目安排。 | O6: √ | S6: √ | T6: 线下管控 | V6: 历史项目应用评价资料 （数字化综合绩效评估、管理规范问题清单等）。 | W6: 各级单位-项目承担部门-项目负责人、各级单位-项目承担部门-负责人、各级单位-归口管理部门-项目管理人员、各级单位-归口管理部门-负责人、省公司-数字化部-数字化项目管理中心项目储备管控专责、省公司-数字化部-规划技术处处长 | X6: 每季度 | Y6: 抽查 | AA6: 年度 | AB6: 抽查 | AH6: 是 | AI6: 是 | AJ6: 《国家电网有限公司关于优化调整公司数字化建设投入管理的通知》（国家电网数字〔2025〕17号） 《国家电网有限公司电网数字化建设管理办法》（国家电网企管〔2020〕849号） 《国家电网公司信息系统深化应用管理办法》国家电网企管〔2014〕1216号 《国网湖南省电力有限公司数字化项目管理实施细则》（湘电公司数字〔2024〕447号 ） | AK6: 国网数字化部 | AL6: 增加对应制度及文件名称：《国网湖南省电力有限公司数字化项目管理实施细则》（湘电公司数字〔2024〕447号 ） | AM6: 修改责任主体，补充制度 | AN6: =A6=[2]数字化与研发投入!A6 -> TRUE | AO6: =B6=[2]数字化与研发投入!B6 -> TRUE | AP6: =C6=[2]数字化与研发投入!C6 -> TRUE | AQ6: =D6=[2]数字化与研发投入!D6 -> TRUE | AR6: =E6=[2]数字化与研发投入!E6 -> TRUE | AS6: =F6=[2]数字化与研发投入!F6 -> TRUE | AT6: =G6=[2]数字化与研发投入!G6 -> TRUE | AU6: =H6=[2]数字化与研发投入!H6 -> TRUE | ... BX6: =AK6=[2]数字化与研发投入!AK6 -> TRUE
I7: 数字化项目管理业务-1.储备立项的程序控制-控制措施04 | J7: 强化立项不相容控制，落实评审与复核责任。 | T7: 线下管控 | V7: 项目评审意见。 | W7: 各级单位-项目需求部门-需求提报人、各级单位-项目需求部门-负责人、各级单位-归口管理部门-项目管理人员、各级单位-归口管理部门-负责人、经研院-项目投资管理中心（评审中心）-非基建项目评审专责 | X7: 每季度 | Y7: 抽查 | AA7: 年度 | AB7: 抽查 | AH7: 是 | AI7: 是 | AJ7: 《国家电网有限公司关于优化调整公司数字化建设投入管理的通知》（国家电网数字〔2025〕17号） 《国家电网有限公司电网数字化建设管理办法》（国家电网企管〔2020〕849号）《国网湖南省电力有限公司数字化项目管理实施细则》（湘电公司数字〔2024〕447号 ） | AK7: 国网数字化部 | AL7: 增加对应制度及文件名称：《国网湖南省电力有限公司数字化项目管理实施细则》（湘电公司数字〔2024〕447号 ） | AM7: 修改责任主体，补充制度 | AN7: =A7=[2]数字化与研发投入!A7 -> TRUE | AO7: =B7=[2]数字化与研发投入!B7 -> TRUE | AP7: =C7=[2]数字化与研发投入!C7 -> TRUE | AQ7: =D7=[2]数字化与研发投入!D7 -> TRUE | AR7: =E7=[2]数字化与研发投入!E7 -> TRUE | AS7: =F7=[2]数字化与研发投入!F7 -> TRUE | AT7: =G7=[2]数字化与研发投入!G7 -> TRUE | AU7: =H7=[2]数字化与研发投入!H7 -> TRUE | ... BX7: =AK7=[2]数字化与研发投入!AK7 -> TRUE
F8: 需求论证会发现的典型问题有：（对应新增控制措施1-05） 一是建设成效不足，普遍采用“提升效率”等模糊词汇描述预期成果，实际项目未对公司财务提质增效、机构编制精干、减员增效等方面产生实质性效益；二是建设依据不足，所依据的文件与本项目的建设内容缺乏直接关联，难以支撑立项合理性；三是跨专业协同不足，各部门仅从自身视角提出需求，忽视了与其他系统的数据贯通与流程衔接，导致重复建设与数据孤岛问题。 | I8: 数字化项目管理业务-1.储备立项的程序控制-控制措施05 | J8: 归口管理部门对需求统筹进行评审。新建信息系统（功能模块）的设计开发类需求需进行需求论证 | L8: √ | T8: 线下管控 | V8: 1.需求统筹意见 2.公司级需求论证意见（新建开发类需求） | W8: 各级单位-项目需求部门-需求提报人、各级单位-项目需求部门-负责人、省公司-数字化部-规划技术处处长 | X8: 每季度 | Y8: 抽查 | AA8: 年度 | AB8: 抽查 | AJ8: 《国网湖南省电力有限公司关于加强 数字化项目前期管理的指导意见（试行）》 | AK8: 国网数字化部 | AL8: 新增控制措施及对增加对应制度及文件名称：《国网湖南省电力有限公司关于加强 数字化项目前期管理的指导意见（试行）》 | AM8: 新增控制措施 | AN8: =A8=[2]数字化与研发投入!A8 -> TRUE | AO8: =B8=[2]数字化与研发投入!B8 -> TRUE | AP8: =C8=[2]数字化与研发投入!C8 -> TRUE | AQ8: =D8=[2]数字化与研发投入!D8 -> TRUE | AR8: =E8=[2]数字化与研发投入!E8 -> TRUE | AS8: =F8=[2]数字化与研发投入!F8 -> TRUE | AT8: =G8=[2]数字化与研发投入!G8 -> TRUE | AU8: =H8=[2]数字化与研发投入!H8 -> TRUE | ... BX8: =AK8=[2]数字化与研发投入!AK8 -> TRUE
D9: 计划和预算安排 | E9: 项目计划预算安排不合理、调整不及时，未根据项目实际情况进行计划分解和调整，导致提前或滞后确认成本，引发合规风险。 | G9: 2.计划预算安排合规性 | H9: 项目计划预算安排与项目实际进度的一致性控制。 | I9: 数字化项目管理业务-2.计划预算安排合规性-控制措施01 | J9: 归口管理部门对项目储备金额建立计划与预算的复核机制，按实际预估周期安排年度计划和预算。 | L9: √ | N9: √ | Q9: √ | S9: √ | T9: 线下管控 | V9: 1.项目储备资料； 2.计划调整文件； 3.预算下达文件。 | W9: 各级单位-项目承担部门-项目负责人、各级单位-项目承担部门-负责人、各级单位-归口管理部门-计划管理人员、各级单位-归口管理部门-负责人、各级单位-财务部门-预算管理人员、各级单位-财务部门-负责人、省公司-数字化部-规划技术处处长 | X9: 每月 | Y9: 抽查 | AA9: 年度 | AB9: 抽查 | AH9: 是 | AI9: 是 | AJ9: 《国家电网有限公司工程财务管理办法》（国家电网企管〔2023〕28号） 《国家电网有限公司全面预算管理办法》（国家电网企管〔2026〕101号） 《国网湖南省电力有限公司数字化项目管理实施细则》（湘电公司数字〔2024〕447号 ） | AK9: 国网数字化部 | AL9: 增加对应制度及文件名称：《国网湖南省电力有限公司数字化项目管理实施细则》（湘电公司数字〔2024〕447号 ） | AM9: 修改责任主体，补充制度 | AN9: =A9=[2]数字化与研发投入!A9 -> TRUE | AO9: =B9=[2]数字化与研发投入!B9 -> TRUE | AP9: =C9=[2]数字化与研发投入!C9 -> TRUE | AQ9: =D9=[2]数字化与研发投入!D9 -> TRUE | AR9: =E9=[2]数字化与研发投入!E9 -> TRUE | AS9: =F9=[2]数字化与研发投入!F9 -> TRUE | AT9: =G9=[2]数字化与研发投入!G9 -> TRUE | AU9: =H9=[2]数字化与研发投入!H9 -> TRUE | ... BX9: =AK9=[2]数字化与研发投入!AK9 -> TRUE
I10: 数字化项目管理业务-2.计划预算安排合规性-控制措施02 | J10: 年中增补项目分年度下达计划和预算。 | N10: √ | Q10: √ | S10: √ | T10: 线下管控 | V10: 1.可研资料； 2.项目立项文件； 3.进度确认材料； 4.项目采购文件； 5.合同； 6.预算下达文件； 7.预算计划调整文件。 | W10: 各级单位-项目承担部门-项目负责人、各级单位-项目承担部门-负责人、各级单位-归口管理部门-计划管理人员、各级单位-归口管理部门-负责人、各级单位-财务部门-预算管理人员、各级单位-财务部门-负责人、各级单位-发展部门-综合计划管理人员、各级单位-发展部门-负责人、省公司-数字化部-项目管理专责 | X10: 每月 | Y10: 抽查 | AA10: 年度 | AB10: 抽查 | AH10: 是 | AI10: 是 | AJ10: 《国家电网有限公司电网数字化建设管理办法》（国家电网企管〔2020〕849号） 《国家电网有限公司工程财务管理办法》（国家电网企管〔2023〕28号） 《国家电网有限公司全面预算管理办法》（国家电网企管〔2026〕101号） 《国网湖南省电力有限公司数字化项目管理实施细则》（湘电公司数字〔2024〕447号 ） | AK10: 国网数字化部 | AL10: 增加对应制度及文件名称：《国网湖南省电力有限公司数字化项目管理实施细则》（湘电公司数字〔2024〕447号 ） | AM10: 修改责任主体，补充制度 | AN10: =A10=[2]数字化与研发投入!A10 -> TRUE | AO10: =B10=[2]数字化与研发投入!B10 -> TRUE | AP10: =C10=[2]数字化与研发投入!C10 -> TRUE | AQ10: =D10=[2]数字化与研发投入!D10 -> TRUE | AR10: =E10=[2]数字化与研发投入!E10 -> TRUE | AS10: =F10=[2]数字化与研发投入!F10 -> TRUE | AT10: =G10=[2]数字化与研发投入!G10 -> TRUE | AU10: =H10=[2]数字化与研发投入!H10 -> TRUE | ... BX10: =AK10=[2]数字化与研发投入!AK10 -> TRUE
I11: 数字化项目管理业务-2.计划预算安排合规性-控制措施03 | J11: 根据外部环境和项目本身变化，及时调整计划和预算。 | N11: √ | Q11: √ | S11: √ | T11: 线下管控 | V11: 1.可研资料； 2.项目立项文件； 3.项目采购文件； 4.综合计划； 5.预算下达文件； 6.进度确认材料； 7.调整文件； 8.合同。 | W11: 各级单位-项目承担部门-项目负责人、各级单位-项目承担部门-负责人、各级单位-归口管理部门-计划管理人员、各级单位-归口管理部门-负责人、各级单位-财务部门-预算管理人员、各级单位-财务部门-负责人、各级单位-发展部门-综合计划管理人员、各级单位-发展部门-负责人、省公司-数字化部-计划建设处处长 | X11: 每月 | Y11: 抽查 | AA11: 年度 | AB11: 抽查 | AH11: 是 | AI11: 是 | AJ11: 《国家电网有限公司电网数字化建设管理办法》（国家电网企管〔2020〕849号） 《国家电网有限公司工程财务管理办法》（国家电网企管〔2023〕28号） 《国家电网有限公司全面预算管理办法》（国家电网企管〔2026〕101号） 《国网湖南省电力有限公司数字化项目管理实施细则》（湘电公司数字〔2024〕447号 ） | AK11: 国网数字化部 | AL11: 增加对应制度及文件名称：《国网湖南省电力有限公司数字化项目管理实施细则》（湘电公司数字〔2024〕447号 ） | AM11: 修改责任主体，补充制度 | AN11: =A11=[2]数字化与研发投入!A11 -> TRUE | AO11: =B11=[2]数字化与研发投入!B11 -> TRUE | AP11: =C11=[2]数字化与研发投入!C11 -> TRUE | AQ11: =D11=[2]数字化与研发投入!D11 -> TRUE | AR11: =E11=[2]数字化与研发投入!E11 -> TRUE | AS11: =F11=[2]数字化与研发投入!F11 -> TRUE | AT11: =G11=[2]数字化与研发投入!G11 -> TRUE | AU11: =H11=[2]数字化与研发投入!H11 -> TRUE | ... BX11: =AK11=[2]数字化与研发投入!AK11 -> TRUE
A12: 数字化项目管理业务 | B12: 二、项目实施管理 | C12: 会计信息真实完整 | D12: 成本入账 | E12: 成本入账与进度结算金额不符，项目审核缺位，易引发虚列研发成本、提前确认项目成本风险。 | F12: 5.会计信息不准确：存在虚增隐瞒收入，虚增减成本费用；隐瞒负债，少计应付账款或借款；收入成本不匹配；收入、成本确认不及时、不准确等问题。 25.结算不准确，多结算工程款：存在费用多计（甲供物资、施工费、监理费、监造费、设计费、其他费用及税金等定额套用错误）；工程保险费等费用重复计列；部分服务内容（可研、设计、结算等）未全部开展但全额计列费用；无正当理由变更初始合同计价规则，调增劳务分包费；重复结算人工费用；超标准列支人工费、外委研究支出等问题。 | G12: 3.入账成本准确性 | H12: 入账金额准确性、成本支出真实性控制。 | I12: 数字化项目管理业务-3.入账成本准确性-控制措施01 | J12: 项目承担部门严格按合同约定管控项目执行进度，审核是否存在违约行为，根据实际进度收取发票、填写报账单。 | L12: √ | M12: √ | O12: √ | T12: 线下管控 | V12: 1.项目费用支出明细清单及相关资料； 2.合同； 3.项目进度报审表； 4.项目人员备案表。 | W12: 各级单位-项目承担部门-项目负责人、各级单位-项目承担部门-负责人 | X12: 每年 | Y12: 抽查 | AA12: 年度 | AB12: 抽查 | AH12: 是 | AI12: 是 | AJ12: 《国家电网有限公司电网数字化建设管理办法》（国家电网企管〔2020〕849号）《国网湖南省电力有限公司数字化项目管理实施细则》（湘电公司数字〔2024〕447号 ） | AK12: 国网数字化部 | AL12: 增加对应制度及文件名称：《国网湖南省电力有限公司数字化项目管理实施细则》（湘电公司数字〔2024〕447号 ）、《国网湖南信通公司数字化项目发票入账与资金支付操作手册》（湘电信通函〔2025〕22号） | AM12: 补充制度 | AN12: =A12=[2]数字化与研发投入!A12 -> TRUE | AO12: =B12=[2]数字化与研发投入!B12 -> TRUE | AP12: =C12=[2]数字化与研发投入!C12 -> TRUE | AQ12: =D12=[2]数字化与研发投入!D12 -> TRUE | AR12: =E12=[2]数字化与研发投入!E12 -> TRUE | AS12: =F12=[2]数字化与研发投入!F12 -> TRUE | AT12: =G12=[2]数字化与研发投入!G12 -> TRUE | AU12: =H12=[2]数字化与研发投入!H12 -> TRUE | ... BX12: =AK12=[2]数字化与研发投入!AK12 -> TRUE
I13: 数字化项目管理业务-3.入账成本准确性-控制措施02 | J13: 归口管理部门复核项目完成情况、项目人员备案表等材料的完整性和合规性。 | O13: √ | T13: 线下管控 | V13: 1.项目费用支出明细清单及相关资料； 2.合同； 3.项目人员备案表； 4.项目进度材料。 | W13: 各级单位-归口管理部门-项目管理人员、各级单位-归口管理部门-负责人、省公司-数字化部-项目管理专责、省公司-项目管理中心-进度管控专责 | X13: 每年 | Y13: 抽查 | AA13: 年度 | AB13: 抽查 | AH13: 是 | AI13: 是 | AJ13: 《国家电网有限公司电网数字化建设管理办法》（国家电网企管〔2020〕849号）《国网湖南省电力有限公司数字化项目管理实施细则》（湘电公司数字〔2024〕447号 ） | AK13: 国网数字化部 | AL13: 增加对应制度及文件名称：《国网湖南省电力有限公司数字化项目管理实施细则》（湘电公司数字〔2024〕447号 ） | AM13: 修改责任主体，补充制度 | AN13: =A13=[2]数字化与研发投入!A13 -> TRUE | AO13: =B13=[2]数字化与研发投入!B13 -> TRUE | AP13: =C13=[2]数字化与研发投入!C13 -> TRUE | AQ13: =D13=[2]数字化与研发投入!D13 -> TRUE | AR13: =E13=[2]数字化与研发投入!E13 -> TRUE | AS13: =F13=[2]数字化与研发投入!F13 -> TRUE | AT13: =G13=[2]数字化与研发投入!G13 -> TRUE | AU13: =H13=[2]数字化与研发投入!H13 -> TRUE | ... BX13: =AK13=[2]数字化与研发投入!AK13 -> TRUE
I14: 数字化项目管理业务-3.入账成本准确性-控制措施03 | J14: 财务部门对成本报账单金额与结算金额、发票金额一致性、准确性进行审核。 | N14: √ | O14: √ | P14: √ | Q14: √ | T14: 系统已建 | U14: 智慧共享财务平台 | V14: 1.发票； 2.报账单； 3.合同； 4.项目进度报审表。 | W14: 各级单位-财务部门-成本管理人员、各级单位-财务部门-负责人 | X14: 每年 | Y14: 抽查 | AA14: 年度 | AB14: 抽查 | AD14: 成本入账监督场景 | AE14: 每月 | AF14: 全量检查 | AH14: 是 | AI14: 是 | AJ14: 《国家电网有限公司电网数字化建设管理办法》（国家电网企管〔2020〕849号） | AK14: 国网数字化部 | AL14: 1.无变化，直接引用 | AN14: =A14=[2]数字化与研发投入!A14 -> TRUE | AO14: =B14=[2]数字化与研发投入!B14 -> TRUE | AP14: =C14=[2]数字化与研发投入!C14 -> TRUE | AQ14: =D14=[2]数字化与研发投入!D14 -> TRUE | AR14: =E14=[2]数字化与研发投入!E14 -> TRUE | AS14: =F14=[2]数字化与研发投入!F14 -> TRUE | AT14: =G14=[2]数字化与研发投入!G14 -> TRUE | AU14: =H14=[2]数字化与研发投入!H14 -> TRUE | ... BX14: =AK14=[2]数字化与研发投入!AK14 -> TRUE
B15: 二、项目实施管理 | C15: 资金资产安全 | D15: 专业分包 | E15: 分包超范围、超比例，易致信息系统建设质量失控，滋生虚增成本、套取资金等风险。 | F15: 45.数字化项目建设环节管控不严：存在项目建设内容发生变更未按规定履行审批程序；系统开发环境、测试环境和运行环境未进行分离；承建单位专业分包比例过高等问题。 5.会计信息不准确：存在虚增隐瞒收入，虚增减成本费用；隐瞒负债，少计应付账款或借款；收入成本不匹配；收入、成本确认不及时、不准确等问题。 | G15: 4.专业分包比例合规性 | H15: 专业分包链路穿透与比例合规性控制。 | I15: 数字化项目管理业务-4.专业分包比例合规性-控制措施01 | J15: 项目承担部门对分包内容备案、分包人员台账、实际分包比例进行检查，不得将核心业务分包、超出规定比例分包等。 | M15: √ | O15: √ | T15: 线下管控 | V15: 1.合同； 2.分包备案资料； 3.可研资料； 4.技术规范书。 | W15: 各级单位-项目承担部门-项目负责人、各级单位-项目承担部门-负责人 | X15: 每月 | Y15: 抽查 | AA15: 年度 | AB15: 抽查 | AH15: 是 | AI15: 是 | AJ15: 《国网信通部关于进一步规范和加强信息化建设分包管理工作的通知》（信通计划〔2018〕20号） 《国家电网有限公司电网数字化项目技术管理办法》（国网（信息/3）287-2021） 《国家电网有限公司电网数字化项目分包管理规范（试行）》（国家电网数字〔2024〕81 号 ） | AK15: 国网数字化部 | AL15: 1.无变化，直接引用 | AN15: =A15=[2]数字化与研发投入!A15 -> TRUE | AO15: =B15=[2]数字化与研发投入!B15 -> TRUE | AP15: =C15=[2]数字化与研发投入!C15 -> TRUE | AQ15: =D15=[2]数字化与研发投入!D15 -> TRUE | AR15: =E15=[2]数字化与研发投入!E15 -> TRUE | AS15: =F15=[2]数字化与研发投入!F15 -> TRUE | AT15: =G15=[2]数字化与研发投入!G15 -> TRUE | AU15: =H15=[2]数字化与研发投入!H15 -> TRUE | ... BX15: =AK15=[2]数字化与研发投入!AK15 -> TRUE
G16: 4.专业分包比例合规性 | H16: 专业分包链路穿透与比例合规性控制。 | I16: 数字化项目管理业务-4.专业分包比例合规性-控制措施02 | J16: 项目承担部门建立分包台账，定期排查分包情况，禁止超比例分包、层层分包。 | M16: √ | O16: √ | T16: 线下管控 | V16: 1.合同； 2.分包备案资料； 3.可研资料； 4.技术规范书。 | W16: 各级单位-项目承担部门-项目负责人、各级单位-项目承担部门-负责人 | X16: 每月 | Y16: 抽查 | AA16: 年度 | AB16: 抽查 | AH16: 是 | AI16: 是 | AJ16: 《国网信通部关于进一步规范和加强信息化建设分包管理工作的通知》（信通计划〔2018〕20号） 《国家电网有限公司电网数字化项目技术管理办法》（国网（信息/3）287-2021） 《国家电网有限公司电网数字化项目分包管理规范（试行）》（国家电网数字〔2024〕81 号 ） | AK16: 国网数字化部 | AL16: 1.无变化，直接引用 | AN16: =A16=[2]数字化与研发投入!A16 -> TRUE | AO16: =B16=[2]数字化与研发投入!B16 -> TRUE | AP16: =C16=[2]数字化与研发投入!C16 -> TRUE | AQ16: =D16=[2]数字化与研发投入!D16 -> TRUE | AR16: =E16=[2]数字化与研发投入!E16 -> TRUE | AS16: =F16=[2]数字化与研发投入!F16 -> TRUE | AT16: =G16=[2]数字化与研发投入!G16 -> TRUE | AU16: =H16=[2]数字化与研发投入!H16 -> TRUE | ... BX16: =AK16=[2]数字化与研发投入!AK16 -> TRUE
I17: 数字化项目管理业务-4.专业分包比例合规性-控制措施03 | J17: 归口管理部门建立“总包-分包”合同穿透链路，通过合同与项目的关联查看总包单位为系统内单位的业主单位、总包单位、分包单位的对应关系。 数字化部负责落实公司电网数字化项目分包管理制度，建立健全本单位电网数字化项目分包管理机制。 | M17: √ | O17: √ | S17: √ | T17: 系统待建 | U17: 数字化法治企业建设平台 | V17: 1.合同； 2.分包备案资料； 3.可研资料； 4.技术规范书。 | W17: 各级单位-归口管理部门-项目管理人员、各级单位-归口管理部门-负责人、省公司-数字化部-项目管理专责 | X17: 每月 | Y17: 抽查 | AA17: 年度 | AB17: 抽查 | AD17: 项目分包管理监督场景 | AE17: 每年 | AF17: 抽查 | AH17: 是 | AI17: 是 | AJ17: 《国网信通部关于进一步规范和加强信息化建设分包管理工作的通知》（信通计划〔2018〕20号） 《国家电网有限公司电网数字化项目技术管理办法》（国网（信息/3）287-2021） 《国家电网有限公司电网数字化项目分包管理规范（试行）》（国家电网数字〔2024〕81 号 ） | AK17: 国网数字化部 | AL17: 修改了控制措施 | AM17: 修改控制措施，修改责任主体 | AN17: =A17=[2]数字化与研发投入!A17 -> TRUE | AO17: =B17=[2]数字化与研发投入!B17 -> TRUE | AP17: =C17=[2]数字化与研发投入!C17 -> TRUE | AQ17: =D17=[2]数字化与研发投入!D17 -> TRUE | AR17: =E17=[2]数字化与研发投入!E17 -> TRUE | AS17: =F17=[2]数字化与研发投入!F17 -> TRUE | AT17: =G17=[2]数字化与研发投入!G17 -> TRUE | AU17: =H17=[2]数字化与研发投入!H17 -> TRUE | ... BX17: =AK17=[2]数字化与研发投入!AK17 -> TRUE
I18: 数字化项目管理业务-4.专业分包比例合规性-控制措施04 | J18: 归口管理部门建立“总包-分包”人员的穿透链路，核查总包单位为系统内单位的项目团队成员单位信息，分析人员隶属是否遵循合同约定。 数字化部负责本单位电网数字化项目分包工作的督导和检查。 | M18: √ | O18: √ | S18: √ | T18: 线下管控 | V18: 1.合同； 2.分包备案资料； 3.可研资料； 4.技术规范书。 | W18: 各级单位-归口管理部门-项目管理人员、各级单位-归口管理部门-负责人、省公司-数字化部-项目管理专责 | X18: 每月 | Y18: 抽查 | AA18: 年度 | AB18: 抽查 | AD18: 项目分包管理监督场景 | AE18: 每年 | AF18: 抽查 | AH18: 是 | AI18: 是 | AJ18: 《国网信通部关于进一步规范和加强信息化建设分包管理工作的通知》（信通计划〔2018〕20号） 《国家电网有限公司电网数字化项目技术管理办法》（国网（信息/3）287-2021） 《国家电网有限公司电网数字化项目分包管理规范（试行）》（国家电网数字〔2024〕81 号 ） | AK18: 国网数字化部 | AL18: 修改了控制措施 | AM18: 修改控制措施，修改责任主体 | AN18: =A18=[2]数字化与研发投入!A18 -> TRUE | AO18: =B18=[2]数字化与研发投入!B18 -> TRUE | AP18: =C18=[2]数字化与研发投入!C18 -> TRUE | AQ18: =D18=[2]数字化与研发投入!D18 -> TRUE | AR18: =E18=[2]数字化与研发投入!E18 -> TRUE | AS18: =F18=[2]数字化与研发投入!F18 -> TRUE | AT18: =G18=[2]数字化与研发投入!G18 -> TRUE | AU18: =H18=[2]数字化与研发投入!H18 -> TRUE | ... BX18: =AK18=[2]数字化与研发投入!AK18 -> TRUE
I19: 数字化项目管理业务-4.专业分包比例合规性-控制措施05 | J19: 财务部门构建“总包-分包”资金支付穿透链路，分析总包单位为系统内单位的资金流向是否符合合同主体穿透控制要求。 | M19: √ | O19: √ | P19: √ | Q19: √ | S19: √ | T19: 系统待建 | U19: 智慧共享财务平台 | V19: 1.合同； 2.分包备案资料； 3.可研资料； 4.技术规范书。 | W19: 各级单位-财务部门-工程管理人员、各级单位-财务部门-负责人 | X19: 每月 | Y19: 抽查 | AA19: 年度 | AB19: 抽查 | AD19: 项目分包管理监督场景 | AE19: 每年 | AF19: 抽查 | AH19: 是 | AI19: 是 | AJ19: 《国网信通部关于进一步规范和加强信息化建设分包管理工作的通知》（信通计划〔2018〕20号） 《国家电网有限公司电网数字化项目技术管理办法》（国网（信息/3）287-2021） 《国家电网有限公司电网数字化项目分包管理规范（试行）》（国家电网数字〔2024〕81 号 ） | AK19: 国网数字化部 | AL19: 1.无变化，直接引用 | AN19: =A19=[2]数字化与研发投入!A19 -> TRUE | AO19: =B19=[2]数字化与研发投入!B19 -> TRUE | AP19: =C19=[2]数字化与研发投入!C19 -> TRUE | AQ19: =D19=[2]数字化与研发投入!D19 -> TRUE | AR19: =E19=[2]数字化与研发投入!E19 -> TRUE | AS19: =F19=[2]数字化与研发投入!F19 -> TRUE | AT19: =G19=[2]数字化与研发投入!G19 -> TRUE | AU19: =H19=[2]数字化与研发投入!H19 -> TRUE | ... BX19: =AK19=[2]数字化与研发投入!AK19 -> TRUE
A20: 数字化项目管理业务 | B20: 三、竣工验收转资 | C20: 资金资产安全 | D20: 现场资产盘点 | E20: 资产卡片信息与合同信息、研发及信息系统设备台账、设备实物不符，资产管理不规范，存在资产流失风险。 | F20: 46.数字化项目验收管控不严：存在部分数字化项目合同约定的交付物雷同或内容不实；部分功能未实现；未履行测试或验证；验收人员组成不合理，业务部门未参与验收等问题。 | G20: 5.资产信息真实性 | H20: 账卡物一致性控制。 | I20: 数字化项目管理业务-5.资产信息真实性-控制措施01 | J20: 使用保管部门规范保管、使用资产，不得未经审批处置。 | L20: √ | M20: √ | R20: √ | T20: 系统已建 | U20: 智慧共享财务平台（目前ERP） | V20: 1.资产卡片清单； 2.I6000台账。 | W20: 各级单位-使用保管部门-使用保管人员、各级单位-使用保管部门-负责人 | X20: 每年 | Y20: 抽查 | AA20: 年度 | AB20: 抽查 | AD20: 资产建卡与赋值监督场景 | AE20: 每季度 | AF20: 抽查 | AH20: 是 | AI20: 是 | AJ20: 《国家电网公司固定资产管理办法》国网（财/2）593-2023（通用） 《国家电网公司无形资产管理办法》国网（财/2）205-2014 | AK20: 国网数字化部 | AL20: 1.无变化，直接引用 | AN20: =A20=[2]数字化与研发投入!A20 -> TRUE | AO20: =B20=[2]数字化与研发投入!B20 -> TRUE | AP20: =C20=[2]数字化与研发投入!C20 -> TRUE | AQ20: =D20=[2]数字化与研发投入!D20 -> TRUE | AR20: =E20=[2]数字化与研发投入!E20 -> TRUE | AS20: =F20=[2]数字化与研发投入!F20 -> TRUE | AT20: =G20=[2]数字化与研发投入!G20 -> TRUE | AU20: =H20=[2]数字化与研发投入!H20 -> TRUE | ... BX20: =AK20=[2]数字化与研发投入!AK20 -> TRUE
I21: 数字化项目管理业务-5.资产信息真实性-控制措施02 | J21: 实物管理部门数字化部定期开展实物盘点，核对设备台账与现场实物的一致性。 | M21: √ | R21: √ | T21: 线下管控 | V21: I6000台账。 | W21: 各级单位-使用保管部门-使用保管人员、各级单位-使用保管部门-负责人、各级单位-实物管理部门-设备管理人员、各级单位-实物管理部门-负责人、省公司-数字化部-信息运行专责 | X21: 每年 | Y21: 抽查 | AA21: 年度 | AB21: 抽查 | AH21: 是 | AI21: 是 | AJ21: 《国家电网公司固定资产管理办法》国网（财/2）593-2023（通用） 《国家电网公司无形资产管理办法》国网（财/2）205-2014 | AK21: 国网数字化部 | AL21: 1.无变化，直接引用 | AM21: 修改控制措施，修改责任主体 | AN21: =A21=[2]数字化与研发投入!A21 -> TRUE | AO21: =B21=[2]数字化与研发投入!B21 -> TRUE | AP21: =C21=[2]数字化与研发投入!C21 -> TRUE | AQ21: =D21=[2]数字化与研发投入!D21 -> TRUE | AR21: =E21=[2]数字化与研发投入!E21 -> TRUE | AS21: =F21=[2]数字化与研发投入!F21 -> TRUE | AT21: =G21=[2]数字化与研发投入!G21 -> TRUE | AU21: =H21=[2]数字化与研发投入!H21 -> TRUE | ... BX21: =AK21=[2]数字化与研发投入!AK21 -> TRUE
I22: 数字化项目管理业务-5.资产信息真实性-控制措施03 | J22: 财务部门对固定资产购置价值信息与决算金额一致性进行检查。 | O22: √ | Q22: √ | T22: 系统待建 | U22: 智慧共享财务平台 | V22: 1.合同； 2.资产卡片清单； 3.转资信息表； 4.验收盘点表； 5.竣工决算报告。 | W22: 各级单位-财务部门-工程财务人员、各级单位-财务部门-负责人 | X22: 每年 | Y22: 抽查 | AA22: 年度 | AB22: 抽查 | AD22: 资产建卡与赋值监督场景 | AE22: 每季度 | AF22: 抽查 | AH22: 是 | AI22: 是 | AJ22: 《国家电网公司固定资产管理办法》国网（财/2）593-2023（通用） 《国家电网公司无形资产管理办法》国网（财/2）205-2014 | AK22: 国网数字化部 | AL22: 1.无变化，直接引用 | AN22: =A22=[2]数字化与研发投入!A22 -> TRUE | AO22: =B22=[2]数字化与研发投入!B22 -> TRUE | AP22: =C22=[2]数字化与研发投入!C22 -> TRUE | AQ22: =D22=[2]数字化与研发投入!D22 -> TRUE | AR22: =E22=[2]数字化与研发投入!E22 -> TRUE | AS22: =F22=[2]数字化与研发投入!F22 -> TRUE | AT22: =G22=[2]数字化与研发投入!G22 -> TRUE | AU22: =H22=[2]数字化与研发投入!H22 -> TRUE | ... BX22: =AK22=[2]数字化与研发投入!AK22 -> TRUE
C23: 资金资产安全 | D23: 项目验收 | E23: 合同交付物雷同或内容不实，验收人员组成不合理，未发现项目存在的问题，造成资源浪费风险。 | F23: 46.数字化项目验收管控不严：存在部分数字化项目合同约定的交付物雷同或内容不实；部分功能未实现；未履行测试或验证；验收人员组成不合理，业务部门未参与验收等问题。 | G23: 6.项目验收质量 | H23: 验收流程规范性、人员组成合规性、资料准确完整性控制 | I23: 数字化项目管理业务-6.项目验收质量-控制措施01 | J23: 归口管理部门规范验收流程，实行内部交叉验收机制，相互监督制约。 | L23: √ | M23: √ | T23: 线下管控 | V23: 1.验收计划； 2.验收报告。 | W23: 各级单位-归口管理部门-项目管理人员、各级单位-归口管理部门-负责人、省公司-数字化部-项目管理专责 | X23: 每月 | Y23: 抽查 | AA23: 年度 | AB23: 抽查 | AH23: 是 | AI23: 是 | AJ23: 《国家电网有限公司电网数字化项目竣工验收管理规范》（试行）数字计划〔2025〕13号 《国网数字化部关于进一步加强信息系统上下线及检修管理的通知》数字运行〔2024〕54 号《国网湖南省电力有限公司数字化项目管理实施细则》（湘电公司数字〔2024〕447号 ） | AK23: 国网数字化部 | AL23: 增加对应制度及文件名称：《国网湖南省电力有限公司数字化项目管理实施细则》（湘电公司数字〔2024〕447号 ）、《关于进一步加强数字化项目验收管理的通知（试行）》 | AM23: 修改责任主体，补充制度 | AN23: =A23=[2]数字化与研发投入!A23 -> TRUE | AO23: =B23=[2]数字化与研发投入!B23 -> TRUE | AP23: =C23=[2]数字化与研发投入!C23 -> TRUE | AQ23: =D23=[2]数字化与研发投入!D23 -> TRUE | AR23: =E23=[2]数字化与研发投入!E23 -> TRUE | AS23: =F23=[2]数字化与研发投入!F23 -> TRUE | AT23: =G23=[2]数字化与研发投入!G23 -> TRUE | AU23: =H23=[2]数字化与研发投入!H23 -> TRUE | ... BX23: =AK23=[2]数字化与研发投入!AK23 -> TRUE
I24: 数字化项目管理业务-6.项目验收质量-控制措施02 | J24: 归口管理部门根据项目可研和合同等资料，对项目成果进行审核。 | O24: √ | R24: √ | T24: 线下管控 | V24: 1.验收计划； 2.验收报告； 3.项目可研及合同； 4.项目档案资料。 | W24: 各级单位-项目承担部门-项目负责人、各级单位-项目承担部门-负责人、各级单位-归口管理部门-管理部门人员、各级单位-归口管理部门-负责人、省公司-项目管理中心-评审管理专责 | X24: 每月 | Y24: 抽查 | AA24: 年度 | AB24: 抽查 | AH24: 是 | AI24: 是 | AJ24: 《国家电网有限公司电网数字化项目竣工验收管理规范》（试行）数字计划〔2025〕13号 《国网数字化部关于进一步加强信息系统上下线及检修管理的通知》数字运行〔2024〕54 号 《国网湖南省电力有限公司数字化项目管理实施细则》（湘电公司数字〔2024〕447号 ） 《关于进一步加强数字化项目验收管理的通知（试行）》 | AK24: 国网数字化部 | AL24: 增加对应制度及文件名称：《国网湖南省电力有限公司数字化项目管理实施细则》（湘电公司数字〔2024〕447号 ）、《关于进一步加强数字化项目验收管理的通知（试行）》 | AM24: 修改责任主体，补充制度 | AN24: =A24=[2]数字化与研发投入!A24 -> TRUE | AO24: =B24=[2]数字化与研发投入!B24 -> TRUE | AP24: =C24=[2]数字化与研发投入!C24 -> TRUE | AQ24: =D24=[2]数字化与研发投入!D24 -> TRUE | AR24: =E24=[2]数字化与研发投入!E24 -> TRUE | AS24: =F24=[2]数字化与研发投入!F24 -> TRUE | AT24: =G24=[2]数字化与研发投入!G24 -> TRUE | AU24: =H24=[2]数字化与研发投入!H24 -> TRUE | ... BX24: =AK24=[2]数字化与研发投入!AK24 -> TRUE
I25: 数字化项目管理业务-6.项目验收质量-控制措施03 | J25: 归口管理部门复核验收组构成合理性，检查业务部门参与。 | S25: √ | T25: 线下管控 | V25: 1.验收计划； 2.验收报告（重点查阅验收意见及专家签到表）。 | W25: 各级单位-归口管理部门-项目管理人员、各级单位-归口管理部门-负责人、省公司-项目管理中心项目-评审管理专责（200万元及以上项目） | X25: 每月 | Y25: 抽查 | AA25: 年度 | AB25: 抽查 | AH25: 是 | AI25: 是 | AJ25: 《国家电网有限公司电网数字化建设管理办法》（国家电网企管〔2020〕849号） 《国家电网有限公司电网数字化项目竣工验收管理规范》（试行）数字计划〔2025〕13号 《国网湖南省电力有限公司数字化项目管理实施细则》（湘电公司数字〔2024〕447号 ） | AK25: 国网数字化部 | AL25: 增加对应制度及文件名称：《国网湖南省电力有限公司数字化项目管理实施细则》（湘电公司数字〔2024〕447号 ）、《关于进一步加强数字化项目验收管理的通知（试行）》 | AM25: 修改责任主体，补充制度 | AN25: =A25=[2]数字化与研发投入!A25 -> TRUE | AO25: =B25=[2]数字化与研发投入!B25 -> TRUE | AP25: =C25=[2]数字化与研发投入!C25 -> TRUE | AQ25: =D25=[2]数字化与研发投入!D25 -> TRUE | AR25: =E25=[2]数字化与研发投入!E25 -> TRUE | AS25: =F25=[2]数字化与研发投入!F25 -> TRUE | AT25: =G25=[2]数字化与研发投入!G25 -> TRUE | AU25: =H25=[2]数字化与研发投入!H25 -> TRUE | ... BX25: =AK25=[2]数字化与研发投入!AK25 -> TRUE
C26: 资金资产安全、税务合规 | D26: 项目转资 | E26: 未及时完成转资，造成资产折旧计提延迟，进而引发当期利润虚增、资产账面价值不实及税务合规风险。 | G26: 7.项目转资合规性 | H26: 项目转资及时性，折旧计提准确性控制。 | I26: 数字化项目管理业务-7.项目转资合规性-控制措施01 | J26: 归口管理部门对转资及时性、竣工验收资料完整性和审批流程合规性进行检查。 | M26: √ | O26: √ | R26: √ | T26: 线下管控 | V26: 1.合同； 2.项目验收意见。 | W26: 各级单位-归口管理部门-项目管理人员、各级单位-归口管理部门-负责人 | X26: 每季度 | Y26: 全量检查 | AA26: 年度 | AB26: 抽查 | AH26: 是 | AI26: 是 | AJ26: 《国家电网有限公司电网数字化项目竣工验收管理规范（试行）》（数字计划〔2025〕13号） 《国家电网有限公司工程财务管理办法》（国家电网企管〔2023〕28号） | AK26: 国网数字化部 | AL26: 1.无变化，直接引用 | AN26: =A26=[2]数字化与研发投入!A26 -> TRUE | AO26: =B26=[2]数字化与研发投入!B26 -> TRUE | AP26: =C26=[2]数字化与研发投入!C26 -> TRUE | AQ26: =D26=[2]数字化与研发投入!D26 -> TRUE | AR26: =E26=[2]数字化与研发投入!E26 -> TRUE | AS26: =F26=[2]数字化与研发投入!F26 -> TRUE | AT26: =G26=[2]数字化与研发投入!G26 -> TRUE | AU26: =H26=[2]数字化与研发投入!H26 -> TRUE | ... BX26: =AK26=[2]数字化与研发投入!AK26 -> TRUE
I27: 数字化项目管理业务-7.项目转资合规性-控制措施02 | J27: 财务部门负责资产卡片计提折旧的检查。 | Q27: √ | T27: 系统已建 | U27: 智慧共享财务平台 | V27: 1.固定资产卡片清单。 | W27: 各级单位-财务部门-资产管理人员、各级单位-财务部门-负责人 | X27: 每季度 | Y27: 全量检查 | AA27: 年度 | AB27: 抽查 | AH27: 是 | AI27: 是 | AJ27: 《国家电网有限公司电网数字化项目竣工验收管理规范（试行）》（数字计划〔2025〕13号） 《国家电网有限公司工程财务管理办法》（国家电网企管〔2023〕28号） | AK27: 国网数字化部 | AL27: 1.无变化，直接引用 | AN27: =A27=[2]数字化与研发投入!A27 -> TRUE | AO27: =B27=[2]数字化与研发投入!B27 -> TRUE | AP27: =C27=[2]数字化与研发投入!C27 -> TRUE | AQ27: =D27=[2]数字化与研发投入!D27 -> TRUE | AR27: =E27=[2]数字化与研发投入!E27 -> TRUE | AS27: =F27=[2]数字化与研发投入!F27 -> TRUE | AT27: =G27=[2]数字化与研发投入!G27 -> TRUE | AU27: =H27=[2]数字化与研发投入!H27 -> TRUE | ... BX27: =AK27=[2]数字化与研发投入!AK27 -> TRUE
A28: 科技项目管理业务 | B28: 一、项目立项管理 | C28: 资金资产安全 | D28: 项目储备及立项 | E28: 未依据科技规划及公司实际需求，项目储备存在偏离主业与战略方向，重复立项风险。 | F28: 42.研究开发项目管理不规范：存在专利申请时间早于项目开始时间；复用以前年度科技项目的研究内容。 | G28: 8.储备立项的程序 | H28: 项目储备规范化、精益化。 | I28: 科技项目管理业务-8.储备立项的程序-控制措施01 | J28: 科技部门建立项目查重机制，避免重复储备和立项。 | L28: √ | M28: √ | S28: √ | T28: 系统已建 | U28: 科技项目管理系统（一体化创新平台） | V28: 1.项目库； 2.可研报告/项目建议书； 3.评审意见表。 | W28: 各级单位-科技部门-管理人员 | X28: 年度 | Y28: 全量 | AA28: 年度 | AB28: 全量 | AH28: 是 | AI28: 是 | AJ28: 《国家电网有限公司科技项目管理办法》国家电网企管〔2024〕71号 《国家电网有限公司科技项目储备库管理细则》国家电网企管〔2019〕429号 《国网湖南省电力有限公司关于印发进一步加强科技项目全过程管理具体举措》湘电公司科〔2025〕239号 | AK28: 国网科技部 | AM28: 补充制度 | AN28: =A28=[2]数字化与研发投入!A28 -> TRUE | AO28: =B28=[2]数字化与研发投入!B28 -> TRUE | AP28: =C28=[2]数字化与研发投入!C28 -> TRUE | AQ28: =D28=[2]数字化与研发投入!D28 -> TRUE | AR28: =E28=[2]数字化与研发投入!E28 -> TRUE | AS28: =F28=[2]数字化与研发投入!F28 -> TRUE | AT28: =G28=[2]数字化与研发投入!G28 -> TRUE | AU28: =H28=[2]数字化与研发投入!H28 -> TRUE | ... BX28: =AK28=[2]数字化与研发投入!AK28 -> TRUE
I29: 科技项目管理业务-8.储备立项的程序-控制措施02 | J29: 科技部门建立项目论证机制，避免项目偏离主业和战略方向。 | L29: √ | M29: √ | S29: √ | T29: 线下管控 | V29: 1.项目库； 2.可研报告； 3.可研评审意见以及批复。 | W29: 各级单位-科技部门-负责人 | X29: 年度 | Y29: 全量 | AA29: 年度 | AB29: 全量 | AH29: 是 | AI29: 是 | AJ29: 《国家电网有限公司科技项目管理办法》国家电网企管〔2024〕71号 《国家电网有限公司科技项目储备库管理细则》国家电网企管〔2019〕429号 《国网湖南省电力有限公司关于印发进一步加强科技项目全过程管理具体举措》湘电公司科〔2025〕239号 | AK29: 国网科技部 | AM29: 补充制度 | AN29: =A29=[2]数字化与研发投入!A29 -> TRUE | AO29: =B29=[2]数字化与研发投入!B29 -> TRUE | AP29: =C29=[2]数字化与研发投入!C29 -> TRUE | AQ29: =D29=[2]数字化与研发投入!D29 -> TRUE | AR29: =E29=[2]数字化与研发投入!E29 -> TRUE | AS29: =F29=[2]数字化与研发投入!F29 -> TRUE | AT29: =G29=[2]数字化与研发投入!G29 -> TRUE | AU29: =H29=[2]数字化与研发投入!H29 -> TRUE | ... BX29: =AK29=[2]数字化与研发投入!AK29 -> TRUE
A30: 科技项目管理业务 | B30: 二、项目实施管理 | C30: 会计信息真实完整 | D30: 计划和预算安排 | E30: 项目计划未根据项目实际进展情况及时调整，导致合同执行不到位等合规风险。 | G30: 9.计划调整及时性 | H30: 项目计划预算安排与项目实际进度的一致性。 | I30: 科技项目管理业务-9.计划调整及时性-控制措施01 | J30: 科技项目承担部门根据外部环境和项目实施情况，及时申请调整。 | M30: √ | N30: √ | T30: 系统已建 | U30: 智慧共享财务平台 | V30: 1.项目实施材料； 2.合同； 3.项目立项文件； 4.经费变更申请表、科技项目责任书、科技项目变更申请表等调整文件。 | W30: 各级单位-科技项目承担部门-项目负责人、各级单位-科技项目承担部门-负责人、各级单位-科技部门-管理人员、各级单位-科技部门-负责人、各级单位-发展部门-管理人员、各级单位-发展部门-负责人、各级单位-财务部门-预算管理人员、各级单位-财务部门-负责人 | X30: 年度 | Y30: 抽查 | AA30: 年度 | AB30: 抽查 | AD30: 预算编制及调整 | AE30: 年度 | AF30: 抽查 | AH30: 是 | AI30: 是 | AJ30: 《国家电网有限公司科技项目管理办法》国家电网企管〔2024〕71号 《国家电网公司科技项目预算编制实施细则》国家电网企管〔2017〕1066号 《国家电网有限公司总部管理科技项目实施及验收管理细则》国家电网企管〔2024〕71号 《国网湖南省电力有限公司关于印发进一步加强科技项目全过程管理具体举措》湘电公司科〔2025〕239号 | AK30: 国网科技部 | AM30: 补充制度 | AN30: =A30=[2]数字化与研发投入!A30 -> TRUE | AO30: =B30=[2]数字化与研发投入!B30 -> TRUE | AP30: =C30=[2]数字化与研发投入!C30 -> TRUE | AQ30: =D30=[2]数字化与研发投入!D30 -> TRUE | AR30: =E30=[2]数字化与研发投入!E30 -> TRUE | AS30: =F30=[2]数字化与研发投入!F30 -> TRUE | AT30: =G30=[2]数字化与研发投入!G30 -> TRUE | AU30: =H30=[2]数字化与研发投入!H30 -> TRUE | ... BX30: =AK30=[2]数字化与研发投入!AK30 -> TRUE
I31: 科技项目管理业务-9.计划调整及时性-控制措施02 | J31: 外部环境和项目本身情况发生重大变化，未按规定及时调整投资方案并采取止损措施的，按照中央企业违规经营管理办法追究责任。 | S31: √ | T31: 线下管控 | V31: 1.项目实施材料； 2.合同； 3.项目立项文件； 4.调整文件。 | W31: 各级单位-科技项目承担部门-项目负责人、各级单位-科技项目承担部门-负责人、各级单位-科技部门-管理人员、各级单位-科技部门-负责人 | X31: 年度 | Y31: 抽查 | AA31: 年度 | AB31: 抽查 | AH31: 是 | AI31: 是 | AJ31: 《国家电网有限公司科技项目管理办法》国家电网企管〔2024〕71号 《国家电网有限公司总部管理科技项目实施工作指南(2026年版)》 《国家电网有限公司总部管理科技项目实施及验收管理细则》国家电网企管〔2024〕71号 《中央企业违规经营投资责任追究实施办法》国务院国资委令第46号 《国网湖南省电力有限公司关于印发进一步加强科技项目全过程管理具体举措》湘电公司科〔2025〕239号 | AK31: 国网科技部 | AM31: 补充制度 | AN31: =A31=[2]数字化与研发投入!A31 -> TRUE | AO31: =B31=[2]数字化与研发投入!B31 -> TRUE | AP31: =C31=[2]数字化与研发投入!C31 -> TRUE | AQ31: =D31=[2]数字化与研发投入!D31 -> TRUE | AR31: =E31=[2]数字化与研发投入!E31 -> TRUE | AS31: =F31=[2]数字化与研发投入!F31 -> TRUE | AT31: =G31=[2]数字化与研发投入!G31 -> TRUE | AU31: =H31=[2]数字化与研发投入!H31 -> TRUE | ... BX31: =AK31=[2]数字化与研发投入!AK31 -> TRUE
D32: 成本入账 | E32: 成本入账与进度结算金额不符，项目审核缺位，易引发提前或滞后确认项目成本风险。 | F32: 5.会计信息不准确：存在虚增隐瞒收入、虚增减成本费用、隐瞒负债、少计应付账款或借款、收入成本不匹配、收入和成本确认不及时或不准确等问题。 25.结算不准确，多结算工程款：存在费用多计（甲供物资、施工费、监理费、监造费、设计费、其他费用及税金等定额套用错误）、工程保险费等费用重复计列、部分服务内容（可研、设计、结算等）未全部开展但全额计列费用、无正当理由变更初始合同计价规则并调增劳务分包费、重复结算人工费用、超标准列支人工费和外委研究支出等问题。 | G32: 10.入账成本准确性 | H32: 报账金额准确性、成本支出真实性 | I32: 科技项目管理业务-10.入账成本准确性-控制措施01 | J32: 项目承担部门严格按合同约定管控项目执行进度，根据实际进度办理入账流程。 | M32: √ | O32: √ | P32: √ | T32: 系统已建 | U32: 智慧共享财务平台 | V32: 1.报账单； 2.合同； 3.进度确认单； 4.技术合同相关登记、认定材料。 | W32: 各级单位-科技项目承担部门-项目负责人、各级单位-科技项目承担部门-负责人、各级单位-科技部门-管理人员、各级单位-科技部门-负责人、各级单位-财务部门-成本管理人员、各级单位-财务部门-负责人 | X32: 每月 | Y32: 全量检查 | AA32: 每月 | AB32: 全量检查 | AD32: 在报账单提交环节，检查报账金额与项目实际结算金额、发票金额是否一致；若不一致，系统自动预警并反馈经办人，经办人修改后可重新提交。 | AE32: 实时 | AF32: 全量检查 | AH32: 是 | AI32: 是 | AJ32: 《研发经费投入统计与核算管理规范》国家电网财〔2025〕25 号 《国家电网公司研究开发费财务管理办法》国家电网企管〔2014〕742号 《国家电网公司科技预算项目实施细则》国家电网企管（2017）1066号 《国网湖南省电力有限公司关于印发进一步加强科技项目全过程管理具体举措》湘电公司科〔2025〕239号 | AK32: 国网科技部、国网 财务部 | AM32: 补充制度 | AN32: =A32=[2]数字化与研发投入!A32 -> TRUE | AO32: =B32=[2]数字化与研发投入!B32 -> TRUE | AP32: =C32=[2]数字化与研发投入!C32 -> TRUE | AQ32: =D32=[2]数字化与研发投入!D32 -> TRUE | AR32: =E32=[2]数字化与研发投入!E32 -> TRUE | AS32: =F32=[2]数字化与研发投入!F32 -> TRUE | AT32: =G32=[2]数字化与研发投入!G32 -> TRUE | AU32: =H32=[2]数字化与研发投入!H32 -> TRUE | ... BX32: =AK32=[2]数字化与研发投入!AK32 -> TRUE
I33: 科技项目管理业务-10.入账成本准确性-控制措施02 | J33: 项目承担部门负责核查研发费用明细，杜绝研发费用与日常经费混淆列支、规范专家咨询费等人工成本按标准列支、审核专利费用承担主体与合同约定完全一致。 | M33: √ | O33: √ | T33: 线下管控 | V33: 项目费用支出明细清单及相关资料。 | W33: 各级单位-科技项目承担部门-项目负责人、各级单位-科技项目承担部门-负责人、各级单位-科技部门-管理人员、各级单位-科技部门-负责人 | X33: 每月 | Y33: 全量检查 | AA33: 每月 | AB33: 全量检查 | AH33: 是 | AI33: 是 | AJ33: 《研发经费投入统计与核算管理规范》国家电网财〔2025〕25 号 《国家电网公司研究开发费财务管理办法》国家电网企管〔2014〕742号 《国家电网公司科技预算项目实施细则》国家电网企管（2017）1066号 《国网湖南省电力有限公司关于印发进一步加强科技项目全过程管理具体举措》湘电公司科〔2025〕239号 | AK33: 国网科技部、国网 财务部 | AM33: 补充制度 | AN33: =A33=[2]数字化与研发投入!A33 -> TRUE | AO33: =B33=[2]数字化与研发投入!B33 -> TRUE | AP33: =C33=[2]数字化与研发投入!C33 -> TRUE | AQ33: =D33=[2]数字化与研发投入!D33 -> TRUE | AR33: =E33=[2]数字化与研发投入!E33 -> TRUE | AS33: =F33=[2]数字化与研发投入!F33 -> TRUE | AT33: =G33=[2]数字化与研发投入!G33 -> TRUE | AU33: =H33=[2]数字化与研发投入!H33 -> TRUE | ... BX33: =AK33=[2]数字化与研发投入!AK33 -> TRUE
I34: 科技项目管理业务-10.入账成本准确性-控制措施03 | J34: 财务部门对成本报账单金额与结算金额、发票金额一致性、合规性，列支范围准确性进行审核。 | N34: √ | O34: √ | P34: √ | Q34: √ | T34: 系统已建 | U34: 智慧共享财务平台 | V34: 发票、报账单、合同、服务确认单。 | W34: 各级单位-科技项目承担部门-项目负责人、各级单位-科技项目承担部门-负责人、各级单位-科技部门-管理人员、各级单位-财务部门-成本管理人员 | X34: 每月 | Y34: 全量检查 | AA34: 每月 | AB34: 全量检查 | AD34: 在报账单入账审核环节，检查报账金额与项目实际结算金额、发票金额是否一致；若不一致，系统自动预警并反馈经办人，经办人修改后可重新提交。 | AE34: 实时 | AF34: 全量检查 | AH34: 是 | AI34: 是 | AJ34: 《研发经费投入统计与核算管理规范》国家电网财〔2025〕25 号 《国家电网公司研究开发费财务管理办法》国家电网企管〔2014〕742号 《国家电网公司科技预算项目实施细则》国家电网企管（2017）1066号 《国网湖南省电力有限公司关于印发进一步加强科技项目全过程管理具体举措》湘电公司科〔2025〕239号 | AK34: 国网科技部、国网 财务部 | AM34: 补充制度 | AN34: =A34=[2]数字化与研发投入!A34 -> TRUE | AO34: =B34=[2]数字化与研发投入!B34 -> TRUE | AP34: =C34=[2]数字化与研发投入!C34 -> TRUE | AQ34: =D34=[2]数字化与研发投入!D34 -> TRUE | AR34: =E34=[2]数字化与研发投入!E34 -> TRUE | AS34: =F34=[2]数字化与研发投入!F34 -> TRUE | AT34: =G34=[2]数字化与研发投入!G34 -> TRUE | AU34: =H34=[2]数字化与研发投入!H34 -> TRUE | ... BX34: =AK34=[2]数字化与研发投入!AK34 -> TRUE
C35: 资金资产安全、税务合规 | D35: 研发加计扣除 | E35: 加计扣除项目界定不准确，导致公司面临税务合规风险。 | G35: 11.研发项目加计扣除合规性 | H35: 研发支出加计扣除准确性、合规性。 | I35: 科技项目管理业务-11.研发项目加计扣除合规性-控制措施01 | J35: 项目承担部门对项目是否属于新技术、新产品、新工艺等符合条件的研发活动进行判断，为准确申报研发费用加计扣除提供依据。 | M35: √ | O35: √ | T35: 线下管控 | V35: 1.任务书； 2.合同； 3.发票； 4.技术合同相关登记、认定材料； 5.研发成果佐证资料； 6.关联交易明细账。 | W35: 各级单位-科技项目承担部门-项目负责人、各级单位-科技部门-管理人员 | X35: 每季度 | Y35: 抽查 | AA35: 每季度 | AB35: 抽查 | AH35: 是 | AI35: 是 | AJ35: 《研发费用加计扣除政策执行指引（2.0版）》 《国家电网公司研究开发费财务管理办法》国家电网企管〔2014〕742号 | AK35: 国网科技部、国网 财务部 | AN35: =A35=[2]数字化与研发投入!A35 -> TRUE | AO35: =B35=[2]数字化与研发投入!B35 -> TRUE | AP35: =C35=[2]数字化与研发投入!C35 -> TRUE | AQ35: =D35=[2]数字化与研发投入!D35 -> TRUE | AR35: =E35=[2]数字化与研发投入!E35 -> TRUE | AS35: =F35=[2]数字化与研发投入!F35 -> TRUE | AT35: =G35=[2]数字化与研发投入!G35 -> TRUE | AU35: =H35=[2]数字化与研发投入!H35 -> TRUE | ... BX35: =AK35=[2]数字化与研发投入!AK35 -> TRUE
I36: 科技项目管理业务-11.研发项目加计扣除合规性-控制措施02 | J36: 项目承担部门负责提供研发成果佐证资料和技术合同相关登记、认定材料。 | M36: √ | O36: √ | T36: 线下管控 | V36: 1.任务书； 2.合同； 3.发票； 4.技术合同相关登记、认定材料； 5.研发成果佐证资料； 6.关联交易明细账。 | W36: 各级单位-科技项目承担部门-项目负责人 | X36: 每季度 | Y36: 抽查 | AA36: 每季度 | AB36: 抽查 | AH36: 是 | AI36: 是 | AJ36: 《研发费用加计扣除政策执行指引（2.0版）》 《国家电网公司研究开发费财务管理办法》国家电网企管〔2014〕742号 | AK36: 国网科技部、国网 财务部 | AN36: =A36=[2]数字化与研发投入!A36 -> TRUE | AO36: =B36=[2]数字化与研发投入!B36 -> TRUE | AP36: =C36=[2]数字化与研发投入!C36 -> TRUE | AQ36: =D36=[2]数字化与研发投入!D36 -> TRUE | AR36: =E36=[2]数字化与研发投入!E36 -> TRUE | AS36: =F36=[2]数字化与研发投入!F36 -> TRUE | AT36: =G36=[2]数字化与研发投入!G36 -> TRUE | AU36: =H36=[2]数字化与研发投入!H36 -> TRUE | ... BX36: =AK36=[2]数字化与研发投入!AK36 -> TRUE
A37: 科技项目管理业务 | B37: 二、项目实施管理 | C37: 资金资产安全、税务合规 | D37: 研发加计扣除 | E37: 加计扣除项目界定不准确，导致公司面临税务合规风险。 | G37: 11.研发项目加计扣除合规性 | I37: 科技项目管理业务-11.研发项目加计扣除合规性-控制措施03 | J37: 财务部门根据政府科技主管部门出具的技术合同相关登记、认定材料和第三方审计机构出具的专项鉴定报告，对研发加计扣除金额进行复核计算。 | M37: √ | O37: √ | T37: 系统已建 | U37: 智慧共享财务平台 | V37: 1.任务书； 2.合同； 3.发票； 4.技术合同相关登记、认定材料； 5.研发成果佐证资料； 6.关联交易明细账。 | W37: 各级单位-财务部门-税务管理人员、各级单位-财务部门-负责人 | X37: 每季度 | Y37: 抽查 | AA37: 每季度 | AB37: 抽查 | AD37: 建立研发项目准确合规享受加计扣除监督场景，加计扣除整体情况及明细进行监督展示。 | AE37: 每月 | AF37: 抽查 | AH37: 是 | AI37: 是 | AJ37: 《研发费用加计扣除政策执行指引（2.0版）》 《国家电网公司研究开发费财务管理办法》国家电网企管〔2014〕742号 | AK37: 国网科技部、国网 财务部 | AN37: =A37=[2]数字化与研发投入!A37 -> TRUE | AO37: =B37=[2]数字化与研发投入!B37 -> TRUE | AP37: =C37=[2]数字化与研发投入!C37 -> TRUE | AQ37: =D37=[2]数字化与研发投入!D37 -> TRUE | AR37: =E37=[2]数字化与研发投入!E37 -> TRUE | AS37: =F37=[2]数字化与研发投入!F37 -> TRUE | AT37: =G37=[2]数字化与研发投入!G37 -> TRUE | AU37: =H37=[2]数字化与研发投入!H37 -> TRUE | ... BX37: =AK37=[2]数字化与研发投入!AK37 -> TRUE
C38: 会计信息真实完整 | D38: 研发投入统计 | E38: 研发费用与生产、管理费用边界模糊，未通过“研发支出”科目核算，存在研发投入统计不准确风险。 | F38: 43.研究开发项目关键环节管控不严：存在研究开发项目项目自主度不高，外委比例过高；研发经费统计不精准；科研经费列支不正确；采取组装、集成、套牌贴牌等手段，虚假完成攻关任务等问题。 | G38: 12.研发费用核算与分摊准确性 | H38: 研发投入核算准确性、规范性。 | I38: 科技项目管理业务-12.研发费用核算与分摊准确性-控制措施01 | J38: 各项目承担部门根据项目立项信息及实际情况，负责识别本专业管理项目的研发属性，并对合理性负责，维护“研发项目分类”“学科领域及研究方向”数据标签。 | M38: √ | T38: 系统已建 | U38: 智慧共享财务平台 科技创新综合服务管理平台 | V38: 1.各类项目清单； 2.项目建议书或可研报告； 3.任务书。 | W38: 各级单位-科技项目承担部门-项目负责人 | X38: 年度 | Y38: 全量检查 | AA38: 年度 | AB38: 全量检查 | AD38: 预算发布校验研发投入相关字段必填性。 | AE38: 年度 | AF38: 全量检查 | AH38: 是 | AI38: 是 | AJ38: 《研发经费投入统计与核算管理规范》国家电网财〔2025〕25 号 《中央企业违规经营投资责任追究实施办法》国务院国资委令第46号 《国网湖南省电力有限公司关于进一步做好研发经费投入统计与核算管理工作》湘电公司财〔2025〕126号 | AK38: 国网科技部、国网 财务部 | AM38: 补充制度 | AN38: =A38=[2]数字化与研发投入!A38 -> TRUE | AO38: =B38=[2]数字化与研发投入!B38 -> TRUE | AP38: =C38=[2]数字化与研发投入!C38 -> TRUE | AQ38: =D38=[2]数字化与研发投入!D38 -> TRUE | AR38: =E38=[2]数字化与研发投入!E38 -> TRUE | AS38: =F38=[2]数字化与研发投入!F38 -> TRUE | AT38: =G38=[2]数字化与研发投入!G38 -> TRUE | AU38: =H38=[2]数字化与研发投入!H38 -> TRUE | ... BX38: =AK38=[2]数字化与研发投入!AK38 -> TRUE
I39: 科技项目管理业务-12.研发费用核算与分摊准确性-控制措施02 | J39: 对项目管理部门科技研发投入统计不实，虚列虚报研发投入的，依照中央企业违规经营投资管理办法追究责任。 | S39: √ | T39: 线下管控 | V39: 1.各类项目清单； 2.项目建议书或可研报告； 3.任务书。 | W39: 各级单位-科技部门-管理人员、各级单位-科技部门-负责人 | X39: 年度 | Y39: 全量检查 | AA39: 年度 | AB39: 全量检查 | AH39: 是 | AI39: 是 | AJ39: 《研发经费投入统计与核算管理规范》国家电网财〔2025〕25 号 《中央企业违规经营投资责任追究实施办法》国务院国资委令第46号 《国网湖南省电力有限公司关于进一步做好研发经费投入统计与核算管理工作》湘电公司财〔2025〕126号 | AK39: 国网科技部、国网 财务部 | AM39: 补充制度 | AN39: =A39=[2]数字化与研发投入!A39 -> TRUE | AO39: =B39=[2]数字化与研发投入!B39 -> TRUE | AP39: =C39=[2]数字化与研发投入!C39 -> TRUE | AQ39: =D39=[2]数字化与研发投入!D39 -> TRUE | AR39: =E39=[2]数字化与研发投入!E39 -> TRUE | AS39: =F39=[2]数字化与研发投入!F39 -> TRUE | AT39: =G39=[2]数字化与研发投入!G39 -> TRUE | AU39: =H39=[2]数字化与研发投入!H39 -> TRUE | ... BX39: =AK39=[2]数字化与研发投入!AK39 -> TRUE
D40: 研发项目核算 | E40: 各级统一管理的科技项目，牵头方、受托方、委托方项目信息不一致，可能导致项目投入统计不准确。 | G40: 13.内部受托研发项目三方信息一致性控制 | H40: 内部受托项目牵头方、委托方、受托方项目信息的一致性。 | I40: 科技项目管理业务-13.内部受托研发项目三方信息一致性-控制措施01 | J40: 牵头方单位负责牵头创建内部受委托项目，并建立内部项目管理共享机制，项目同步传递至受托方并系统控制，受托方不再单独建项。 | M40: √ | O40: √ | P40: √ | Q40: √ | T40: 系统已建 | U40: 科技创新综合服务管理平台 | V40: 1.科技创新综合服务管理平台项目台账； 2.项目可研批复； 3.项目任务书及合同。 | W40: 各级单位-科技项目承担部门-项目负责人、各级单位-科技部门-管理人员 | X40: 每季度 | Y40: 全量检查 | AA40: 每季度 | AB40: 全量检查 | AD40: 建立内部受委托方项目关联关系，通过牵头方项目可穿透查询受委托方项目及项目的结算、牵头方项目编码自动关联形成协同单据及凭证，对项目信息的一致性进行提示。 | AE40: 每年 | AF40: 全量检查 | AH40: 是 | AI40: 是 | AJ40: 《研发经费投入统计与核算管理规范》国家电网财〔2025〕25 号 《国网湖南省电力有限公司关于进一步做好研发经费投入统计与核算管理工作》湘电公司财〔2025〕126号 | AK40: 国网科技部 | AM40: 补充制度 | AN40: =A40=[2]数字化与研发投入!A40 -> TRUE | AO40: =B40=[2]数字化与研发投入!B40 -> TRUE | AP40: =C40=[2]数字化与研发投入!C40 -> TRUE | AQ40: =D40=[2]数字化与研发投入!D40 -> TRUE | AR40: =E40=[2]数字化与研发投入!E40 -> TRUE | AS40: =F40=[2]数字化与研发投入!F40 -> TRUE | AT40: =G40=[2]数字化与研发投入!G40 -> TRUE | AU40: =H40=[2]数字化与研发投入!H40 -> TRUE | ... BX40: =AK40=[2]数字化与研发投入!AK40 -> TRUE
...

Sheet Sheet1
A1: 1、 | B1: 数字化项目管理业务-1.储备立项的程序控制-控制措施05 | C1: 归口管理部门对需求统筹进行评审。新建信息系统（功能模块）的设计开发类需求需进行需求论证 | D1: =A1&B1&C1 -> 1、数字化项目管理业务-1.储备立项的程序控制-控制措施05归口管理部门对需求统筹进行评审。新建信息系统（功能模块）的设计开发类需求需进行需求论证 | G1: 1、数字化项目管理业务-1.储备立项的程序控制-控制措施05归口管理部门对需求统筹进行评审。新建信息系统（功能模块）的设计开发类需求需进行需求论证 2、科技项目管理业务-15科研成果权属保护有效性-控制措施04科技部门对知识产权的价值进行定期评估，对低价值专利定期放弃维护。
A2: 2、 | B2: 科技项目管理业务-15科研成果权属保护有效性-控制措施04 | C2: 科技部门对知识产权的价值进行定期评估，对低价值专利定期放弃维护。 | D2: =A2&B2&C2 -> 2、科技项目管理业务-15科研成果权属保护有效性-控制措施04科技部门对知识产权的价值进行定期评估，对低价值专利定期放弃维护。
C6: A
A7: 3、 | B7: 数字化项目管理业务-1.储备立项的程序控制-控制措施03
A8: 6、 | B8: 数字化项目管理业务-2.计划预算安排合规性-控制措施01 | C8: 《国网湖南省电力有限公司数字化项目管理实施细则》（湘电公司数字〔2024〕447号 ） | F8: 1、 | G8: 《国网湖南省电力有限公司数字化项目管理实施细则》（湘电公司数字〔2024〕447号 ） | H8: =F8&G8 -> 1、《国网湖南省电力有限公司数字化项目管理实施细则》（湘电公司数字〔2024〕447号 ） | J8: 1、《国网湖南省电力有限公司数字化项目管理实施细则》（湘电公司数字〔2024〕447号 ） 2、《关于进一步加强数字化项目验收管理的通知（试行）》 3、《国网湖南省电力有限公司关于加强 数字化项目前期管理的指导意见（试行）》 4、 5、 6、 7、 8、 9、
A9: 12、 | B9: 数字化项目管理业务-6.项目验收质量-控制措施02 | C9: 《关于进一步加强数字化项目验收管理的通知（试行）》 | F9: 2、 | G9: 《关于进一步加强数字化项目验收管理的通知（试行）》 | H9: =F9&G9 -> 2、《关于进一步加强数字化项目验收管理的通知（试行）》
A10: 5、 | B10: 数字化项目管理业务-1.储备立项的程序控制-控制措施05 | C10: 《国网湖南省电力有限公司关于加强 数字化项目前期管理的指导意见（试行）》 | F10: 3、 | G10: 《国网湖南省电力有限公司关于加强 数字化项目前期管理的指导意见（试行）》 | H10: =F10&G10 -> 3、《国网湖南省电力有限公司关于加强 数字化项目前期管理的指导意见（试行）》
A11: 1、 | B11: 数字化项目管理业务-1.储备立项的程序控制-控制措施01 | F11: 4、 | H11: =F11&G11 -> 4、
A12: 2、 | B12: 数字化项目管理业务-1.储备立项的程序控制-控制措施02 | F12: 5、 | H12: =F12&G12 -> 5、
A13: 4、 | B13: 数字化项目管理业务-1.储备立项的程序控制-控制措施04 | F13: 6、 | H13: =F13&G13 -> 6、
A14: 9、 | B14: 数字化项目管理业务-3.入账成本准确性-控制措施01 | F14: 7、 | H14: =F14&G14 -> 7、
A15: 10、 | B15: 数字化项目管理业务-3.入账成本准确性-控制措施02 | F15: 8、 | H15: =F15&G15 -> 8、
A16: 11、 | B16: 数字化项目管理业务-6.项目验收质量-控制措施01 | F16: 9、 | H16: =F16&G16 -> 9、
A23: 1、 | B23: 数字化项目管理业务-4.专业分包比例合规性-控制措施03 | C23: 归口管理部门建立“总包-分包”合同穿透链路，通过合同与项目的关联查看总包单位为系统内单位的业主单位、总包单位、分包单位的对应关系。 数字化部负责落实公司电网数字化项目分包管理制度，建立健全本单位电网数字化项目分包管理机制。 | D23: =A23&B23&C23 -> 1、数字化项目管理业务-4.专业分包比例合规性-控制措施03归口管理部门建立“总包-分包”合同穿透链路，通过合同与项目的关联查看总包单位为系统内单位的业主单位、总包单位、分包单位的对应关系。 数字化部负责落实公司电网数字化项目分包管理制度，建立健全本单位电网数字化项目分包管理机制。 | H23: 1、数字化项目管理业务-4.专业分包比例合规性-控制措施03归口管理部门建立“总包-分包”合同穿透链路，通过合同与项目的关联查看总包单位为系统内单位的业主单位、总包单位、分包单位的对应关系。 数字化部负责落实公司电网数字化项目分包管理制度，建立健全本单位电网数字化项目分包管理机制。 2、数字化项目管理业务-4.专业分包比例合规性-控制措施04归口管理部门建立“总包-分包”人员的穿透链路，核查总包单位为系统内单位的项目团队成员单位信息，分析人员隶属是否遵循合同约定。 数字化部负责本单位电网数字化项目分包工作的督导和检查。 3、数字化项目管理业务-5.资产信息真实性-控制措施02实物管理部门数字化部定期开展实物盘点，核对设备台账与现场实物的一致性。
