Workbook

Sheet 业务流程
A1: 一级流程 | B1: 二级流程 | C1: 三级流程 | D1: 末级流程编号 | E1: 末级流程名称 | F1: 涉及价值管控风险的流程
A2: 市场营销 | B2: 电力市场营销管理 | C2: 有序用电管理 | D2: YX-01-01-01 | E2: 有序用电基础信息管理流程
D3: YX-01-01-02 | E3: 有序用电方案制定流程
D4: YX-01-01-03 | E4: 有序用电预警管理流程
D5: YX-01-01-04 | E5: 有序用电方案实施流程
D6: YX-01-01-05 | E6: 有序用电监督检查管理流程
D7: YX-01-01-06 | E7: 有序用电统计分析管理流程
C8: 市场分析预测管理 | D8: YX-01-02-01 | E8: 短期电力市场分析预测管理流程
D9: YX-01-02-02 | E9: 迎峰度夏（冬）电力供需分析预测管理流程
C10: 能效服务管理 | D10: YX-01-03-01 | E10: 能效服务网络建设运行管理流程
D11: YX-01-03-02 | E11: 能效服务指标管理流程
D12: YX-01-03-03 | E12: 能效服务项目管理流程
C13: 综合能源管理 | D13: YX-01-04-01 | E13: 综合能源服务管理流程 | F13: √
D14: YX-01-04-02 | E14: 需求侧响应管理流程
C15: 自备电厂管理 | D15: YX-01-04-01 | E15: 自备电厂机组并网与电力供应协议管理流程
C16: 智能用电管理 | D16: YX-01-05-01 | E16: 智能充换电服务网络建设项目实施管理流程
D17: YX-01-05-02 | E17: 智能充换电服务网络运营服务管理流程
D18: YX-01-05-03 | E18: 智能充换电服务网络充电设施缺陷管理流程
B19: 营业管理 | C19: 供电营业区管理 | D19: YX-02-01-01 | E19: 供电营业区域管理流程
D20: YX-02-01-02 | E20: 供电营业许可证管理流程
C21: 业扩报装 | D21: YX-02-02-01 | E21: 业扩报装流程与服务要求制定流程 | F21: √
D22: YX-02-02-02 | E22: 220kV及以上业扩报装管理流程
D23: YX-02-02-03 | E23: 110kV业扩报装管理流程
D24: YX-02-02-04 | E24: 35kV业扩报装管理流程
D25: YX-02-02-05 | E25: 10kV业扩报装管理流程
D26: YX-02-02-06 | E26: 低压业扩报装管理流程
D27: YX-02-02-07 | E27: 国家重点工程业扩报装协调管理流程
C28: 变更用电管理 | D28: YX-02-03-01 | E28: 减容管理流程
D29: YX-02-03-02 | E29: 减容恢复管理流程
D30: YX-02-03-03 | E30: 暂停管理流程
D31: YX-02-03-04 | E31: 暂停恢复管理流程
D32: YX-02-03-05 | E32: 暂拆管理流程
D33: YX-02-03-06 | E33: 暂拆复装管理流程
D34: YX-02-03-07 | E34: 暂换管理流程
D35: YX-02-03-08 | E35: 暂换恢复管理流程
D36: YX-02-03-09 | E36: 迁址管理流程
D37: YX-02-03-10 | E37: 移表管理流程
D38: YX-02-03-11 | E38: 销户管理流程
D39: YX-02-03-12 | E39: 过户管理流程
D40: YX-02-03-13 | E40: 更名管理流程
...

Sheet 流程图

Sheet 迁改工程管理（0818）
A1: 风控矩阵—迁改工程管理
A2: 业务条线 | B2: 业务领域 | C2: 控制目标 | D2: 业务流程步骤 | E2: 经营风险 | F2: 典型问题 | G2: 关键控制点 | H2: 控制要求 | I2: 控制措施编号 | J2: 控制措施 | K2: 控制措施分类 | T2: 控制方式 | U2: 控制系统 | V2: 控制载体 | W2: 责任主体 | X2: 业务自评价 | AA2: 集团监督评价 | AD2: 数字化监督场景 | AH2: 现有制度及文件落实情况 | AK2: 总部审核部门 | BW2: 省公司部门 | BX2: 对应岗位1 | BY2: 三级单位 | BZ2: 对应岗位2 | CA2: 四级单位 | CB2: 对应岗位3
K3: 不相容岗位 | L3: 分级授权 | M3: 业务真实性控制 | N3: 预算管控 | O3: 合同控制 | P3: 收付控制 | Q3: 会计监督 | R3: 财产保护 | S3: 分析与评价 | X3: 评价频率 | Y3: 评价范围 | Z3: 评价结论 | AA3: 评价频率 | AB3: 评价范围 | AC3: 评价结论 | AD3: 数字化监督场景 | AE3: 评价频率 | AF3: 评价范围 | AG3: 评价结论 | AH3: 是否已要求 | AI3: 是否满足要求 | AJ3: 对应制度及文件名称
A4: 迁改工程管理 | B4: 一、方案编制与审批 | C4: 资金资产安全 | D4: 资产估值 | E4: 未在方案审批结束前完成资产评估工作，导致所获补偿金额低于被迁改资产评估价值。 | G4: 1.被迁改资产价值控制 | H4: 资产估值报告完整、准确。 | I4: 迁改工程管理-1.被迁改资产价值控制-控制措施01 | J4: 省公司牵头部门应建立健全《迁改工程管理办法》，明确职责分工、补偿模式、合同签订、资金收支等管控要点，防范垫支风险。 | O4: √ | P4: √ | T4: 线下管控 | V4: 《迁改工程管理办法》 《国网湖南省电力有限公司电力线路杆迁管理办法》 | W4: 省公司-牵头部门-迁改工程管理人员 | AH4: 否 | AI4: 否 | AJ4: 《迁改工程管理办法》 《国网湖南省电力有限公司电力线路杆迁管理办法》 | AK4: 国网发展部、国网设备部、国网财务部 | AL4: =A4=[2]迁改工程管理!A4 -> TRUE | AM4: =B4=[2]迁改工程管理!B4 -> TRUE | AN4: =C4=[2]迁改工程管理!C4 -> TRUE | AO4: =D4=[2]迁改工程管理!D4 -> TRUE | AP4: =E4=[2]迁改工程管理!E4 -> TRUE | AQ4: =F4=[2]迁改工程管理!F4 -> TRUE | AR4: =G4=[2]迁改工程管理!G4 -> TRUE | AS4: =H4=[2]迁改工程管理!H4 -> TRUE | ... BV4: =AK4=[2]迁改工程管理!AK4 -> TRUE | BW4: 省公司设备部 | BX4: 省公司设备部:杆迁管理专责 | BY4: 无 | BZ4: 无 | CA4: 无 | CB4: 无
I5: 迁改工程管理-1.被迁改资产价值控制-控制措施02 | J5: 如存在异地实物补偿等需要进行资产评估情况，各级单位迁改管理部门应按照管理要求，对需聘请第三方机构出具鉴定报告的迁改资产，应组织开展鉴定工作，及时向第三方机构提供经济行为决策依据、资产权属证明、相关合同等资料。 | R5: √ | T5: 线下管控 | V5: 1.资产估值报告； 2.被拆资产卡片的清单。 | W5: 各级单位-设备部门-设备资产管理人员 | X5: 年度 | Y5: 抽查 | AA5: 年度 | AB5: 抽查 | AH5: 是 | AI5: 是 | AJ5: 《国家电网有限公司资产评估管理办法》（国家电网企管〔2025〕360号）第三章 | AK5: 国网设备部 | AL5: =A5=[2]迁改工程管理!A5 -> TRUE | AM5: =B5=[2]迁改工程管理!B5 -> TRUE | AN5: =C5=[2]迁改工程管理!C5 -> TRUE | AO5: =D5=[2]迁改工程管理!D5 -> TRUE | AP5: =E5=[2]迁改工程管理!E5 -> TRUE | AQ5: =F5=[2]迁改工程管理!F5 -> TRUE | AR5: =G5=[2]迁改工程管理!G5 -> TRUE | AS5: =H5=[2]迁改工程管理!H5 -> TRUE | ... BV5: =AK5=[2]迁改工程管理!AK5 -> TRUE | BW5: 省公司设备部、财务部 | BX5: 1.省公司设备部:杆迁管理专责; 2.省公司财务部：资产产权管理岗。 | BY5: 1.地市公司：市公司运检部、配电部、财务部； 2.省超输公司：运检部、财务部。 | BZ5: 1.市公司运检部：杆迁管理专责； 2.市公司配电部：配网技术管理专责； 3.市公司财务部：资产产权管理专责； 4.省超输公司运检部：实物资产管理专责。 5.省超输公司财务部：资产与保险管理专责。 | CA5: 1.区县公司：电网技术部、财务部； 2.市检修公司（输电检修公司、电缆检修公司）：无； 3.省超输公司分部：无。 | CB5: 1.区县公司电网技术部：大修技改管理专责； 2.区县公司财务部：工程资产财务管理专责。
I6: 迁改工程管理-1.被迁改资产价值控制-控制措施03 | J6: 各级单位财务部门复核第三方机构鉴定报告的资产范围与拆旧资产范围是否一致，估值方法是否准确。 | Q6: √ | R6: √ | S6: √ | T6: 线下管控 | V6: 1.资产估值报告； 2.被拆资产卡片的清单。 | W6: 各级单位-财务部门-资产管理人员 | X6: 年度 | Y6: 抽查 | AA6: 年度 | AB6: 抽查 | AH6: 是 | AI6: 是 | AJ6: 《国家电网有限公司资产评估管理办法》（国家电网企管〔2025〕360号）第三章 | AK6: 国网财务部 | AL6: =A6=[2]迁改工程管理!A6 -> TRUE | AM6: =B6=[2]迁改工程管理!B6 -> TRUE | AN6: =C6=[2]迁改工程管理!C6 -> TRUE | AO6: =D6=[2]迁改工程管理!D6 -> TRUE | AP6: =E6=[2]迁改工程管理!E6 -> TRUE | AQ6: =F6=[2]迁改工程管理!F6 -> TRUE | AR6: =G6=[2]迁改工程管理!G6 -> TRUE | AS6: =H6=[2]迁改工程管理!H6 -> TRUE | ... BV6: =AK6=[2]迁改工程管理!AK6 -> TRUE | BW6: 省公司财务部 | BX6: 省公司财务部:资产产权管理岗 | BY6: 1.地市公司：市公司财务部； 2.省超输公司：财务部。 | BZ6: 1.市公司财务部：资产产权管理专责； 2.省超输公司财务部：资产与保险管理专责。 | CA6: 区县公司：财务部； 检修公司：/； 省超输公司分部：/。 | CB6: 1.区县公司财务部：工程资产财务管理专责。
D7: 可研编制及审批 | E7: 迁改可研方案编制不合理，不能满足电网发展要求，不符合国家、行业、公司标准规定，影响电网稳定运行。 | F7: 32.迁改工程管理不规范：存在未签合同，垫资实施；迁改工程款未足额回收；未按规定履行迁改批复、审批程序；未按规定办理环评水保、林农地占用手续，存在停工、惩罚等风险；迁改工程废旧物资未回收；迁改移交资产未建卡入账；迁改协议未明确资产归属等问题。 | G7: 2.电网功能适应性控制 | H7: 杆迁工程应严格履行批复、审批程序，包含红线规划、设计方案、环评水保等，迁改后资产不低于原有容量、标准，匹配现有架构。。 | I7: 迁改工程管理-2.电网功能适应性控制-控制措施01 | J7: 各级单位迁改工程项目管理部门建立迁改工程方案分级审批机制。 | L7: √ | T7: 线下管控 | V7: 1、方案评审意见； 2、方案批复； 3.迁改申请； 4.会商意见或会议纪要等（若有）。 | W7: 各级单位-迁改工程项目管理部门-技术管理人员 | X7: 年度 | Y7: 抽查 | AA7: 年度 | AB7: 抽查 | AH7: 否 | AK7: 国网发展部、国网设备部、国网基建部 | AL7: =A7=[2]迁改工程管理!A7 -> TRUE | AM7: =B7=[2]迁改工程管理!B7 -> TRUE | AN7: =C7=[2]迁改工程管理!C7 -> TRUE | AO7: =D7=[2]迁改工程管理!D7 -> TRUE | AP7: =E7=[2]迁改工程管理!E7 -> TRUE | AQ7: =F7=[2]迁改工程管理!F7 -> FALSE | AR7: =G7=[2]迁改工程管理!G7 -> TRUE | AS7: =H7=[2]迁改工程管理!H7 -> FALSE | ... BV7: =AK7=[2]迁改工程管理!AK7 -> TRUE | BW7: 省公司发展部、设备部 | BX7: 1.省公司设备部：输电检修专责； 2.省公司发展部：项目可研核准管理岗。 | BY7: 1.地市公司：市公司运检部、配电部、发策部 2.省超输公司：运检部。 | BZ7: 1.市公司运检部：杆迁管理专责； 2.市公司配电部：配网技术管理专责； 3.市公司发策部：主网规划专责； 4.省超输公司运检部：检修组组长兼杆线迁移、停电检修专责。 | CA7: 1.区县公司：电网技术部； 2.市检修公司（输电检修公司、电缆检修公司）：无； 3.省超输公司分部：无。 | CB7: 1.区县公司电网技术部：大修技改管理专责。
I8: 迁改工程管理-2.电网功能适应性控制-控制措施02 | J8: 各级单位迁改工程项目管理部门，组织相关部门开展审查新建资产设计方案是否落实国网公司输变电工程通用设计、标准物料、反事故措施及公司相关技术标准等要求。 | R8: √ | T8: 线下管控 | V8: 估（概）算表 迁改项目可研报告及批复 | W8: 各级单位-迁改工程项目管理部门-技术管理人员 | X8: 年度 | Y8: 抽查 | AA8: 年度 | AB8: 抽查 | AH8: 否 | AK8: 国网发展部、国网设备部、国网基建部 | AL8: =A8=[2]迁改工程管理!A8 -> TRUE | AM8: =B8=[2]迁改工程管理!B8 -> TRUE | AN8: =C8=[2]迁改工程管理!C8 -> TRUE | AO8: =D8=[2]迁改工程管理!D8 -> TRUE | AP8: =E8=[2]迁改工程管理!E8 -> TRUE | AQ8: =F8=[2]迁改工程管理!F8 -> TRUE | AR8: =G8=[2]迁改工程管理!G8 -> TRUE | AS8: =H8=[2]迁改工程管理!H8 -> TRUE | ... BV8: =AK8=[2]迁改工程管理!AK8 -> TRUE | BW8: 省公司设备部 | BX8: 省公司设备部:杆迁管理专责 | BY8: 1.地市公司：市公司运检部、配电部； 2.省超输公司：运检部。 | BZ8: 1.市公司运检部：杆迁管理专责； 2.市公司配电部：配网技术管理专责； 3.省超输公司运检部：检修组组长兼杆线迁移、停电检修专责。 | CA8: 1.区县公司：电网技术部； 2.市检修公司（输电检修公司、电缆检修公司）：生产技术室； 3.省超输公司分部：无。 | CB8: 1.区县公司电网技术部：大修技改管理专责； 2.市检修公司生产技术室：大修技改管理专责。
I9: 迁改工程管理-2.电网功能适应性控制-控制措施03 | J9: 各级单位对主要技术原则发生改变或造价变化较大的项目重新履行方案编制、审批或设计变更程序。 | S9: √ | T9: 线下管控 | V9: 1.设计变更审批单（实施过程）； 2.迁改项目可研、初设审批表（实施前） 2.技术方案调整后批复 | W9: 各级单位-迁改工程项目管理部门-技术管理人员 | X9: 年度 | Y9: 抽查 | AA9: 年度 | AB9: 抽查 | AH9: 否 | AK9: 国网发展部、国网设备部、国网基建部 | AL9: =A9=[2]迁改工程管理!A9 -> TRUE | AM9: =B9=[2]迁改工程管理!B9 -> TRUE | AN9: =C9=[2]迁改工程管理!C9 -> TRUE | AO9: =D9=[2]迁改工程管理!D9 -> TRUE | AP9: =E9=[2]迁改工程管理!E9 -> TRUE | AQ9: =F9=[2]迁改工程管理!F9 -> TRUE | AR9: =G9=[2]迁改工程管理!G9 -> TRUE | AS9: =H9=[2]迁改工程管理!H9 -> TRUE | ... BV9: =AK9=[2]迁改工程管理!AK9 -> TRUE | BW9: 省公司设备部 | BX9: 省公司设备部：输电检修专责。 | BY9: 1.地市公司：市公司运检部、配电部； 2.省超输公司：运检部。 | BZ9: 1.市公司运检部：杆迁管理专责； 2.市公司配电部：配网技术管理专责； 3.省超输公司运检部：检修组组长兼杆线迁移、停电检修专责。 | CA9: 1.区县公司：电网技术部； 2.市检修公司（输电检修公司、电缆检修公司）：生产技术室； 3.省超输公司分部：无。 | CB9: 1.区县公司电网技术部：大修技改管理专责； 2.市检修公司生产技术室：大修技改管理专责。
I10: 迁改工程管理-2.电网功能适应性控制-控制措施04 | J10: 各单位迁改工程项目管理部门，依照路径变动、占地面积或填挖方情况，组织杆迁工程开展环境影响评价和编制水土保持方案。 | S10: √ | T10: 线下管控 | V10: 1.环境评估报告； 2.水土保持方案。 | W10: 各单位-迁改工程项目管理部门-技术管理岗 | X10: 年度 | Y10: 抽查 | AA10: 年度 | AB10: 抽查 | AH10: 是 | AI10: 是 | AJ10: 《国网湖南电力建设部关于加强电网项目环境影响评价和水土保持方案管理的通知》 | AK10: 国网设备部、国网基建部 | BW10: 省公司设备部、建设部 | BX10: 1.省公司设备部：输电检修专责； 2.省公司建设部：主网迁改工程管理岗。 | BY10: 1.地市公司：市公司运检部、配电部、建设部； 2.省超输公司：运检部。 | BZ10: 1.市公司运检部：杆迁管理专责； 2.市公司建设部：环评水保专责； 3.省超输公司运检部：检修组组长兼杆线迁移、停电检修专责。 | CA10: 1.区县公司：无； 2.市检修公司（输电检修公司、电缆检修公司）：无； 3.省超输公司分部：无。 | CB10: 无
A11: 迁改工程管理 | B11: 二、方案答复及协议签订 | C11: 资金资产安全 | D11: 货币补偿迁改协议签订 | E11: 补偿金额不准确、回收时间不明确，引起资产价值流失。 | F11: 32.迁改工程管理不规范：存在未签合同，垫资实施；迁改工程款未足额回收；未按规定履行迁改批复、审批程序；迁改工程废旧物资未回收；迁改移交资产未建卡入账；迁改协议未明确资产归属等问题。 | G11: 3.补偿金额与回收时间控制 | H11: 补偿金额按拆旧资产估值与新建资产价值孰高确定，回收时间在合同中明确约定。 | I11: 迁改工程管理-3.补偿金额与回收时间控制-控制措施01 | J11: 各级单位牵头管理部门，组织相关部门在合同中明确补偿金额、回收时间、补偿资金到位与项目实施有序衔接的条款。 | O11: √ | P11: √ | R11: √ | T11: 系统待建 | U11: 数字化法治企业建设平台 | V11: 1.迁改协议（合同）； 2.资产估值报告（若有，根据管控要求）； 3.项目可研（初设）批复。 | W11: 各级单位-牵头管理部门-迁改工程管理人员 | X11: 年度 | Y11: 抽查 | AA11: 年度 | AB11: 抽查 | AD11: 迁改工程合同管理-补偿金额回收监督​​ | AE11: 每月 | AF11: 全量检查 | AH11: 否 | AK11: 国网发展部 | AL11: =A11=[2]迁改工程管理!A10 -> TRUE | AM11: =B11=[2]迁改工程管理!B10 -> TRUE | AN11: =C11=[2]迁改工程管理!C10 -> TRUE | AO11: =D11=[2]迁改工程管理!D10 -> TRUE | AP11: =E11=[2]迁改工程管理!E10 -> TRUE | AQ11: =F11=[2]迁改工程管理!F10 -> TRUE | AR11: =G11=[2]迁改工程管理!G10 -> TRUE | AS11: =H11=[2]迁改工程管理!H10 -> TRUE | ... BV11: =AK11=[2]迁改工程管理!AK10 -> TRUE | BW11: 省公司设备部 | BX11: 省公司设备部:杆迁管理专责 | BY11: 1.地市公司：市公司运检部、配电部； 2.省超输公司：运检部。 | BZ11: 1.市公司运检部：杆迁管理专责； 2.市公司配电部：配网技术管理专责； 3.省超输公司运检部：检修组组长兼杆线迁移、停电检修专责。 | CA11: 1.区县公司：电网技术部； 2.市检修公司（输电检修公司、电缆检修公司）：无； 3.省超输公司分部：无。 | CB11: 1.区县公司电网技术部：大修技改管理专责。
I12: 迁改工程管理-3.补偿金额与回收时间控制-控制措施02 | J12: 各级单位牵头管理部门，组织相关部门经优化论证后或现场实施中发生方案变更致使补偿资金发生变动的，履行变更程序后，及时签订补充协议。 | O12: √ | P12: √ | T12: 线下管控 | V12: 1.迁改协议（合同）； 2.补充协议。 | W12: 各级单位-牵头管理部门-迁改工程管理人员 | X12: 年度 | Y12: 抽查 | AA12: 年度 | AB12: 抽查 | AD12: 迁改工程合同管理-补偿金额回收监督​​ | AE12: 每月 | AF12: 全量检查 | AH12: 否 | AK12: 国网发展部 | AL12: =A12=[2]迁改工程管理!A11 -> TRUE | AM12: =B12=[2]迁改工程管理!B11 -> TRUE | AN12: =C12=[2]迁改工程管理!C11 -> TRUE | AO12: =D12=[2]迁改工程管理!D11 -> TRUE | AP12: =E12=[2]迁改工程管理!E11 -> TRUE | AQ12: =F12=[2]迁改工程管理!F11 -> TRUE | AR12: =G12=[2]迁改工程管理!G11 -> TRUE | AS12: =H12=[2]迁改工程管理!H11 -> TRUE | ... BV12: =AK12=[2]迁改工程管理!AK11 -> TRUE | BW12: 省公司设备部：无。 | BX12: 无 | BY12: 1.地市公司：市公司运检部、配电部； 2.省超输公司：运检部。 | BZ12: 1.市公司运检部：杆迁管理专责； 2.市公司配电部：配网技术管理专责； 3.省超输公司运检部：检修组组长兼杆线迁移、停电检修专责。 | CA12: 1.区县公司：电网技术部； 2.市检修公司（输电检修公司、电缆检修公司）：无； 3.省超输公司分部：无。 | CB12: 1.区县公司电网技术部：大修技改管理专责。
I13: 迁改工程管理-3.补偿金额与回收时间控制-控制措施03 | J13: 各级单位财务部门复核合同补偿金额、回收时间、补偿资金到位与项目实施有序衔接的条款。 | Q13: √ | R13: √ | T13: 系统待建 | U13: 数字化法治企业建设平台 | V13: 1.迁改协议（合同）； 2.资产估值报告（若有，根据管控要求）； 3.项目可研（初设）批复。 | W13: 各级单位-财务部门-工程财务人员 | X13: 年度 | Y13: 抽查 | AA13: 年度 | AB13: 抽查 | AD13: 迁改工程合同管理-补偿金额回收监督​​ | AE13: 每月 | AF13: 全量检查 | AH13: 否 | AK13: 国网财务部 | AL13: =A13=[2]迁改工程管理!A12 -> TRUE | AM13: =B13=[2]迁改工程管理!B12 -> TRUE | AN13: =C13=[2]迁改工程管理!C12 -> TRUE | AO13: =D13=[2]迁改工程管理!D12 -> TRUE | AP13: =E13=[2]迁改工程管理!E12 -> TRUE | AQ13: =F13=[2]迁改工程管理!F12 -> TRUE | AR13: =G13=[2]迁改工程管理!G12 -> TRUE | AS13: =H13=[2]迁改工程管理!H12 -> TRUE | ... BV13: =AK13=[2]迁改工程管理!AK12 -> TRUE | BW13: 省公司财务部 | BX13: 省公司财务部:工程核算管理岗 | BY13: 1.地市公司：市公司财务部； 2.省超输公司：财务部。 | BZ13: 1.市公司财务部：非基建工程项目核算管理专责； 2.省超输公司财务部：资本性项目核算管理专责。 | CA13: 区县公司：财务部； 检修公司：/； 省超输公司分部：/。 | CB13: 1.区县公司财务部：工程资产财务管理专责。
C14: 会计会计信息真实完整 | D14: 迁改协议签订 | E14: 未严格区分政府性迁改和商业性迁改，经营成果反映不真实。 | G14: 4.迁改业务类型的审核控制 | H14: 区分资金性质，被迁改资产类型、迁改目的，按对应会计准则核算、规范使用科目。 | I14: 迁改工程管理-4.迁改业务类型的审核控制-控制措施01 | J14: 各级单位牵头管理部门明确迁改资产范围、补偿资金来源、迁改业务动因、新建资产产权归属等内容。 | O14: √ | T14: 线下管控 | V14: 1.迁改协议（合同）； 2.政府相关文件或纪要（若为政策性迁改）； 3.迁改申请表。 | W14: 各级单位-牵头管理部门-迁改工程管理人员 | X14: 年度 | Y14: 抽查 | AA14: 年度 | AB14: 抽查 | AD14: 迁改工程实施管理-核算准确性监督 | AE14: 每月 | AF14: 抽查 | AH14: 否 | AK14: 国网发展部 | AL14: =A14=[2]迁改工程管理!A13 -> TRUE | AM14: =B14=[2]迁改工程管理!B13 -> TRUE | AN14: =C14=[2]迁改工程管理!C13 -> TRUE | AO14: =D14=[2]迁改工程管理!D13 -> TRUE | AP14: =E14=[2]迁改工程管理!E13 -> TRUE | AQ14: =F14=[2]迁改工程管理!F13 -> TRUE | AR14: =G14=[2]迁改工程管理!G13 -> TRUE | AS14: =H14=[2]迁改工程管理!H13 -> TRUE | ... BV14: =AK14=[2]迁改工程管理!AK13 -> TRUE | BW14: 省公司设备部：无。 | BX14: 无 | BY14: 1.地市公司：市公司运检部、配电部； 2.省超输公司：运检部。 | BZ14: 1.市公司运检部：杆迁管理专责； 2.市公司配电部：配网技术管理专责； 3.省超输公司运检部：检修组组长兼杆线迁移、停电检修专责。 | CA14: 1.区县公司：电网技术部； 2.市检修公司（输电检修公司、电缆检修公司）：无； 3.省超输公司分部：无。 | CB14: 1.区县公司电网技术部：大修技改管理专责。
I15: 迁改工程管理-4.迁改业务类型的审核控制-控制措施02 | J15: 各级单位财务部门按照不同补偿方式及资金来源固化通用报账规则，实现精准核算。 | Q15: √ | T15: 系统待建 | U15: 智慧共享财务平台 | V15: 1.迁改协议（合同）； 2.收款凭证； 3.支出凭证。 | W15: 各级单位-财务部门-工程财务人员 | X15: 年度 | Y15: 抽查 | AA15: 年度 | AB15: 抽查 | AD15: 迁改工程实施管理-核算准确性监督 | AE15: 每月 | AF15: 抽查 | AH15: 否 | AK15: 国网财务部 | AL15: =A15=[2]迁改工程管理!A14 -> TRUE | AM15: =B15=[2]迁改工程管理!B14 -> TRUE | AN15: =C15=[2]迁改工程管理!C14 -> TRUE | AO15: =D15=[2]迁改工程管理!D14 -> TRUE | AP15: =E15=[2]迁改工程管理!E14 -> TRUE | AQ15: =F15=[2]迁改工程管理!F14 -> TRUE | AR15: =G15=[2]迁改工程管理!G14 -> TRUE | AS15: =H15=[2]迁改工程管理!H14 -> TRUE | ... BV15: =AK15=[2]迁改工程管理!AK14 -> TRUE | BW15: 省公司财务部：无。 | BX15: 无 | BY15: 1.地市公司：市公司财务部； 2.省超输公司：财务部。 | BZ15: 1.市公司财务部：非基建工程项目核算管理专责； 2.省超输公司财务部：资本性项目核算管理专责。 | CA15: 区县公司：财务部； 检修公司：/； 省超输公司分部：/。 | CB15: 1.区县公司财务部：工程资产财务管理专责。
C16: 资金资产安全 | E16: 归属公司的拆旧资产但未在协议中明确，引起资产价值流失。 | G16: 5.拆旧资产归属控制 | H16: 资产归属及处置方式与协议约定一致。 | I16: 迁改工程管理-5.拆旧资产归属控制-控制措施01 | J16: 各级单位财务部门复核迁改协议中是否载明拆旧资产的归属主体。 | O16: √ | T16: 线下管控 | V16: 迁改协议（合同） | W16: 各级单位-财务部门-工程财务人员 | X16: 年度 | Y16: 抽查 | AA16: 年度 | AB16: 抽查 | AH16: 否 | AK16: 国网财务部 | AL16: =A16=[2]迁改工程管理!A15 -> TRUE | AM16: =B16=[2]迁改工程管理!B15 -> TRUE | AN16: =C16=[2]迁改工程管理!C15 -> TRUE | AO16: =D16=[2]迁改工程管理!D15 -> TRUE | AP16: =E16=[2]迁改工程管理!E15 -> TRUE | AQ16: =F16=[2]迁改工程管理!F15 -> TRUE | AR16: =G16=[2]迁改工程管理!G15 -> TRUE | AS16: =H16=[2]迁改工程管理!H15 -> TRUE | ... BV16: =AK16=[2]迁改工程管理!AK15 -> TRUE | BW16: 省公司财务部：无。 | BX16: 无 | BY16: 1.地市公司：市公司财务部； 2.省超输公司：财务部。 | BZ16: 1.市公司财务部：非基建工程项目核算管理专责； 2.省超输公司财务部：资产与保险管理专责。 | CA16: 区县公司：财务部； 检修公司：/； 省超输公司分部：/。 | CB16: 1.区县公司财务部：工程资产财务管理专责。
A17: 迁改工程管理 | B17: 三、项目实施 | C17: 资金资产安全 | D17: 货币补偿迁改拆旧实施 | E17: 补偿资金到位前开展资产拆旧工作，引起资产价值流失。 | F17: 32.迁改工程管理不规范：存在未签合同，垫资实施；迁改工程款未足额回收；未按规定履行迁改批复、审批程序；迁改工程废旧物资未回收；迁改移交资产未建卡入账；迁改协议未明确资产归属等问题。 | G17: 6.资产拆旧时点控制 | H17: 补偿资金到账后开展拆旧工作。 | I17: 迁改工程管理-6.资产拆旧时点控制-控制措施01 | J17: 各级单位财务部门规范收款凭证的工程名称，核对收款金额与协议（合同）是否一致。 | P17: √ | Q17: √ | T17: 线下管控 | V17: 1.迁改协议（合同）； 2.收款凭证； 3.银行回单。 | W17: 各级单位-财务部门-工程财务人员 | X17: 年度 | Y17: 抽查 | AA17: 年度 | AB17: 抽查 | AD17: 迁改工程实施管理-拆旧实施监督 | AE17: 每月 | AF17: 抽查 | AH17: 否 | AK17: 国网财务部 | AL17: =A17=[2]迁改工程管理!A16 -> TRUE | AM17: =B17=[2]迁改工程管理!B16 -> TRUE | AN17: =C17=[2]迁改工程管理!C16 -> TRUE | AO17: =D17=[2]迁改工程管理!D16 -> TRUE | AP17: =E17=[2]迁改工程管理!E16 -> TRUE | AQ17: =F17=[2]迁改工程管理!F16 -> TRUE | AR17: =G17=[2]迁改工程管理!G16 -> TRUE | AS17: =H17=[2]迁改工程管理!H16 -> TRUE | ... BV17: =AK17=[2]迁改工程管理!AK16 -> TRUE | BW17: 省公司财务部：无。 | BX17: 无 | BY17: 1.地市公司：市公司财务部； 2.省超输公司：财务部。 | BZ17: 1.市公司财务部：非基建工程项目核算管理专责； 2.省超输公司财务部：资本性项目核算管理专责。 | CA17: 区县公司：财务部； 检修公司：/； 省超输公司分部：/。 | CB17: 1.区县公司财务部：工程资产财务管理专责。
I18: 迁改工程管理-6.资产拆旧时点控制-控制措施02 | J18: 各级单位迁改工程项目管理部门明确资金回收后拆旧启动的工作机制，确保拟迁改电力设备停役前补偿金回收到位。 | P18: √ | R18: √ | T18: 系统待建 | U18: 智慧共享财务平台 | V18: 1.迁改协议（合同）； 2.收款凭证； 3.银行回单； 4.固定资产报废审批单。 | W18: 各级单位-牵头管理部门-迁改工程管理人员 | X18: 年度 | Y18: 抽查 | AA18: 年度 | AB18: 抽查 | AD18: 迁改工程实施管理-拆旧实施监督 | AE18: 每月 | AF18: 抽查 | AH18: 否 | AK18: 国网设备部 | AL18: =A18=[2]迁改工程管理!A17 -> TRUE | AM18: =B18=[2]迁改工程管理!B17 -> TRUE | AN18: =C18=[2]迁改工程管理!C17 -> TRUE | AO18: =D18=[2]迁改工程管理!D17 -> TRUE | AP18: =E18=[2]迁改工程管理!E17 -> TRUE | AQ18: =F18=[2]迁改工程管理!F17 -> TRUE | AR18: =G18=[2]迁改工程管理!G17 -> TRUE | AS18: =H18=[2]迁改工程管理!H17 -> TRUE | ... BV18: =AK18=[2]迁改工程管理!AK17 -> TRUE | BW18: 省公司设备部：无。 | BX18: 无 | BY18: 1.地市公司：市公司运检部、配电部； 2.省超输公司：运检部。 | BZ18: 1.市公司运检部：杆迁管理专责； 2.市公司配电部：配网技术管理专责； 3.省超输公司运检部：检修组组长兼杆线迁移、停电检修专责。 | CA18: 1.区县公司：电网技术部； 2.市检修公司（输电检修公司、电缆检修公司）：无； 3.省超输公司分部：项目管理室。 | CB18: 1.区县公司电网技术部：大修技改管理专责； 2.省超输公司项目管理室：技经专责。
C19: 税务合规 | D19: 货币补偿迁改税务处理 | E19: 未根据迁改资产性质、拆旧物资归属以及补偿资金来源等因素，区别进行增值税处理，导致税款多缴或漏缴。 | G19: 7.增值税风险控制 | H19: 根据迁改资产性质、拆旧物资归属以及补偿资金来源，确保增值税缴纳准确。 | I19: 迁改工程管理-7.增值税风险控制-控制措施01 | J19: 各级单位财务部门在智慧共享财务平台嵌入开票规则预置，税务岗应按标准预置规则执行。 | T19: 系统待建 | U19: 智慧共享财务平台 | V19: 1.迁改协议（合同）； 2.增值税发票。 | W19: 各级单位-财务部门-税务管理人员 | X19: 年度 | Y19: 抽查 | AA19: 年度 | AB19: 抽查 | AD19: 迁改工程实施管理-税务合规性监督 | AE19: 每月 | AF19: 抽查 | AH19: 否 | AK19: 国网财务部 | AL19: =A19=[2]迁改工程管理!A18 -> TRUE | AM19: =B19=[2]迁改工程管理!B18 -> TRUE | AN19: =C19=[2]迁改工程管理!C18 -> TRUE | AO19: =D19=[2]迁改工程管理!D18 -> TRUE | AP19: =E19=[2]迁改工程管理!E18 -> TRUE | AQ19: =F19=[2]迁改工程管理!F18 -> TRUE | AR19: =G19=[2]迁改工程管理!G18 -> TRUE | AS19: =H19=[2]迁改工程管理!H18 -> TRUE | ... BV19: =AK19=[2]迁改工程管理!AK18 -> TRUE | BW19: 省公司财务部 | BX19: 省公司财务部：税收管理岗 | BY19: 1.地市公司：市公司财务部； 2.省超输公司：财务部。 | BZ19: 1.市公司财务部：非基建工程项目核算管理专责； 2.省超输公司财务部：税务管理专责。 | CA19: 区县公司：财务部； 检修公司：/； 省超输公司分部：/。 | CB19: 1.区县公司财务部：工程资产财务管理专责。
I20: 迁改工程管理-7.增值税风险控制-控制措施02 | J20: 各级单位财务部门定期开展增值税专项复核，确保计税范围与税率适用准确性，及时完成补缴、退税及账务调整。 | Q20: √ | T20: 线下管控 | V20: 1.迁改协议（合同）； 2.增值税发票。 | W20: 各级单位-财务部门-税务管理人员 | X20: 年度 | Y20: 抽查 | AA20: 年度 | AB20: 抽查 | AD20: 迁改工程实施管理-税务合规性监督 | AE20: 每月 | AF20: 抽查 | AH20: 否 | AK20: 国网财务部 | AL20: =A20=[2]迁改工程管理!A19 -> TRUE | AM20: =B20=[2]迁改工程管理!B19 -> TRUE | AN20: =C20=[2]迁改工程管理!C19 -> TRUE | AO20: =D20=[2]迁改工程管理!D19 -> TRUE | AP20: =E20=[2]迁改工程管理!E19 -> TRUE | AQ20: =F20=[2]迁改工程管理!F19 -> TRUE | AR20: =G20=[2]迁改工程管理!G19 -> TRUE | AS20: =H20=[2]迁改工程管理!H19 -> TRUE | ... BV20: =AK20=[2]迁改工程管理!AK19 -> TRUE | BW20: 省公司财务部 | BX20: 省公司财务部：税收管理岗 | BY20: 1.地市公司：市公司财务部； 2.省超输公司：财务部。 | BZ20: 1.市公司财务部：非基建工程项目核算管理专责； 2.省超输公司财务部：税务管理专责。 | CA20: 区县公司：财务部； 检修公司：/； 省超输公司分部：/。 | CB20: 1.区县公司财务部：工程资产财务管理专责。
B21: 四、竣工与归档 | C21: 资金资产安全 | D21: 实物补偿迁改新建资产管理 | E21: 验收不规范，增加电网运行安全风险。 | G21: 8.新建资产功能性验证 | H21: 迁改后资产不低于原有容量、标准，匹配现有架构。 | I21: 迁改工程管理-8.新建资产功能性验证-控制措施01 | J21: 各级单位实物资产运维部门须严格按规组织验收，对存在问题未整改到位的项目，影响设备安全稳定运行的，一律不予办理停送电手续，确保新建资产的功能、建设标准和运行水平不低于原有电力设施。 | R21: √ | T21: 线下管控 | V21: 竣工验收报告。 | W21: 各级单位-实物资产管理部门-设备资产管理人员 | X21: 年度 | Y21: 抽查 | AA21: 年度 | AB21: 抽查 | AH21: 否 | AK21: 国网设备部 | AL21: =A21=[2]迁改工程管理!A20 -> TRUE | AM21: =B21=[2]迁改工程管理!B20 -> TRUE | AN21: =C21=[2]迁改工程管理!C20 -> TRUE | AO21: =D21=[2]迁改工程管理!D20 -> TRUE | AP21: =E21=[2]迁改工程管理!E20 -> TRUE | AQ21: =F21=[2]迁改工程管理!F20 -> TRUE | AR21: =G21=[2]迁改工程管理!G20 -> TRUE | AS21: =H21=[2]迁改工程管理!H20 -> TRUE | ... BV21: =AK21=[2]迁改工程管理!AK20 -> TRUE | BW21: 省公司设备部：无。 | BX21: 无 | BY21: 1.地市公司：市公司运检部、配电部； 2.省超输公司：运检部。 | BZ21: 1.市公司运检部：杆迁管理专责； 2.市公司配电部：配网技术管理专责； 3.省超输公司运检部：实物资产管理专责。 | CA21: 1.区县公司：电网技术部； 2.市检修公司（输电检修公司、电缆检修公司）：生产技术室； 3.省超输公司分部：项目管理室。 | CB21: 1.区县公司电网技术部：大修技改管理专责； 2.市检修公司生产技术室：大修技改管理专责； 3.省超输公司分部项目管理室：质量专责。
E22: 建卡不规范、入账金额不准确，导致账实不符。 | G22: 9.新建资产价值确定 | H22: 建卡完整、规范，赋值准确。 | I22: 迁改工程管理-9.新建资产价值确定-控制措施01 | J22: 各级单位设备部门建立资产卡片与设备台账关联一致性核查机制，确保资产建卡准确、完整。 | R22: √ | T22: 线下管控 | V22: 1.移交协议； 2.转资明细。 | W22: 各级单位-设备部门-设备资产管理人员 | X22: 年度 | Y22: 抽查 | AA22: 年度 | AB22: 抽查 | AH22: 是 | AI22: 是 | AJ22: 《国家电网有限公司工程财务管理办法》（国家电网企管〔2023〕28号）第六章 | AK22: 国网设备部 | AL22: =A22=[2]迁改工程管理!A21 -> TRUE | AM22: =B22=[2]迁改工程管理!B21 -> TRUE | AN22: =C22=[2]迁改工程管理!C21 -> TRUE | AO22: =D22=[2]迁改工程管理!D21 -> TRUE | AP22: =E22=[2]迁改工程管理!E21 -> TRUE | AQ22: =F22=[2]迁改工程管理!F21 -> TRUE | AR22: =G22=[2]迁改工程管理!G21 -> TRUE | AS22: =H22=[2]迁改工程管理!H21 -> TRUE | ... BV22: =AK22=[2]迁改工程管理!AK21 -> TRUE | BW22: 省公司设备部：无。 | BX22: 无 | BY22: 1.地市公司：市公司运检部、配电部； 2.省超输公司：运检部。 | BZ22: 1.市公司运检部：杆迁管理专责； 2.市公司配电部：配网技术管理专责； 3.省超输公司运检部：实物资产管理专责。 | CA22: 1.区县公司：电网技术部； 2.市检修公司（输电检修公司、电缆检修公司）：无； 3.省超输公司分部：安生办。 | CB22: 1.区县公司电网技术部：大修技改管理专责； 2.省超输公司分部安生办：运行专责。
I23: 迁改工程管理-9.新建资产价值确定-控制措施02 | J23: 各级单位财务部门复核资产创建的类型和数量与移交协议的一致性，严格按照估值报告或决算报告中进行资产赋值。 | R23: √ | T23: 线下管控 | V23: 1.资产估值报告； 2.结（决）算报告； 3.移交协议。 | W23: 各级单位-财务部门-资产管理人员 | X23: 年度 | Y23: 抽查 | AA23: 年度 | AB23: 抽查 | AH23: 是 | AI23: 是 | AJ23: 《国家电网有限公司固定资产管理办法》（国家电网企管〔2023〕28号）第四章 | AK23: 国网财务部 | AL23: =A23=[2]迁改工程管理!A22 -> TRUE | AM23: =B23=[2]迁改工程管理!B22 -> TRUE | AN23: =C23=[2]迁改工程管理!C22 -> TRUE | AO23: =D23=[2]迁改工程管理!D22 -> TRUE | AP23: =E23=[2]迁改工程管理!E22 -> TRUE | AQ23: =F23=[2]迁改工程管理!F22 -> TRUE | AR23: =G23=[2]迁改工程管理!G22 -> TRUE | AS23: =H23=[2]迁改工程管理!H22 -> TRUE | ... BV23: =AK23=[2]迁改工程管理!AK22 -> TRUE | BW23: 省公司财务部：无。 | BX23: 无 | BY23: 1.地市公司：市公司财务部； 2.省超输公司：财务部。 | BZ23: 1.市公司财务部：资产产权管理专责； 2.省超输公司财务部：资产与保险管理专责、资本性项目核算管理专责。 | CA23: 区县公司：财务部； 检修公司：/； 省超输公司分部：/。 | CB23: 1.区县公司财务部：工程资产财务管理专责。
A24: 迁改工程管理 | B24: 四、竣工与归档 | C24: 资金资产安全 | D24: 拆旧资产技术鉴定 | E24: 拆旧资产未进行技术鉴定，导致后续处置不规范，引起资产价值流失。 | F24: 32.迁改工程管理不规范：存在未签合同，垫资实施；迁改工程款未足额回收；未按规定履行迁改批复、审批程序；迁改工程废旧物资未回收；迁改移交资产未建卡入账；迁改协议未明确资产归属等问题。 | G24: 10.技术鉴定控制 | H24: 规范开展技术鉴定，出具鉴定意见。 | I24: 迁改工程管理-10.技术鉴定控制-控制措施01 | J24: 各级单位实物资产管理部门对迁改资产开展技术鉴定，未满足技术要求的及时完成整改；无法进行全量技术鉴定的，实物资产管理部门应复核迁改提出方或施工单位提供的资料证明。是否存在收回利用价值。 | R24: √ | T24: 线下管控 | V24: 1.拟退役资产技术鉴定单； 2.固定资产报废审批表； 3.协议（合同）； 4.迁改提出方或施工单位提供的资料证明。 | W24: 各级单位-实物资产管理部门-设备资产管理人员 | X24: 年度 | Y24: 抽查 | AA24: 年度 | AB24: 抽查 | AH24: 是 | AI24: 是 | AJ24: 《国家电网有限公司固定资产管理办法》（国家电网企管〔2023〕28号）第四章 | AK24: 国网设备部 | AL24: =A24=[2]迁改工程管理!A23 -> TRUE | AM24: =B24=[2]迁改工程管理!B23 -> TRUE | AN24: =C24=[2]迁改工程管理!C23 -> TRUE | AO24: =D24=[2]迁改工程管理!D23 -> TRUE | AP24: =E24=[2]迁改工程管理!E23 -> TRUE | AQ24: =F24=[2]迁改工程管理!F23 -> TRUE | AR24: =G24=[2]迁改工程管理!G23 -> TRUE | AS24: =H24=[2]迁改工程管理!H23 -> TRUE | ... BV24: =AK24=[2]迁改工程管理!AK23 -> TRUE | BW24: 省公司设备部：无。 | BX24: 无 | BY24: 1.地市公司：市公司运检部、配电部、物资部； 2.省超输公司：运检部、物资部。 | BZ24: 1.市公司运检部：杆迁管理专责； 2.市公司配电部：配网技术管理专责； 3.市公司物资部：数字物流专责； 4.省超输公司运检部：实物资产管理专责； 5.省超输公司物资部：。 | CA24: 1.区县公司：电网技术部； 2.市检修公司（输电检修公司、电缆检修公司）：生产技术室。 3.省超输公司分部：安生办。 | CB24: 1.区县公司电网技术部：大修技改管理专责； 2.市检修公司生产技术室：大修技改管理专责； 3.省超输公司分部安生办：检修专责。
I25: 迁改工程管理-10.技术鉴定控制-控制措施02 | J25: 各级单位财务部门复核拆旧流程发起前已完成技术鉴定。 | R25: √ | T25: 线下管控 | V25: 1.拟退役资产技术鉴定单； 2.固定资产报废审批表； 3.协议（合同）。 | W25: 各级单位-财务部门-资产管理人员 | X25: 年度 | Y25: 抽查 | AA25: 年度 | AB25: 抽查 | AH25: 是 | AI25: 是 | AJ25: 《国家电网有限公司固定资产管理办法》（国家电网企管〔2023〕28号）第四章 | AK25: 国网财务部 | AL25: =A25=[2]迁改工程管理!A24 -> TRUE | AM25: =B25=[2]迁改工程管理!B24 -> TRUE | AN25: =C25=[2]迁改工程管理!C24 -> TRUE | AO25: =D25=[2]迁改工程管理!D24 -> TRUE | AP25: =E25=[2]迁改工程管理!E24 -> TRUE | AQ25: =F25=[2]迁改工程管理!F24 -> TRUE | AR25: =G25=[2]迁改工程管理!G24 -> TRUE | AS25: =H25=[2]迁改工程管理!H24 -> TRUE | ... BV25: =AK25=[2]迁改工程管理!AK24 -> TRUE | BW25: 省公司财务部：无。 | BX25: 无 | BY25: 1.地市公司：市公司财务部； 2.省超输公司：财务部。 | BZ25: 1.市公司财务部：非基建工程项目核算管理专责； 2.省超输公司财务部：资产与保险管理专责。 | CA25: 区县公司：财务部； 检修公司：/； 省超输公司分部：/。 | CB25: 1.区县公司财务部：工程资产财务管理专责。
D26: 拆旧回收 | E26: 迁改工程拆退的物资，未办理报废、退库或移交手续，引起资产价值流失。 | F26: 32.迁改工程管理不规范：工程款未足额回收及废旧物资未规范处置将造成直接经济损失。资产未建卡入账及权属不明等问题，导致账实不符并可能引发资产侵占，严重影响国有资产保值增值。 | G26: 11.拆旧资产处置控制 | H26: 及时完成报废、退库或移交手续，确保账实相符、价值完整。 | I26: 迁改工程管理-11.拆旧资产处置控制-控制措施01 | J26: 拆旧物资归属迁改提出方的，各级单位财务部门复核与迁改提出方的移交手续是否完备。 | R26: √ | T26: 线下管控 | V26: 1.迁改协议（合同）； 2.移交证明； 3.固定资产报废审批表。 | W26: 各级单位-财务部门-工程财务人员（资产管理人员） | X26: 年度 | Y26: 抽查 | AA26: 年度 | AB26: 抽查 | AD26: 迁改工程竣工管理-拆旧资产处置监督​ | AE26: 每月 | AF26: 全量检查 | AH26: 否 | AK26: 国网财务部 | AL26: =A26=[2]迁改工程管理!A25 -> TRUE | AM26: =B26=[2]迁改工程管理!B25 -> TRUE | AN26: =C26=[2]迁改工程管理!C25 -> TRUE | AO26: =D26=[2]迁改工程管理!D25 -> TRUE | AP26: =E26=[2]迁改工程管理!E25 -> TRUE | AQ26: =F26=[2]迁改工程管理!F25 -> TRUE | AR26: =G26=[2]迁改工程管理!G25 -> TRUE | AS26: =H26=[2]迁改工程管理!H25 -> TRUE | ... BV26: =AK26=[2]迁改工程管理!AK25 -> TRUE | BW26: 省公司财务部：无。 | BX26: 无 | BY26: 1.地市公司：市公司财务部； 2.省超输公司：财务部。 | BZ26: 1.市公司财务部：非基建工程项目核算管理专责； 2.省超输公司财务部：资产与保险管理专责。 | CA26: 区县公司：财务部； 检修公司：/； 省超输公司分部：/。 | CB26: 1.区县公司财务部：工程资产财务管理专责。
I27: 迁改工程管理-11.拆旧资产处置控制-控制措施02 | J27: 拆旧物资归属公司的，各级单位财务部门复核是否规范履行报废、退库程序。 | R27: √ | T27: 系统待建 | U27: 智慧共享财务平台 | V27: 1.迁改协议（合同）； 2.固定资产报废审批表； 3.拆旧物资退库单。 | W27: 各级单位-财务部门-工程财务人员 | X27: 年度 | Y27: 抽查 | AA27: 年度 | AB27: 抽查 | AD27: 迁改工程竣工管理-拆旧资产处置监督​ | AE27: 每月 | AF27: 全量检查 | AH27: 是 | AI27: 是 | AJ27: 《国家电网有限公司报废物资管理办法》（国家电网企管〔2025〕325号）第五章 | AK27: 国网财务部 | AL27: =A27=[2]迁改工程管理!A26 -> TRUE | AM27: =B27=[2]迁改工程管理!B26 -> TRUE | AN27: =C27=[2]迁改工程管理!C26 -> TRUE | AO27: =D27=[2]迁改工程管理!D26 -> TRUE | AP27: =E27=[2]迁改工程管理!E26 -> TRUE | AQ27: =F27=[2]迁改工程管理!F26 -> TRUE | AR27: =G27=[2]迁改工程管理!G26 -> TRUE | AS27: =H27=[2]迁改工程管理!H26 -> TRUE | ... BV27: =AK27=[2]迁改工程管理!AK26 -> TRUE | BW27: 省公司财务部：无。 | BX27: 无 | BY27: 1.地市公司：市公司财务部； 2.省超输公司：财务部。 | BZ27: 1.市公司财务部：非基建工程项目核算管理专责； 2.省超输公司财务部：资产与保险管理专责。 | CA27: 区县公司：财务部； 检修公司：/； 省超输公司分部：/。 | CB27: 1.区县公司财务部：工程资产财务管理专责。
D28: 货币补偿迁改资金清算 | E28: 按实结算的迁改工程，未根据最终审定金额办理资金清算，引起资产价值流失或履约风险。 | F28: 32.迁改工程管理不规范：存在未签合同，垫资实施；迁改工程款未足额回收；未按规定履行迁改批复、审批程序；迁改工程废旧物资未回收；迁改移交资产未建卡入账；迁改协议未明确资产归属等问题。 | G28: 12.迁改资金清算控制 | H28: 及时完成迁改资金清算，确保账实相符、价值完整。 | I28: 迁改工程管理-12.迁改资金清算控制-控制措施01 | J28: 各级单位迁改工程项目管理部门应及时委托具备资质的第三方（或财政审核中心）对工程量及费用进行审定，保证审定结果真实、准确、合规。 | M28: √ | R28: √ | T28: 线下管控 | V28: 1.迁改协议（合同）； 2.结算审核报告。 | W28: 各级单位-迁改工程项目管理部门-项目经理（技经人员） | X28: 年度 | Y28: 抽查 | AA28: 年度 | AB28: 抽查 | AD28: 迁改工程竣工管理-迁改资金清算监督​ | AE28: 每月 | AF28: 全量检查 | AH28: 否 | AK28: 国网设备部、国网基建部 | AL28: =A28=[2]迁改工程管理!A27 -> TRUE | AM28: =B28=[2]迁改工程管理!B27 -> TRUE | AN28: =C28=[2]迁改工程管理!C27 -> TRUE | AO28: =D28=[2]迁改工程管理!D27 -> TRUE | AP28: =E28=[2]迁改工程管理!E27 -> TRUE | AQ28: =F28=[2]迁改工程管理!F27 -> TRUE | AR28: =G28=[2]迁改工程管理!G27 -> TRUE | AS28: =H28=[2]迁改工程管理!H27 -> TRUE | ... BV28: =AK28=[2]迁改工程管理!AK27 -> TRUE | BW28: 省公司设备部：无。 | BX28: 无 | BY28: 1.地市公司：市公司运检部、配电部； 2.省超输公司：运检部。 | BZ28: 1.市公司运检部：杆迁管理专责； 2.市公司配电部：配网技术管理专责； 3.省超输公司运检部：迁改计划专责。 | CA28: 1.区县公司：电网技术部； 2.市检修公司（输电检修公司、电缆检修公司）：无； 3.省超输公司分部：项目管理室。 | CB28: 1.区县公司电网技术部：大修技改管理专责； 2.省超输公司分部项目管理室：技经专责。
I29: 迁改工程管理-12.迁改资金清算控制-控制措施02 | J29: 各级单位迁改工程项目管理部门应在审定完成后及时开展清算工作，推进清算手续办理，实现收支匹配。 | R29: √ | T29: 系统待建 | U29: 智慧共享财务平台 | V29: 1.迁改协议（合同）； 2.结算审核报告； 3.收款凭证； 4.支出凭证。 | W29: 各级单位-迁改工程项目管理部门-项目经理（技经人员） | X29: 年度 | Y29: 抽查 | AA29: 年度 | AB29: 抽查 | AD29: 迁改工程竣工管理-迁改资金清算监督​ | AE29: 每月 | AF29: 全量检查 | AH29: 否 | AK29: 国网设备部、国网基建部 | AL29: =A29=[2]迁改工程管理!A28 -> TRUE | AM29: =B29=[2]迁改工程管理!B28 -> TRUE | AN29: =C29=[2]迁改工程管理!C28 -> TRUE | AO29: =D29=[2]迁改工程管理!D28 -> TRUE | AP29: =E29=[2]迁改工程管理!E28 -> TRUE | AQ29: =F29=[2]迁改工程管理!F28 -> TRUE | AR29: =G29=[2]迁改工程管理!G28 -> TRUE | AS29: =H29=[2]迁改工程管理!H28 -> TRUE | ... BV29: =AK29=[2]迁改工程管理!AK28 -> TRUE | BW29: 省公司设备部：无。 | BX29: 无 | BY29: 1.地市公司：市公司运检部、配电部； 2.省超输公司：运检部。 | BZ29: 1.市公司运检部：杆迁管理专责； 2.市公司配电部：配网技术管理专责； 3.省超输公司运检部：迁改计划专责。 | CA29: 1.区县公司：电网技术部； 2.市检修公司（输电检修公司、电缆检修公司）：无； 3.省超输公司分部：项目管理室。 | CB29: 1.区县公司电网技术部：大修技改管理专责； 2.省超输公司分部项目管理室：技经专责。
I30: 迁改工程管理-12.迁改资金清算控制-控制措施03 | J30: 各级单位财务部门应定期对迁改项目收支明细进行核查，推动牵头管理部门及时完成资金回收或退还。 | Q30: √ | R30: √ | T30: 系统待建 | U30: 智慧共享财务平台 | V30: 1.迁改协议（合同）； 2.结算审核报告； 3.收款凭证； 4.支出凭证。 | W30: 各级单位-财务部门-工程财务人员 | X30: 年度 | Y30: 抽查 | AA30: 年度 | AB30: 抽查 | AD30: 迁改工程竣工管理-迁改资金清算监督​ | AE30: 每月 | AF30: 全量检查 | AH30: 否 | AK30: 国网财务部 | AL30: =A30=[2]迁改工程管理!A29 -> TRUE | AM30: =B30=[2]迁改工程管理!B29 -> TRUE | AN30: =C30=[2]迁改工程管理!C29 -> TRUE | AO30: =D30=[2]迁改工程管理!D29 -> TRUE | AP30: =E30=[2]迁改工程管理!E29 -> TRUE | AQ30: =F30=[2]迁改工程管理!F29 -> TRUE | AR30: =G30=[2]迁改工程管理!G29 -> TRUE | AS30: =H30=[2]迁改工程管理!H29 -> TRUE | ... BV30: =AK30=[2]迁改工程管理!AK29 -> TRUE | BW30: 省公司财务部：无。 | BX30: 无 | BY30: 1.地市公司：市公司财务部； 2.省超输公司：财务部。 | BZ30: 1.市公司财务部：非基建工程项目核算管理专责； 2.省超输公司财务部：资本性项目核算管理专责。 | CA30: 区县公司：财务部； 检修公司：/； 省超输公司分部：/。 | CB30: 1.区县公司财务部：工程资产财务管理专责。
AL31: =A31=[2]迁改工程管理!A30 -> TRUE | AM31: =B31=[2]迁改工程管理!B30 -> TRUE | AN31: =C31=[2]迁改工程管理!C30 -> TRUE | AO31: =D31=[2]迁改工程管理!D30 -> TRUE | AP31: =E31=[2]迁改工程管理!E30 -> TRUE | AQ31: =F31=[2]迁改工程管理!F30 -> TRUE | AR31: =G31=[2]迁改工程管理!G30 -> TRUE | AS31: =H31=[2]迁改工程管理!H30 -> TRUE | ... BV31: =AK31=[2]迁改工程管理!AK30 -> TRUE

Sheet 意见建议
A1: 业务条线 | B1: 业务领域 | C1: 控制目标 | D1: 业务流程步骤 | E1: 经营风险 | F1: 对应典型问题 | G1: 关键控制点 | H1: 控制要求 | I1: 控制措施 | J1: 控制措施编号 | K1: 控制措施分类 | T1: 控制方式（枚举值） | U1: 内控载体 | V1: 控制系统 | W1: 系统控制层次 | Z1: 责任主体 | AA1: 业务自评价 | AD1: 集团监督评价 | AG1: 数字化监督场景 | AK1: 现有制度及文件落实情况 | AN1: 总部审核部门 | AR1: 意见建议
K2: 不相容岗位 | L2: 分级授权 | M2: 业务真实性校验 | N2: 预算管控 | O2: 合同控制 | P2: 收付控制 | Q2: 会计监督 | R2: 财产保护 | S2: 分析与评价 | W2: 系统类别（一级部署系统/各单位自建系统） （如F列为“系统已有”或“系统待建”，则填写） | X2: 系统管理层级（总部/二级单位/三级单位） （如F列为“系统已有”或“系统待建”，则填写） | Y2: 总部管理部门 （如k列为“总部”，则填写） | AA2: 评价频率 | AB2: 评价范围 | AC2: 评价结论 | AD2: 评价频率 | AE2: 评价范围 | AF2: 评价结论 | AG2: 数字化监督场景 | AH2: 评价频率 | AI2: 评价范围 | AJ2: 评价结论 | AK2: 是否已要求 | AL2: 是否满足要求 | AM2: 对应制度及文件名称
A3: 员 工 报 账 业 务 | B3: 二、通用报账 | C3: 税务合规 | D3: 青苗赔偿资金申 请支付 | E3: 与赔付人实际不一致，虚列套取资金，造成青苗赔偿费多付、错付。 | F3: 随便列举：8.违规发放薪酬：存在企业负责人违规发放薪酬；员工惩处结果执行不到位,未扣减相应薪酬等问题。 | G3: 22.青苗赔偿支付对象的确定 | H3: 青苗赔付资金支付对象与现场一致。 | I3: 1.归口管理部门对资金支付与补偿协议支付条款进行校验； | J3: 营销售电业务-1.系统客户信息创建-控制措施01 | K3: √ | M3: √ | O3: √ | P3: √ | Q3: √ | R3: √ | T3: 系统已建 | U3: 1.用地批复文件； 2.地方补偿标准文件； | V3: 智慧共享财务平台 | W3: 一级部署系统 | X3: 总部 | Y3: 财务部 | Z3: 各级单位-各部门-报账人员、各级单位-各部门-负责人、各级单位-项目归口管理部门-负责人 | AA3: 每季度 | AB3: 抽查 | AD3: 每年 | AE3: 抽查 | AG3: 青苗赔偿费监督场景 | AH3: 每年 | AI3: 抽查 | AK3: 是 | AL3: 是 | AM3: 《国家电网有限公司会计基础管理办法》（国家电网企管〔2019〕132号）附件：电网企业经济业务审核手册 | AN3: 财务部

Sheet Sheet2
A1: 系统已建 | B1: 一级系统 | C1: 总部
A2: 系统待建 | B2: 各单位自建系统 | C2: 二级单位
A3: 线下管控 | C3: 三级单位

Sheet WpsReserved_CellImgList
