Workbook

Sheet 隔页
A1: 二、财务管理

Sheet 财务矩阵
A1: 财务管理风控矩阵
A2: 业 务 条 线 | B2: 业 务 领 域 | C2: 控 制 目 标 | D2: 业务流程步骤 | E2: 经营风险 | F2: 典型问题 | G2: 关键控制点 | H2: 控制要求 | I2: 控制措施 编号 | J2: 控制措施 | K2: 控制措施分类 | T2: 控制方式 | U2: 控制系统 | V2: 控制载体 | W2: 责任主体 | X2: 业务自评价 | AA2: 集团监督评价 | AD2: 数字化监督场景 | AH2: 现有制度及文件落实情况 | AK2: 总部审核部门
K3: 不相容岗位 | L3: 分级授权 | M3: 业务真实性控制 | N3: 预算管控 | O3: 合同控制 | P3: 收付控制 | Q3: 会计监督 | R3: 财产保护 | S3: 分析与评价 | X3: 评价频率 | Y3: 评价范围 | Z3: 评价结论 | AA3: 评价频率 | AB3: 评价范围 | AC3: 评价结论 | AD3: 数字化监督场景 | AE3: 监督频率 | AF3: 监督范围 | AG3: 评价结论 | AH3: 是否已要求 | AI3: 是否满足要求 | AJ3: 对应制度及文件名称
A4: 财务管理 | B4: 一、核算范围 | C4: 会计信息真实完整 | D4: 会计主体管理 | E4: 会计主体创建不规范、不及时，影响合并范围完整性、准确性，导致会计信息不准确。 | F4: 会计主体创建不合规：对工商登记持股超过50%的实际经营企业，未创建会计主体单独核算，导致合并范围不完整、合并报表信息不准确。 | G4: 1.会计主体完整性管控 | H4: 会计主体与工商、产权登记衔接一致，合并范围完整。 | I4: 财务管理-1.会计主体完整性管控-控制措施01 | J4: 合并范围完整性控制。每月，各级单位会计人员在线跟踪比对工商、产权登记与报表合并范围一致性，以控制为基础，原则上工商登记持股50%以上企业均需办理产权登记、规范取得控制权并纳入合并范围。确有问题的，应及时规范调整。 | M4: √ | Q4: √ | T4: 线上管控-待建 | U4: 智慧共享财务平台、主数据管理平台（MDM3.0) | V4: 1.会计核算主体建立（变更）申请单 2.营业执照、产权登记资料等 | W4: 各级单位-财务资产部-总账报表管理、各级单位-财务资产部-资产及产权管理 | X4: 每月 | Y4: 全查 | AA4: 每年 | AB4: 全查 | AD4: 合并范围完整性监督场景 | AE4: 每月 | AF4: 全查 | AH4: 是 | AI4: 是 | AJ4: 《国家电网有限公司会计基础管理办法》（国家电网企管〔2019〕132号）第四章 核算与报告第三十七条、第四十四条 《国家电网有限公司关于做好2025年度财务决算工作的通知》（国家电网财〔2025〕649号） | AK4: 国网财务部
I5: 财务管理-1.会计主体完整性管控-控制措施02 | J5: 会计主体创建和变更控制。各级单位财务人员应遵循先产权后工商的要求，根据产权和工商登记结果，及时创建会计主体，并履行二级单位、国网财务部审批程序，规范纳入合并范围。对于无人资组织、未办理工商登记的会计主体，由二级单位分管财务领导审批后，提交国网财务部审批。 | L5: √ | M5: √ | T5: 线上管控-已建 | U5: 智慧共享财务平台、主数据管理平台（MDM3.0) | V5: 1.会计核算主体建立（变更）申请单 2.工商登记、税务登记、产权登记资料等 | W5: 各级单位-财务资产部-总账报表管理、各级单位-财务资产部-资产及产权管理 | X5: 每月 | Y5: 全查 | AA5: 每年 | AB5: 全查 | AD5: 会计主体创建变更规范性监督场景 | AE5: 每月 | AF5: 全查 | AH5: 是 | AI5: 是 | AJ5: 《国家电网有限公司会计基础管理办法》（国家电网企管〔2019〕132号）第四章 核算与报告第三十七条、第四十四条 《关于智慧共享财务平台与人资0系统管理融合有关事项的通知》（财会〔2025〕15号） | AK5: 国网财务部
E6: 科目维度使用不统一、不规范，影响会计信息准确性和可比性。 | F6: 科目维度使用不规范：凭证科目维度与实际业务不匹配，影响会计信息反映准确性；集团内不同单位对同类业务核算科目维度不统一，导致会计信息不可比。 | G6: 2.业务完整性管控 | H6: 统一会计科目和管理维度体系，规范科目维度使用，确保会计信息准确可比。 | I6: 财务管理-2.业务完整性管控-控制措施01 | J6: 会计科目和管理维度统一性规范性控制。国网公司建立统一的会计科目和管理维度体系，并实施分业态管理，各级单位根据业态标识规范引用。在公司统一体系下，各级单位因自身业务特点和内部管理要求，确需对相关管理维度枚举值进行细化的，需依次履行二级单位、国网财务部审批程序。 | L6: √ | Q6: √ | T6: 线上管控-已建 | U6: 智慧共享财务平台、主数据管理平台（MDM2.0） | V6: 1.管理维度体系清单 2.管理维度系统截图 3.管理维度细化申请与审批记录 | W6: 市公司-财务资产部-会计核算处（数据处）总账管理 | X6: 每年 | Y6: 全查 | AA6: 每年 | AB6: 全查 | AD6: 科目维度规范性监督场景 | AE6: 每年 | AF6: 全查 | AH6: 是 | AI6: 是 | AJ6: 《国家电网有限公司会计基础管理办法》（国家电网企管〔2019〕132号）第四章 核算与报告第四十条、第四十四条 《国家电网有限公司财务管理通则》（国家电网企管〔2020〕763号）第三章 管理内容与管理流程第二节 会计核算第二十一条 | AK6: 国网财务部
C7: 资金资产安全、税务合规 | E7: 部分属于成本中心的分支机构，因独立核算增值税，存在进项税长期大额留抵情况，导致资金长期占用风险。 | F7: 分支机构责任中心判定缺少管控：未对新设分支机构责任中心进行定性审批，导致部分成本费用中心采取增值税独立核算模式，因应税收入较少，导致进项税长期大额留抵，地方财政紧张申请退税困难，严重影响资金使用效率。 | G7: 3.分支机构责任中心判定 | H7: 新设分支机构必须准确、合理进行责任中心判定，并明确增值税核算缴纳方式。 | I7: 财务管理-3.分支机构开办费列支管控-控制措施01 | J7: 各级单位在新设分支机构时，财务部门应当根据分支机构职责定位、主营业务，准确判定责任中心类型。对外交易业务相对独立、收入来源较为稳定的利润中心，可申请增值税独立核算；无可靠收入来源、仅发挥业务支撑作用的成本中心、费用中心，原则上应向税务机关办理与总机构汇总核算增值税。 | M7: √ | R7: √ | T7: 线下管控 | V7: 1.分支机构设立的决策性文件； 2.分支机构设立审批表 | W7: 各级单位-财务资产部-预算管理、税金管理、市公司-财务资产部-会计核算处（数据处）总账管理 | X7: 每年 | Y7: 全查 | AA7: 每年 | AB7: 全查 | AH7: 是 | AI7: 是 | AJ7: 《国家电网有限公司税务管理办法》（国家电网财〔2026〕202号）第三章第十一条、第四章第十八条 | AK7: 国网财务部
C8: 税务合规 | D8: 纳税主体管理 | E8: 税务登记或信息变更不及时、证件遗失或未按规定办理登记等情况，导致税务主体资格问题，影响正常经营并可能被处以罚款。 | F8: 未在规定时间内完成税务登记/变更，违反税收征管法相关要求，面临税务机关处罚。 | G8: 4.纳税主体税务登记控制 | H8: 纳税主体设立及税务登记变更信息准确、及时完整。 | I8: 财务管理-4.纳税主体税务登记控制-控制措施01 | J8: 在办理完成产权、工商登记后，各级单位财务部需进行税务登记，应综合考虑业务类型、经营规模等因素，科学选择纳税模式。存续期间发生信息变更时，应当在工商登记变更后及时完成税务登记证变更。 | M8: √ | Q8: √ | T8: 线上管控-已建 | U8: 智慧共享财务平台 | V8: 1.设立及变更登记决策文件 2.工商登记、税务登记、产权登记资料等 | W8: 各级单位-财务资产部-税金管理、资产及产权管理、各级单位-办公室（党委办公室）-法律事务管理、市公司-法律合规部-合规处（数据处）法治合规事务管理 | X8: 每年 | Y8: 全查 | AA8: 每年 | AB8: 全查 | AH8: 是 | AI8: 是 | AJ8: 《国家电网有限公司税务管理办法》（国家电网财〔2026〕202号）第三章第十条到第十四条 | AK8: 国网财务部
A9: 财务管理 | B9: 一、核算范围 | C9: 会计信息真实完整 | D9: 会计政策管理 | E9: 会计政策和会计估计分类和分级授权标准不明确，导致执行不统一，影响会计信息准确性和可比性。 | F9: 会计政策和会计估计分类和分级授权不规范：未明确会计政策和会计估计分类管控和分级授权标准，导致会计信息执行不统一、反映不准确。 | G9: 5.会计政策和会计估计分类管控和分级授权管理 | H9: 明确会计政策、会计估计分类管控和分级授权标准。 | I9: 财务管理-5.会计政策和会计估计分类管控和分级授权管理-控制措施01 | J9: 会计政策和会计估计分类管控及分级授权控制。国网公司统一建立会计政策和会计估计分类管控及分级授权标准，明确政策清单，对应收款项坏账计提组合及比例、固定资产折旧方法和年限区间、投资性房地产后续计量方法等，由国网公司统一确定；对固定资产折旧年限等公司统一政策下的具体执行值，由各级单位履行决策程序后确定具体执行标准，并向国网公司备案或经总部审批。 | L9: √ | T9: 线上管控-待建 | U9: 智慧共享财务平台 | V9: 1.会计政策和会计估计分类管控清单（待总部下发） 2.会计政策、会计估计分级授权清单（待总部下发） | W9: 国网财务部-总账管理人员、市公司-财务资产部-会计核算处（数据处）总账管理、市公司-财务资产部-工程资产处资产管理 | X9: 每年 | Y9: 全查 | AA9: 每年 | AB9: 全查 | AD9: 会计政策、会计估计分类管控及分级授权标准监督场景 | AE9: 每年 | AF9: 全查 | AH9: 是 | AI9: 是 | AJ9: 《国家电网有限公司会计基础管理办法》（国家电网企管〔2019〕132号）第四章 核算与报告第三十九条、第四十四条 | AK9: 国网财务部
E10: 会计政策和会计估计执行不统一、不规范，导致会计信息不准确、经营业绩失真。 | F10: 会计政策和会计估计执行不统一：未严格执行公司统一的会计政策和会计估计，导致会计信息反映不准确、不可比。 | G10: 6.会计政策和会计估计执行管控 | H10: 严格执行统一的会计政策和会计估计标准。 | I10: 财务管理-6.会计政策和会计估计执行管控-控制措施01 | J10: 会计政策和会计估计执行统一性控制。国网公司将统一会计政策和会计估计管控要求嵌入在线业财处理流程，确保全流程规范遵循。每月末，各级单位财务人员对本单位统一政策执行情况进行全面检查，确保反映准确。 | Q10: √ | T10: 线上管控-待建 | U10: 智慧共享财务平台 | V10: 1.会计政策和会计估计分类管控清单（待总部下发） 2.会计政策、会计估计分级授权清单（待总部下发） | W10: 国网财务部-总账管理人员、各级单位-财务资产部-总账报表管理 | X10: 每月 | Y10: 抽查 | AA10: 每年 | AB10: 抽查 | AD10: 会计政策和会计估计规范性监督场景 | AE10: 每月 | AF10: 抽查 | AH10: 是 | AI10: 是 | AJ10: 《国家电网有限公司会计基础管理办法》（国家电网企管〔2019〕132号）第四章 核算与报告第三十九条、第四十四条 | AK10: 国网财务部
E11: 会计政策和会计估计变更不规范、随意调节，跨年调整经营指标，导致会计信息不准确、经营业绩失真。 | F11: 会计政策和会计估计变更流程不规范：变更程序不规范、审核把关不严，滥用变更人为调节年度间财务状况、经营成果，导致会计信息不准确。 | G11: 7.会计政策和会计估计变更审批 | H11: 会计政策和会计估计变更审批统一规范。 | I11: 财务管理-7.会计政策和会计估计变更审批-控制措施01 | J11: 会计政策和会计估计变更审批控制。对会计政策和会计估计变更事项，根据分类管控及分级授权标准，分层级履行党组（党委）会前置研究、董事会或类似机构决策等程序。 | L11: √ | T11: 线下管控 | V11: 1.内部决策文件 | W11: 各级单位-财务资产部-总账报表管理 | X11: 每年 | Y11: 抽查 | AA11: 每年 | AB11: 抽查 | AH11: 是 | AI11: 是 | AJ11: 《国家电网有限公司会计基础管理办法》（国家电网企管〔2019〕132号）第四章 核算与报告第三十九条、第四十四条 | AK11: 国网财务部
C12: 资金资产安全、会计信息真实完整 | D12: 会计岗位管理 | E12: 会计不相容权责未分离，审核审批不合规，容易引发财务舞弊，造成资金挪用、资产损失、会计信息失真。 | F12: 不相容岗位权责未分离：会计兼任出纳、业务审批、财产保管等职责，导致资金资产损失长期隐匿未被发现；凭证制单与审核、审批由同一人负责，容易造成会计舞弊。 | G12: 8.会计不相容岗位管控 | H12: 严格会计不相容岗位相分离。 | I12: 财务管理-8.会计不相容岗位管控-控制措施01 | J12: 不相容岗位相分离控制。各级单位财务部门严格按照不相容岗位相分离的要求，规范设置会计岗位、匹配财务人员。 | K12: √ | L12: √ | T12: 线上管控-已建 | U12: 智慧共享财务平台 | V12: 1.岗位设置与岗位职责说明 2.系统角色和权限配置表 | W12: 各级单位-财务资产部-主任、市公司-财务资产部-主任 | X12: 每月 | Y12: 全查 | AA12: 每年 | AB12: 全查 | AD12: 不相容岗位分离监督场景 | AE12: 每年 | AF12: 全查 | AH12: 是 | AI12: 是 | AJ12: 《国家电网有限公司会计基础管理办法》（国家电网企管〔2019〕132号）第三章 会计机构和会计人员第十六条 《会计基础工作规范》（征求意见稿）第二章 会计机构和会计岗位第十一条 | AK12: 国网财务部
I13: 财务管理-8.会计不相容岗位管控-控制措施02 | J13: 各级单位严格落实财务人员任职回避制度。单位负责人直系亲属不得担任本单位财务机构负责人和会计主管，财务机构负责人和会计主管的直系亲属不得在本单位会计机构中担任出纳。 | K13: √ | T13: 线下管控 | V13: 1.岗位人员清单 2.出纳及财务主任人员信息表 | W13: 各级单位-财务资产部-主任、市公司-财务资产部-主任 | X13: 每年 | Y13: 全查 | AA13: 每年 | AB13: 全查 | AH13: 是 | AI13: 是 | AJ13: 《国家电网有限公司司库管理办法》（国网（财/2）3452023）第十章第二百八十三条 《国家电网有限公司会计基础管理办法》（国家电网企管〔2019〕132号）第三章 会计机构和会计人员第二十条 | AK13: 国网财务部
I14: 财务管理-8.会计不相容岗位管控-控制措施03 | J14: 各级单位要建立资金管理岗轮岗、交流和强制休假机制。替岗人员应在替岗期间完成现金、银行账户余额、重要票据核对及未达账项核实工作，并编制核查报告、审核存档。 | K14: √ | T14: 线下管控 | V14: 1.岗位交接表 2.稽核报告 3.考勤表 | W14: 各级单位-财务资产部-资金管理 | X14: 每季度 | Y14: 全查 | AA14: 每季度 | AB14: 全查 | AH14: 是 | AI14: 是 | AJ14: 《国家电网有限公司司库管理办法》（国网（财/2）3452023）第十一章第二百八十四条 | AK14: 国网财务部
A15: 财务管理 | B15: 一、核算范围 | C15: 资金资产安全、会计信息真实完整 | D15: 会计岗位管理 | E15: 会计岗位交接不规范，影响会计工作组织和会计信息质量。 | F15: 会计岗位交接资料不完整、监交不到位：移交清册等资料不完整，资金、凭证、账簿等财务数据未核对，交接过程未经过监交人监督，交接前后财务信息不衔接、不准确。 | G15: 9.会计岗位交接管控 | H15: 规范会计工作交接，确保会计资料衔接一致。 | I15: 财务管理-9.会计岗位交接管控-控制措施01 | J15: 会计工作交接规范性控制。各级单位财务人员办理移交手续前，应完成未了事项，编制移交清册，并与接管人员逐项核对确认。办理交接手续，必须有监交人负责监交；交接完毕后，交接双方和监交人员要在移交清册上签名或者盖章。财务负责人的岗位交接，应该由分管财务工作的领导监交。 | K15: √ | Q15: √ | T15: 线上管控-待建 | U15: 智慧共享财务平台 | V15: 1.会计岗位交接报告 | W15: 各级单位-财务资产部-会计岗位人员、各级单位-财务资产部-主任、各级单位-领导干部-副总经理 | X15: 每年 | Y15: 全查 | AA15: 每年 | AB15: 全查 | AH15: 是 | AI15: 是 | AJ15: 《国家电网有限公司会计基础管理办法》（国家电网企管〔2019〕132号）第三章 会计机构和会计人员第三节 会计工作交接 《国家电网有限公司司库管理办法》（国网（财/2）3452024）第三章第二百八十五条 | AK15: 国网财务部
B16: 二、账户管理 | C16: 资金资产安全 | D16: 银行账户开立 | E16: 银行账户开立未履行审批手续，易滋生账外账及小金库，账户未纳入系统统一监管，账实不符，引发资金流失风险。 | F16: 1.银行账户未批先设：未经上级或总部批准擅自在线下开立账户。 2.银行账户开立后，未纳入中台统一管理。 3.基本账户超范围开立 4.非经营类账户未纳入中台统一管理 | G16: 10.银行账户合规开立控制 | H16: 严格履行银行账户开立审批手续，规范开户渠道、开户主体，严禁未批先设；定期从人民银行或基本户开户银行获取全量账户清单，排查“应纳未纳”风险。 | I16: 财务管理-10.银行账户合规开立控制-控制措施01 | J16: 各级单位财务部门从严控制银行账户开立机构，基本账户不得出现违反公司规定的标准开立，其他账户应在开户机构白名单范围内选择，不在白名单范围内的开户事项，须履行二级单位本部审核和总部审批。 | L16: √ | M16: √ | T16: 线上管控-已建 | U16: 智慧共享财务平台 | V16: 1.银行账户开立申请单或银行账户开立业务办理回执 | W16: 各级单位-财务资产部-出纳管理、各级单位-财务资产部-资金管理 | X16: 每季度 | Y16: 抽查 | AA16: 每年 | AB16: 抽查 | AH16: 是 | AI16: 是 | AJ16: 《国家电网有限公司司库管理办法》（国网（财/2）3452023）第三章第二十八条、第三十条、第三十一条 | AK16: 国网财务部
I17: 财务管理-10.银行账户合规开立控制-控制措施02 | J17: 各级单位业务部门按照“谁开立谁负责”原则，通过智慧共享财务平台办理银行账户开立申请，并履行内部审批，开立后在规定时间内完成智慧共享财务平台信息维护。 | L17: √ | O17: √ | T17: 线上管控-已建 | U17: 智慧共享财务平台 | V17: 1.银行账户开立业务办理回执 2.银行账户开立申请单 | W17: 各级单位-业务部门-经办人员、各级单位-业务部门-部门负责人、各级单位-财务资产部-出纳管理、各级单位-财务资产部-资金管理、各级单位-财务资产部-主任 | X17: 每季度 | Y17: 抽查 | AA17: 每年 | AB17: 抽查 | AH17: 是 | AI17: 是 | AJ17: 《国家电网有限公司司库管理办法》（国网（财/2）3452023）第三章第三十条、第三十一条、第三十二条、第三十三条、第三十四条、第三十五条 | AK17: 国网财务部
I18: 财务管理-10.银行账户合规开立控制-控制措施03 | J18: 各级单位财务部门（经营类账户）或业务部门（非经营类账户）规范银行账户开立经办管理，须由本人或授权人员办理，经办人员应为正式编制，手续须由至少两名人员共同办理，强化岗位制衡。其中，非经营类账户指含党团工会、出资举办的事业单位以及以公司名义设立或举办的各类组织、单位等所有非并表主体账户。 | K18: √ | T18: 线下管控 | V18: 1.银行账户开立业务办理回执（两名经办人员签字） | W18: 各级单位-财务资产部-财务主任、各级单位-财务资产部-经办人员 | X18: 每季度 | Y18: 抽查 | AA18: 每年 | AB18: 抽查 | AH18: 是 | AI18: 是 | AJ18: 《国家电网有限公司司库管理办法》（国网（财/2）3452023）第三章第三十六条 《国家电网有限公司关于印发〈“四严五强六十条”资金安全管理规程〉及资金安全监控规则的通知》（国家电网财[2021]329号）第26条 | AK18: 国网财务部
I19: 财务管理-10.银行账户合规开立控制-控制措施04 | J19: 各级单位财务部门定期从人民银行或基本户开户银行获取全量已开立银行结算账户清单，与智慧共享财务平台账户台账逐项核对，排查“应纳未纳”等异常，确保账户台账全面覆盖、信息完整。 | M19: √ | S19: √ | T19: 线下管控 | V19: 1.开立银行账户清单 | W19: 各级单位-财务资产部-出纳管理、各级单位-财务资产部-资金管理 | X19: 每季度 | Y19: 抽查 | AA19: 每年 | AB19: 抽查 | AH19: 否 | AI19: 否 | AK19: 国网财务部
I20: 财务管理-10.银行账户合规开立控制-控制措施05 | J20: 中国电财严格核验内部账户开立审批手续，审批流程完备合规后方可受理开户业务。 | M20: √ | T20: 线上管控-已建 | U20: 智慧共享财务平台 | V20: 1.银行账户开立申请单 | W20: 中国电财-直属营业部门或营业部门（司库服务部门）-综合柜员-结算业务负责人 | X20: 每季度 | Y20: 抽查 | AA20: 每年 | AB20: 抽查 | AH20: 是 | AI20: 是 | AJ20: 《中国电力财务有限公司结算账户管理规定》（中国电财〔2024〕215号）第三章第二十三条 | AK20: 国网财务部
A21: 财务管理 | B21: 二、账户管理 | C21: 资金资产安全 | D21: 银行账户开立 | E21: 银行账户开立未履行审批手续，易滋生账外账及小金库，账户未纳入系统统一监管，账实不符，引发资金流失风险。 | F21: 1.银行账户未批先设：未经上级或总部批准擅自在线下开立账户。 2.银行账户开立后，未纳入中台统一管理。 3.基本账户超范围开立 4.非经营类账户未纳入中台统一管理。 | G21: 10.银行账户合规开立控制 | H21: 严格履行银行账户开立审批手续，规范开户渠道、开户主体，严禁未批先设；定期从人民银行或基本户开户银行获取全量账户清单，排查“应纳未纳”风险。 | I21: 财务管理-10.银行账户合规开立控制-控制措施06 | J21: 各级单位财务部门严格执行“先有产权、再建核算账套、后开账户”规则，推动账户模块与产权系统、核算系统数据贯通。产权发生变更时，系统自动推送账户调整预警任务，强制同步办理变更或撤销，杜绝“工商已注销、账户未撤销”。针对系统内产权划转，建立专用账户变更流程，划转完成后原单位账户台账自动删除，新单位自动继承账户信息，无需手工操作。 | M21: √ | T21: 线上管控-待建 | U21: 智慧共享财务平台 | V21: 1.系统中已销户账户清单 2.产权变动相关资料 | W21: 各级单位-财务资产部-出纳管理、各级单位-财务资产部-资金管理、各级单位-财务资产部-会计核算管理、各级单位-财务资产部-资产及产权管理、各级单位-财务资产部-主任 | X21: 每季度 | Y21: 抽查 | AA21: 每年 | AB21: 抽查 | AH21: 否 | AI21: 否 | AK21: 国网财务部
E22: 银行账户未及时办理监控授权，资金动向无法实时监测，异常交易识别不及时，易诱发资金违规占用及挪用风险。 | F22: 对具备监控条件的银行账户未及时办理监控授权（银企直联），造成个别账户脱离监管，造成资金损失风险。 | G22: 11.银行账户办理监控控制 | H22: 银行账户及时纳入监控，定期监控资金流水动向及频次。 | I22: 财务管理-11.银行账户办理监控控制-控制措施01 | J22: 各级单位财务部门（经营类账户）或业务部门（非经营类账户）对具备监控条件的银行账户在完成开立时在规定时间内办理监控授权，确保纳入公司资金监控体系。 | L22: √ | M22: √ | T22: 线上管控-待建 | U22: 智慧共享财务平台 | V22: 1.《资金结算系统账户服务注册（变更）申请表》 | W22: 各级单位-财务资产部-出纳管理、各级单位-财务资产部-资金管理、各级单位-财务资产部-主任、各级单位-业务部门-经办人员、各级单位-业务部门-部门负责人 | X22: 每季度 | Y22: 抽查 | AA22: 每年 | AB22: 抽查 | AH22: 是 | AI22: 是 | AJ22: 《国家电网有限公司司库管理办法》（国网（财/2）3452023）第三章第三十七条、第三十八条 | AK22: 国网财务部
I23: 财务管理-11.银行账户办理监控控制-控制措施02 | J23: 各单位应在完成银行账户变更相关手续后15个工作日内办理授权变更工作，银行账户撤销应在终止监控授权后及时办理销户手续。 | L23: √ | M23: √ | T23: 线上管控-已建 | U23: 智慧共享财务平台 | V23: 1.《资金结算系统账户服务注册（变更）申请表》 2.《资金结算系统 CA 证书（变更）申请单》 3.《终止银企互联账户授权书》 | W23: 各级单位-财务资产部-出纳管理、各级单位-财务资产部-资金管理、各级单位-财务资产部-主任、各级单位-业务部门-经办人、各级单位-业务部门-部门负责人 | X23: 每季度 | Y23: 抽查 | AA23: 年度 | AB23: 抽查 | AH23: 是 | AI23: 是 | AJ23: 《国家电网有限公司司库管理办法》（国网（财/2）345-2027）第三章第三十七条 | AK23: 国网财务部
C24: 资金资产安全 | D24: 商户号开立 | E24: 商户号开立未履行审批手续，缺少财务监督，易形成账外资金、私设小金库，引发资金流失风险。 | F24: 商户号未按规定履行审批流程，未严格审核开户机构（服务商）资质和协议，开通了转账功能，导致资金损失风险。 | G24: 12.商户号合规开立控制 | H24: 严格履行商户号开立审批手续，规范开户渠道、开户主体，严禁未批先设，严禁超标准开设。 | I24: 财务管理-12.商户号合规开立控制-控制措施01 | J24: 各级单位业务部门严格执行商户号开立白名单（微信、支付宝、银联商务、电e宝）管理，通过智慧共享财务平台办理商户号开立审批，不在白名单范围内的开户事项，须履行二级单位本部审核和总部审批，严禁未批先开。开立后在规定时间内完成智慧共享财务平台纳管，未经审批私自开立及未按规定时间纳管的商户号的视为小金库。 | L24: √ | M24: √ | O24: √ | T24: 线上管控-待建 | U24: 智慧共享财务平台 | V24: 1.营业执照 2.组织机构设置文件 3.商户号开立业务办理回执（若有） | W24: 各级单位-财务资产部-出纳管理、各级单位-财务资产部-资金管理、各级单位-财务资产部-主任、各级单位-业务部门-经办人员、各级单位-业务部门-部门负责人 | X24: 每季度 | Y24: 抽查 | AA24: 每年 | AB24: 抽查 | AH24: 是 | AI24: 是 | AJ24: 《国网财务部关于规范和加强商户号管理的通知》（财金[2025]2号）第二章第1条、第3条、第5条 | AK24: 国网财务部
I25: 财务管理-12.商户号合规开立控制-控制措施02 | J25: 各级单位财务部门对商户号开立协议进行审核，核验绑定账户为本单位或上级单位对公账户，向关联银行账户提现资金周期不得超过T+1且自动划转。 | M25: √ | O25: √ | P25: √ | T25: 线上管控-待建 | U25: 智慧共享财务平台、数字化法治企业建设平台 | V25: 1.商户号开立协议 | W25: 各级单位-财务资产部-出纳管理、各级单位-财务资产部-资金管理、各级单位-财务资产部-主任 | X25: 每季度 | Y25: 抽查 | AA25: 每年 | AB25: 抽查 | AH25: 是 | AI25: 是 | AJ25: 《国网财务部关于规范和加强商户号管理的通知》（财金[2025]2号）第二章第4条，第三章第7条 | AK25: 国网财务部
E26: 商户号未及时办理监控授权，资金动向无法实时监测，异常交易识别不及时，易诱发资金违规占用及挪用风险。 | F26: 1.商户号未办理监控授权； 2.提现周期较长，向关联银行账户提现周期超过T+1日，资金未能及时回笼，存在资金沉淀及安全风险。 | G26: 13.商户号办理监控控制 | H26: 商户号及时纳入监控，定期监控资金流水动向及频次。 | I26: 财务管理-13.商户号办理监控控制-控制措施01 | J26: 各级单位业务部门对具备监控条件的商户号在完成开立手续后的规定时间内向数科公司办理商户号监控授权，确保纳入公司资金监控体系。 | L26: √ | M26: √ | T26: 线上管控-已建 | U26: 智慧共享财务平台 | V26: 1.监控授权书 | W26: 各级单位-业务部门-经办人、各级单位-业务部门-部门负责人 | X26: 每季度 | Y26: 抽查 | AA26: 每年 | AB26: 抽查 | AH26: 是 | AI26: 是 | AJ26: 《国网财务部关于规范和加强商户号管理的通知》（财金[2025]2号）第四章第10条 《国家电网有限公司司库管理办法》（国网（财/2）3452023）第三章第三十七条 | AK26: 国网财务部
I27: 财务管理-13.商户号办理监控控制-控制措施02 | J27: 各级单位财务部门监控商户号资金，核查是否存在除“T+1”日自动划转至上级账户外的资金沉淀。 | P27: √ | T27: 线上管控-待建 | U27: 智慧共享财务平台 | V27: 1.资金流水明细 2.余额调节表 | W27: 各级单位-财务资产部-出纳管理、各级单位-财务资产部-资金管理、各级单位-财务资产部-主任 | X27: 每季度 | Y27: 抽查 | AA27: 每年 | AB27: 抽查 | AH27: 是 | AI27: 是 | AJ27: 《国网财务部关于规范和加强商户号管理的通知》（财金[2025]2号）第四章第12条 | AK27: 国网财务部
A28: 财务管理 | B28: 二、账户管理 | C28: 资金资产安全 | D28: 数字钱包开立 | E28: 数字钱包开立未履行审批手续，易滋生账外账及小金库，未纳入系统统一监管，账实不符，引发资金流失风险。 | G28: 14.数字钱包合规开立控制 | H28: 严格履行数字钱包开立审批手续，规范开户渠道、开户主体，严禁未批先设。 | I28: 财务管理-14.数字钱包合规开立控制-控制措施01 | J28: 通过智慧共享财务平台办理数字钱包开、变、销审批，限定工行、农行、中行、建行、交行、邮储6家银行办理，超出管控标准及开户范围的，须经各二级单位本部审核和总部审批；相关手续办结后规定时间内，须在智慧共享财务平台完成开户信息维护。 | L28: √ | M28: √ | T28: 线上管控-已建 | U28: 智慧共享财务平台 | V28: 1.数字钱包开立申请 2.数字钱包开立业务办理回执 3.数字钱包登记审批单 4.数字钱包台账 | W28: 各级单位-财务资产部-出纳管理、各级单位-财务资产部-资金管理、各级单位-财务资产部-主任、各级单位-业务部门-经办人员、各级单位-业务部门-部门负责人 | X28: 每季度 | Y28: 抽查 | AA28: 每年 | AB28: 抽查 | AH28: 是 | AI28: 是 | AJ28: 《国家电网有限公司司库管理办法》（国网（财/2）3452023）第三章第二十八条、第三十五条 | AK28: 国网财务部
I29: 财务管理-14.数字钱包合规开立控制-控制措施02 | J29: 各级单位财务部门规范数字钱包开立经办管理，须由本人或授权人员办理，经办人员应为正式编制，手续须由至少两名人员共同办理，强化岗位制衡。 | K29: √ | T29: 线下管控 | V29: 1.数字钱包开立业务办理回执 | W29: 各级单位-财务资产部-主任、各级单位-财务资产部-经办人员 | X29: 每季度 | Y29: 抽查 | AA29: 每年 | AB29: 抽查 | AH29: 是 | AI29: 是 | AJ29: 《国家电网有限公司司库管理办法》（国网（财/2）3452023）第三章第三十六条 | AK29: 国网财务部
G30: 15.数字钱包监控控制 | H30: 数字钱包及时纳入监控，定期监控资金流水动向及频次。 | I30: 财务管理-15.数字钱包办理监控控制-控制措施01 | J30: 各级单位对具备监控条件的数字钱包在完成开立后，需在规定时限内办理监控授权，确保纳入公司资金监控体系。 | L30: √ | M30: √ | T30: 线上管控-已建 | U30: 智慧共享财务平台 | V30: 1.《银企互联数字人民币钱包授权书》 2.《资金结算系统数字人民币钱包服务注册（变更）申请表》 3.《资金结算系统数字人民币钱包流程注册（变更）申请表》 | W30: 各级单位-财务资产部-出纳管理、各级单位-财务资产部-资金管理、各级单位-财务资产部-主任 | X30: 每季度 | Y30: 抽查 | AA30: 每年 | AB30: 抽查 | AH30: 是 | AI30: 是 | AJ30: 《国家电网有限公司司库管理办法》（国网（财/2）3452023）第三章第三十七条 | AK30: 国网财务部
C31: 资金资产安全 | D31: 银行账户变更 | E31: 银行账户变更不及时，与经营信息不一致；账户信息变更后未同步更新智慧共享财务平台登记信息，可能导致台账数据失真。 | G31: 16.银行账户变更及时性、必要性控制 | H31: 银行账户信息纳入管控并及时变更 | I31: 财务管理-16.银行账户变更及时性控制-控制措施01 | J31: 各级单位财务部门（经营类账户）或业务部门（非经营类账户）对于银行账户经营信息、账户属性发生变动的，及时完成变更分级审批流程；对于经营类账户的特殊事项变更（包括集团账户变更为独立账户、监控账户变更为无法监控账户、其他分类变更为专用账户），须经各二级单位本部审核和公司总部审批；账户信息变更后，按规定时间在智慧共享财务平台维护登记，确保银行账户台账信息准确、账实相符。 | L31: √ | M31: √ | T31: 线上管控-已建 | U31: 智慧共享财务平台 | V31: 1.《资金结算系统账户服务注册（变更）申请书》 | W31: 各级单位-财务资产部-出纳管理、各级单位-财务资产部-资金管理、各级单位-财务资产部-主任 各级单位-业务部门-经办人员、各级单位-业务部门-部门负责人 | X31: 每季度 | Y31: 抽查 | AA31: 每年 | AB31: 抽查 | AH31: 是 | AI31: 是 | AJ31: 《国家电网有限公司司库管理办法》（国网（财/2）3452023）第三章第三十条、第三十五条、第三十七条、第三十八条 《国家电网有限公司关于印发〈“四严五强六十条”资金安全管理规程〉及资金安全监控规则的通知》（国家电网财[2021]329号）第26条、27条 | AK31: 国网财务部
I32: 财务管理-16.银行账户变更及时性控制-控制措施02 | J32: 各级单位财务部门（经营类账户）或业务部门（非经营类账户）规范银行账户变更经办管理，经办人员应为正式编制，手续须由至少两名人员共同办理，强化岗位制衡。 | K32: √ | T32: 线下管控 | V32: 1.银行账户变更业务办理回执（两名经办人员签字） | W32: 各级单位-财务资产部-财务主任、各级单位-业务部门-部门负责人 | X32: 每季度 | Y32: 抽查 | AA32: 每年 | AB32: 抽查 | AH32: 是 | AI32: 是 | AJ32: 《国家电网有限公司司库管理办法》（国网（财/2）3452023）第三章第三十六条 | AK32: 国网财务部
C33: 资金资产安全 | D33: 商户号变更 | E33: 商户号变更不及时，与经营信息不一致；账户信息变更后未同步更新智慧共享财务平台登记信息，可能导致台账数据失真。 | G33: 17.商户号变更及时性、必要性控制 | H33: 商户号信息纳入管控并及时变更 | I33: 财务管理-17.商户号信息纳入管控并及时变更-控制措施01 | J33: 各级单位业务部门对商户号相关信息发生变更时，应在智慧共享财务平台发起商户号变更申请，其中，商户号关联银行账户变更通过各二级单位本部审核、公司总部审批，其他变更由各二级单位自行管理。完成线下信息变更及线上变更登记审批后，须在规定时间内在智慧共享财务平台维护登记，确保商户号台账信息准确、账实相符。 | L33: √ | M33: √ | T33: 线上管控-已建 | U33: 智慧共享财务平台 | V33: 1.《资金结算系统商户号服务注册（变更）申请书》 | W33: 各级单位-财务资产部-出纳管理、各级单位-财务资产部--资金管理、各级单位-财务资产部-主任、各级单位-业务部门-经办人员、各级单位-业务部门-部门负责人 | X33: 每季度 | Y33: 抽查 | AA33: 每年 | AB33: 抽查 | AH33: 是 | AI33: 是 | AJ33: 《国家电网有限公司司库管理办法》（国网（财/2）3452023）第三章第三十条、第三十五条、第三十七条、第三十八条 《国网财务部关于规范和加强商户号管理的通知》（财金[2025]2号）第五章一十五条 | AK33: 国网财务部
A34: 财务管理 | B34: 二、账户管理 | C34: 资金资产安全 | D34: 数字钱包变更 | E34: 数字钱包变更不及时，与经营信息不一致；账户信息变更后未同步更新智慧共享财务平台登记信息，可能导致台账数据失真。 | G34: 18.数字钱包变更及时性、必要性控制 | H34: 数字钱包信息纳入管控并及时变更 | I34: 财务管理-18.数字钱包信息纳入管控并及时变更-控制措施01 | J34: 各级单位财务部门对于数字钱包经营信息、账户属性发生变动的，及时完成变更分级审批流程，对于特殊事项变更（监控账户变更为无法监控账户），须经各二级单位本部审核和公司总部审批；信息变更后，按规定时间在智慧共享财务平台维护登记，确保数字钱台账信息准确、账实相符。 | L34: √ | M34: √ | T34: 线上管控-已建 | U34: 智慧共享财务平台 | V34: 1.《资金结算系统数字人民币钱包服务注册（变更）申请书》 | W34: 各级单位-财务资产部-出纳管理、各级单位-财务资产部-资金管理、各级单位-财务资产部-主任、各级单位-业务部门-经办人员、各级单位-业务部门-部门负责人 | X34: 每季度 | Y34: 抽查 | AA34: 每年 | AB34: 抽查 | AH34: 是 | AI34: 是 | AJ34: 《国家电网有限公司司库管理办法》（国网（财/2）3452023）第三章第三十条、第三十二条、第三十三条、第三十五条、第三十七条、第三十八条 | AK34: 国网财务部
I35: 财务管理-18.数字钱包信息纳入管控并及时变更-控制措施02 | J35: 各级单位财务部门规范数字钱包变更经办管理，经办人员应为正式编制，手续须由至少两名人员共同办理，强化岗位制衡。 | K35: √ | T35: 线下管控 | V35: 1.数字钱包变更业务办理回执（两名经办人员签字） | W35: 各级单位-财务资产部-主任、各级单位-业务部门-部门负责人 | X35: 每季度 | Y35: 抽查 | AA35: 每年 | AB35: 抽查 | AH35: 是 | AI35: 是 | AJ35: 《国家电网有限公司司库管理办法》（国网（财/2）3452023）第三章第三十六条 | AK35: 国网财务部
C36: 资金资产安全 | D36: 银行账户撤销 | E36: 银行账户撤销不及时，销户滞后于工商主体注销，久悬账户未及时注销，应销未销诱发“账外账”风险。 | F36: 1.银行账户注销不及时：开立主体已完成工商注销，但账户仍存续。 2.低效、无效账户及久悬账户未及时清理。 3.银行已销户未登记：银行账户已注销，但在中台台账登记不及时。 | G36: 19.银行账户注销及时性、规范性控制 | H36: 银行账户在工商变更或注销前、业务完结后（如工程完结农民工专户及时注销）完成账户注销，及时登记台账。 | I36: 财务管理-19.银行账户注销及时性、规范性控制-控制措施01 | J36: 各级单位财务部门（经营类账户）或业务部门（非经营类账户）规范银行账户撤销经办管理，须由本人或授权人员办理，经办人员应为正式编制，手续须由至少两名人员共同办理，强化岗位制衡。 | K36: √ | T36: 线下管控 | V36: 1.银行账户撤销业务办理回执（两人签字） | W36: 各级单位-财务资产部-主任、各级单位-业务部门-部门负责人 | X36: 每季度 | Y36: 抽查 | AA36: 每年 | AB36: 抽查 | AH36: 是 | AI36: 是 | AJ36: 《国家电网有限公司司库管理办法》（国网（财/2）3452023）第三章第三节第三十六条 | AK36: 国网财务部
I37: 财务管理-19.银行账户注销及时性、规范性控制-控制措施02 | J37: 各级单位财务部门（经营类账户）或业务部门（非经营类账户）规范办理银行账户注销，终止监控授权后按制度要求时限办理销户，严格执行先销账户、后销工商主体顺序，注销相关手续办结后在规定时间内，完成智慧共享财务平台销户登记，报二级单位备案。 | L37: √ | M37: √ | T37: 线上管控-已建 | U37: 智慧共享财务平台 | V37: 1.《资金结算系统账户服务注册（变更）申请表》 2.银行账户撤销业务办理回执 | W37: 各级单位-财务资产部-出纳管理、各级单位-财务资产部-资金管理、各级单位-财务资产部-主任、各级单位-业务部门-经办人员、各级单位-业务部门-部门负责人 | X37: 每季度 | Y37: 抽查 | AA37: 每年 | AB37: 抽查 | AH37: 是 | AI37: 是 | AJ37: 《国家电网有限公司司库管理办法》（国网（财/2）3452023）第三章第二十九条、第三十六条、第三十七条 | AK37: 国网财务部
I38: 财务管理-19.银行账户注销及时性、规范性控制-控制措施03 | J38: 各级单位财务部门加强低效、无效账户监控。销户资金应及时、全量回笼。 | Q38: √ | T38: 线上管控-待建 | U38: 智慧共享财务平台 | V38: 1.低效账户督办单 2.银行账户撤销业务办理回执（若有） | W38: 各级单位-财务资产部-出纳管理、各级单位-财务资产部-资金管理、各级单位-财务资产部-主任、各级单位-业务部门-经办人员、各级单位-业务部门-部门负责人 | X38: 每季度 | Y38: 抽查 | AA38: 每年 | AB38: 抽查 | AH38: 是 | AI38: 是 | AJ38: 《国家电网有限公司司库管理办法》（国网（财/2）3452023）第三章第三十九条、第十一章第二百九十八条 | AK38: 国网财务部
C39: 资金资产安全 | D39: 商户号撤销 | E39: 商户号撤销不及时，销户滞后于工商主体注销，应销未销诱发“账外账”风险。 | G39: 20.商户号注销及时性、规范性控制 | H39: 商户号在工商注销前完成账户注销，及时登记台账。 | I39: 财务管理-20.商户号注销及时性、规范性控制-控制措施01 | J39: 各级单位业务部门提交商户号撤销资料，负责资料完整性、真实性。 | M39: √ | T39: 线下管控 | V39: 1.商户号注销申请书 | W39: 各级单位-业务部门-经办人员、各级单位-业务部门-部门负责人 | X39: 每季度 | Y39: 抽查 | AA39: 每年 | AB39: 抽查 | AH39: 否 | AI39: 否 | AK39: 国网财务部
I40: 财务管理-20.商户号注销及时性、规范性控制-控制措施02 | J40: 各级单位业务部门规范商户号注销程序，及时完成商户号资金清算。商户号注销时，应在智慧共享财务平台发起商户号注销申请，注销审批流程由各二级单位审批。销户资金应及时、全量回笼。 | L40: √ | M40: √ | T40: 线上管控-待建 | U40: 智慧共享财务平台 | V40: 1.商户号撤销业务办理回执（若有） | W40: 各级单位-财务资产部-出纳管理、各级单位-财务资产部-资金管理、各级单位-财务资产部-主任、各级单位-业务部门-经办人员、各级单位-业务部门-部门负责人 | X40: 每季度 | Y40: 抽查 | AA40: 每年 | AB40: 抽查 | AH40: 是 | AI40: 是 | AJ40: 《国家电网有限公司司库管理办法》（国网（财/2）3452023）第三章第二十九条、第三十六条、第三十七条 《国网财务部关于规范和加强商户号管理的通知》（财金[2025]2号）第二章第6条 | AK40: 国网财务部
...

Sheet 预算
A2: 业 务 条 线 | B2: 业 务 领 域 | C2: 控 制 目 标 | D2: 业务流程步骤 | E2: 经营风险 | F2: 典型问题 | G2: 关键控制点 | H2: 控制要求 | I2: 控制措施 编号 | J2: 控制措施 | K2: 控制措施分类 | T2: 控制方式 | U2: 控制系统 | V2: 控制载体 | W2: 责任主体 | X2: 业务自评价 | AA2: 集团监督评价 | AD2: 数字化监督场景 | AH2: 现有制度及文件落实情况 | AK2: 总部审核部门
K3: 不相容岗位 | L3: 分级授权 | M3: 业务真实性控制 | N3: 预算管控 | O3: 合同控制 | P3: 收付控制 | Q3: 会计监督 | R3: 财产保护 | S3: 分析与评价 | X3: 评价频率 | Y3: 评价范围 | Z3: 评价结论 | AA3: 评价频率 | AB3: 评价范围 | AC3: 评价结论 | AD3: 数字化监督场景 | AE3: 监督频率 | AF3: 监督范围 | AG3: 评价结论 | AH3: 是否已要求 | AI3: 是否满足要求 | AJ3: 对应制度及文件名称
A4: 财务管理 | B4: 三、预算管理 | C4: 会计信息真实完整、资金资产安全、税务合规 | D4: 战略支撑 （事前） | E4: 1.财务规划与公司战略协同不足，未有效承接战略指标体系。 2.规划没有科学分解到年度预算，落地执行出现偏差。 3.预算编制未与核价规则有效衔接，导致核价结果不及预期，进而影响战略目标的实现。 | F4: 规划目标与战略脱节：未按照战略目标体系设置规划目标，各级规划目标未有效协同，目标测算未与核价规则衔接，年度决算完成后未与规划目标进行对比分析。 | G4: 21.规划目标与战略一致性审核 | H4: 规划目标测算有效衔接战略指标体系及核价规则，推动规划投资全部纳入核价、核价规则深度融入经营，经营成果有效落实规划。 | I4: 财务管理-21.规划目标与战略一致性审核-控制措施01 | J4: 战略指标一致性审查。国网及各二级单位财务部门在规划编制环节核查经营目标与战略指标体系的一致性，对指标缺失或脱节的情形，不予通过。 | N4: √ | Q4: √ | T4: 线下管控 | V4: 1.公司战略规划方案 2.公司预算方案。 | W4: 各级单位-财务部门-预算管理人员 | X4: 年度 | Y4: 全量 | AA4: 年度 | AB4: 全量 | AH4: 是 | AI4: 是 | AJ4: 《国家电网有限公司全面预算管理办法》（国网（财/2）375-2026）第三条、第十四条 | AK4: 国网财务部
I5: 财务管理-21.规划目标与战略一致性审核-控制措施02 | J5: 建立“五年规划、三年核价、年度经营”相贯通的滚动预算管控机制。国网及各二级单位财务部门在智慧共享财务平台部署多维联动测算模型，建立“1+N”管控场景（1个监管业务典型场景，N个非监管业务个性化场景），在进行财务规划编制时，以核价参数为约束，合理安排规划期年度经营目标、投资和成本，逐年滚动预测，对比分析规划目标、核价参数落实情况，科学编制预算。 | N5: √ | Q5: √ | S5: √ | T5: 线上管控-待建 | U5: 智慧共享财务平台 | V5: 1.公司战略规划方案 2.公司预算方案 3.多维联动测算模型。 | W5: 各级单位-财务部门-预算管理人员 | X5: 年度 | Y5: 全量 | AA5: 年度 | AB5: 全量 | AD5: 多维联动测算模型 | AE5: 年度 | AF5: 全量 | AH5: 是 | AI5: 是 | AJ5: 《国家电网有限公司全面预算管理办法》（国网（财/2）375-2026）第三条、第十四条、第二十二条 | AK5: 国网财务部
E6: 1.决策依据不充分，对经营形势研判不足，缺乏充分调研和可行性分析。 2.决策流程不规范，未严格履行决策程序，导致预算决策出现偏差。 3.预算调整不及时，预算基础或边际条件发生重大变化时，未及时履行预算调整程序。 | F6: 预算决策流程不规范：重大项目投资未按规定履行本单位“三重一大”决策程序；预算决策流程流于形式，部分事项先执行后补签、越权审批或缺少书面记录；项目已出现明显亏损或环境变化，仍继续投入，缺少主动中止或调整的机制。 | G6: 22.预算决策程序审核 | H6: 预算决策依据充分、完整，程序规范、有效，及时响应预算基础或边际条件重大变化，确保公司经营稳健。 | I6: 财务管理-22.预算决策程序审核-控制措施01 | J6: 强化事前可研论证。每年，各级单位业务部门结合实际情况，明确本专业投入重点，并据此组织开展可研评审及项目储备。原则上所有纳入业务预算的项目均需履行项目储备程序，并向财务部门提供项目清单，清单中包括以下信息：项目名称、金额、建设内容、可研评审及批复文号等。 | M6: √ | N6: √ | T6: 线下管控 | V6: 1.项目立项相关材料 2.储备项目明细。 | W6: 各级单位-业务部门-经办人 | X6: 年度 | Y6: 抽查 | AA6: 年度 | AB6: 抽查 | AH6: 是 | AI6: 是 | AJ6: 《国家电网有限公司全面预算管理办法》（国网（财/2）375-2026）第十六条、第二十四条第二十二条;财预〔2025〕27号 国网财务部关于印发《国家电网有限公司财务支出可研经济性与财务合规性评价工作指引（2025）》的通知第一章1.4 | AK6: 国网财务部
I7: 财务管理-22.预算决策程序审核-控制措施02 | J7: 规范决策程序。各级单位办公室、法律部门等归口管理部门制定决策事项清单，对需纳入“三重一大”决策的预算事项进行明确；对预算方案决策程序进行合规性审核，决策会议由专人记录，会议纪要由会议主持人或公司主要负责同志签发，事后及时归档，确保决策流程完整规范。 | M7: √ | N7: √ | T7: 线下管控 | V7: 1.决策事项清单 2.会议纪要。 | W7: 各级单位-业务部门-经办人 | X7: 年度 | Y7: 全量 | AA7: 年度 | AB7: 全量 | AH7: 是 | AI7: 是 | AJ7: 《国家电网有限公司全面预算管理办法》（国网（财/2）375-2026）第十四条、第十五条 | AK7: 国网财务部
I8: 财务管理-22.预算决策程序审核-控制措施03 | J8: 及时履行预算调整程序。在预算基础或边际条件发生重大变化时，各级单位业务部门要及时向财务部提出预算调整建议，财务部门要及时组织开展经营分析，及时启动预算调整程序，在预算调整批复后，及时推进落地实施，确保公司稳健经营。 | N8: √ | Q8: √ | T8: 线上管控-已建 | U8: 智慧共享财务平台 | V8: 1.公司预算调整方案 2.决策记录。 | W8: 各级单位-业务部门-经办人、各级单位-财务部门-预算管理人员 | X8: 年度 | Y8: 全量 | AA8: 年度 | AB8: 全量 | AD8: 预算调整模块 | AE8: 年度 | AF8: 全量 | AH8: 是 | AI8: 是 | AJ8: 《国家电网有限公司全面预算管理办法》（国网（财/2）375-2026）第三十七条、第三十八条、三十九条 | AK8: 国网财务部
E9: 1.预算责任泛化。预算责任框架体系尚未健全完善，立项颗粒度不精细，预期目标不明确，导致资源错配或低效使用。 2.资源分配不精准。资源投入与公司重点任务脱节，区域、网架资源分配不均衡、布局不合理，影响电网均衡发展。 | F9: 生产性投入不足：资源分配结构不合理，生产性投入占比偏低，难以满足安全生产、设备运维等核心业务需求。 | G9: 23.资源配置精准性管控 | H9: 资源分配满足公司战略落地、监审核价、业务发展等预期目标要求，并确保预算责任主体明确。 | I9: 财务管理-23.资源配置精准性管控-控制措施01 | J9: 完善预算责任框架体系。各级单位财务部门在智慧共享财务平台中，完善预算责任框架体系，细化成本中心、利润中心，延伸至供电所或班组（产业、金融、国际、战新等其他业务板块根据自身业务实际设置成本中心、利润中心），并将预算指标层层分解。 | N9: √ | Q9: √ | T9: 线上管控-待建 | U9: 智慧共享财务平台 | V9: 1.预算责任框架体系。 | W9: 各级单位-财务部门-预算管理人员 | X9: 年度 | Y9: 全量 | AA9: 年度 | AB9: 全量 | AD9: 预算下达模块 | AE9: 年度 | AF9: 全量 | AH9: 是 | AI9: 是 | AJ9: 《国家电网有限公司全面预算管理办法》（国网（财/2）375-2026）第三十二条、第三十三条 | AK9: 国网财务部
I10: 财务管理-23.资源配置精准性管控-控制措施02 | J10: 强化财务支出分类管理。健全财务支出四级分类体系，对于资产动因类支出，原则上应关联至三级同源目录资产（价值核算单元）；对于组织动因类支出，分解至具体业务单元或部门，原则上以供电所为最小单元进行建项和执行管控。 | N10: √ | Q10: √ | T10: 线下管控 | V10: 1.预算分解明细。 | W10: 各级单位-财务部门-成本管理人员 | X10: 年度 | Y10: 全量 | AA10: 年度 | AB10: 全量 | AH10: 是 | AI10: 是 | AJ10: 《国家电网有限公司全面预算管理办法》（国网（财/2）375-2026）第三十二条、第三十三条 | AK10: 国网财务部
I11: 财务管理-23.资源配置精准性管控-控制措施03 | J11: 依托作业标准成本开展资源配置。国网财务部根据业务部门、各级单位在线填报或通过系统推送变电站数量、线路长度、人员数量等业务动因参数，组织审定各业务投向、各级单位标准成本，并以此为基础，编制下达检修运维费用预算。电网业务板块，各级单位财务部门开展本地化改造，在上级核定的成本预算范围内，开展本层级检修运维费用预算分解。产业、金融、国际、战新等其他业务板块，开展其他运营标准成本本地化改造，加强费用预算管控。 | N11: √ | Q11: √ | T11: 线上管控-已建 | U11: 智慧共享财务平台 | V11: 1.标准成本体系。 | W11: 各级单位-财务部门-成本管理人员 | X11: 年度 | Y11: 全量 | AA11: 年度 | AB11: 全量 | AD11: 预算下达模块 | AE11: 年度 | AF11: 全量 | AH11: 是 | AI11: 是 | AJ11: 《国家电网有限公司全面预算管理办法》（国网（财/2）375-2026）第二十五条、第三十二条 | AK11: 国网财务部
A12: 财务管理 | B12: 三、预算管理 | C12: 会计信息真实完整、资金资产安全、税务合规 | D12: 执行控制 （事中） | E12: 缺乏经营目标过程管控，未及时进行预算执行情况分析，导致预算执行不均衡或年度预算目标无法完成。 | F12: 未完成预算下达指标：决算审核后，部分经营指标未完成年度预算下达目标。 | G12: 24.预算执行情况分析 | H12: 严格预算执行控制，及时发现和报告重大预算事项，顺利实现公司战略及经营目标。 | I12: 财务管理-24.预算执行情况分析-控制措施01 | J12: 定期开展预算执行情况分析。国网及各级单位财务部门设定月度预算执行目标，在智慧共享财务平台部署，并设置预警阈值，每月，各级单位财务部门将实际执行进度与预算进度进行对比分析，并提前制定预控措施，确保均衡规范完成年度目标，其中：对于电网监管业务，重点关注电量及增速、电价水平、成本入账进度、利润水平等执行情况及均衡性；对于产业、金融、国际、战新及原集体企业等市场化业务，重点关注利润进度、毛利率水平、关联交易情况等。 | N12: √ | Q12: √ | S12: √ | T12: 线上管控-待建 | U12: 智慧共享财务平台 | V12: 1.预算执行分析报告。 | W12: 各级单位-财务部门-预算管理人员 | X12: 年度 | Y12: 抽查 | AA12: 年度 | AB12: 抽查 | AD12: 预算分析模块 | AE12: 每月 | AF12: 全量 | AH12: 是 | AI12: 是 | AJ12: 《国家电网有限公司全面预算管理办法》（国网（财/2）375-2026）第四十条-第四十三条 | AK12: 国网财务部
E13: 成本预算执行管控不严，导致成本列支不规范、超预算列支等问题，包括： （1）无预算、超预算列支成本，导致预算管控失效，引发资金管控风险； （2）预算单控费用执行不严，“三公”经费、会议费等重点支出预算未实施单项控制，引发重点费用管控失效风险； （3）资本性支出与成本性支出未严格区分，导致会计核算混乱，引发会计信息质量失真； （4）项目支出不规范，实际列支内容与预算安排不一致，引发项目资金滥用及会计信息失真风险； | F13: 成本性项目及资本性项目列支超年度预算：部分成本性项目及资本性项目在列支时，未及时履行调整流程，导致实际支出超出年度预算。 | G13: 25.各会计科目、项目预算系统编制及控制 | H13: 公司可控费用纳入预算统一管理，严禁发生预算外支出。 | I13: 财务管理-25.各会计科目、项目预算系统编制及控制-控制措施01 | J13: 系统部署项目预算控制规则。国网及各二级单位财务部门根据项目可研批复金额，在智慧共享财务平台中对各类成本性、资本性项目、费用科目配置预算及控制规则，通过系统预警、规则强控，确保无预算不支出、有预算不超支。 | N13: √ | Q13: √ | T13: 线上管控-已建 | U13: 智慧共享财务平台 | V13: 1.业务预算需求审批表 2.项目可研评审批复文件。 | W13: 各级单位-财务部门-项目管理人员 | X13: 年度 | Y13: 抽查 | AA13: 年度 | AB13: 抽查 | AD13: 财务预算编审控制和预算申报服务模块 | AE13: 年度 | AF13: 全量 | AH13: 是 | AI13: 是 | AJ13: 《国家电网有限公司全面预算管理办法》（国网（财/2）375-2026）第三十五条 | AK13: 国网财务部
F14: 单项费用控制失效：对于“三公” 经费、会议费进行总额控制，未单独进行预算分解，无法进行单项控制。 | G14: 26.重点单项费用预算编制及控制 | H14: 重点费用单项列支规范，与预算下达指标保持一致。 | I14: 财务管理-26.重点单项费用预算编制及控制-控制措施01 | J14: 上级部署单控费用预算。国网及各二级单位财务部门在智慧共享财务平台中根据年度预算对“三公”经费、会议费等实施单项控制，由上级单位在系统中核定，各级单位如需调整需履行预算调整程序，确保重点费用预算能控、在控。 | N14: √ | Q14: √ | T14: 线上管控-已建 | U14: 智慧共享财务平台 | V14: 1.费用支出明细 2.单项费用预算。 | W14: 各级单位-财务部门-预算管理人员 | X14: 年度 | Y14: 抽查 | AA14: 年度 | AB14: 抽查 | AD14: 财务预算申报服务模块 | AE14: 年度 | AF14: 全量 | AH14: 是 | AI14: 是 | AJ14: 《国家电网有限公司全面预算管理办法》（国网（财/2）375-2026）第三十五条 | AK14: 国网财务部
F15: 项目立项管理不规范：项目可研审核不严格，例如，存在通过生产大修项目购买电脑、隔离开关等固定资产的情况。 | G15: 27.项目可研经济性、财务合规性检查 | H15: 项目立项规范合规，项目支出性质准确。 | I15: 财务管理-27.项目可研经济性、财务合规性检查-控制措施01 | J15: 开展项目支出性质检查。各级单位财务部门协同各级业务归口管理部门、各级经研院所组织开展项目可研经济性、财务合规性评审，检查立项依据是否充分、立项类别是否准确，重点关注：报告中应包含维修资产的设备编码、资产原值等关键信息，检查项目金额是否超过维修资产原值的50%，物料清单中是否包含固定资产目录中设备。 | N15: √ | Q15: √ | T15: 线下管控 | V15: 1.项目可研报告或建议书 2.储备项目明细。 | W15: 各级单位-财务部门-项目管理人员 | X15: 年度 | Y15: 抽查 | AA15: 年度 | AB15: 抽查 | AH15: 是 | AI15: 是 | AJ15: 《国家电网有限公司全面预算管理办法》（国网（财/2）375-2026）第十六条、第二十二条;财预〔2025〕27号 国网财务部关于印发《国家电网有限公司财务支出可研经济性与财务合规性评价工作指引（2025）》的通知第一章1.4 | AK15: 国网财务部
F16: 项目结算不准确：多结算施工费用；虚列项目，跨期结算项目费用，结算依据不充分。 | G16: 28.项目预算执行控制 | H16: 项目支出规范，实际列支内容与预算安排保持一致。 | I16: 财务管理-28.项目预算执行控制-控制措施01 | J16: 开展项目实施内容检查。各级单位业务部门在项目完工后，应组织专业机构出具项目结算报告，并对项目支出内容进行检查，重点关注：施工费结算方式是否与合同一致、是否采购可研报告之外的物料、实施内容是否变更，如有变更是否履行变更程序等。各级单位财务部门在智慧共享财务平台中对项目支出合同、发票、上传的材料，参考项目可研报告中项目实施内容，从完整性、规范性、合理性等方面进行线上审核，确保项目支出规范。 | M16: √ | N16: √ | Q16: √ | T16: 线上管控-已建 | U16: 智慧共享财务平台 | V16: 1.项目结算报告 2.项目支出报账材料 3.项目可研报告。 | W16: 各级单位-业务部门-经办人、各级单位-财务部门-项目管理人员 | X16: 年度 | Y16: 抽查 | AA16: 年度 | AB16: 抽查 | AD16: 采购服务报账模块 | AE16: 年度 | AF16: 全量 | AH16: 是 | AI16: 是 | AJ16: 《国家电网有限公司全面预算管理办法》（国网（财/2）375-2026）第三十四条、第三十五条 | AK16: 国网财务部
A17: 财务管理 | B17: 三、预算管理 | C17: 会计信息真实完整、资金资产安全、税务合规 | D17: 执行控制 （事中） | E17: （5）成本开支内容不符合输配电成本监审要求，影响输配电价格核定，引发监管合规风险。 | F17: 监管单位成本预算安排规模与监审要求不符：材料修理费、其他运营费用安排严重偏离成本监审费率，与非监管单位关联交易利润率超10%，监管业务中列支广告宣传费（不含停电故障信息公告、电力安全保护宣传、电力设备安全警示等）等。 | G17: 29.预算编制与输配电成本一致性审核 | H17: 成本开支符合输配电成本监审要求。 | I17: 财务管理-29.预算编制与输配电成本一致性审核-控制措施01 | J17: 强化核价规则约束。各级单位财务部门根据成本监审及核价规则，设置预警规则，监控成本执行情况，重点关注：材料修理费、其他运营费用（含管理类费用）费率是否与核价费率严重偏离，引发成本核减或费率下滑风险；对广告宣传费、研究开发费等特殊敏感会计科目严格审核，确保相关成本支出符合成本监审要求。 | N17: √ | Q17: √ | T17: 线下管控 | V17: 1.成本支出相关资料。 | W17: 各级单位-财务部门-电价管理人员 | X17: 年度 | Y17: 抽查 | AA17: 年度 | AB17: 抽查 | AH17: 是 | AI17: 是 | AJ17: 《国家电网有限公司全面预算管理办法》（国网（财/2）375-2026）第二十二条、第三十五条 | AK17: 国网财务部
C18: 会计信息真实完整、资金资产安全、税务合规 | D18: 闭环管控 （事后） | E18: 未按照预算责任框架体系对各级经营单元进行投入产出评价，未对资源配置提出针对性管理建议，导致资源投入与业务指标提升关联度不高，引发低效无效风险。 | F18: 投入产出评价结果失真。受预算责任框架体系不完善、资源投向不清晰、资源投入与业务指标提升关联度不高等影响，投入产出评价结果不精准，无法有效指导后续资源分配。 | G18: 75.投入产出分析评价 | H18: 依托预算责任体系及项目四级分类体系，开展投入产出分析，指导后续资源配置。 | I18: 财务管理-75.投入产出分析评价-控制措施01 | J18: 定期开展投入产出评价。各级单位财务部门定期组织相关业务部门，对已完工项目投入产出情况开展评价，其中：对于资产动因类支出，通过与作业标准成本比、与同类设备支出水平比、检查预期目标实现情况等方式进行评价；对于组织动因类支出，通过横向对标、与历史水平对比等方式开展评价。 | N18: √ | Q18: √ | S18: √ | T18: 线下管控 | V18: 1.项目投入明细 2.项目产出评价结果。 | W18: 各级单位-财务部门-项目管理人员 | X18: 年度 | Y18: 抽查 | AA18: 年度 | AB18: 抽查 | AH18: 是 | AI18: 是 | AJ18: 《国家电网有限公司全面预算管理办法》（国网（财/2）375-2026）第四十一条、第四十二条、第四十三条 | AK18: 国网财务部
I19: 财务管理-75.投入产出分析评价-控制措施02 | J19: 加强评价结果应用。各级单位财务部门定期将投入产出评价结果推送业务部门，并指导后续业务预算审核； 各级单位业务部门结合实际对评价结果进行分析，对评价规则进行完善和反馈，持续提升评价精准性，并参考开展后续投向安排、设备选型等工作。 | N19: √ | Q19: √ | S19: √ | T19: 线下管控 | V19: 1.项目投入明细 2.项目产出评价结果。 | W19: 各级单位-业务部门-经办人、各级单位-财务部门-项目管理人员 | X19: 年度 | Y19: 抽查 | AA19: 年度 | AB19: 抽查 | AH19: 是 | AI19: 是 | AJ19: 《国家电网有限公司全面预算管理办法》（国网（财/2）375-2026）第四十一条、第四十二条、第四十三条、第三十六条 | AK19: 国网财务部
C20: 会计信息真实完整、资金资产安全、税务合规 | D20: 考核评价 （事后） | E20: 业绩考核指标体系制定不科学、执行不到位，未能有效引导各级单位落实公司战略要求，导致评价失真或偏离经营目标。 | F20: 考核指标设定不合理。指标设定明显超出下级单位能力，引发指标造假等问题。 | G20: 76.指标体系科学性审核 | H20: 充分发挥业绩考核指挥棒作用，引导各级单位精准完成经营目标。 | I20: 财务管理-76.指标体系科学性审核-控制措施01 | J20: 精简高效设置财务考核指标体系。每年，国网财务部及各二级单位财务部门结合公司战略及年度重点工作、各业务板块经营目标，差异化制定财务关键业绩考核指标，充分征求各级单位意见建议，重点关注：指标体系完整性、目标设置合理性、指标量化可比性。 | N20: √ | Q20: √ | S20: √ | T20: 线下管控 | V20: 1.年度关键业绩指标考核体系。 | W20: 各级单位-财务部门-预算管理人员 | X20: 年度 | Y20: 全量 | AA20: 年度 | AB20: 全量 | AH20: 是 | AI20: 是 | AJ20: 《国家电网有限公司全面预算管理办法》（国网（财/2）375-2026）第四十条、第四十一条、第四十二条、第四十三条 | AK20: 国网财务部
I21: 财务管理-76.指标体系科学性审核-控制措施02 | J21: 规范财务业绩考核工作流程。每年，国网财务部及各二级单位财务部门将关键业绩指标体系及考核规则通过智慧共享财务平台推送至企管部业绩考核系统，考核阶段，指标数据通过智慧共享财务平台自动获取，线上开展各级单位业绩还原事项评审，确保考核评价公平性、透明性。 | N21: √ | Q21: √ | S21: √ | T21: 线上管控-待建 | U21: 智慧共享财务平台 | V21: 1.决算报表、财务快报 2.特殊事项说明。 | W21: 各级单位-财务部门-预算管理人员 | X21: 年度 | Y21: 全量 | AA21: 年度 | AB21: 全量 | AD21: 预算考核模块 | AE21: 年度 | AH21: 是 | AI21: 是 | AJ21: 《国家电网有限公司全面预算管理办法》（国网（财/2）375-2026）第四十条、第四十一条、第四十二条、第四十三条 | AK21: 国网财务部

Sheet 整体情况
I1: 财务管理矩阵整体情况
A2: 会计 | B2: 会计 | C2: 预算 | D2: 预算 | E2: 股权 | F2: 股权 | G2: 资金 | H2: 资金 | I2: 序号 | J2: 业务领域 | K2: 步骤 | L2: 专业 | M2: 控制点 | N2: 控制措施 | O2: 备注
A3: 会计 | B3: 核算范围管理 | C3: 预算 | D3: 战略支撑 （事前） | E3: 股权 | F3: 1.股权投资项目储备 | G3: 资金 | H3: 银行账户开立 | I3: 1 | J3: 产权管理 | K3: 股权投资项目储备 | L3: 股权 | M3: 2 | N3: 9
A4: 会计 | B4: 会计政策管理 | C4: 预算 | D4: 经营决策 （事前） | E4: 股权 | F4: 2.投资项目决策管理 | G4: 资金 | H4: 商户号开立 | I4: 2 | K4: 投资项目决策管理 | L4: 股权 | M4: 1 | N4: 3
A5: 会计 | B5: 会计岗位管理 | C5: 预算 | D5: 资源分配 （事前） | E5: 股权 | F5: 3.股权投资项目计划预算管理 | G5: 资金 | H5: 数字钱包开立 | I5: 3 | K5: 股权投资项目计划预算管理 | L5: 股权 | M5: 1 | N5: 3
A6: 会计 | B6: 收入核算管理 | C6: 预算 | D6: 执行控制 （事中） | E6: 股权 | F6: 4.股权投资项目实施管理 | G6: 资金 | H6: 银行账户变更 | I6: 4 | K6: 股权投资项目实施管理 | L6: 股权 | M6: 3 | N6: 11
A7: 会计 | B7: 成本费用核算管理 | C7: 预算 | D7: 闭环管控 （事后） | E7: 股权 | F7: 5.股权投资项目后评价管理 | G7: 资金 | H7: 商户号变更 | I7: 5 | K7: 分支机构管理 | L7: 股权 | M7: 1 | N7: 2
A8: 会计 | B8: 往来会计管理 | C8: 预算 | D8: 考核评价 （事后） | E8: 股权 | F8: 6.股东权利行使与公司治理管理 | G8: 资金 | H8: 数字钱包变更 | I8: 6 | K8: 股权优化清理管理 | L8: 股权 | M8: 1 | N8: 6
A9: 会计 | B9: 总账会计管理 | E9: 股权 | F9: 7.股权优化清理管理 | G9: 资金 | H9: 账户使用-收入 | I9: 7 | K9: 股权转让项目管理 | L9: 股权 | M9: 5 | N9: 11
A10: 会计 | B10: 会计档案管理 | E10: 股权 | F10: 8.分支机构管理 | G10: 资金 | H10: 账户使用-支付 | I10: 8 | K10: 股权划转项目管理 | L10: 股权 | M10: 2 | N10: 6
E11: 股权 | F11: 9.股权转让项目管理 | G11: 资金 | H11: 账户使用-对账 | I11: 9 | K11: 增资扩股项目管理 | L11: 股权 | M11: 3 | N11: 8
E12: 股权 | F12: 10.股权划转项目管理 | G12: 资金 | H12: 账户使用-前置机数据管理 | I12: 10 | K12: 终止清算项目管理 | L12: 股权 | M12: 2 | N12: 6
E13: 股权 | F13: 11.增资扩股项目管理 | G13: 资金 | H13: 账户使用-密钥 | I13: 11 | K13: 股东权利行使与公司治理管理 | L13: 股权 | M13: 4 | N13: 16
E14: 股权 | F14: 12.终止清算项目管理 | G14: 资金 | H14: 账户使用-印鉴 | I14: 12 | K14: 参股企业运营管理 | L14: 股权 | M14: 5 | N14: 17
E15: 股权 | F15: 13.参股企业运营管理 | G15: 资金 | H15: 银行账户撤销 | I15: 13 | K15: 资产评估管理 | L15: 股权 | M15: 4 | N15: 11
E16: 股权 | F16: 14.资产评估管理 | G16: 资金 | H16: 商户号撤销 | I16: 14 | J16: 核算范围 | K16: 会计主体管理 | L16: 会计 | M16: 2 | N16: 3 | O16: 原核算范围管理
G17: 资金 | H17: 数字钱包撤销 | I17: 15 | K17: 会计政策管理 | L17: 会计 | M17: 3 | N17: 3
G18: 资金 | H18: 担保管理 | I18: 16 | K18: 会计岗位管理 | L18: 会计 | M18: 2 | N18: 4
G19: 资金 | H19: 人员管理 | I19: 17 | K19: 人员管理 | L19: 资金 | M19: 1 | N19: 3 | O19: 并入会计岗位管理
I20: 17 | J20: 账户管理 | K20: 银行账户开立 | L20: 资金 | M20: 2 | N20: 7
I21: 18 | K21: 商户号开立 | L21: 资金 | M21: 2 | N21: 4
I22: 19 | K22: 数字钱包开立 | L22: 资金 | M22: 2 | N22: 3
I23: 20 | K23: 银行账户变更 | L23: 资金 | M23: 1 | N23: 2
I24: 21 | K24: 商户号变更 | L24: 资金 | M24: 1 | N24: 1
I25: 22 | K25: 数字钱包变更 | L25: 资金 | M25: 1 | N25: 2
I26: 23 | K26: 银行账户撤销 | L26: 资金 | M26: 1 | N26: 3
I27: 24 | K27: 商户号撤销 | L27: 资金 | M27: 1 | N27: 2
I28: 25 | K28: 数字钱包撤销 | L28: 资金 | M28: 1 | N28: 2
I29: 26 | K29: 账户核算范围管理 | L29: 会计 | M29: 1 | N29: 1 | O29: 自会计主体管理分离
I30: 27 | J30: 预算管理 | K30: 战略支撑（事前） | L30: 预算 | M30: 1 | N30: 2
I31: 28 | K31: 经营决策（事前） | L31: 预算 | M31: 1 | N31: 3
I32: 29 | K32: 资源分配（事前） | L32: 预算 | M32: 1 | N32: 3
I33: 30 | K33: 执行控制（事中） | L33: 预算 | M33: 6 | N33: 6
I34: 31 | J34: 会计核算 | K34: 收入核算管理 | L34: 会计 | M34: 2 | N34: 7
I35: 32 | K35: 成本费用核算管理 | L35: 会计 | M35: 3 | N35: 4
I36: 33 | K36: 往来会计管理 | L36: 会计 | M36: 5 | N36: 7
I37: 34 | J37: 资金活动 | K37: 账户使用-收入 | L37: 资金 | M37: 3 | N37: 10
I38: 35 | K38: 账户使用-支付 | L38: 资金 | M38: 5 | N38: 18
I39: 36 | K39: 账户使用-对账 | L39: 资金 | M39: 3 | N39: 4
I40: 37 | K40: 账户使用-前置机数据管理 | L40: 资金 | M40: 1 | N40: 2
...

Sheet Sheet1
A1: 风控矩阵-财务管理
A2: 业 务 条 线 | B2: 业 务 领 域 | C2: 控 制 目 标 | D2: 业务流程步骤 | E2: 经营风险 | F2: 典型问题 | G2: 关键控制点 | H2: 控制要求 | I2: 控制措施 编号 | J2: 控制措施 | K2: 控制措施分类 | T2: 控制方式 | U2: 控制系统 | V2: 控制载体 | W2: 责任主体 | X2: 业务自评价 | AA2: 集团监督评价 | AD2: 数字化监督场景 | AH2: 现有制度及文件落实情况 | AK2: 总部审核部门 | AL2: 关联关系
K3: 不相容岗位 | L3: 分级授权 | M3: 业务真实性校验 | N3: 预算管控 | O3: 合同控制 | P3: 收付控制 | Q3: 会计监督 | R3: 财产保护 | S3: 分析与评价 | X3: 评价频率 | Y3: 评价范围 | Z3: 评价结论 | AA3: 评价频率 | AB3: 评价范围 | AC3: 评价结论 | AD3: 数字化监督场景 | AE3: 监督频率 | AF3: 监督范围 | AG3: 评价结论 | AH3: 是否已要求 | AI3: 是否满足要求 | AJ3: 对应制度及文件名称
A4: 财务管理 | B4: 会计核算 | C4: 会计信息真实完整 | D4: 核算范围管理 | E4: 会计主体创建不规范、不及时，影响合并范围完整性、准确性，导致会计信息不准确。 | F4: 会计主体创建不合规：对工商登记持股超过50%的实际经营企业、未创建会计主体单独核算，导致合并范围不完整、合并报表信息不准确。 | G4: 1.会计主体完整性管控 | H4: 会计主体与工商登记、人资组织、产权组织衔接一致，合并范围完整。 | I4: 会计核算-1.会计主体完整性管控-控制措施01 | J4: 1.合并范围完整性控制。每月，各单位会计人员在线跟踪比对工商、产权登记与报表合并范围一致性，原则上工商登记持股50%以上企业需全部办理产权登记、规范取得控制权并纳入合并范围。确有问题的，应及时规范调整。 | M4: √ | Q4: √ | T4: 线上管控-待建 | U4: 智慧共享财务平台、主数据管理平台（MDM3.0) | V4: 1.会计核算主体建立（变更）申请单 2.工商登记、税务登记、产权登记资料等 | W4: 各单位-财务部-总账管理 | X4: 每月 | Y4: 全量 | AA4: 年度 | AB4: 全量 | AD4: 合并范围完整性监督场景（已建） | AE4: 每月 | AF4: 全量 | AH4: 是 | AI4: 是 | AJ4: 1.《国家电网有限公司会计基础管理办法》（国家电网企管〔2019〕132号）-第四章 核算与报告-第三十七条、第四十四条 2.《国家电网有限公司关于做好2025年度财务决算工作的通知》（国家电网财〔2025〕649号） | AK4: 财务部
I5: 会计核算-1.会计主体完整性管控-控制措施02 | J5: 2.会计主体创建和变更控制：各单位会计人员应遵循先产权后工商的要求，根据产权和工商登记结果，及时创建会计主体，并履行二级单位、总部财务部审批程序，规范纳入合并范围。对于无人资组织、未办理工商登记的会计主体，由二级单位分管财务领导审批后，提交国网财务部审批。 | L5: √ | M5: √ | T5: 线上管控-已建 | U5: 智慧共享财务平台、主数据管理平台（MDM3.0) | V5: 1.会计核算主体建立（变更）申请单 2.人资部门关于会计主体建立（变更）的文件 3.工商登记、税务登记、产权登记资料等 | W5: 各单位-财务部-总账管理 | X5: 每月 | Y5: 全量 | AA5: 年度 | AB5: 全量 | AD5: 会计主体创建变更规范性监督场景（已建） | AE5: 每月 | AF5: 全量 | AH5: 是 | AI5: 是 | AJ5: 1.《国家电网有限公司会计基础管理办法》（国家电网企管〔2019〕132号）-第四章 核算与报告-第三十七条、第四十四条 2.《关于智慧共享财务平台与人资2.0系统管理融合有关事项的通知》（财会〔2025〕15号） | AK5: 财务部
E6: 银行账户核算不完整，会计信息不准确，产生资金安全风险。 | F6: 银行账户核算不完整：账内银行账户与开户清单、账内商户号与开立商户号清单不一致，存在账外资金，导致资金失管、账实不符，引发资金安全风险。 | G6: 2.账户完整性管控 | H6: 银行账户和商户号核算完整、准确。 | I6: 会计核算-2.账户完整性管控-控制措施01 | J6: 银行账户和商户号核算完整性控制。每年10月底前、次年1月初，各单位会计人员会同决算审计会计师事务所，前往人民银行或基本户开户行打印全量开户清单；登录各商户号网上平台，获取全量商户号清单。逐一与账内核算银行账户和商户号进行比对，确保以公司名义开立、可独立支配账户资金、承担资金安全管理责任的银行账户和商户号，均完整纳入账内核算。 | M6: √ | Q6: √ | T6: 线上管控-待建 | U6: 智慧共享财务平台 | V6: 1.银行账户开立清单 2.商户号清单 | W6: 各单位-财务部-总账管理 | X6: 每季 | Y6: 全量 | AA6: 年度 | AB6: 全量 | AD6: 账户完整性监督场景（待建） | AE6: 每季 | AF6: 全量 | AH6: 是 | AI6: 是 | AJ6: 1.《国家电网有限公司司库管理办法》（国家电网企管〔2023〕88号）-第三章 银行账户（数字钱包）管理-第二十五条 2.《国网财务部关于进一步加强社会保障有关账户管理和资金核算的通知》（财金〔2024〕12号） 3.《国家电网有限公司2025年度财务决算审计工作指引》 | AK6: 财务部
E7: 科目维度使用不统一、不规范，影响会计信息准确性和可比性。 | F7: 科目维度使用不规范：凭证科目维度与实际业务不匹配，影响会计信息反映准确性；集团内不同单位对同类业务核算科目维度不统一，导致会计信息不可比。 | G7: 3.业务完整性管控 | H7: 统一会计科目和管理维度体系，规范科目维度使用，确保会计信息准确可比。 | I7: 会计核算-3.业务完整性管控-控制措施01 | J7: 会计科目和管理维度统一性规范性控制。 公司总部建立统一的会计科目和管理维度体系，并实施分业态管理，各单位根据业态标识规范引用。在公司统一体系下，各单位因自身业务特点和内部管理要求，确需对相关管理维度枚举值进行细化的，需依次履行二级单位、总部财务部审批程序。 | L7: √ | Q7: √ | T7: 线上管控-已建 | U7: 智慧共享财务平台 | V7: 1.集团会计科目和管理维度体系清单 2.科目维度系统配置文件 3.维度细化申请与审批记录 | W7: 各单位-财务部-总账管理 | X7: 年度 | Y7: 全量 | AA7: 年度 | AB7: 全量 | AD7: 科目维度规范性监督场景（已建） | AE7: 年度 | AF7: 全量 | AH7: 是 | AI7: 是 | AJ7: 1.《国家电网有限公司会计基础管理办法》（国家电网企管〔2019〕132号）-第四章 核算与报告-第四十条、第四十四条 2.《国家电网有限公司财务管理通则》（国家电网企管〔2020〕763号）-第三章 管理内容与管理流程-第二节 会计核算-第二十一条 | AK7: 财务部 | AL7: 关联预算管理-3.资源配置精准性管控-控制措施01
C8: 会计信息真实完整 | D8: 会计政策管理 | E8: 会计政策和会计估计分类和分级授权标准不明确，导致执行不统一，影响会计信息准确性和可比性。 | F8: 会计政策和会计估计分类和分级授权不规范：未明确会计政策和会计估计分类管控和分级授权标准，导致会计信息执行不统一、反映不准确。 | G8: 4.会计政策和会计估计分类管控和分级授权管理 | H8: 明确会计政策、会计估计分类管控和分级授权标准。 | I8: 会计核算-4.会计政策和会计估计分类管控和分级授权管理-控制措施01 | J8: 会计政策和会计估计分类管控及分级授权控制：公司总部统一建立会计政策和会计估计分类管控及分级授权标准，明确政策清单，对应收款项坏账计提比例、固定资产折旧方法和年限区间、投资性房地产后续计量方法等，由公司总部统一确定；对固定资产折旧年限等公司统一政策下的具体执行值，由各单位履行决策程序后确定具体执行标准并向公司总部备案。 | L8: √ | T8: 线上管控-待建 | U8: 智慧共享财务平台 | V8: 1.会计政策和会计估计分类管控清单 2.会计政策、会计估计分级授权清单 | W8: 总部-财务部-总账管理 | X8: 年度 | Y8: 全量 | AA8: 年度 | AB8: 全量 | AD8: 会计政策、会计估计分类管控及分级授权标准监督场景（待建） | AE8: 年度 | AF8: 全量 | AH8: 是 | AI8: 是 | AJ8: 《国家电网有限公司会计基础管理办法》（国家电网企管〔2019〕132号）-第四章 核算与报告-第三十九条、第四十四条 | AK8: 财务部
A9: 财务管理 | B9: 会计核算 | C9: 会计信息真实完整 | D9: 会计政策管理 | E9: 会计政策和会计估计执行不统一、不规范，导致会计信息不准确、经营业绩失真。 | F9: 会计政策和会计估计执行不统一：未严格执行公司统一的会计政策和会计估计，导致会计信息反映不准确、不可比。 | G9: 5.会计政策和会计估计执行管控 | H9: 严格执行统一的会计政策和会计估计标准。 | I9: 会计核算-5.会计政策和会计估计执行管控-控制措施01 | J9: 会计政策和会计估计执行统一性控制：公司总部将统一会计政策和会计估计管控要求嵌入在线业财处理流程，确保全流程规范遵循。每月末，各单位会计人员对本单位统一政策执行情况进行全面检查，确保反映准确。 | Q9: √ | T9: 线上管控-待建 | U9: 智慧共享财务平台 | V9: 1.会计政策和会计估计分类管控清单 2.会计政策、会计估计分级授权清单 | W9: 总部-财务部-总账管理 各单位-财务部-总账管理 | X9: 年度 | Y9: 抽查 | AA9: 年度 | AB9: 抽查 | AD9: 会计政策和会计估计规范性监督场景（待建） | AE9: 年度 | AF9: 抽查 | AH9: 是 | AI9: 是 | AJ9: 《国家电网有限公司会计基础管理办法》（国家电网企管〔2019〕132号）-第四章 核算与报告-第三十九条、第四十四条 | AK9: 财务部
E10: 会计政策和会计估计变更不规范、随意调节，跨年调整经营指标，导致会计信息不准确、经营业绩失真。 | F10: 会计政策和会计估计变更流程不规范：变更程序不规范、审核把关不严，滥用变更人为调节年度间财务状况、经营成果，导致会计信息不准确。 | G10: 6.会计政策和会计估计变更审批 | H10: 会计政策和会计估计变更审批统一规范。 | I10: 会计核算-6.会计政策和会计估计变更审批-控制措施01 | J10: 会计政策和会计估计变更审批控制。对会计政策和会计估计变更事项，根据分类管控及分级授权标准，分层级履行党组（党委）会前置研究、董事会或类似机构决策等程序。 | L10: √ | T10: 线下管控 | V10: 会计政策和会计估计变更申请单 | W10: 各单位-财务部-总账管理 | X10: 年度 | Y10: 抽查 | AA10: 年度 | AB10: 抽查 | AH10: 是 | AI10: 是 | AJ10: 《国家电网有限公司会计基础管理办法》（国家电网企管〔2019〕132号）-第四章 核算与报告-第三十九条、第四十四条 | AK10: 财务部
C11: 企业经营管理合法合规、资金资产安全、会计信息真实完整 | D11: 会计岗位管理 | E11: 会计不相容权责未分离，审核审批不合规，容易引发财务舞弊，造成资金挪用、资产损失、会计信息失真。 | F11: 不相容岗位权责未分离：会计兼任出纳、业务审批、财产保管等职责，导致资金资产损失长期隐匿未被发现；凭证制单与审核、审批由同一人负责，容易造成会计舞弊。 | G11: 7.会计不相容岗位管控 | H11: 严格会计不相容岗位相分离。 | I11: 会计核算-7.会计不相容岗位管控-控制措施01 | J11: 不相容岗位相分离控制。各单位财务部门严格按照不相容岗位相分离的要求，规范设置会计岗位、匹配会计人员。 | K11: √ | L11: √ | T11: 线下管控 | V11: 1.岗位设置与岗位职责说明 2.系统角色和权限配置表 | W11: 各单位-财务部-财务负责人 | X11: 月度 | Y11: 全量 | AA11: 年度 | AB11: 全量 | AH11: 是 | AI11: 是 | AJ11: 1.《国家电网有限公司会计基础管理办法》（国家电网企管〔2019〕132号）-第三章 会计机构和会计人员-第十六条 2.《会计基础工作规范》（征求意见稿）-第二章 会计机构和会计岗位-第十一条 | AK11: 财务部
E12: 会计岗位交接不规范，影响会计工作组织和会计信息质量。 | F12: 会计岗位交接资料不完整、监交不到位：移交清册等资料不完整，资金、凭证、账簿等财务数据未核对，交接过程未经过监交人监督，交接前后财务信息不衔接、不准确。 | G12: 8.会计岗位交接管控 | H12: 规范会计工作交接，确保会计资料衔接一致。 | I12: 会计核算-8.会计岗位交接管控-控制措施03 | J12: 会计工作交接规范性控制。各单位会计人员办理移交手续前，应完成未了事项，编制移交清册，并与接管人员逐项核对确认。办理交接手续，必须有监交人负责监交；交接完毕后，交接双方和监交人员要在移交清册上签名或者盖章。 | Q12: √ | T12: 线下管控 | V12: 1.会计岗位交接清单 2.移交清册 3.本岗位相关业务流程、信息系统功能、注意事项及未了事项等的书面说明 4.交接归档留存资料 | W12: 各单位-财务部-风险内控与稽核评价管理 | X12: 年度 | Y12: 全量 | AA12: 年度 | AB12: 全量 | AH12: 是 | AI12: 是 | AJ12: 《国家电网有限公司会计基础管理办法》（国家电网企管〔2019〕132号）-第三章 会计机构和会计人员-第三节 会计工作交接 | AK12: 财务部
A13: 财务管理 | B13: 会计核算 | C13: 会计信息真实完整、资金资产安全 | D13: 收入核算管理 | E13: 收入真实性核查不足、收入确认不完整、不准确，提前、延后或跨期确认收入，未严格核查“三流”一致性、“两头在外”购销业务，导致收入核算不准确、经营成果不可靠、资金与合规风险。 | F13: 5.收入确认不完整、不准确：业务部门未及时提交履约进度等结算资料、资料不完整，导致收入确认不完整、不准确；业务部门违规开展虚假贸易，伪造收入结算资料，导致会计信息失真；财务部门未准确区分总额法和净额法，导致收入核算不准确。 | G13: 9.售电收入管控 | H13: 严格审核营财数据一致性，确保售电收入确认完整。 | I13: 会计核算-9.售电收入管控-控制措施01 | J13: 1.营财数据一致性控制。每月末，各单位财务人员对售电收入财务汇总账与营销账务的一致性进行全面核对，发现营财差异，需及时查明原因，并进行营财联动调整，严禁财务手工调整。 | M13: √ | Q13: √ | S13: √ | T13: 线上管控-待建 | U13: 智慧共享财务平台、营销2.0系统 | V13: 1.营销传入电费凭证 2.营财对账记录 | W13: 各单位-营销部-电费电价管理 各单位-财务部-电费电价管理 | X13: 每季 | Y13: 抽查 | AA13: 每季 | AB13: 抽查 | AD13: 营财数据一致性监督场景（已建） | AE13: 每月 | AF13: 全量 | AH13: 是 | AI13: 是 | AJ13: 《关于明确营销2.0系统与智慧共享财务平台系统集成有关问题的意见》（营销营业〔2023〕86号）-二、高频业务处理流程标准化 | AK13: 财务部
I14: 会计核算-9.售电收入管控-控制措施02 | J14: 2.售电业务营财集成控制。总部营销部、财务部根据业务场景，共同制定营财集成规则并在线固化。各单位财务人员在月度结账前，全面排查非集成售电收入凭证，对异常情况及时查明原因，规范冲销调整。 | M14: √ | Q14: √ | T14: 线上管控-待建 | U14: 智慧共享财务平台 | V14: 营财一体化核算规则 | W14: 总部-财务部-总账管理 总部-财务部-电费电价管理 各单位-财务部-总账管理 | X14: 每季 | Y14: 抽查 | AA14: 每季 | AB14: 抽查 | AH14: 是 | AI14: 是 | AJ14: 1.《关于明确营销2.0系统与智慧共享财务平台系统集成有关问题的意见》（营销营业〔2023〕86号）-二、高频业务处理流程标准化 2.《国家电网有限公司2025年度财务决算审计工作指引》 | AK14: 财务部
G15: 10.非电收入管控 | H15: 严格审核收入真实性、准确性、完整性， 准确反映经营成果。 | I15: 会计核算-10.非电收入管控-控制措施01 | J15: 1.收入真实性监督。各单位会计人员在收入报账审核时，通过检查合同、发票、出库单、物流单、签收单、完工验收单等，识别虚构业务情形，对收入真实性进行监督。 | M15: √ | O15: √ | Q15: √ | T15: 线上管控-待建 | U15: 智慧共享财务平台 | V15: 合同、发票、出库单、物流单、签收单、完工验收单等收入报账附件 | W15: 各单位-财务部-收入会计 | X15: 每月 | Y15: 抽查 | AA15: 每月 | AB15: 抽查 | AD15: 收入真实性监督场景（待建） | AE15: 每月 | AF15: 抽查 | AH15: 是 | AI15: 是 | AJ15: 1.《国家电网有限公司会计核算办法》（国家电网企管〔2026〕101号）-第四章、第十九章至第二十三章 2.《国家电网有限公司会计基础管理办法》（国家电网企管〔2019〕132号）-附则-一、收入业务 3.《会计基础工作规范》（征求意见稿）-第五章 会计监督-第三十九条 4.《国家电网有限公司2025年度财务决算审计工作指引》 | AK15: 财务部
I16: 会计核算-10.非电收入管控-控制措施02 | J16: 2.收入完整性监督。各单位会计人员通过检查收款记录、结算单据以及业务系统中销售发货、服务进度、施工进度等记录，对收入报账的完整性进行监督。 | M16: √ | Q16: √ | T16: 线上管控-待建 | U16: 智慧共享财务平台 | V16: 合同、发票、银行回单、结算单据、销售发货单、服务进度表、施工进度表等收入报账附件 | W16: 各单位-财务部-收入会计 | X16: 每月 | Y16: 抽查 | AA16: 每月 | AB16: 抽查 | AD16: 收入完整性监督场景（待建） | AE16: 每月 | AF16: 抽查 | AH16: 是 | AI16: 是 | AJ16: 1.《国家电网有限公司会计核算办法》（国家电网企管〔2026〕101号）-第四章、第十九章至第二十三章 2.《国家电网有限公司会计基础管理办法》（国家电网企管〔2019〕132号）-附则-一、收入业务 3.《会计基础工作规范》（征求意见稿）-第五章 会计监督-第三十九条 4.《国家电网有限公司2025年度财务决算审计工作指引》 | AK16: 财务部
I17: 会计核算-10.非电收入管控-控制措施03 | J17: 3.收入确认准确性控制。各单位会计人员根据合同、物流仓储记录等，准确判断合同中承担的主要责任或代理责任，规范选取总额法或净额法核算。公司总部细化产品服务分类，在线固化各类型业务核算规则，实施收入确认准确性在线、精准控制。 | M17: √ | Q17: √ | T17: 线上管控-待建 | U17: 智慧共享财务平台 | V17: 1.合同 2.物流仓储记录 | W17: 总部-财务部-总账管理 各单位-财务部-收入会计 | X17: 每月 | Y17: 抽查 | AA17: 每月 | AB17: 抽查 | AD17: 收入确认准确性监督场景（待建） | AE17: 每月 | AF17: 抽查 | AH17: 是 | AI17: 是 | AJ17: 1.《国家电网有限公司关于强化“三道防线”协同管控切实防范贸易业务风险的通知》（国家电网财〔2024〕406号） 2.《国家电网有限公司2025年度财务决算审计工作指引》 | AK17: 财务部
I18: 会计核算-10.非电收入管控-控制措施04 | J18: 4.资金流、发票流、账务流一致性监督。各单位会计人员严格审核业务执行中与上下游企业资金收付和发票开具情况，对按净额法核算的业务，原则上不得介入上下游资金流、发票流，避免垫付资金风险。发现“三流”不一致带来的资金垫付风险，应停止办理报账，并及时向单位负责人报告。 | M18: √ | P18: √ | Q18: √ | T18: 线上管控-待建 | U18: 智慧共享财务平台 | V18: 1.合同 2.银行回单 3.发票 | W18: 各单位-财务部-收入会计 | X18: 每季 | Y18: 抽查 | AA18: 年度 | AB18: 抽查 | AD18: “三流”一致性监督场景（待建） | AE18: 每季 | AF18: 抽查 | AH18: 是 | AI18: 是 | AJ18: 1.《国家电网有限公司关于强化“三道防线”协同管控切实防范贸易业务风险的通知》（国家电网财〔2024〕406号） 2.《国家电网有限公司2025年度财务决算审计工作指引》 | AK18: 财务部
I19: 会计核算-10.非电收入管控-控制措施05 | J19: 5.贸易业务规范性监督。对于“两头在外”购销业务，各单位会计人员严格审核业务审批、上下游关联关系、仓储物流、毛利率水平等情况，发现异常情况及时截停业务。对于业务部门提交垫付资金、大额预付、往来款项互抵等异常事项，财务部门要向本单位主要负责同志和贸易业务分管领导报告，启动业务真实性合规性调查，并暂停资金支付；经调查认定为违规贸易业务的，要逐级上报至总部财务部，并终止支付、督促业务部门停止业务。 | M19: √ | P19: √ | Q19: √ | T19: 线上管控-待建 | U19: 智慧共享财务平台 | V19: 1.业务审批记录 2.上下游关联关系核查资料 3.仓储物流单 4.毛利率分析记录 | W19: 各单位-财务部-收入会计 | X19: 每季 | Y19: 抽查 | AA19: 年度 | AB19: 抽查 | AD19: 贸易业务规范性监督场景（待建） | AE19: 每季 | AF19: 抽查 | AH19: 是 | AI19: 是 | AJ19: 1.《国家电网有限公司关于强化“三道防线”协同管控切实防范贸易业务风险的通知》（国家电网财〔2024〕406号） 2.《国家电网有限公司2025年度财务决算审计工作指引》 | AK19: 财务部
A20: 财务管理 | B20: 会计核算 | C20: 会计信息真实完整、资金资产安全 | D20: 成本费用核算管理 | E20: 成本费用列支不真实、不完整、不规范，造成利润不实、资金资产流失。 | F20: 成本费用不真实、不完整、不规范：成本结转、成本记账无依据或依据不充分，年末发生大额成本入账但与实际履约进度不符，超标准、超预算报销差旅费、会议费等，收入成本不匹配、项目毛利率异常，影响会计信息真实性、准确性。 | G20: 11.成本真实性管控 | H20: 经济业务成本费用真实发生、有据可查。 | I20: 会计核算-11.成本真实性管控-控制措施01 | J20: 成本费用真实性监督。各单位会计人员在成本费用报账审核时，通过检查采购或服务合同、发票以及入库验收、工程施工、劳务考勤等佐证资料，核查实际履约情况，对成本费用真实性进行监督。各单位会计人员在凭证过账审核时，对记账凭证依据的充分性进行监督，重点复核非系统集成记账凭证依据的充分性。 | M20: √ | O20: √ | Q20: √ | T20: 线上管控-待建 | U20: 智慧共享财务平台 | V20: 1.合同 2.发票 3.成本结算明细 | W20: 各单位-财务部-成本会计 | X20: 每月 | Y20: 全量 | AA20: 每季 | AB20: 全量 | AD20: 成本费用报账真实性监督场景（待建） | AE20: 每月 | AF20: 全量 | AH20: 是 | AI20: 是 | AJ20: 1.《国家电网有限公司会计基础管理办法》（国家电网企管〔2019〕132号）-第二章 职责分工 第八条、第四章 核算与报告-第五十四条、附则-二、成本费用业务 2.《国家电网有限公司2025年度财务决算审计工作指引》 | AK20: 财务部
G21: 12.成本合规性、完整性管控 | H21: 经济业务成本费用报账规范、完整，与公司经营相关、符合制度要求。 | I21: 会计核算-12.成本合规性、完整性管控-控制措施01 | J21: 1.成本费用合规性监督。总部会同各单位，将差旅费、“三公”经费等重点费用管控标准嵌入信息系统和业财处理流程，实施在线控制；各单位会计人员在成本报账审核时，对照公司制度要求检查成本费用超标准、超范围等情况，对成本费用合规性进行监督。 | N21: √ | Q21: √ | T21: 线上管控-待建 | U21: 智慧共享财务平台 | V21: 1.系统审核规则 2.报账附件 | W21: 各单位-财务部-成本会计 | X21: 每月 | Y21: 全量 | AA21: 每季 | AB21: 全量 | AD21: 成本费用报账合规性、完整性监督场景（待建） | AE21: 每月 | AF21: 全量 | AH21: 是 | AI21: 是 | AJ21: 《国家电网有限公司会计基础管理办法》（国家电网企管〔2019〕132号）-第二章 职责分工-第八条、第四章 核算与报告-第五十四条、附则-二、成本费用业务 | AK21: 财务部
I22: 会计核算-12.成本合规性、完整性管控-控制措施02 | J22: 2.成本费用完整性监督。各单位会计人员通过检查付款记录、结算单据、月度间成本费用规模以及业务系统中采购收货、服务进度、施工进度等记录，对成本报账的完整性进行监督。 | M22: √ | Q22: √ | T22: 线上管控-待建 | U22: 智慧共享财务平台 | V22: 1.系统审核规则 2.报账附件 | W22: 各单位-财务部-成本会计 | X22: 每月 | Y22: 全量 | AA22: 每季 | AB22: 全量 | AD22: 成本费用报账合规性、完整性监督场景（待建） | AE22: 每月 | AF22: 全量 | AH22: 是 | AI22: 是 | AJ22: 《国家电网有限公司会计基础管理办法》（国家电网企管〔2019〕132号）-第二章 职责分工-第八条、第四章 核算与报告-第五十四条、附则-二、成本费用业务 | AK22: 财务部
G23: 13.收入成本匹配性管控 | H23: 收入确认时点、规模与成本匹配，准确反映公司经营成果。 | I23: 会计核算-13.收入成本匹配性管控-控制措施01 | J23: 收入成本匹配性监督。各单位会计人员通过检查收发货记录、服务履约记录、项目毛利率以及账面合同履约成本、合同负债、往来款项等挂账情况，动态监控合同、项目等收入成本匹配性，及时向业务部门发出预警督办，确保收入成本动态匹配、反映准确。 | M23: √ | O23: √ | Q23: √ | T23: 线上管控-待建 | U23: 智慧共享财务平台 | V23: 1.合同 2.发票 3.收发货记录、服务履约记录 | W23: 各单位-财务部-成本会计 | X23: 每月 | Y23: 全量 | AA23: 每季 | AB23: 全量 | AD23: 收入成本匹配性核查场景（待建） | AE23: 每月 | AF23: 全量 | AH23: 是 | AI23: 是 | AJ23: 1.《国家电网有限公司会计核算办法》（国家电网企管〔2026〕101号）-第十九章 工程施工业务-第二节 项目建设期 2.《国家电网有限公司2025年度财务决算审计工作指引》 | AK23: 财务部
C24: 会计信息真实完整、资金资产安全 | D24: 往来会计管理 | E24: 往来客商使用不规范，通过一次性（过渡）客商无依据暂估收入成本，导致往来信息不准确，存在人为调节利润风险。 | F24: 挂账对象不规范：将可对应至具体客户或供应商的往来款项挂账至一次性（过渡）客商。 | G24: 14.往来挂账规范性管控 | H24: 规范往来客商使用，除特殊情形外不使用一次性（过渡）客商。 | I24: 会计核算-14.往来挂账规范性管控-控制措施01 | J24: 往来挂账规范性控制。各单位会计人员根据具体业务事项，将往来款项规范挂账至具体客户或供应商。除总部统一明确的特殊情形外，不得挂账至一次性（过渡）客商。 | M24: √ | Q24: √ | T24: 线上管控-待建 | U24: 智慧共享财务平台 | V24: 一次性（过渡）客商标准场景清单 | W24: 各单位-财务部-往来管理 | X24: 每季 | Y24: 抽查 | AA24: 每季 | AB24: 抽查 | AD24: 往来挂账规范性监督场景（已建） | AE24: 每季 | AF24: 全量 | AH24: 是 | AI24: 是 | AJ24: 1.《国家电网有限公司会计基础管理办法》（国家电网企管〔2019〕132号）-第四章 核算与报告-第五十六条 2.《国家电网有限公司2025年度财务决算审计工作指引》 | AK24: 财务部
E25: 往来款项清账不及时，债权债务底数不清，易形成呆账、坏账，造成资金损失风险。 | F25: 往来款项清账不及时不规范：往来款项清账不及时、账龄不准确，未及时识别收付款风险，导致坏账计提错误或资金损失。 | G25: 15.往来清账及时性管控 | H25: 及时、规范开展往来清账，确保往来款项余额和账龄准确。 | I25: 会计核算-15.往来清账及时性管控-管控措施01 | J25: 往来清账及时性控制。各单位会计人员动态监测智慧共享财务平台往来款项清账情况，对特殊情况产生的应清未清事项，及时查明原因、规范处理，确保日清日结。 | P25: √ | Q25: √ | T25: 线上管控-已建 | U25: 智慧共享财务平台 | V25: 1.应收台账 2.应付台账 | W25: 各单位-财务部-往来管理 | X25: 每月 | Y25: 全量 | AA25: 每月 | AB25: 全量 | AD25: 往来款项清账及时性监督场景（已建） | AE25: 每月 | AF25: 全量 | AH25: 是 | AI25: 是 | AJ25: 1.《国家电网有限公司会计基础管理办法》（国家电网企管〔2019〕132号）-第四章 核算与报告-第六十二条 2.《国家电网有限公司2025年度财务决算审计工作指引》 | AK25: 财务部
A26: 财务管理 | B26: 会计核算 | C26: 会计信息真实完整、资金资产安全 | D26: 往来会计管理 | E26: 往来款项对账不及时，债权债务底数不清，易造成资金损失风险。 | F26: 往来款项对账不规范：应付款项对账不准确，导致重复付款、超额付款，造成资金损失；对账流于形式，未发现往来款项错收、错付、漏记账、重复记账问题，产生资金挪用、往来舞弊风险。 | G26: 16.往来对账规范性管控 | H26: 规范开展往来对账，确保往来款项余额准确、账实相符。 | I26: 会计核算-16.往来对账规范性管控-管控措施01 | J26: 往来对账规范性控制。对账龄1年以上、逾期、债务人经营异常或单一客商挂账金额重大的往来款项，各单位要会同会计师事务所，在每年2月底前，通过询证函等书面方式，对上年末挂账余额进行对账确认。函证结果不一致的，要在决算中查明原因，规范调整账务。 | Q26: √ | S26: √ | T26: 线下管控 | V26: 询证函等书面对账材料 | W26: 各单位-财务部-往来管理 | X26: 年度 | Y26: 全量 | AA26: 年度 | AB26: 全量 | AH26: 是 | AI26: 是 | AJ26: 1.《国家电网有限公司会计基础管理办法》（国家电网企管〔2019〕132号）-第四章 核算与报告-第六十二条 2.《国家电网有限公司2025年度财务决算审计工作指引》 | AK26: 财务部
E27: 应收款项回收不及时、长期挂账，造成资金占用、坏账损失风险。应付款项支付不及时，导致合同违约、信用受损，产生舆情及合规风险。 | F27: 债权债务清理不及时：应收款项催收不及时、回款周期长，资金周转压力大，增加坏账损失风险；应付款项长期挂账未清理，容易引发合同与法律纠纷。 | G27: 17.长期挂账款项管理 | H27: 建立长期挂账款项清理机制，避免长期挂账、逾期挂账。 | I27: 会计核算-17.长期挂账款项管理-控制措施01 | J27: 1.往来款项收付及时性监督。各单位财务部门集成应用合同收付款结构化数据，在合同约定的收付款节点前，及时向业务部门经办人员发送收付款报账提醒。 | Q27: √ | S27: √ | T27: 线上管控-待建 | U27: 智慧共享财务平台、数字化法治企业建设平台 | V27: 1.系统预警规则 2.应收台账 3.应付台账 | W27: 各单位-财务部-往来管理 | X27: 每月 | Y27: 抽查 | AA27: 每季 | AB27: 抽查 | AD27: 往来款项收付及时性监督场景（待建） | AE27: 每月 | AF27: 全量 | AH27: 是 | AI27: 是 | AJ27: 《国家电网有限公司会计基础管理办法》（国家电网企管〔2019〕132号）-第四章 核算与报告-第六十二条 | AK27: 财务部
I28: 会计核算-17.长期挂账款项管理-控制措施02 | J28: 2.往来款项风险监测预警。各单位财务部门集成应用工商等大数据，对长账龄、逾期、债务人经营异常等往来款项，按月向业务部门在线发送往来状态和风险预警，并建立在线督办台账，加强过程管控。 | Q28: √ | S28: √ | T28: 线上管控-待建 | U28: 智慧共享财务平台 | V28: 1.长账龄、逾期、债务人经营异常往来款项清单 2.督办台账 | W28: 各单位-财务部-往来管理 | X28: 每月 | Y28: 抽查 | AA28: 每季 | AB28: 抽查 | AD28: 往来款项风险监测预警监督场景（待建） | AE28: 每月 | AF28: 全量 | AH28: 是 | AI28: 是 | AJ28: 1.《国家电网有限公司会计基础管理办法》（国家电网企管〔2019〕132号）-第四章 核算与报告-第六十二条 2.《国家电网有限公司2025年度财务决算审计工作指引》 | AK28: 财务部
E29: 坏账准备计提不及时、不准确，影响资产计量真实性，导致会计信息质量受损；往来款项核销不规范，导致资产流失及合规风险。 | F29: 坏账计提不准确、往来款项核销不规范：坏账计提未执行公司统一政策，高风险债务人应收款项未按单项认定计提坏账，导致坏账计提金额不准确；往来款项核销依据不充分、审批程序不合规，违规核销损害公司利益。 | G29: 18.坏账准备及往来款项处置管理 | H29: 统一坏账计提政策，确保坏账计提金额准确；严格清查核实往来款项无法收付情况，规范履行核销程序。 | I29: 会计核算-18.坏账准备及往来款项处置管理-控制措施01 | J29: 1.应收款项坏账计提准确性控制。对组合认定款项，公司总部统一在线配置各类组合计提比例；各单位会计人员动态、在线监测应收款项账龄准确性，确保自动、准确计提；对个别认定款项，各单位会计人员在线跟踪监测长账龄、逾期、债务人经营异常等款项，组织业务部门及时评估回收风险，回收风险较大的，按单项认定足额计提坏账。 | Q29: √ | T29: 线上管控-已建 | U29: 智慧共享财务平台 | V29: 1.坏账计提规则 2.长账龄、逾期、债务人经营异常等往来款项清单 | W29: 总部-财务部-总账管理 各单位-财务部-往来管理 | X29: 年度 | Y29: 抽查 | AA29: 年度 | AB29: 抽查 | AD29: 坏账准备计提准确性监督场景（已建） | AE29: 每月 | AF29: 全量 | AH29: 是 | AI29: 是 | AJ29: 1.《国家电网有限公司会计基础管理办法》（国家电网企管〔2019〕132号）-第四章 核算与报告-第六十二条、第七章 附则-三、资产业务-（三）坏账准备 2.《国家电网有限公司会计核算办法》（国家电网企管〔2026〕101号）-第二章 债权债务-第一节 债权管理 3.《国家电网有限公司2025年度财务决算审计工作指引》 | AK29: 财务部
I30: 会计核算-18.坏账准备及往来款项处置管理-控制措施02 | J30: 2.往来款项核销规范性控制。对确实无法收回的应收款项或无需支付的应付款项，各单位会计人员严格审核业务部门提供的企业吊销、法院判决裁定等佐证，会同业务部门规范履行内部决策、中介机构鉴证等程序后，进行账销案存处理。 | L30: √ | Q30: √ | T30: 线下管控 | V30: 1.应收款项核销佐证依据 2.应付款项核销佐证依据 3.内部决策文件 4.中介机构鉴证报告 | W30: 各单位-财务部-往来管理 | X30: 年度 | Y30: 抽查 | AA30: 年度 | AB30: 抽查 | AH30: 是 | AI30: 是 | AJ30: 1.《国家电网有限公司会计基础管理办法》（国家电网企管〔2019〕132号）-第四章 核算与报告-第六十二条、第七章 附则-三、资产业务-（三）坏账准备 2.《国家电网有限公司会计核算办法》（国家电网企管〔2026〕101号）-第二章 债权债务-第一节 债权管理、第二节 债务管理 3.《国家电网有限公司2025年度财务决算审计工作指引》 | AK30: 财务部
A31: 财务管理 | B31: 会计核算 | C31: 会计信息真实完整、资金资产安全 | D31: 总账会计管理 | E31: 关联交易未协同、抵销不充分，导致会计信息不准确。 | F31: 关联交易协同不充分：关联交易双方业务处理不同步、凭证未协同、存在单方挂账，导致合并抵销不充分、会计信息不准确。 | G31: 19.关联交易协同管控 | H31: 内部关联交易协同抵销充分、准确。 | I31: 会计核算-19.关联交易协同管控-控制措施01 | J31: 关联交易抵销充分性控制：各单位严格遵循公司统一的关联交易“发票码、资金码”协同抵销规则，所有内部交易事项均双方协同入账、同步生成上级单位抵销凭证。 | M31: √ | Q31: √ | T31: 线上管控-已建 | U31: 智慧共享财务平台 | V31: 系统关联交易协同抵销规则 | W31: 各单位-财务部-总账管理 | X31: 每月 | Y31: 全量 | AA31: 每月 | AB31: 全量 | AD31: 关联交易协同监督场景（已建） | AE31: 每月 | AF31: 全量 | AH31: 是 | AI31: 是 | AJ31: 1.《国家电网有限公司会计基础管理办法》（国家电网企管〔2019〕132号）-第四章 核算与报告-第三节 会计凭证 第五十六条 2.《国家电网有限公司财务管理通则》（国家电网企管〔2020〕763号）-第三章 管理内容与管理流程-第二节 会计核算-第二十六条、二十七条 | AK31: 财务部
E32: 期末结账不规范，导致账务数据不准确。 | F32: 期末结账不规范：账务处理不完整，损益类科目结转方向不规范，结账后随意调账，导致会计信息不准确。 | G32: 20.期末结账规范性管控 | H32: 规范期末结转，确保账证、账账、账实核对一致。 | I32: 会计核算-20.期末结账规范性管控-控制措施01 | J32: 期末结账规范性控制。各单位财务部门明确结账流程、相关岗位职责、账期关闭时间要求等；总账会计检查当期账务处理完整性、规范性，包括银行对账、往来清账、税费计提、资产折旧摊销、过渡科目结转、损益业务结转等，完成结账后关闭账期。 | M32: √ | Q32: √ | T32: 线上管控-已建 | U32: 智慧共享财务平台 | V32: 1.系统期末结账规则 2.期末检查记录 | W32: 各单位-财务部-总账管理 | X32: 每月 | Y32: 全量 | AA32: 每月 | AB32: 全量 | AD32: 期末结账规范性监督场景（已建） | AE32: 每月 | AF32: 全量 | AH32: 是 | AI32: 是 | AJ32: 《国家电网有限公司会计基础管理办法》（国家电网企管〔2019〕132号）-第四章 核算与报告-第六十三条 | AK32: 财务部
E33: 银行账户余额不准确，银企对账不规范，产生资金安全风险。 | F33: 银行账户余额不准确：对账数据获取不及时、不准确，银行余额调节表未经审核签字，未及时发现未达账项或差错，导致资金损失、会计信息不准确。 | G33: 21.银行账户余额准确性管控 | H33: 明确银企对账职责与流程，及时处理未达账项，确保银行账务数据完整准确。 | I33: 会计核算-21.银行账户余额准确性管控-控制措施01 | J33: 银行存款余额准确性控制。各单位财务部门安排出纳以外的人员获取银行对账单，按月编制银行存款余额调节表，并由财务部门负责人复核、签字；存在未达账项的，要及时清理，不得出现2个月以上未达账项，年末不得出现未达账项。 | K33: √ | L33: √ | M33: √ | Q33: √ | T33: 线上管控-已建 | U33: 智慧共享财务平台 | V33: 1.银行回单、对账单 2.银行余额调节表 | W33: 各单位-财务部-资金管理 各单位-财务部-财务负责人 | X33: 每月 | Y33: 全量 | AA33: 每月 | AB33: 全量 | AD33: 银企对账准确性监督场景（已建） | AE33: 每月 | AF33: 全量 | AH33: 是 | AI33: 是 | AJ33: 《国家电网有限公司司库管理办法》（国家电网企管〔2023〕88号）-第三章 银行账户（数字钱包）管理-第四十四条 | AK33: 财务部
E34: 资产盘点未核实、减值依据不充分，导致资产价值不准确、账实不一致 | F34: 资产账实不符。实物资产长期未盘点或盘点流于形式，长库龄、闲置、毁损资产未计提减值，导致资产账实不一致。 | G34: 22.资产账实一致性核查 | H34: 及时核查资产盘点结果，开展资产减值测试，确保账实相符、反映准确。 | I34: 会计核算-22.资产账实一致性核查-控制措施01 | J34: 1.资产物资账实一致性监督。每年末，各单位会计人员向相关部门获取经实物管理部门、财务部门、会计师事务所监盘人员三方签字盖章的固定资产、存货等实物资产盘点结果，核查账实一致性及实物状态，对发现的账实不符或资产减值迹象，履行审批程序后规范进行账务处理。 | M34: √ | Q34: √ | T34: 线下管控 | V34: 实物资产盘点表 | W34: 各单位-财务部-总账管理 | X34: 年度 | Y34: 抽查 | AA34: 年度 | AB34: 抽查 | AH34: 是 | AI34: 是 | AJ34: 1.《国家电网有限公司固定资产管理办法》（国家电网企管〔2023〕28号）-第四章 固定资产变动-第二十六条、第七章 固定资产日常管理-第五十二条 2.《国家电网有限公司2025年度财务决算审计工作指引》-二、 会计信息质量审计-第三条 实物资产 | AK34: 财务部
I35: 会计核算-22.资产账实一致性核查-控制措施02 | J35: 2.资产减值充分性监督。每月末，各单位会计人员在线获取在建工程停工状态、长库龄存货等信息，及时向相关业务部门发送减值风险预警，并建立督办台账、限期完成核实反馈，确保资产价值反映准确。 | M35: √ | Q35: √ | T35: 线下管控 | V35: 资产减值督办台账 | W35: 各单位-财务部-总账管理 | X35: 年度 | Y35: 抽查 | AA35: 年度 | AB35: 抽查 | AH35: 是 | AI35: 是 | AJ35: 1.《国家电网有限公司会计基础管理办法》（国家电网企管〔2019〕132号）-第四章 核算与报告-第五节 财务会计报告 第六十八条 2.《国家电网有限公司2025年度财务决算审计工作指引》-二、 会计信息质量审计-第三条 实物资产 | AK35: 财务部
E36: 期初调整不规范，通过期初调整跨年调节经营指标，导致会计信息不实、经营业绩失真。 | F36: 期初调整不规范：期初调整程序不规范、审核把关不严，滥用会计调整人为调节年度间财务状况、经营成果，导致会计信息不实、掩饰真实经营状况。 | G36: 23.期初调整规范性管控 | H36: 严格履行期初调整程序，规范期初调整行为。 | I36: 会计核算-23.期初调整规范性管控-控制措施01 | J36: 期初调整规范性控制。对重大会计差错更正等期初调整事项，各单位经内部决策审批后，纳入年度财务决算备案报告向公司总部提出调整申请，总部审核批复后方可进行期初账务处理。对重大会计差错更正，各单位应查明原因，识别跨期调节风险，严肃追究相关单位和相关人员责任。 | L36: √ | Q36: √ | T36: 线下管控 | V36: 1.重大会计差错更正等期初调整佐证材料 2.年度财务决算备案情况说明 | W36: 各单位-财务部-总账管理 | X36: 年度 | Y36: 全量 | AA36: 年度 | AB36: 全量 | AH36: 是 | AI36: 是 | AJ36: 1.《国家电网有限公司会计基础管理办法》（国家电网企管〔2019〕132号）-第四章 核算与报告-第一节 一般要求 第六十五条 2.《国家电网有限公司2025年度财务决算审计工作指引》-二、 会计信息质量审计-第十八条 期初调整 | AK36: 财务部
A37: 财务管理 | B37: 会计核算 | C37: 会计信息真实完整、资金资产安全 | D37: 总账会计管理 | E37: 财务报告编报不规范、披露不合规，会计师事务所选聘不规范、评价不到位，导致报表数据不准确、会计信息反映不实、审计意见不合规，引发监管问责及合规风险。 | F37: 财务报告编审不规范：财务报表与账务数据不一致，表内、表间数据不勾稽，报表异常波动未经审核，年度决算报告未经审议，自行选聘决算审计事务所出具审计报告，导致会计信息反映不实、决算审计的独立性与公允性受损。 | G37: 24.财务报告编报及报出 | H37: 严格按照国家财务会计制度及企业会计准则规定，规范编制、审核、披露财务报告，全面、完整、真实、准确反映企业财务状况和经营成果。 | I37: 会计核算-24.财务报告编报及报出-控制措施01 | J37: 1.财务报表编报规范性控制。公司总部在线固化财务报表出具标准流程和相关稽核规则，确保账表一致、表内和表间数据衔接。各单位结合管理实际，自行增补报表稽核规则，对异常波动数据及时分析原因，确保报表反映完整、准确。 | Q37: √ | S37: √ | T37: 线上管控-已建 | U37: 智慧共享财务平台 | V37: 1.报表取数、运算、稽核公式清单 2.异常波动事项原因分析 | W37: 各单位-财务部-报表管理 | X37: 每月 | Y37: 全量 | AA37: 每月 | AB37: 全量 | AD37: 财务报表编报规范性监督场景（已建） | AE37: 每月 | AF37: 全量 | AH37: 是 | AI37: 是 | AJ37: 《国家电网有限公司会计基础管理办法》（国家电网企管〔2019〕132号）-第四章 核算与报告-第六十八条、第六十九条 | AK37: 财务部
I38: 会计核算-24.财务报告编报及报出-控制措施02 | J38: 2.年度财务决算报告披露规范性控制。按照“三重一大”授权清单，各单位财务决算报告规范履行党委会前置研究、董事会决策程序后，报送上级监管部门或对外披露。财务报表须经单位主要负责人、总会计师（分管财务工作负责人）、会计机构负责人（会计主管人员）签章。 | L38: √ | T38: 线下管控 | V38: 1.年度决算报告 2.内部决策文件 | W38: 各单位-财务部-报表管理 | X38: 年度 | Y38: 全量 | AA38: 年度 | AB38: 全量 | AH38: 是 | AI38: 是 | AJ38: 《国家电网有限公司会计基础管理办法》（国家电网企管〔2019〕132号）-第四章 核算与报告-第七十八条 | AK38: 财务部
I39: 会计核算-24.财务报告编报及报出-控制措施03 | J39: 3.决算审计会计师事务所管理控制。公司总部统一选聘各层级单位财务决算审计会计师事务所，各单位严格执行总部选聘结果，并按年对会计师事务所决算审计工作进行评价。 | L39: √ | S39: √ | T39: 线下管控 | V39: 1.会计师事务所财务决算审计合同 2.财务决算审计会计师事务所评价表 | W39: 各单位-财务部-报表管理 | X39: 年度 | Y39: 全量 | AA39: 年度 | AB39: 全量 | AH39: 是 | AI39: 是 | AJ39: 《国家电网有限公司会计基础管理办法》（国家电网企管〔2019〕132号）-第四章 核算与报告-第七十六条 | AK39: 财务部
C40: 会计信息真实完整 | D40: 会计档案管理 | E40: 会计档案归档不准确、不完整，导致档案信息缺失，引发合规风险。 | F40: 会计档案归档不规范：会计档案归档不完整，电子会计资料不满足国家归档要求，导致档案信息不完整、不准确。 | G40: 25.会计档案归档 | H40: 明确会计档案归档范围和管理要求，规范纸质和电子会计档案归档管理，确保档案完整、准确。 | I40: 会计核算-25.会计档案归档-控制措施01 | J40: 会计资料归档规范性控制。各单位会计人员应按照归档范围和要求，定期将会计凭证、会计账簿、财务会计报告、银行对账单等归档资料整理立卷，检查电子会计档案是否符合电子化归档要求，编制会计档案保管清册，确保规范归档。 | M40: √ | S40: √ | T40: 线下管控 | V40: 1.会计档案保管清册 2.会计档案归档记录 | W40: 各单位-财务部-会计档案管理 | X40: 年度 | Y40: 全量 | AA40: 年度 | AB40: 全量 | AH40: 是 | AI40: 是 | AJ40: 《国家电网有限公司会计基础管理办法》（国家电网企管〔2019〕132号）-第六章 会计档案-第二节 会计归档和保管 第九十七条 | AK40: 财务部
...

Sheet 导出列表_列D
A1: 列D | B1: 计数
A2: 股权投资项目储备 | B2: 9 | C2: =VLOOKUP(A2,整体情况!K:N,4,0) -> 9 | D2: =B2-C2 -> 0
A3: 股权划转项目管理 | B3: 6 | C3: =VLOOKUP(A3,整体情况!K:N,4,0) -> 6 | D3: =B3-C3 -> 0
A4: 增资扩股项目管理 | B4: 8 | C4: =VLOOKUP(A4,整体情况!K:N,4,0) -> 8 | D4: =B4-C4 -> 0
A5: 终止清算项目管理 | B5: 6 | C5: =VLOOKUP(A5,整体情况!K:N,4,0) -> 6 | D5: =B5-C5 -> 0
A6: 参股企业运营管理 | B6: 17 | C6: =VLOOKUP(A6,整体情况!K:N,4,0) -> 17 | D6: =B6-C6 -> 0
A7: 资产评估管理 | B7: 11 | C7: =VLOOKUP(A7,整体情况!K:N,4,0) -> 11 | D7: =B7-C7 -> 0
A8: 投资项目决策管理 | B8: 3 | C8: =VLOOKUP(A8,整体情况!K:N,4,0) -> 3 | D8: =B8-C8 -> 0
A9: 股权投资项目计划预算管理 | B9: 3 | C9: =VLOOKUP(A9,整体情况!K:N,4,0) -> 3 | D9: =B9-C9 -> 0
A10: 股权投资项目实施管理 | B10: 11 | C10: =VLOOKUP(A10,整体情况!K:N,4,0) -> 11 | D10: =B10-C10 -> 0
A11: 股权投资项目后评价管理 | B11: 5 | C11: =VLOOKUP(A11,整体情况!K:N,4,0) -> 5 | D11: =B11-C11 -> 0
A12: 股东权利行使与公司治理管理 | B12: 16 | C12: =VLOOKUP(A12,整体情况!K:N,4,0) -> 16 | D12: =B12-C12 -> 0
A13: 股权优化清理管理 | B13: 6 | C13: =VLOOKUP(A13,整体情况!K:N,4,0) -> 6 | D13: =B13-C13 -> 0
... A46: 总账会计管理 | B46: 9 | C46: =VLOOKUP(A46,整体情况!K:N,4,0) -> 9 | D46: =B46-C46 -> 0

Sheet 汇总wfx
A1: 风控矩阵-财务管理
A2: 业 务 条 线 | B2: 业 务 领 域 | C2: 控 制 目 标 | D2: 业务流程步骤 | E2: 经营风险 | F2: 典型问题 | G2: 关键控制点 | H2: 控制要求 | I2: 控制措施 编号 | J2: 控制措施 | K2: 控制措施分类 | T2: 控制方式 | U2: 控制系统 | V2: 控制载体 | W2: 责任主体 | X2: 业务自评价 | AA2: 集团监督评价 | AD2: 数字化监督场景 | AH2: 现有制度及文件落实情况 | AK2: 总部审核部门 | AL2: 关联关系
K3: 不相容岗位 | L3: 分级授权 | M3: 业务真实性校验 | N3: 预算管控 | O3: 合同控制 | P3: 收付控制 | Q3: 会计监督 | R3: 财产保护 | S3: 分析与评价 | X3: 评价频率 | Y3: 评价范围 | Z3: 评价结论 | AA3: 评价频率 | AB3: 评价范围 | AC3: 评价结论 | AD3: 数字化监督场景 | AE3: 监督频率 | AF3: 监督范围 | AG3: 评价结论 | AH3: 是否已要求 | AI3: 是否满足要求 | AJ3: 对应制度及文件名称
C4: 企业经营管理合法合规、资金资产安全、会计信息真实完整 | D4: 会计岗位管理 | E4: 会计不相容权责未分离，审核审批不合规，容易引发财务舞弊，造成资金挪用、资产损失、会计信息失真。 | F4: 不相容岗位权责未分离：会计兼任出纳、业务审批、财产保管等职责，导致资金资产损失长期隐匿未被发现；凭证制单与审核、审批由同一人负责，容易造成会计舞弊。 | G4: 7.会计不相容岗位管控 | H4: 严格会计不相容岗位相分离。 | I4: 会计核算-7.会计不相容岗位管控-控制措施01 | J4: 不相容岗位相分离控制。各单位财务部门严格按照不相容岗位相分离的要求，规范设置会计岗位、匹配会计人员。 | K4: √ | L4: √ | T4: 线下管控 | V4: 1.岗位设置与岗位职责说明 2.系统角色和权限配置表 | W4: 各单位-财务部-财务负责人 | X4: 月度 | Y4: 全量 | AA4: 年度 | AB4: 全量 | AH4: 是 | AI4: 是 | AJ4: 1.《国家电网有限公司会计基础管理办法》（国家电网企管〔2019〕132号）-第三章 会计机构和会计人员-第十六条 2.《会计基础工作规范》（征求意见稿）-第二章 会计机构和会计岗位-第十一条 | AK4: 财务部
E5: 会计岗位交接不规范，影响会计工作组织和会计信息质量。 | F5: 会计岗位交接资料不完整、监交不到位：移交清册等资料不完整，资金、凭证、账簿等财务数据未核对，交接过程未经过监交人监督，交接前后财务信息不衔接、不准确。 | G5: 8.会计岗位交接管控 | H5: 规范会计工作交接，确保会计资料衔接一致。 | I5: 会计核算-8.会计岗位交接管控-控制措施03 | J5: 会计工作交接规范性控制。各单位会计人员办理移交手续前，应完成未了事项，编制移交清册，并与接管人员逐项核对确认。办理交接手续，必须有监交人负责监交；交接完毕后，交接双方和监交人员要在移交清册上签名或者盖章。 | Q5: √ | T5: 线下管控 | V5: 1.会计岗位交接清单 2.移交清册 3.本岗位相关业务流程、信息系统功能、注意事项及未了事项等的书面说明 4.交接归档留存资料 | W5: 各单位-财务部-风险内控与稽核评价管理 | X5: 年度 | Y5: 全量 | AA5: 年度 | AB5: 全量 | AH5: 是 | AI5: 是 | AJ5: 《国家电网有限公司会计基础管理办法》（国家电网企管〔2019〕132号）-第三章 会计机构和会计人员-第三节 会计工作交接 | AK5: 财务部
C6: 资金资产安全 | D6: 人员管理 | E6: 不相容岗位未严格分离、任职回避执行不到位、轮岗休假管控不足，导致资金制衡失效，引发资金挪用风险。 | G6: 42.人员管理 | H6: 严格按照不相容岗位相分离原则，执行回避制度，建立资金岗位定期轮换、交流和强制休假机制，防范资金挪用风险。 | I6: 财务管理-42.人员管理-控制措施01 | J6: 各单位严格遵循不相容岗位分离管控要求，分别配备出纳、资金收支审核和资金收支审批岗位，且不得兼任。出纳、资金收支审核等资金管理关键岗位应使用正式编制员工。 | K6: √ | T6: 线下管控 | V6: 岗位人员清单 | W6: 各单位-财务部-财务负责人 | X6: 每年 | Y6: 全量检查 | AA6: 每年 | AB6: 全量检查 | AH6: 是 | AI6: 是 | AJ6: 《国家电网有限公司司库管理办法》（国网（财/2）345-2023）第十章第二百五十五条 | AK6: 财务部
I7: 财务管理-42.人员管理-控制措施02 | J7: 各单位严格落实财务人员任职回避制度，单位负责人的直系亲属不得担任本单位财务机构负责人和会计主管，财务机构负责人和会计主管的直系亲属不得在本单位会计机构中担任出纳。 | K7: √ | T7: 线下管控 | V7: 岗位人员清单 | W7: 各单位-财务部-财务负责人 | X7: 每年 | Y7: 全量检查 | AA7: 每年 | AB7: 全量检查 | AH7: 是 | AI7: 是 | AJ7: 《国家电网有限公司司库管理办法》（国网（财/2）345-2023）第十章二百五十六条 | AK7: 财务部
I8: 财务管理-42.人员管理-控制措施03 | J8: 各单位要建立资金岗位轮岗、交流和强制休假机制。替岗人员应在替岗期间完成现金、银行账户余额、重要票据核对及未达账项核实工作，并编制核查报告、审核存档。 | K8: √ | Q8: √ | T8: 线下管控 | V8: 1.岗位交接表； 2.稽核报告 | W8: 各单位-财务部-财务负责人 | X8: 每季度 | Y8: 全量检查 | AA8: 每季度 | AB8: 全量检查 | AH8: 是 | AI8: 是 | AJ8: 《国家电网有限公司司库管理办法》（国网（财/2）345-2023）第十章二百五十七、二百五十八条 | AK8: 财务部
